Workbook
Name _Toc225350871: '5.4.1.1-4 Atmos deposition'!$C$1
Name _Toc225350871: '5.5.1.1-2 Leaching and runoff'!$C$1
Name AgResidue_Equations_FieldBurning.VEERG_6_4_1_1__1__MethaneEmissionsFromBurningOfCropResidues: _xlfn.LAMBDA(_xlpm.Mburnc,_xlpm.CCc,_xlpm.EFCH4,_xlpm.C_CH4, _xlpm.Mburnc * _xlpm.CCc * _xlpm.EFCH4 * _xlpm.C_CH4 * 10 ^ (-3))
Name AgResidue_Equations_FieldBurning.VEERG_6_4_1_1__1__MethaneEmissionsFromBurningOfCropResidues_FunctionName: _xlfn.LAMBDA("VEERG_6_4_1_1__1__MethaneEmissionsFromBurningOfCropResidues")
Name AgResidue_Equations_FieldBurning.VEERG_6_4_1_1__1__MethaneEmissionsFromBurningOfCropResidues_LatexEquation: _xlfn.LAMBDA("E_{CH4}=\sum_{c}(M_{burn,c}\times CC_{c}\times EF_{CH4}\times C_{CH4}\times 10^{-3})")
Name AgResidue_Equations_FieldBurning.VEERG_6_4_1_1__1__MethaneEmissionsFromBurningOfCropResidues_NIRReference: _xlfn.LAMBDA("")
Name AgResidue_Equations_FieldBurning.VEERG_6_4_1_1__1__MethaneEmissionsFromBurningOfCropResidues_Source: _xlfn.LAMBDA("VEERG 2026: 6.4.1.1, Equation (1)")
Name AgResidue_Equations_FieldBurning.VEERG_6_4_1_1__1__MethaneEmissionsFromBurningOfCropResidues_Title: _xlfn.LAMBDA("Methane emissions from the burning of crop residues")
Name AgResidue_Equations_FieldBurning.VEERG_6_4_1_1__1__MethaneEmissionsFromBurningOfCropResidues_Unit: _xlfn.LAMBDA("t CH4")
Name AgResidue_Equations_FieldBurning.VEERG_6_4_1_1__1__MethaneEmissionsFromBurningOfCropResidues_Variable: _xlfn.LAMBDA("ECH4")
Name AgResidue_Equations_FieldBurning.VEERG_6_4_1_1__2__NitrousOxideEmissionsFromBurningOfCropResidues: _xlfn.LAMBDA(_xlpm.Mburnc,_xlpm.NCAGc,_xlpm.EFN2O,_xlpm.CN2O, _xlpm.Mburnc * _xlpm.NCAGc * _xlpm.EFN2O * _xlpm.CN2O * 10 ^ (-3))
Name AgResidue_Equations_FieldBurning.VEERG_6_4_1_1__2__NitrousOxideEmissionsFromBurningOfCropResidues_FunctionName: _xlfn.LAMBDA("VEERG_6_4_1_1__2__NitrousOxideEmissionsFromBurningOfCropResidues")
Name AgResidue_Equations_FieldBurning.VEERG_6_4_1_1__2__NitrousOxideEmissionsFromBurningOfCropResidues_LatexEquation: _xlfn.LAMBDA("E_{N2O}=\sum_{c}(M_{burn,c}\times NC_{AGc}\times EF_{N2O}\times C_{N2O}\times 10^{-3})")
Name AgResidue_Equations_FieldBurning.VEERG_6_4_1_1__2__NitrousOxideEmissionsFromBurningOfCropResidues_NIRReference: _xlfn.LAMBDA("")
Name AgResidue_Equations_FieldBurning.VEERG_6_4_1_1__2__NitrousOxideEmissionsFromBurningOfCropResidues_Source: _xlfn.LAMBDA("VEERG 2026: 6.4.1.1, Equation (2)")
Name AgResidue_Equations_FieldBurning.VEERG_6_4_1_1__2__NitrousOxideEmissionsFromBurningOfCropResidues_Title: _xlfn.LAMBDA("Nitrous oxide emissions from the burning of crop residues")
Name AgResidue_Equations_FieldBurning.VEERG_6_4_1_1__2__NitrousOxideEmissionsFromBurningOfCropResidues_Unit: _xlfn.LAMBDA("t N2O")
Name AgResidue_Equations_FieldBurning.VEERG_6_4_1_1__2__NitrousOxideEmissionsFromBurningOfCropResidues_Variable: _xlfn.LAMBDA("EN2O")
Name AgResidue_Equations_FieldBurning.VEERG_6_4_1_1__3__MassOfCropResidueBurnt: _xlfn.LAMBDA(_xlpm.Pc,_xlpm.RAGc,_xlpm.Sc,_xlpm.DMc,_xlpm.Zc,_xlpm.Fc, _xlpm.Pc * _xlpm.RAGc * _xlpm.Sc * _xlpm.DMc * _xlpm.Zc * _xlpm.Fc)
Name AgResidue_Equations_FieldBurning.VEERG_6_4_1_1__3__MassOfCropResidueBurnt_FunctionName: _xlfn.LAMBDA("VEERG_6_4_1_1__3__MassOfCropResidueBurnt")
Name AgResidue_Equations_FieldBurning.VEERG_6_4_1_1__3__MassOfCropResidueBurnt_LatexEquation: _xlfn.LAMBDA("M_{burn,c}=P_{c}\times R_{AGc}\times S_{c}\times DM_{c}\times Z_{c}\times F_{c}")
Name AgResidue_Equations_FieldBurning.VEERG_6_4_1_1__3__MassOfCropResidueBurnt_NIRReference: _xlfn.LAMBDA("")
Name AgResidue_Equations_FieldBurning.VEERG_6_4_1_1__3__MassOfCropResidueBurnt_Source: _xlfn.LAMBDA("VEERG 2026: 6.4.1.1, Equation (3)")
Name AgResidue_Equations_FieldBurning.VEERG_6_4_1_1__3__MassOfCropResidueBurnt_Title: _xlfn.LAMBDA("Mass of residue of crop c burnt")
Name AgResidue_Equations_FieldBurning.VEERG_6_4_1_1__3__MassOfCropResidueBurnt_Unit: _xlfn.LAMBDA("kg")
Name AgResidue_Equations_FieldBurning.VEERG_6_4_1_1__3__MassOfCropResidueBurnt_Variable: _xlfn.LAMBDA("Mburnc")
Name AgResidues_Equations_CropResidues.VEERG_6_1_1_1__1__NitrousOxideEmissionsFromCropResidues: _xlfn.LAMBDA(_xlpm.Mc,_xlpm.EFNi,_xlpm.CgN2O, _xlpm.Mc * _xlpm.EFNi * _xlpm.CgN2O * 10 ^ (-3))
Name AgResidues_Equations_CropResidues.VEERG_6_1_1_1__1__NitrousOxideEmissionsFromCropResidues_FunctionName: _xlfn.LAMBDA("VEERG_6_1_1_1__1__NitrousOxideEmissionsFromCropResidues")
Name AgResidues_Equations_CropResidues.VEERG_6_1_1_1__1__NitrousOxideEmissionsFromCropResidues_LatexEquation: _xlfn.LAMBDA("E=\sum_{c}{M_{c}\times EF_{N}\times C_{g,N2O}\times 10^{-3}}")
Name AgResidues_Equations_CropResidues.VEERG_6_1_1_1__1__NitrousOxideEmissionsFromCropResidues_NIRReference: _xlfn.LAMBDA("")
Name AgResidues_Equations_CropResidues.VEERG_6_1_1_1__1__NitrousOxideEmissionsFromCropResidues_Source: _xlfn.LAMBDA("VEERG 2026: 6.1.1.1, Equation (1)")
Name AgResidues_Equations_CropResidues.VEERG_6_1_1_1__1__NitrousOxideEmissionsFromCropResidues_Title: _xlfn.LAMBDA("Nitrous oxide emissions from the return of crop residues across all crops c to the soil")
Name AgResidues_Equations_CropResidues.VEERG_6_1_1_1__1__NitrousOxideEmissionsFromCropResidues_Unit: _xlfn.LAMBDA("t N2O")
Name AgResidues_Equations_CropResidues.VEERG_6_1_1_1__1__NitrousOxideEmissionsFromCropResidues_Variable: _xlfn.LAMBDA("E")
Name AgResidues_Equations_CropResidues.VEERG_6_1_1_1__2__MassOfNitrogenInCropResidues_LatexEquation: _xlfn.LAMBDA("M_{c}=(P_{c}\times R_{AGc}\times(1-F_{c}-FFOD_{c})\times DM_{c}\times NC_{AGc})+(P_{c}\times R_{AGc}\times R_{BGc}\times DM_{c}\times NC_{BGc})")
Name AgResidues_Equations_CropResidues.VEERG_6_1_1_1__2__MassOfNitrogenInCropResidues_NIRReference: _xlfn.LAMBDA("")
Name AgResidues_Equations_CropResidues.VEERG_6_1_1_1__2__MassOfNitrogenInCropResidues_Source: _xlfn.LAMBDA("VEERG 2026: 6.1.1.1, Equation (2)")
Name AgResidues_Equations_CropResidues.VEERG_6_1_1_1__2__MassOfNitrogenInCropResidues_Title: _xlfn.LAMBDA("Mass of nitrogen in crop residues returned to the soil")
Name AgResidues_Equations_CropResidues.VEERG_6_1_1_1__2__MassOfNitrogenInCropResidues_Unit: _xlfn.LAMBDA("kg N")
Name AgResidues_Equations_CropResidues.VEERG_6_1_1_1__2__MassOfNitrogenInCropResidues_Variable: _xlfn.LAMBDA("Mc")
Name AgResidues_Equations_CropResidues.VEERG_6_1_1_2__1__FractionOfCropResidueRemovedBaled: _xlfn.LAMBDA(_xlpm.B,_xlpm.MB,_xlpm.Pc,_xlpm.RAGc, IFERROR((_xlpm.B * _xlpm.MB) / (_xlpm.Pc * _xlpm.RAGc), 0))
Name AgResidues_Equations_CropResidues.VEERG_6_1_1_2__1__FractionOfCropResidueRemovedBaled_LatexEquation: _xlfn.LAMBDA("FFOD_{c,baled}=\frac{B\times M_{B}}{P_{c}\times R_{AG,c}}")
Name AgResidues_Equations_CropResidues.VEERG_6_1_1_2__1__FractionOfCropResidueRemovedBaled_NIRReference: _xlfn.LAMBDA("")
Name AgResidues_Equations_CropResidues.VEERG_6_1_1_2__1__FractionOfCropResidueRemovedBaled_Source: _xlfn.LAMBDA("VEERG 2026: 6.1.1.2, Equation (1)")
Name AgResidues_Equations_CropResidues.VEERG_6_1_1_2__1__FractionOfCropResidueRemovedBaled_Title: _xlfn.LAMBDA("Fraction of crop residue that is removed for crop c, calculated where residues are baled")
Name AgResidues_Equations_CropResidues.VEERG_6_1_1_2__1__FractionOfCropResidueRemovedBaled_Unit: _xlfn.LAMBDA("dimensionless")
Name AgResidues_Equations_CropResidues.VEERG_6_1_1_2__1__FractionOfCropResidueRemovedBaled_Variable: _xlfn.LAMBDA("FFODcbaled")
Name AgResidues_Equations_CropResidues.VEERG_6_1_1_2__1__FractionOfCropResidueRemovedBaled_Variation: _xlfn.LAMBDA("VARIATION FROM SOURCE: Added 'baled' to variable subscript")
Name AgResidues_Equations_CropResidues.VEERG_6_1_1_2__1a__FractionOfCropResidueRemoved: _xlfn.LAMBDA(_xlpm.FFODcbaled,_xlpm.FFODcother, _xlpm.FFODcbaled + _xlpm.FFODcother)
Name AgResidues_Equations_CropResidues.VEERG_6_1_1_2__1a__FractionOfCropResidueRemoved_LatexEquation: _xlfn.LAMBDA("FFOD_{c} = FFOD_{c,baled} + FFOD_{c,other}")
Name AgResidues_Equations_CropResidues.VEERG_6_1_1_2__1a__FractionOfCropResidueRemoved_NIRReference: _xlfn.LAMBDA("")
Name AgResidues_Equations_CropResidues.VEERG_6_1_1_2__1a__FractionOfCropResidueRemoved_Source: _xlfn.LAMBDA("")
Name AgResidues_Equations_CropResidues.VEERG_6_1_1_2__1a__FractionOfCropResidueRemoved_Title: _xlfn.LAMBDA("Fraction of crop residue that is removed for crop c")
Name AgResidues_Equations_CropResidues.VEERG_6_1_1_2__1a__FractionOfCropResidueRemoved_Unit: _xlfn.LAMBDA("dimensionless")
Name AgResidues_Equations_CropResidues.VEERG_6_1_1_2__1a__FractionOfCropResidueRemoved_Variable: _xlfn.LAMBDA("FFODc")
Name AgResidues_Equations_CropResidues.VEERG_6_1_1_2__1a__FractionOfCropResidueRemoved_Variation: _xlfn.LAMBDA("VARIATION FROM SOURCE: Added this equation to accommodate user-defined residue removal other than baling.")
Name AgResidues_Equations_Leaching.VEERG_6_3_1_1__1__LeachingAndRunoffEmissionsCropAndPastureResidue: _xlfn.LAMBDA(_xlpm.Mleachcp,_xlpm.EFleach,_xlpm.CgN2O, _xlpm.Mleachcp * _xlpm.EFleach * _xlpm.CgN2O * 10 ^ (-3))
Name AgResidues_Equations_Leaching.VEERG_6_3_1_1__1__LeachingAndRunoffEmissionsCropAndPastureResidue_LatexEquation: _xlfn.LAMBDA("E_{N2O}=\sum_{c}\sum_{p}(M_{leach,cp}\times EF_{leach}\times Cg_{N2O}\times 10^{-3})")
Name AgResidues_Equations_Leaching.VEERG_6_3_1_1__1__LeachingAndRunoffEmissionsCropAndPastureResidue_NIRReference: _xlfn.LAMBDA("")
Name AgResidues_Equations_Leaching.VEERG_6_3_1_1__1__LeachingAndRunoffEmissionsCropAndPastureResidue_Source: _xlfn.LAMBDA("VEERG 2026: 6.3.1.1, Equation (1)")

Sheet Home
A1: #VALUE!
A3: =HYPERLINK("#'Home'!A1", "Home") -> Home
A4: =HYPERLINK("#'Results - Activity period'!A1", "Results - Activity period") -> Results - Activity period
A5: =HYPERLINK("#'Results - Product EI'!A1", "Results - Product Emissions Intensity") -> Results - Product Emissions Intensity
A8: INPUTS
A9: =HYPERLINK("#'Input - Enterprise'!A1", "Enterprise") -> Enterprise
A10: =HYPERLINK("#'Input - Site'!A1", "Site") -> Site
A11: =HYPERLINK("#'Input - Feedlot'!A1", "Feedlot") -> Feedlot
A12: =HYPERLINK("#'Input - Livestock sales'!A1", "Livestock sales") -> Livestock sales
A13: =HYPERLINK("#'Input - Beef cattle purchases'!A1", "Beef cattle purchases") -> Beef cattle purchases
A14: =HYPERLINK("#'Input - Fuel'!A1", "Fuel") -> Fuel
A15: =HYPERLINK("#'Input - Electricity'!A1", "Electricity") -> Electricity
A16: =HYPERLINK("#'Input - Common farm inputs'!A1", "Common farm inputs") -> Common farm inputs
A17: =HYPERLINK("#'Input - Livestock farm Inputs'!A1", "Livestock farm Inputs") -> Livestock farm Inputs
A18: =HYPERLINK("#'Input - Freight'!A1", "Freight") -> Freight
A19: =HYPERLINK("#'Input - Solid waste'!A1", "Solid waste") -> Solid waste
A20: =HYPERLINK("#'Input - Manure sent off-site'!A1", "Manure sent off-site") -> Manure sent off-site
A21: =HYPERLINK("#'Input - Data quality'!A1", "Data quality") -> Data quality
A22: =HYPERLINK("#'Input - Fert Prod System'!A1", "Fert Prod System") -> Fert Prod System
A23: =HYPERLINK("#'Input - Fertiliser'!A1", "Fertiliser") -> Fertiliser
A26: CALCULATIONS
A27: =HYPERLINK("#'3.1.1.1-2 Enteric Methane'!A1", "3.1.1.1-2 Enteric Methane") -> 3.1.1.1-2 Enteric Methane
A28: =HYPERLINK("#'4.1.1.1-2 Methane'!A1", "4.1.1.1-2 Manure Methane") -> 4.1.1.1-2 Manure Methane
A29: =HYPERLINK("#'4.1.1.3-4 Direct N20'!A1", "4.1.1.3-4 Manure Direct N2O") -> 4.1.1.3-4 Manure Direct N2O
A30: =HYPERLINK("#'4.1.1.5-6 Atmos Deposition'!A1", "4.1.1.5-6 Manure Atmos Dep") -> 4.1.1.5-6 Manure Atmos Dep
A31: =HYPERLINK("#'4.1.1.9 Manure applied to soils'!A1", "4.1.1.9 Manure applied to soils") -> 4.1.1.9 Manure applied to soils
A32: =HYPERLINK("#'8.1.1.1-2 Transport fuel'!A1", "8.1.1.1-2 Transport fuel") -> 8.1.1.1-2 Transport fuel
A33: =HYPERLINK("#'8.2.1.1-2 Stationary fuel'!A1", "8.2.1.1-2 Stationary fuel") -> 8.2.1.1-2 Stationary fuel
A34: =HYPERLINK("#'10.1.1-2 Solid waste treatment'!A1", "10.1.1.1-2 Solid waste") -> 10.1.1.1-2 Solid waste
A35: =HYPERLINK("#'14.1.1-2 Purchased electricity'!A1", "14.1.1-2 Purchased electricity") -> 14.1.1-2 Purchased electricity
A36: =HYPERLINK("#'15 Scope 3'!A1", "15 Scope 3") -> 15 Scope 3
A37: =HYPERLINK("#'Calcs - Manure sent off-site'!A1", "Calcs - Manure sent off-site") -> Calcs - Manure sent off-site
A38: =HYPERLINK("#'5.1.1.1-2 Inorganic fert N2O'!A1", "5.1.1.1-2 Inorganic fert N2O") -> 5.1.1.1-2 Inorganic fert N2O
A39: =HYPERLINK("#'5.1.1.3-4 Inorganic fert CO2'!A1", "5.1.1.3-4 Inorganic fert CO2") -> 5.1.1.3-4 Inorganic fert CO2
A40: =HYPERLINK("#'5.2.1.1-2 Organic Fert N2O'!A1", "5.2.1.1-2 Organic Fert N2O") -> 5.2.1.1-2 Organic Fert N2O
A41: =HYPERLINK("#'5.3.1.1-2 Lime CO2'!A1", "5.3.1.1-2 Lime CO2") -> 5.3.1.1-2 Lime CO2
A42: =HYPERLINK("#'5.4.1.1-4 Atmos deposition'!A1", "5.4.1.1-4 Atmos deposition") -> 5.4.1.1-4 Atmos deposition
A43: =HYPERLINK("#'5.5.1.1-2 Leaching and runoff'!A1", "5.5.1.1-2 Leaching and runoff") -> 5.5.1.1-2 Leaching and runoff
A46: APPENDICES
A47: =HYPERLINK("#'Constants - Feedlot'!A1", "Constants - Feedlot") -> Constants - Feedlot
...

Sheet Results - Activity period
A1: #VALUE! | C1: Results - Activity period
A3: =HYPERLINK("#'Home'!A1", "Home") -> Home
A4: =HYPERLINK("#'Results - Activity period'!A1", "Results - Activity period") -> Results - Activity period | D4: ="Emissions breakdown for activities running between " & TEXT(X_Cell_Site_StartDate, "dd mmmm yyyy") & " and " & TEXT('Input - Enterprise'!E13, "dd mmmm yyyy") -> Emissions breakdown for activities running between 01 January 2025 and 31 December 2025
A5: =HYPERLINK("#'Results - Product EI'!A1", "Results - Product Emissions Intensity") -> Results - Product Emissions Intensity
D6: Scope 1
A8: INPUTS | D8: Scope 1 source | E8: GHG emissions method 1 | F8: GHG emissions method 2 | G8: GHG Unit | H8: CO2-e emissions method 1 | I8: CO2-e emissions method 2
A9: =HYPERLINK("#'Input - Enterprise'!A1", "Enterprise") -> Enterprise | D9: 3.1.1.1-2 Enteric Methane | E9: {=VEERG_3_1_1_1__1_TotalAnnualMethaneFromEntericFermentation_Result_Method1} -> 37.95238 | F9: {=VEERG_3_1_1_1__1_TotalAnnualMethaneFromEntericFermentation_Result_Method2} -> 37.95238 | G9: t CH4 | H9: {=Common_Equations.Common_ConvertCH4ToCO2e(E9,_xlfn.XLOOKUP("CH4", Table_GWPData[Gas],Table_GWPData[CO2-e factor]))} -> 1062.6666 | I9: {=Common_Equations.Common_ConvertCH4ToCO2e(F9,_xlfn.XLOOKUP("CH4", Table_GWPData[Gas],Table_GWPData[CO2-e factor]))} -> 1062.6666 | J9: t CO2e
A10: =HYPERLINK("#'Input - Site'!A1", "Site") -> Site | D10: 4.1.1.1-2 Manure Methane | E10: {=VEERG_4_1_1_1__1_TotalAnnualMethaneEmissions_Result_Method1} -> 2.6279078 | F10: {=VEERG_4_1_1_1__1_TotalAnnualMethaneEmissions_Result_Method2} -> 2.6279078 | G10: t CH4 | H10: {=Common_Equations.Common_ConvertCH4ToCO2e(E10,_xlfn.XLOOKUP("CH4", Table_GWPData[Gas],Table_GWPData[CO2-e factor]))} -> 73.581417 | I10: {=Common_Equations.Common_ConvertCH4ToCO2e(F10,_xlfn.XLOOKUP("CH4", Table_GWPData[Gas],Table_GWPData[CO2-e factor]))} -> 73.581417 | J10: t CO2e
A11: =HYPERLINK("#'Input - Feedlot'!A1", "Feedlot") -> Feedlot | D11: 4.1.1.3-4 Manure Direct N20 | E11: {=VEERG_4_1_1_3__1_TotalAnnualDirectNitrousOxideEmissions_Result_Method1} -> 0.80616789 | F11: {=VEERG_4_1_1_3__1_TotalAnnualDirectNitrousOxideEmissions_Result_Method2} -> 0.80616789 | G11: t N2O | H11: {=Common_Equations.Common_ConvertN2OToCO2e(E11,_xlfn.XLOOKUP("N2O", Table_GWPData[Gas],Table_GWPData[CO2-e factor]))} -> 213.63449 | I11: {=Common_Equations.Common_ConvertN2OToCO2e(F11,_xlfn.XLOOKUP("N2O", Table_GWPData[Gas],Table_GWPData[CO2-e factor]))} -> 213.63449 | J11: t CO2e
A12: =HYPERLINK("#'Input - Livestock sales'!A1", "Livestock sales") -> Livestock sales | D12: 4.1.1.5-6 Manure Atmospheric Deposition | E12: {=VEERG_4_1_1_5__1_TotalAnnualAtmosphericDepositionEmissions_Result_Method1} -> 0.14584825 | F12: {=VEERG_4_1_1_5__1_TotalAnnualAtmosphericDepositionEmissions_Result_Method1} -> 0.14584825 | G12: t N2O | H12: {=Common_Equations.Common_ConvertN2OToCO2e(E12,_xlfn.XLOOKUP("N2O", Table_GWPData[Gas],Table_GWPData[CO2-e factor]))} -> 38.649786 | I12: {=Common_Equations.Common_ConvertN2OToCO2e(F12,_xlfn.XLOOKUP("N2O", Table_GWPData[Gas],Table_GWPData[CO2-e factor]))} -> 38.649786 | J12: t CO2e
A13: =HYPERLINK("#'Input - Beef cattle purchases'!A1", "Beef cattle purchases") -> Beef cattle purchases | D13: 8.1.1.1-2 Transport fuel CO2 | E13: {=VEERG_8_1_1_1__1_FuelCombustionTransport_Result_CO2} -> 83.182 | F13: =E13 -> 83.182 | G13: t CO2 | H13: =E13 -> 83.182 | I13: =F13 -> 83.182 | J13: t CO2e
A14: =HYPERLINK("#'Input - Fuel'!A1", "Fuel") -> Fuel | D14: 8.1.1.1-2 Transport fuel CH4 | E14: {=VEERG_8_1_1_1__1_FuelCombustionTransport_Result_CH4} -> 0.19906 | F14: =E14 -> 0.19906 | G14: t CH4 | H14: {=Common_Equations.Common_ConvertCH4ToCO2e(E14,_xlfn.XLOOKUP("CH4", Table_GWPData[Gas],Table_GWPData[CO2-e factor]))} -> 5.57368 | I14: {=Common_Equations.Common_ConvertCH4ToCO2e(F14,_xlfn.XLOOKUP("CH4", Table_GWPData[Gas],Table_GWPData[CO2-e factor]))} -> 5.57368 | J14: t CO2e
A15: =HYPERLINK("#'Input - Electricity'!A1", "Electricity") -> Electricity | D15: 8.1.1.1-2 Transport fuel N2O | E15: {=VEERG_8_1_1_1__1_FuelCombustionTransport_Result_N2O} -> 0.5845 | F15: =E15 -> 0.5845 | G15: t N2O | H15: {=Common_Equations.Common_ConvertN2OToCO2e(E15,_xlfn.XLOOKUP("N2O", Table_GWPData[Gas],Table_GWPData[CO2-e factor]))} -> 154.8925 | I15: {=Common_Equations.Common_ConvertN2OToCO2e(F15,_xlfn.XLOOKUP("N2O", Table_GWPData[Gas],Table_GWPData[CO2-e factor]))} -> 154.8925 | J15: t CO2e
A16: =HYPERLINK("#'Input - Common farm inputs'!A1", "Common farm inputs") -> Common farm inputs | D16: 8.2.1.1-2 Stationary fuel CO2 | E16: {=VEERG_8_2_1_1__1_FuelCombustionStationary_Result_CO2} -> 29.0708 | F16: =E16 -> 29.0708 | G16: t CO2 | H16: =E16 -> 29.0708 | I16: =F16 -> 29.0708 | J16: t CO2e
A17: =HYPERLINK("#'Input - Livestock farm Inputs'!A1", "Livestock farm Inputs") -> Livestock farm Inputs | D17: 8.2.1.1-2 Stationary fuel CH4 | E17: {=VEERG_8_2_1_1__1_FuelCombustionStationary_Result_CH4} -> 0.0724 | F17: =E17 -> 0.0724 | G17: t CH4 | H17: {=Common_Equations.Common_ConvertCH4ToCO2e(E17,_xlfn.XLOOKUP("CH4", Table_GWPData[Gas],Table_GWPData[CO2-e factor]))} -> 2.0272 | I17: {=Common_Equations.Common_ConvertCH4ToCO2e(F17,_xlfn.XLOOKUP("CH4", Table_GWPData[Gas],Table_GWPData[CO2-e factor]))} -> 2.0272 | J17: t CO2e
A18: =HYPERLINK("#'Input - Freight'!A1", "Freight") -> Freight | D18: 8.2.1.1-2 Stationary fuel N2O | E18: {=VEERG_8_2_1_1__1_FuelCombustionStationary_Result_N2O} -> 0.0714 | F18: =E18 -> 0.0714 | G18: t N2O | H18: {=Common_Equations.Common_ConvertN2OToCO2e(E18,_xlfn.XLOOKUP("N2O", Table_GWPData[Gas],Table_GWPData[CO2-e factor]))} -> 18.921 | I18: {=Common_Equations.Common_ConvertN2OToCO2e(F18,_xlfn.XLOOKUP("N2O", Table_GWPData[Gas],Table_GWPData[CO2-e factor]))} -> 18.921 | J18: t CO2e
A19: =HYPERLINK("#'Input - Solid waste'!A1", "Solid waste") -> Solid waste | D19: 10.1.1-2 Solid waste treatment | E19: {=VEERG_10_1_1_1__1_EmissionsFromWasteManagement_Scope1_Result_Method1} -> 438.82805 | F19: =E19 -> 438.82805 | G19: t CO2-e | H19: =E19 -> 438.82805 | I19: =F19 -> 438.82805 | J19: t CO2e
A20: =HYPERLINK("#'Input - Manure sent off-site'!A1", "Manure sent off-site") -> Manure sent off-site | D20: Total | H20: =SUM(H9:H19) -> 2121.0276 | I20: =SUM(I9:I19) -> 2121.0276 | J20: t CO2e
A21: =HYPERLINK("#'Input - Data quality'!A1", "Data quality") -> Data quality
A22: =HYPERLINK("#'Input - Fert Prod System'!A1", "Fert Prod System") -> Fert Prod System
A23: =HYPERLINK("#'Input - Fertiliser'!A1", "Fertiliser") -> Fertiliser | D23: Scope 2
D25: Scope 2 source | E25: GHG emissions method 1 | F25: GHG emissions method 2 | G25: GHG Unit | H25: CO2-e emissions method 1 | I25: CO2-e emissions method 2
A26: CALCULATIONS | D26: {="14.1.1-2 Purchased electricity " & IF(X_Cell_Electricity_CalculationMethod="Location-based (simpler)", "(Location-based)", "(Market-based)")} -> 14.1.1-2 Purchased electricity (Location-based) | E26: {=IF(X_Cell_Electricity_CalculationMethod="Location-based (simpler)", VEERG_14_1_1__1_LocationBasedScopeElectricityEmissions_Result_Method1, VEERG_14_1_2__1_MarketBasedScopeElectricityEmissionsVariation_Result_Method1)} -> 16.8 | F26: =E26 -> 16.8 | G26: t CO2e | H26: =E26 -> 16.8 | I26: =F26 -> 16.8 | J26: t CO2e
A27: =HYPERLINK("#'3.1.1.1-2 Enteric Methane'!A1", "3.1.1.1-2 Enteric Methane") -> 3.1.1.1-2 Enteric Methane | D27: Total scope 2 | H27: =SUM(H26:H26) -> 16.8 | I27: =SUM(I26:I26) -> 16.8 | J27: t CO2e
A28: =HYPERLINK("#'4.1.1.1-2 Methane'!A1", "4.1.1.1-2 Manure Methane") -> 4.1.1.1-2 Manure Methane
A29: =HYPERLINK("#'4.1.1.3-4 Direct N20'!A1", "4.1.1.3-4 Manure Direct N2O") -> 4.1.1.3-4 Manure Direct N2O
A30: =HYPERLINK("#'4.1.1.5-6 Atmos Deposition'!A1", "4.1.1.5-6 Manure Atmos Dep") -> 4.1.1.5-6 Manure Atmos Dep | D30: Scope 3
A31: =HYPERLINK("#'4.1.1.9 Manure applied to soils'!A1", "4.1.1.9 Manure applied to soils") -> 4.1.1.9 Manure applied to soils
A32: =HYPERLINK("#'8.1.1.1-2 Transport fuel'!A1", "8.1.1.1-2 Transport fuel") -> 8.1.1.1-2 Transport fuel | D32: Scope 3 source | E32: GHG emissions method 1 | F32: GHG emissions method 2 | G32: GHG Unit | H32: CO2-e emissions method 1 | I32: CO2-e emissions method 2
A33: =HYPERLINK("#'8.2.1.1-2 Stationary fuel'!A1", "8.2.1.1-2 Stationary fuel") -> 8.2.1.1-2 Stationary fuel | D33: 15.1.1.1 Total emissions from purchased livestock - Cattle | E33: {=VEERG_15_1_1_1__1_EmissionsFromPurchasedLivestock_Pigs_Result_Method1} -> 0 | F33: {=VEERG_15_1_1_1__1_EmissionsFromPurchasedLivestock_Pigs_Result_Method2} -> 0 | G33: t CO2e | H33: =E33 -> 0 | I33: =F33 -> 0 | J33: t CO2e
A34: =HYPERLINK("#'10.1.1-2 Solid waste treatment'!A1", "10.1.1.1-2 Solid waste") -> 10.1.1.1-2 Solid waste | D34: 15.2.1.1 Emissions from purchased feed | E34: {=VEERG_15_2_1_1__1_EmissionsFromPurchasedFeed_Result_Method1} -> 0.785052 | F34: {=VEERG_15_2_1_1__1_EmissionsFromPurchasedFeed_Result_Method1} -> 0.785052 | G34: t CO2e | H34: =E34 -> 0.785052 | I34: =F34 -> 0.785052 | J34: t CO2e
A35: =HYPERLINK("#'14.1.1-2 Purchased electricity'!A1", "14.1.1-2 Purchased electricity") -> 14.1.1-2 Purchased electricity | D35: 15.7.1.1 Services and contractor operations | E35: {=VEERG_15_7_1_1__1_EmissionsFromPurchasedServices_Result_Method1} -> No data | F35: {=VEERG_15_7_1_1__1_EmissionsFromPurchasedServices_Result_Method2} -> 42 | G35: t CO2e | H35: =E35 -> No data | I35: =F35 -> 42 | J35: t CO2e
A36: =HYPERLINK("#'15 Scope 3'!A1", "15 Scope 3") -> 15 Scope 3 | D36: 15.10.1.1 Other: Cleaning chemicals | E36: {=VEERG_15_10_1_1__1_OtherPurchasedGoodsAndServices_CleaningChemicals_Result_Method1} -> 0.5051 | F36: {=VEERG_15_10_1_1__1_OtherPurchasedGoodsAndServices_CleaningChemicals_Result_Method2} -> 2.73 | G36: t CO2e | H36: =E36 -> 0.5051 | I36: =F36 -> 2.73 | J36: t CO2e
A37: =HYPERLINK("#'Calcs - Manure sent off-site'!A1", "Calcs - Manure sent off-site") -> Calcs - Manure sent off-site | D37: 15.10.1.1 Other: Pharmacy chemicals | E37: {=VEERG_15_10_1_1__1_OtherPurchasedGoodsAndServices_PharmacyChemicals_Result_Method1} -> 0.015636 | F37: {=VEERG_15_10_1_1__1_OtherPurchasedGoodsAndServices_PharmacyChemicals_Result_Method1} -> 0.015636 | G37: t CO2e | H37: =E37 -> 0.015636 | I37: =F37 -> 0.015636 | J37: t CO2e
A38: =HYPERLINK("#'5.1.1.1-2 Inorganic fert N2O'!A1", "5.1.1.1-2 Inorganic fert N2O") -> 5.1.1.1-2 Inorganic fert N2O | D38: 15.10.1.1 Other: Uncategorised | E38: {=VEERG_15_10_1_1__1_OtherPurchasedGoodsAndServices_Uncategorised_Result_Method1} -> No data | F38: {=VEERG_15_10_1_1__1_OtherPurchasedGoodsAndServices_Uncategorised_Result_Method2} -> 4000 | G38: t CO2e | H38: =E38 -> No data | I38: =F38 -> 4000 | J38: t CO2e
A39: =HYPERLINK("#'5.1.1.3-4 Inorganic fert CO2'!A1", "5.1.1.3-4 Inorganic fert CO2") -> 5.1.1.3-4 Inorganic fert CO2 | D39: 15.11.1.1 Fuel | E39: {=VEERG_15_11_1_1__1_TotalUpstreamEmissionsFromFuel_Result} -> 26.794 | F39: =E39 -> 26.794 | G39: t CO2e | H39: =E39 -> 26.794 | I39: =F39 -> 26.794 | J39: t CO2e
A40: =HYPERLINK("#'5.2.1.1-2 Organic Fert N2O'!A1", "5.2.1.1-2 Organic Fert N2O") -> 5.2.1.1-2 Organic Fert N2O | D40: {="15.12.1.1 Purchased electricity " & IF(X_Cell_Electricity_CalculationMethod="Location-based (simpler)", "(Location-based)", "(Market-based)")} -> 15.12.1.1 Purchased electricity (Location-based) | E40: {=IF(X_Cell_Electricity_CalculationMethod="Location-based (simpler)", VEERG_15_12_1_1__1_UpstreamPurchasedElectricityLocationBased_Result, VEERG_15_12_1_1__1_UpstreamPurchasedElectricityMarketBased_Result)} -> 2.7 | F40: =E40 -> 2.7 | G40: t CO2e | H40: =E40 -> 2.7 | I40: =F40 -> 2.7 | J40: t CO2e
A41: =HYPERLINK("#'5.3.1.1-2 Lime CO2'!A1", "5.3.1.1-2 Lime CO2") -> 5.3.1.1-2 Lime CO2 | D41: 15.13.1.1 Waste sent to treatment facility | E41: {=VEERG_10_1_1_1__1_EmissionsFromWasteManagement_Scope3_Result_Method1} -> 441.15 | F41: =E41 -> 441.15 | G41: t CO2e | H41: =E41 -> 441.15 | I41: =F41 -> 441.15 | J41: t CO2e
A42: =HYPERLINK("#'5.4.1.1-4 Atmos deposition'!A1", "5.4.1.1-4 Atmos deposition") -> 5.4.1.1-4 Atmos deposition | D42: 15.14.1.1 Incoming freight | E42: {=VEERG_15_14_1_1__1_EmbeddedEmissionsFromUpstreamFreight_Incoming_Result_Method1} -> No data | F42: {=VEERG_15_14_1_1__1_EmbeddedEmissionsFromUpstreamFreight_Incoming_Result_Method2} -> 5146700 | G42: t CO2e | H42: =E42 -> No data | I42: =F42 -> 5146700 | J42: t CO2e
A43: =HYPERLINK("#'5.5.1.1-2 Leaching and runoff'!A1", "5.5.1.1-2 Leaching and runoff") -> 5.5.1.1-2 Leaching and runoff | D43: 15.14.1.1 Outgoing freight | E43: {=VEERG_15_14_1_1__1_EmbeddedEmissionsFromUpstreamFreight_Outgoing_Result_Method1} -> No data | F43: {=VEERG_15_14_1_1__1_EmbeddedEmissionsFromUpstreamFreight_Outgoing_Result_Method2} -> 432640 | G43: t CO2e | H43: =E43 -> No data | I43: =F43 -> 432640 | J43: t CO2e
...

Sheet Results - Product EI
A1: #VALUE! | C1: Results - Product emissions intensity
A3: =HYPERLINK("#'Home'!A1", "Home") -> Home
A4: =HYPERLINK("#'Results - Activity period'!A1", "Results - Activity period") -> Results - Activity period
A5: =HYPERLINK("#'Results - Product EI'!A1", "Results - Product Emissions Intensity") -> Results - Product Emissions Intensity
A8: INPUTS
A9: =HYPERLINK("#'Input - Enterprise'!A1", "Enterprise") -> Enterprise
A10: =HYPERLINK("#'Input - Site'!A1", "Site") -> Site
A11: =HYPERLINK("#'Input - Feedlot'!A1", "Feedlot") -> Feedlot
A12: =HYPERLINK("#'Input - Livestock sales'!A1", "Livestock sales") -> Livestock sales
A13: =HYPERLINK("#'Input - Beef cattle purchases'!A1", "Beef cattle purchases") -> Beef cattle purchases
A14: =HYPERLINK("#'Input - Fuel'!A1", "Fuel") -> Fuel
A15: =HYPERLINK("#'Input - Electricity'!A1", "Electricity") -> Electricity
A16: =HYPERLINK("#'Input - Common farm inputs'!A1", "Common farm inputs") -> Common farm inputs
A17: =HYPERLINK("#'Input - Livestock farm Inputs'!A1", "Livestock farm Inputs") -> Livestock farm Inputs
A18: =HYPERLINK("#'Input - Freight'!A1", "Freight") -> Freight
A19: =HYPERLINK("#'Input - Solid waste'!A1", "Solid waste") -> Solid waste
A20: =HYPERLINK("#'Input - Manure sent off-site'!A1", "Manure sent off-site") -> Manure sent off-site
A21: =HYPERLINK("#'Input - Data quality'!A1", "Data quality") -> Data quality
A22: =HYPERLINK("#'Input - Fert Prod System'!A1", "Fert Prod System") -> Fert Prod System
A23: =HYPERLINK("#'Input - Fertiliser'!A1", "Fertiliser") -> Fertiliser
A26: CALCULATIONS
A27: =HYPERLINK("#'3.1.1.1-2 Enteric Methane'!A1", "3.1.1.1-2 Enteric Methane") -> 3.1.1.1-2 Enteric Methane
A28: =HYPERLINK("#'4.1.1.1-2 Methane'!A1", "4.1.1.1-2 Manure Methane") -> 4.1.1.1-2 Manure Methane
A29: =HYPERLINK("#'4.1.1.3-4 Direct N20'!A1", "4.1.1.3-4 Manure Direct N2O") -> 4.1.1.3-4 Manure Direct N2O
A30: =HYPERLINK("#'4.1.1.5-6 Atmos Deposition'!A1", "4.1.1.5-6 Manure Atmos Dep") -> 4.1.1.5-6 Manure Atmos Dep
A31: =HYPERLINK("#'4.1.1.9 Manure applied to soils'!A1", "4.1.1.9 Manure applied to soils") -> 4.1.1.9 Manure applied to soils
A32: =HYPERLINK("#'8.1.1.1-2 Transport fuel'!A1", "8.1.1.1-2 Transport fuel") -> 8.1.1.1-2 Transport fuel | D32: ="Emissions for whole production cycle running between " & TEXT(X_Cell_Enterprise_ProductionTimeframeStart, "d mmmm yyyy") & " and " & TEXT(X_Cell_Enterprise_ProductionTimeframeEnd, "d mmmm yyyy") -> Emissions for whole production cycle running between 1 November 2025 and 31 March 2026
A33: =HYPERLINK("#'8.2.1.1-2 Stationary fuel'!A1", "8.2.1.1-2 Stationary fuel") -> 8.2.1.1-2 Stationary fuel
A34: =HYPERLINK("#'10.1.1-2 Solid waste treatment'!A1", "10.1.1.1-2 Solid waste") -> 10.1.1.1-2 Solid waste
A35: =HYPERLINK("#'14.1.1-2 Purchased electricity'!A1", "14.1.1-2 Purchased electricity") -> 14.1.1-2 Purchased electricity | E35: Method 1 | F35: Method 2
A36: =HYPERLINK("#'15 Scope 3'!A1", "15 Scope 3") -> 15 Scope 3 | D36: Emissions for production cycle excluding removals | E36: =Result_EmissionsForWholeProductionCycle_Gross_Method1 -> 2609.7774 | F36: =Result_EmissionsForWholeProductionCycle_Gross_Method2 -> 5585994 | G36: t CO2e
A37: =HYPERLINK("#'Calcs - Manure sent off-site'!A1", "Calcs - Manure sent off-site") -> Calcs - Manure sent off-site | D37: Net emissions for production cycle | E37: =Result_EmissionsForWholeProductionCycle_Net_Method1 -> 2609.7774 | F37: =Result_EmissionsForWholeProductionCycle_Net_Method2 -> 5585994 | G37: t CO2e
A38: =HYPERLINK("#'5.1.1.1-2 Inorganic fert N2O'!A1", "5.1.1.1-2 Inorganic fert N2O") -> 5.1.1.1-2 Inorganic fert N2O
A39: =HYPERLINK("#'5.1.1.3-4 Inorganic fert CO2'!A1", "5.1.1.3-4 Inorganic fert CO2") -> 5.1.1.3-4 Inorganic fert CO2 | D39: ="Product emissions intensity for whole production cycle running between " & TEXT(X_Cell_Enterprise_ProductionTimeframeStart, "d mmmm yyyy") & " and " & TEXT(X_Cell_Enterprise_ProductionTimeframeEnd, "d mmmm yyyy") -> Product emissions intensity for whole production cycle running between 1 November 2025 and 31 March 2026
A40: =HYPERLINK("#'5.2.1.1-2 Organic Fert N2O'!A1", "5.2.1.1-2 Organic Fert N2O") -> 5.2.1.1-2 Organic Fert N2O
A41: =HYPERLINK("#'5.3.1.1-2 Lime CO2'!A1", "5.3.1.1-2 Lime CO2") -> 5.3.1.1-2 Lime CO2
A42: =HYPERLINK("#'5.4.1.1-4 Atmos deposition'!A1", "5.4.1.1-4 Atmos deposition") -> 5.4.1.1-4 Atmos deposition | D42: Product emissions - Mass
A43: =HYPERLINK("#'5.5.1.1-2 Leaching and runoff'!A1", "5.5.1.1-2 Leaching and runoff") -> 5.5.1.1-2 Leaching and runoff | D43: Product | E43: Product type | F43: Amount (tonnnes) | G43: Mass emissions assignment | H43: Emissions intensity (Method 1) | I43: Emissions intensity (Method 2) | J43: Unit
D44: Liveweight sold - excluding removals | E44: Main product | F44: =X_Cell_Enterprise_LiveweightSold -> 5 | G44: =F44/(F44+F46) -> 0.83333333 | H44: =(E36/F44)*G44 -> 434.96289 | I44: =(F36/F44)*G44 -> 930999 | J44: t co2e/t liveweight sold
D45: Liveweight sold - net emissions | E45: Main product | F45: =F44 -> 5 | G45: =G44 -> 0.83333333 | H45: =(E37/F45)*G45 -> 434.96289 | I45: =(F37/F45)*G45 -> 930999 | J45: t co2e/t liveweight sold
...

Sheet Input - Enterprise
A1: #VALUE! | C1: Input - Enterprise
A3: =HYPERLINK("#'Home'!A1", "Home") -> Home
A4: =HYPERLINK("#'Results - Activity period'!A1", "Results - Activity period") -> Results - Activity period
A5: =HYPERLINK("#'Results - Product EI'!A1", "Results - Product Emissions Intensity") -> Results - Product Emissions Intensity | D5: Your business
D7: Farm name | E7: Test Farms
A8: INPUTS | D8: Reporting entity name | E8: Test Farms Pty Ltd
A9: =HYPERLINK("#'Input - Enterprise'!A1", "Enterprise") -> Enterprise
A10: =HYPERLINK("#'Input - Site'!A1", "Site") -> Site | D10: 💡An 'Emissions accounting period' is a 12 month period where the business can report on the emissions, and is typically the same as the business' financial accounting period.
A11: =HYPERLINK("#'Input - Feedlot'!A1", "Feedlot") -> Feedlot
A12: =HYPERLINK("#'Input - Livestock sales'!A1", "Livestock sales") -> Livestock sales | D12: Emissions calculation period start date | E12: 45658 | F12: ← DD/MM/YYYY or DD Month YYYY
A13: =HYPERLINK("#'Input - Beef cattle purchases'!A1", "Beef cattle purchases") -> Beef cattle purchases | D13: Emissions calculation period end date | E13: =DATE(YEAR(E12)+1,MONTH(E12),DAY(E12))-1 -> 46022 | F13: ← Automatically calculated, 12 months after start date
A14: =HYPERLINK("#'Input - Fuel'!A1", "Fuel") -> Fuel
A15: =HYPERLINK("#'Input - Electricity'!A1", "Electricity") -> Electricity
A16: =HYPERLINK("#'Input - Common farm inputs'!A1", "Common farm inputs") -> Common farm inputs | D16: Production
A17: =HYPERLINK("#'Input - Livestock farm Inputs'!A1", "Livestock farm Inputs") -> Livestock farm Inputs
A18: =HYPERLINK("#'Input - Freight'!A1", "Freight") -> Freight | D18: Production timeframe start | E18: 45962 | F18: ← DD/MM/YYYY or DD Month YYYY
A19: =HYPERLINK("#'Input - Solid waste'!A1", "Solid waste") -> Solid waste | D19: Production timeframe end | E19: 46112 | F19: ← DD/MM/YYYY or DD Month YYYY
A20: =HYPERLINK("#'Input - Manure sent off-site'!A1", "Manure sent off-site") -> Manure sent off-site | D20: Production timeframe length | E20: =DATEDIF(E18,E19+1,"m") -> 5 | F20: Months
A21: =HYPERLINK("#'Input - Data quality'!A1", "Data quality") -> Data quality
A22: =HYPERLINK("#'Input - Fert Prod System'!A1", "Fert Prod System") -> Fert Prod System | D22: Liveweight sold | E22: =SUM(Table_Input_LivestockSales[Total liveweight sold])*10^-3 -> 5 | F22: tonnes
A23: =HYPERLINK("#'Input - Fertiliser'!A1", "Fertiliser") -> Fertiliser | D23: Manure produced | E23: 10 | F23: tonnes
D24: Percent manure sold | E24: 0.1 | F24: percent
D25: Percent manure used as fertiliser on own farm | E25: 0.1 | F25: percent
A26: CALCULATIONS
A27: =HYPERLINK("#'3.1.1.1-2 Enteric Methane'!A1", "3.1.1.1-2 Enteric Methane") -> 3.1.1.1-2 Enteric Methane | D27: Percentage of income from liveweight sold | E27: 0.8 | F27: percent
A28: =HYPERLINK("#'4.1.1.1-2 Methane'!A1", "4.1.1.1-2 Manure Methane") -> 4.1.1.1-2 Manure Methane | D28: Percentage of income from manure sold | E28: 0.2 | F28: percent
A29: =HYPERLINK("#'4.1.1.3-4 Direct N20'!A1", "4.1.1.3-4 Manure Direct N2O") -> 4.1.1.3-4 Manure Direct N2O
A30: =HYPERLINK("#'4.1.1.5-6 Atmos Deposition'!A1", "4.1.1.5-6 Manure Atmos Dep") -> 4.1.1.5-6 Manure Atmos Dep
A31: =HYPERLINK("#'4.1.1.9 Manure applied to soils'!A1", "4.1.1.9 Manure applied to soils") -> 4.1.1.9 Manure applied to soils | D31: Carbon removals
A32: =HYPERLINK("#'8.1.1.1-2 Transport fuel'!A1", "8.1.1.1-2 Transport fuel") -> 8.1.1.1-2 Transport fuel
A33: =HYPERLINK("#'8.2.1.1-2 Stationary fuel'!A1", "8.2.1.1-2 Stationary fuel") -> 8.2.1.1-2 Stationary fuel
A34: =HYPERLINK("#'10.1.1-2 Solid waste treatment'!A1", "10.1.1.1-2 Solid waste") -> 10.1.1.1-2 Solid waste | D34: ="Carbon captured from " & TEXT(X_Cell_Site_StartDate, "d mmmm yyyy") & " to " & TEXT(X_Cell_Site_EndDate, "d, mmmm, yyyy") & " from environmental plantings" -> Carbon captured from 1 January 2025 to 31, December, 2025 from environmental plantings
A35: =HYPERLINK("#'14.1.1-2 Purchased electricity'!A1", "14.1.1-2 Purchased electricity") -> 14.1.1-2 Purchased electricity
A36: =HYPERLINK("#'15 Scope 3'!A1", "15 Scope 3") -> 15 Scope 3 | D36: Planting name | E36: Total removed CO2 | F36: Percent allocated to this enterprise | G36: Removal allocated to this enterprise
A37: =HYPERLINK("#'Calcs - Manure sent off-site'!A1", "Calcs - Manure sent off-site") -> Calcs - Manure sent off-site | G37: =Table_Input_Enterprise_PlantingRemovals[[#This Row],[Total removed CO2]]*Table_Input_Enterprise_PlantingRemovals[[#This Row],[Percent allocated to this enterprise]] -> 0
A38: =HYPERLINK("#'5.1.1.1-2 Inorganic fert N2O'!A1", "5.1.1.1-2 Inorganic fert N2O") -> 5.1.1.1-2 Inorganic fert N2O
A39: =HYPERLINK("#'5.1.1.3-4 Inorganic fert CO2'!A1", "5.1.1.3-4 Inorganic fert CO2") -> 5.1.1.3-4 Inorganic fert CO2
A40: =HYPERLINK("#'5.2.1.1-2 Organic Fert N2O'!A1", "5.2.1.1-2 Organic Fert N2O") -> 5.2.1.1-2 Organic Fert N2O
A41: =HYPERLINK("#'5.3.1.1-2 Lime CO2'!A1", "5.3.1.1-2 Lime CO2") -> 5.3.1.1-2 Lime CO2 | D41: Production cycle emissions and removals
A42: =HYPERLINK("#'5.4.1.1-4 Atmos deposition'!A1", "5.4.1.1-4 Atmos deposition") -> 5.4.1.1-4 Atmos deposition
...

Sheet Input - Site
A1: #VALUE! | C1: Input - Site
A3: =HYPERLINK("#'Home'!A1", "Home") -> Home
A4: =HYPERLINK("#'Results - Activity period'!A1", "Results - Activity period") -> Results - Activity period
A5: =HYPERLINK("#'Results - Product EI'!A1", "Results - Product Emissions Intensity") -> Results - Product Emissions Intensity | D5: Location and climate
D7: Location information is used to reference some region and climate-specific emission factors
A8: INPUTS | D8: Tip: Use the web-based GAF Location Helper tool to easily get region and climate information. You will need an internet connection to use the GAF Location Helper.
A9: =HYPERLINK("#'Input - Enterprise'!A1", "Enterprise") -> Enterprise
A10: =HYPERLINK("#'Input - Site'!A1", "Site") -> Site | D10: State | E10: Western Australia | F10: ← Please select
A11: =HYPERLINK("#'Input - Feedlot'!A1", "Feedlot") -> Feedlot | D11: Region (ABS Statistical area level 4) if state is WA | E11: Western Australia - Outback (South) | F11: ← Please select
A12: =HYPERLINK("#'Input - Livestock sales'!A1", "Livestock sales") -> Livestock sales | D12: Leaching zone | E12: NO - Not in leaching zone | F12: ← Please select
A13: =HYPERLINK("#'Input - Beef cattle purchases'!A1", "Beef cattle purchases") -> Beef cattle purchases | D13: Elevation | E13: 307.7 | F13: Meters
A14: =HYPERLINK("#'Input - Fuel'!A1", "Fuel") -> Fuel | D14: Average temperature for reporting period | E14: 18 | F14: Degrees celsius
A15: =HYPERLINK("#'Input - Electricity'!A1", "Electricity") -> Electricity | D15: Total rainfall for reporting period | E15: 601 | F15: Millimetres
A16: =HYPERLINK("#'Input - Common farm inputs'!A1", "Common farm inputs") -> Common farm inputs | D16: Potential evapotranspiration for reporting period | E16: 1326 | F16: Millimetres
A17: =HYPERLINK("#'Input - Livestock farm Inputs'!A1", "Livestock farm Inputs") -> Livestock farm Inputs | D17: Number of frost days for reporting period | E17: 7 | F17: Days
A18: =HYPERLINK("#'Input - Freight'!A1", "Freight") -> Freight | D18: MAP:PET ratio | E18: =E15/E16 -> 0.45324284
A19: =HYPERLINK("#'Input - Solid waste'!A1", "Solid waste") -> Solid waste | D19: Rainfall zone | E19: =Common_InputFunctions.Utility_LookupItemFromMinMax(E15,Table_SourceData_RainfallZones[Min rainfall],Table_SourceData_RainfallZones[Max rainfall],Table_SourceData_RainfallZones[Rainfall Zone]) -> High rainfall
A20: =HYPERLINK("#'Input - Manure sent off-site'!A1", "Manure sent off-site") -> Manure sent off-site | D20: Climate zone | E20: =Common_InputFunctions.Utility_GetClimateZone(E14,E15,E17,E13,E18,Table_SourceData_ClimateZones[Min temp],Table_SourceData_ClimateZones[Max temp],Table_SourceData_ClimateZones[Min rainfall],Table_SourceData_ClimateZones[Max rainfall],Table_SourceData_ClimateZones[Min frost days],Table_SourceData_ClimateZones[Max frost days],Table_SourceData_ClimateZones[Min elevation],Table_SourceData_ClimateZones[Max elevation],Table_SourceData_ClimateZones[Min MAP:PET],Table_SourceData_ClimateZones[Max MAP:PET],Table_SourceData_ClimateZones[Climate zone]) -> Warm temperate dry
A21: =HYPERLINK("#'Input - Data quality'!A1", "Data quality") -> Data quality | D21: Wet or dry climate zone | E21: =Common_InputFunctions.Utility_LookupValueInTable($E$20,Table_SourceData_WetDryZones[Climate zone],Table_SourceData_WetDryZones[Wet or Dry Zone]) -> Dry climate zone
A22: =HYPERLINK("#'Input - Fert Prod System'!A1", "Fert Prod System") -> Fert Prod System | D22: Temperature zone | E22: =Common_InputFunctions.Utility_LookupItemFromMinMax(E14,Table_SourceData_TemperatureZones[Min MAT],Table_SourceData_TemperatureZones[Max MAT],Table_SourceData_TemperatureZones[Temperature Zone]) -> Temperate
A23: =HYPERLINK("#'Input - Fertiliser'!A1", "Fertiliser") -> Fertiliser
A26: CALCULATIONS
A27: =HYPERLINK("#'3.1.1.1-2 Enteric Methane'!A1", "3.1.1.1-2 Enteric Methane") -> 3.1.1.1-2 Enteric Methane
A28: =HYPERLINK("#'4.1.1.1-2 Methane'!A1", "4.1.1.1-2 Manure Methane") -> 4.1.1.1-2 Manure Methane
A29: =HYPERLINK("#'4.1.1.3-4 Direct N20'!A1", "4.1.1.3-4 Manure Direct N2O") -> 4.1.1.3-4 Manure Direct N2O
A30: =HYPERLINK("#'4.1.1.5-6 Atmos Deposition'!A1", "4.1.1.5-6 Manure Atmos Dep") -> 4.1.1.5-6 Manure Atmos Dep
A31: =HYPERLINK("#'4.1.1.9 Manure applied to soils'!A1", "4.1.1.9 Manure applied to soils") -> 4.1.1.9 Manure applied to soils
A32: =HYPERLINK("#'8.1.1.1-2 Transport fuel'!A1", "8.1.1.1-2 Transport fuel") -> 8.1.1.1-2 Transport fuel
A33: =HYPERLINK("#'8.2.1.1-2 Stationary fuel'!A1", "8.2.1.1-2 Stationary fuel") -> 8.2.1.1-2 Stationary fuel
A34: =HYPERLINK("#'10.1.1-2 Solid waste treatment'!A1", "10.1.1.1-2 Solid waste") -> 10.1.1.1-2 Solid waste
A35: =HYPERLINK("#'14.1.1-2 Purchased electricity'!A1", "14.1.1-2 Purchased electricity") -> 14.1.1-2 Purchased electricity
A36: =HYPERLINK("#'15 Scope 3'!A1", "15 Scope 3") -> 15 Scope 3
A37: =HYPERLINK("#'Calcs - Manure sent off-site'!A1", "Calcs - Manure sent off-site") -> Calcs - Manure sent off-site
A38: =HYPERLINK("#'5.1.1.1-2 Inorganic fert N2O'!A1", "5.1.1.1-2 Inorganic fert N2O") -> 5.1.1.1-2 Inorganic fert N2O
A39: =HYPERLINK("#'5.1.1.3-4 Inorganic fert CO2'!A1", "5.1.1.3-4 Inorganic fert CO2") -> 5.1.1.3-4 Inorganic fert CO2
A40: =HYPERLINK("#'5.2.1.1-2 Organic Fert N2O'!A1", "5.2.1.1-2 Organic Fert N2O") -> 5.2.1.1-2 Organic Fert N2O
A41: =HYPERLINK("#'5.3.1.1-2 Lime CO2'!A1", "5.3.1.1-2 Lime CO2") -> 5.3.1.1-2 Lime CO2
A42: =HYPERLINK("#'5.4.1.1-4 Atmos deposition'!A1", "5.4.1.1-4 Atmos deposition") -> 5.4.1.1-4 Atmos deposition
A43: =HYPERLINK("#'5.5.1.1-2 Leaching and runoff'!A1", "5.5.1.1-2 Leaching and runoff") -> 5.5.1.1-2 Leaching and runoff
A46: APPENDICES
...

Sheet Input - Feedlot
A1: #VALUE! | C1: Input - MMS - Feedlot
A3: =HYPERLINK("#'Home'!A1", "Home") -> Home
A4: =HYPERLINK("#'Results - Activity period'!A1", "Results - Activity period") -> Results - Activity period
A5: =HYPERLINK("#'Results - Product EI'!A1", "Results - Product Emissions Intensity") -> Results - Product Emissions Intensity | D5: Herd movement
E7: Domestic | F7: Mid-fed | G7: Long-fed
A8: INPUTS | D8: ="Average number of head between " & TEXT(X_Cell_Site_StartDate, "dd mmm yy") & " and " & TEXT(X_Cell_Site_EndDate, "dd mmm yy") -> Average number of head between 01 Jan 25 and 31 Dec 25 | E8: 1000 | F8: 1000 | G8: 1000 | H8: head
A9: =HYPERLINK("#'Input - Enterprise'!A1", "Enterprise") -> Enterprise | D9: ="Average duration of stay between " & TEXT(X_Cell_Site_StartDate, "dd mmm yy") & " and " & TEXT(X_Cell_Site_EndDate, "dd mmm yy") -> Average duration of stay between 01 Jan 25 and 31 Dec 25 | E9: 90 | F9: 140 | G9: 250 | H9: days
A10: =HYPERLINK("#'Input - Site'!A1", "Site") -> Site
A11: =HYPERLINK("#'Input - Feedlot'!A1", "Feedlot") -> Feedlot | D11: Intake
A12: =HYPERLINK("#'Input - Livestock sales'!A1", "Livestock sales") -> Livestock sales
A13: =HYPERLINK("#'Input - Beef cattle purchases'!A1", "Beef cattle purchases") -> Beef cattle purchases | D13: Method 1 default values (Do not edit) | E13: Domestic | F13: Mid-fed | G13: Long-fed
A14: =HYPERLINK("#'Input - Fuel'!A1", "Fuel") -> Fuel | D14: Feed intake | E14: {=_xlfn.XLOOKUP(1, (Table_SourceData_Feedlot_AnimalCharacteristics[Feedlot type] = E$13) * (Table_SourceData_Feedlot_AnimalCharacteristics[Characteristic] = $D$14), Table_SourceData_Feedlot_AnimalCharacteristics[2020-2023], "Not Found")} -> 10.4 | F14: {=_xlfn.XLOOKUP(1, (Table_SourceData_Feedlot_AnimalCharacteristics[Feedlot type] = F$13) * (Table_SourceData_Feedlot_AnimalCharacteristics[Characteristic] = $D$14), Table_SourceData_Feedlot_AnimalCharacteristics[2020-2023], "Not Found")} -> 10.8 | G14: {=_xlfn.XLOOKUP(1, (Table_SourceData_Feedlot_AnimalCharacteristics[Feedlot type] = G$13) * (Table_SourceData_Feedlot_AnimalCharacteristics[Characteristic] = $D$14), Table_SourceData_Feedlot_AnimalCharacteristics[2020-2023], "Not Found")} -> 8.2 | H14: kg dry matter / head day
A15: =HYPERLINK("#'Input - Electricity'!A1", "Electricity") -> Electricity | D15: Ether extract | E15: {=_xlfn.XLOOKUP(1, (Table_SourceData_Feedlot_DietProperties[Feedlot type] = E$13) * (Table_SourceData_Feedlot_DietProperties[Nutrient analysis] = $D$15), Table_SourceData_Feedlot_DietProperties[2020-2023 Converted to fraction], "Not Found")} -> 4.8 | F15: {=_xlfn.XLOOKUP(1, (Table_SourceData_Feedlot_DietProperties[Feedlot type] = F$13) * (Table_SourceData_Feedlot_DietProperties[Nutrient analysis] = $D$15), Table_SourceData_Feedlot_DietProperties[2020-2023 Converted to fraction], "Not Found")} -> 5 | G15: {=_xlfn.XLOOKUP(1, (Table_SourceData_Feedlot_DietProperties[Feedlot type] = G$13) * (Table_SourceData_Feedlot_DietProperties[Nutrient analysis] = $D$15), Table_SourceData_Feedlot_DietProperties[2020-2023 Converted to fraction], "Not Found")} -> 5.5 | H15: fraction
A16: =HYPERLINK("#'Input - Common farm inputs'!A1", "Common farm inputs") -> Common farm inputs | D16: NDF | E16: {=_xlfn.XLOOKUP(1, (Table_SourceData_Feedlot_DietProperties[Feedlot type] = E$13) * (Table_SourceData_Feedlot_DietProperties[Nutrient analysis] = $D$16), Table_SourceData_Feedlot_DietProperties[2020-2023 Converted to fraction], "Not Found")} -> 22 | F16: {=_xlfn.XLOOKUP(1, (Table_SourceData_Feedlot_DietProperties[Feedlot type] = F$13) * (Table_SourceData_Feedlot_DietProperties[Nutrient analysis] = $D$16), Table_SourceData_Feedlot_DietProperties[2020-2023 Converted to fraction], "Not Found")} -> 22 | G16: {=_xlfn.XLOOKUP(1, (Table_SourceData_Feedlot_DietProperties[Feedlot type] = G$13) * (Table_SourceData_Feedlot_DietProperties[Nutrient analysis] = $D$16), Table_SourceData_Feedlot_DietProperties[2020-2023 Converted to fraction], "Not Found")} -> 24 | H16: fraction
A17: =HYPERLINK("#'Input - Livestock farm Inputs'!A1", "Livestock farm Inputs") -> Livestock farm Inputs | D17: Dry matter digestibility | E17: {=_xlfn.XLOOKUP(1, (Table_SourceData_Feedlot_DietProperties[Feedlot type] = E$13) * (Table_SourceData_Feedlot_DietProperties[Nutrient analysis] = $D$17), Table_SourceData_Feedlot_DietProperties[2020-2023 Converted to fraction], "Not Found")} -> 0.81 | F17: {=_xlfn.XLOOKUP(1, (Table_SourceData_Feedlot_DietProperties[Feedlot type] = F$13) * (Table_SourceData_Feedlot_DietProperties[Nutrient analysis] = $D$17), Table_SourceData_Feedlot_DietProperties[2020-2023 Converted to fraction], "Not Found")} -> 0.81 | G17: {=_xlfn.XLOOKUP(1, (Table_SourceData_Feedlot_DietProperties[Feedlot type] = G$13) * (Table_SourceData_Feedlot_DietProperties[Nutrient analysis] = $D$17), Table_SourceData_Feedlot_DietProperties[2020-2023 Converted to fraction], "Not Found")} -> 0.81 | H17: fraction
A18: =HYPERLINK("#'Input - Freight'!A1", "Freight") -> Freight | D18: Crude protein | E18: {=_xlfn.XLOOKUP(1, (Table_SourceData_Feedlot_DietProperties[Feedlot type] = E$13) * (Table_SourceData_Feedlot_DietProperties[Nutrient analysis] = $D$18), Table_SourceData_Feedlot_DietProperties[2020-2023 Converted to fraction], "Not Found")} -> 0.14 | F18: {=_xlfn.XLOOKUP(1, (Table_SourceData_Feedlot_DietProperties[Feedlot type] = F$13) * (Table_SourceData_Feedlot_DietProperties[Nutrient analysis] = $D$18), Table_SourceData_Feedlot_DietProperties[2020-2023 Converted to fraction], "Not Found")} -> 0.12 | G18: {=_xlfn.XLOOKUP(1, (Table_SourceData_Feedlot_DietProperties[Feedlot type] = G$13) * (Table_SourceData_Feedlot_DietProperties[Nutrient analysis] = $D$18), Table_SourceData_Feedlot_DietProperties[2020-2023 Converted to fraction], "Not Found")} -> 0.12 | H18: fraction
A19: =HYPERLINK("#'Input - Solid waste'!A1", "Solid waste") -> Solid waste | D19: N retention | E19: {=_xlfn.XLOOKUP(1, (Table_SourceData_Feedlot_AnimalCharacteristics[Feedlot type] = E$13) * (Table_SourceData_Feedlot_AnimalCharacteristics[Characteristic] = $D$19), Table_SourceData_Feedlot_AnimalCharacteristics[2020-2023], "Not Found")} -> 20.4 | F19: {=_xlfn.XLOOKUP(1, (Table_SourceData_Feedlot_AnimalCharacteristics[Feedlot type] = F$13) * (Table_SourceData_Feedlot_AnimalCharacteristics[Characteristic] = $D$19), Table_SourceData_Feedlot_AnimalCharacteristics[2020-2023], "Not Found")} -> 12.7 | G19: {=_xlfn.XLOOKUP(1, (Table_SourceData_Feedlot_AnimalCharacteristics[Feedlot type] = G$13) * (Table_SourceData_Feedlot_AnimalCharacteristics[Characteristic] = $D$19), Table_SourceData_Feedlot_AnimalCharacteristics[2020-2023], "Not Found")} -> 7 | H19: percent of intake
A20: =HYPERLINK("#'Input - Manure sent off-site'!A1", "Manure sent off-site") -> Manure sent off-site
A21: =HYPERLINK("#'Input - Data quality'!A1", "Data quality") -> Data quality | D21: Method 2 custom values (Edit if known) | E21: Domestic | F21: Mid-fed | G21: Long-fed
A22: =HYPERLINK("#'Input - Fert Prod System'!A1", "Fert Prod System") -> Fert Prod System | D22: Feed intake | E22: {=_xlfn.XLOOKUP(1, (Table_SourceData_Feedlot_AnimalCharacteristics[Feedlot type] = E$21) * (Table_SourceData_Feedlot_AnimalCharacteristics[Characteristic] = $D$22), Table_SourceData_Feedlot_AnimalCharacteristics[2020-2023], "Not Found")} -> 10.4 | F22: {=_xlfn.XLOOKUP(1, (Table_SourceData_Feedlot_AnimalCharacteristics[Feedlot type] = F$21) * (Table_SourceData_Feedlot_AnimalCharacteristics[Characteristic] = $D$22), Table_SourceData_Feedlot_AnimalCharacteristics[2020-2023], "Not Found")} -> 10.8 | G22: {=_xlfn.XLOOKUP(1, (Table_SourceData_Feedlot_AnimalCharacteristics[Feedlot type] = G$21) * (Table_SourceData_Feedlot_AnimalCharacteristics[Characteristic] = $D$22), Table_SourceData_Feedlot_AnimalCharacteristics[2020-2023], "Not Found")} -> 8.2 | H22: kg dry matter / head day
A23: =HYPERLINK("#'Input - Fertiliser'!A1", "Fertiliser") -> Fertiliser | D23: Ether extract | E23: {=_xlfn.XLOOKUP(1, (Table_SourceData_Feedlot_DietProperties[Feedlot type] = E$21) * (Table_SourceData_Feedlot_DietProperties[Nutrient analysis] = $D$23), Table_SourceData_Feedlot_DietProperties[2020-2023 Converted to fraction], "Not Found")} -> 4.8 | F23: {=_xlfn.XLOOKUP(1, (Table_SourceData_Feedlot_DietProperties[Feedlot type] = F$21) * (Table_SourceData_Feedlot_DietProperties[Nutrient analysis] = $D$23), Table_SourceData_Feedlot_DietProperties[2020-2023 Converted to fraction], "Not Found")} -> 5 | G23: {=_xlfn.XLOOKUP(1, (Table_SourceData_Feedlot_DietProperties[Feedlot type] = G$21) * (Table_SourceData_Feedlot_DietProperties[Nutrient analysis] = $D$23), Table_SourceData_Feedlot_DietProperties[2020-2023 Converted to fraction], "Not Found")} -> 5.5 | H23: fraction
D24: NDF | E24: {=_xlfn.XLOOKUP(1, (Table_SourceData_Feedlot_DietProperties[Feedlot type] = E$21) * (Table_SourceData_Feedlot_DietProperties[Nutrient analysis] = $D$24), Table_SourceData_Feedlot_DietProperties[2020-2023 Converted to fraction], "Not Found")} -> 22 | F24: {=_xlfn.XLOOKUP(1, (Table_SourceData_Feedlot_DietProperties[Feedlot type] = F$21) * (Table_SourceData_Feedlot_DietProperties[Nutrient analysis] = $D$24), Table_SourceData_Feedlot_DietProperties[2020-2023 Converted to fraction], "Not Found")} -> 22 | G24: {=_xlfn.XLOOKUP(1, (Table_SourceData_Feedlot_DietProperties[Feedlot type] = G$21) * (Table_SourceData_Feedlot_DietProperties[Nutrient analysis] = $D$24), Table_SourceData_Feedlot_DietProperties[2020-2023 Converted to fraction], "Not Found")} -> 24 | H24: fraction
D25: Dry matter digestibility | E25: {=_xlfn.XLOOKUP(1, (Table_SourceData_Feedlot_DietProperties[Feedlot type] = E$21) * (Table_SourceData_Feedlot_DietProperties[Nutrient analysis] = $D$25), Table_SourceData_Feedlot_DietProperties[2020-2023 Converted to fraction], "Not Found")} -> 0.81 | F25: {=_xlfn.XLOOKUP(1, (Table_SourceData_Feedlot_DietProperties[Feedlot type] = F$21) * (Table_SourceData_Feedlot_DietProperties[Nutrient analysis] = $D$25), Table_SourceData_Feedlot_DietProperties[2020-2023 Converted to fraction], "Not Found")} -> 0.81 | G25: {=_xlfn.XLOOKUP(1, (Table_SourceData_Feedlot_DietProperties[Feedlot type] = G$21) * (Table_SourceData_Feedlot_DietProperties[Nutrient analysis] = $D$25), Table_SourceData_Feedlot_DietProperties[2020-2023 Converted to fraction], "Not Found")} -> 0.81 | H25: fraction
A26: CALCULATIONS | D26: Crude protein | E26: {=_xlfn.XLOOKUP(1, (Table_SourceData_Feedlot_DietProperties[Feedlot type] = E$21) * (Table_SourceData_Feedlot_DietProperties[Nutrient analysis] = $D$26), Table_SourceData_Feedlot_DietProperties[2020-2023 Converted to fraction], "Not Found")} -> 0.14 | F26: {=_xlfn.XLOOKUP(1, (Table_SourceData_Feedlot_DietProperties[Feedlot type] = F$21) * (Table_SourceData_Feedlot_DietProperties[Nutrient analysis] = $D$26), Table_SourceData_Feedlot_DietProperties[2020-2023 Converted to fraction], "Not Found")} -> 0.12 | G26: {=_xlfn.XLOOKUP(1, (Table_SourceData_Feedlot_DietProperties[Feedlot type] = G$21) * (Table_SourceData_Feedlot_DietProperties[Nutrient analysis] = $D$26), Table_SourceData_Feedlot_DietProperties[2020-2023 Converted to fraction], "Not Found")} -> 0.12 | H26: fraction
A27: =HYPERLINK("#'3.1.1.1-2 Enteric Methane'!A1", "3.1.1.1-2 Enteric Methane") -> 3.1.1.1-2 Enteric Methane | D27: N retention | E27: {=_xlfn.XLOOKUP(1, (Table_SourceData_Feedlot_AnimalCharacteristics[Feedlot type] = E$21) * (Table_SourceData_Feedlot_AnimalCharacteristics[Characteristic] = $D$27), Table_SourceData_Feedlot_AnimalCharacteristics[2020-2023], "Not Found")} -> 20.4 | F27: {=_xlfn.XLOOKUP(1, (Table_SourceData_Feedlot_AnimalCharacteristics[Feedlot type] = F$21) * (Table_SourceData_Feedlot_AnimalCharacteristics[Characteristic] = $D$27), Table_SourceData_Feedlot_AnimalCharacteristics[2020-2023], "Not Found")} -> 12.7 | G27: {=_xlfn.XLOOKUP(1, (Table_SourceData_Feedlot_AnimalCharacteristics[Feedlot type] = G$21) * (Table_SourceData_Feedlot_AnimalCharacteristics[Characteristic] = $D$27), Table_SourceData_Feedlot_AnimalCharacteristics[2020-2023], "Not Found")} -> 7 | H27: percent of intake
A28: =HYPERLINK("#'4.1.1.1-2 Methane'!A1", "4.1.1.1-2 Manure Methane") -> 4.1.1.1-2 Manure Methane
A29: =HYPERLINK("#'4.1.1.3-4 Direct N20'!A1", "4.1.1.3-4 Manure Direct N2O") -> 4.1.1.3-4 Manure Direct N2O | D29: Manure management systems
A30: =HYPERLINK("#'4.1.1.5-6 Atmos Deposition'!A1", "4.1.1.5-6 Manure Atmos Dep") -> 4.1.1.5-6 Manure Atmos Dep
A31: =HYPERLINK("#'4.1.1.9 Manure applied to soils'!A1", "4.1.1.9 Manure applied to soils") -> 4.1.1.9 Manure applied to soils | D31: Stage 1 MMS | E31: Domestic | F31: Mid-fed | G31: Long-fed
A32: =HYPERLINK("#'8.1.1.1-2 Transport fuel'!A1", "8.1.1.1-2 Transport fuel") -> 8.1.1.1-2 Transport fuel | D32: Drylot (feed pad) | E32: 1 | F32: 1 | G32: 1 | H32: percent
A33: =HYPERLINK("#'8.2.1.1-2 Stationary fuel'!A1", "8.2.1.1-2 Stationary fuel") -> 8.2.1.1-2 Stationary fuel | D33: ▼
A34: =HYPERLINK("#'10.1.1-2 Solid waste treatment'!A1", "10.1.1.1-2 Solid waste") -> 10.1.1.1-2 Solid waste | D34: Stage 2 MMS | E34: Domestic | F34: Mid-fed | G34: Long-fed | H34: ► | I34: Destination after stage 2 MMS (Percent)
A35: =HYPERLINK("#'14.1.1-2 Purchased electricity'!A1", "14.1.1-2 Purchased electricity") -> 14.1.1-2 Purchased electricity | D35: ="From Stage 1: " & $D$32 & " to:" -> From Stage 1: Drylot (feed pad) to: | I35: Sold | J35: Fert for own farm (eg crop) | K35: Direct application to soil
A36: =HYPERLINK("#'15 Scope 3'!A1", "15 Scope 3") -> 15 Scope 3 | D36: ='Constants - Feedlot'!D29 -> Solid storage | E36: 0.2 | F36: 0.2 | G36: 0.2 | H36: percent | I36: 0.25 | J36: 0.25 | K36: =1-SUM(I36:J36) -> 0.5
A37: =HYPERLINK("#'Calcs - Manure sent off-site'!A1", "Calcs - Manure sent off-site") -> Calcs - Manure sent off-site | D37: ='Constants - Feedlot'!D30 -> Composting (passive windrow) | E37: 0.2 | F37: 0.2 | G37: 0.2 | H37: percent | I37: 0.25 | J37: 0.25 | K37: =1-SUM(I37:J37) -> 0.5
A38: =HYPERLINK("#'5.1.1.1-2 Inorganic fert N2O'!A1", "5.1.1.1-2 Inorganic fert N2O") -> 5.1.1.1-2 Inorganic fert N2O | D38: Direct application | E38: =1-SUM(E36, E37) -> 0.6 | F38: =1-SUM(F36, F37) -> 0.6 | G38: =1-SUM(G36, G37) -> 0.6 | H38: percent | I38: 0 | J38: 0 | K38: =1-SUM(I38:J38) -> 1
A39: =HYPERLINK("#'5.1.1.3-4 Inorganic fert CO2'!A1", "5.1.1.3-4 Inorganic fert CO2") -> 5.1.1.3-4 Inorganic fert CO2
A40: =HYPERLINK("#'5.2.1.1-2 Organic Fert N2O'!A1", "5.2.1.1-2 Organic Fert N2O") -> 5.2.1.1-2 Organic Fert N2O | D40: Stage 3 MMS | E40: Domestic | F40: Mid-fed | G40: Long-fed | H40: ► | I40: Destination after stage 3 MMS (Percent)
A41: =HYPERLINK("#'5.3.1.1-2 Lime CO2'!A1", "5.3.1.1-2 Lime CO2") -> 5.3.1.1-2 Lime CO2 | D41: ="From Stage 1: " & $D$32 & " to:" -> From Stage 1: Drylot (feed pad) to: | I41: Sold | J41: Fert for own farm (eg crop) | K41: Direct application to soil
A42: =HYPERLINK("#'5.4.1.1-4 Atmos deposition'!A1", "5.4.1.1-4 Atmos deposition") -> 5.4.1.1-4 Atmos deposition | D42: ='Constants - Feedlot'!$D$32 -> Anaerobic lagoon | E42: =SourceData_Feedlot_MMSm1T3_Data -> 0.02 | F42: =SourceData_Feedlot_MMSm1T3_Data -> 0.02 | G42: =SourceData_Feedlot_MMSm1T3_Data -> 0.02 | H42: percent | I42: 0.25 | J42: 0.25 | K42: =1-SUM(I42:J42) -> 0.5
...

Sheet Input - Livestock sales
C1: Input - Livestock sales
A3: =HYPERLINK("#'Home'!A1", "Home") -> Home
A4: =HYPERLINK("#'Results - Activity period'!A1", "Results - Activity period") -> Results - Activity period
A5: =HYPERLINK("#'Results - Product EI'!A1", "Results - Product Emissions Intensity") -> Results - Product Emissions Intensity | D5: ⚠️ Livestock sales are not automatically reflected in the duration and head tables - you will need to manually adjust head count and average liveweight
D6: Transaction name | E6: Class (select) | F6: Sale date | G6: Head sold | H6: Average weight per head (kg) | I6: Total liveweight sold
F7: 45566 | G7: 10 | H7: 500 | I7: =G7*H7 -> 5000
A8: INPUTS | I8: =G8*H8 -> 0
A9: =HYPERLINK("#'Input - Enterprise'!A1", "Enterprise") -> Enterprise | I9: =G9*H9 -> 0
A10: =HYPERLINK("#'Input - Site'!A1", "Site") -> Site | I10: =G10*H10 -> 0
A11: =HYPERLINK("#'Input - Feedlot'!A1", "Feedlot") -> Feedlot | I11: =G11*H11 -> 0
A12: =HYPERLINK("#'Input - Livestock sales'!A1", "Livestock sales") -> Livestock sales | I12: =G12*H12 -> 0
A13: =HYPERLINK("#'Input - Beef cattle purchases'!A1", "Beef cattle purchases") -> Beef cattle purchases | I13: =G13*H13 -> 0
A14: =HYPERLINK("#'Input - Fuel'!A1", "Fuel") -> Fuel | I14: =G14*H14 -> 0
A15: =HYPERLINK("#'Input - Electricity'!A1", "Electricity") -> Electricity | I15: =G15*H15 -> 0
A16: =HYPERLINK("#'Input - Common farm inputs'!A1", "Common farm inputs") -> Common farm inputs | I16: =G16*H16 -> 0
A17: =HYPERLINK("#'Input - Livestock farm Inputs'!A1", "Livestock farm Inputs") -> Livestock farm Inputs
A18: =HYPERLINK("#'Input - Freight'!A1", "Freight") -> Freight
A19: =HYPERLINK("#'Input - Solid waste'!A1", "Solid waste") -> Solid waste
A20: =HYPERLINK("#'Input - Manure sent off-site'!A1", "Manure sent off-site") -> Manure sent off-site
A21: =HYPERLINK("#'Input - Data quality'!A1", "Data quality") -> Data quality
A22: =HYPERLINK("#'Input - Fert Prod System'!A1", "Fert Prod System") -> Fert Prod System
A23: =HYPERLINK("#'Input - Fertiliser'!A1", "Fertiliser") -> Fertiliser
A26: CALCULATIONS
A27: =HYPERLINK("#'3.1.1.1-2 Enteric Methane'!A1", "3.1.1.1-2 Enteric Methane") -> 3.1.1.1-2 Enteric Methane
A28: =HYPERLINK("#'4.1.1.1-2 Methane'!A1", "4.1.1.1-2 Manure Methane") -> 4.1.1.1-2 Manure Methane
A29: =HYPERLINK("#'4.1.1.3-4 Direct N20'!A1", "4.1.1.3-4 Manure Direct N2O") -> 4.1.1.3-4 Manure Direct N2O
A30: =HYPERLINK("#'4.1.1.5-6 Atmos Deposition'!A1", "4.1.1.5-6 Manure Atmos Dep") -> 4.1.1.5-6 Manure Atmos Dep
A31: =HYPERLINK("#'4.1.1.9 Manure applied to soils'!A1", "4.1.1.9 Manure applied to soils") -> 4.1.1.9 Manure applied to soils
A32: =HYPERLINK("#'8.1.1.1-2 Transport fuel'!A1", "8.1.1.1-2 Transport fuel") -> 8.1.1.1-2 Transport fuel
A33: =HYPERLINK("#'8.2.1.1-2 Stationary fuel'!A1", "8.2.1.1-2 Stationary fuel") -> 8.2.1.1-2 Stationary fuel
A34: =HYPERLINK("#'10.1.1-2 Solid waste treatment'!A1", "10.1.1.1-2 Solid waste") -> 10.1.1.1-2 Solid waste
A35: =HYPERLINK("#'14.1.1-2 Purchased electricity'!A1", "14.1.1-2 Purchased electricity") -> 14.1.1-2 Purchased electricity
