Workbook
Name _Toc225350871: '5.4.1.1-4 Atmos deposition'!$C$1
Name _Toc225350871: '5.5.1.1-2 Leaching and runoff'!$C$1
Name AgResidue_Equations_FieldBurning.VEERG_6_4_1_1__1__MethaneEmissionsFromBurningOfCropResidues: _xlfn.LAMBDA(_xlpm.Mburnc,_xlpm.CCc,_xlpm.EFCH4,_xlpm.C_CH4, _xlpm.Mburnc * _xlpm.CCc * _xlpm.EFCH4 * _xlpm.C_CH4 * 10 ^ (-3))
Name AgResidue_Equations_FieldBurning.VEERG_6_4_1_1__1__MethaneEmissionsFromBurningOfCropResidues_FunctionName: _xlfn.LAMBDA("VEERG_6_4_1_1__1__MethaneEmissionsFromBurningOfCropResidues")
Name AgResidue_Equations_FieldBurning.VEERG_6_4_1_1__1__MethaneEmissionsFromBurningOfCropResidues_LatexEquation: _xlfn.LAMBDA("E_{CH4}=\sum_{c}(M_{burn,c}\times CC_{c}\times EF_{CH4}\times C_{CH4}\times 10^{-3})")
Name AgResidue_Equations_FieldBurning.VEERG_6_4_1_1__1__MethaneEmissionsFromBurningOfCropResidues_NIRReference: _xlfn.LAMBDA("")
Name AgResidue_Equations_FieldBurning.VEERG_6_4_1_1__1__MethaneEmissionsFromBurningOfCropResidues_Source: _xlfn.LAMBDA("VEERG 2026: 6.4.1.1, Equation (1)")
Name AgResidue_Equations_FieldBurning.VEERG_6_4_1_1__1__MethaneEmissionsFromBurningOfCropResidues_Title: _xlfn.LAMBDA("Methane emissions from the burning of crop residues")
Name AgResidue_Equations_FieldBurning.VEERG_6_4_1_1__1__MethaneEmissionsFromBurningOfCropResidues_Unit: _xlfn.LAMBDA("t CH4")
Name AgResidue_Equations_FieldBurning.VEERG_6_4_1_1__1__MethaneEmissionsFromBurningOfCropResidues_Variable: _xlfn.LAMBDA("ECH4")
Name AgResidue_Equations_FieldBurning.VEERG_6_4_1_1__2__NitrousOxideEmissionsFromBurningOfCropResidues: _xlfn.LAMBDA(_xlpm.Mburnc,_xlpm.NCAGc,_xlpm.EFN2O,_xlpm.CN2O, _xlpm.Mburnc * _xlpm.NCAGc * _xlpm.EFN2O * _xlpm.CN2O * 10 ^ (-3))
Name AgResidue_Equations_FieldBurning.VEERG_6_4_1_1__2__NitrousOxideEmissionsFromBurningOfCropResidues_FunctionName: _xlfn.LAMBDA("VEERG_6_4_1_1__2__NitrousOxideEmissionsFromBurningOfCropResidues")
Name AgResidue_Equations_FieldBurning.VEERG_6_4_1_1__2__NitrousOxideEmissionsFromBurningOfCropResidues_LatexEquation: _xlfn.LAMBDA("E_{N2O}=\sum_{c}(M_{burn,c}\times NC_{AGc}\times EF_{N2O}\times C_{N2O}\times 10^{-3})")
Name AgResidue_Equations_FieldBurning.VEERG_6_4_1_1__2__NitrousOxideEmissionsFromBurningOfCropResidues_NIRReference: _xlfn.LAMBDA("")
Name AgResidue_Equations_FieldBurning.VEERG_6_4_1_1__2__NitrousOxideEmissionsFromBurningOfCropResidues_Source: _xlfn.LAMBDA("VEERG 2026: 6.4.1.1, Equation (2)")
Name AgResidue_Equations_FieldBurning.VEERG_6_4_1_1__2__NitrousOxideEmissionsFromBurningOfCropResidues_Title: _xlfn.LAMBDA("Nitrous oxide emissions from the burning of crop residues")
Name AgResidue_Equations_FieldBurning.VEERG_6_4_1_1__2__NitrousOxideEmissionsFromBurningOfCropResidues_Unit: _xlfn.LAMBDA("t N2O")
Name AgResidue_Equations_FieldBurning.VEERG_6_4_1_1__2__NitrousOxideEmissionsFromBurningOfCropResidues_Variable: _xlfn.LAMBDA("EN2O")
Name AgResidue_Equations_FieldBurning.VEERG_6_4_1_1__3__MassOfCropResidueBurnt: _xlfn.LAMBDA(_xlpm.Pc,_xlpm.RAGc,_xlpm.Sc,_xlpm.DMc,_xlpm.Zc,_xlpm.Fc, _xlpm.Pc * _xlpm.RAGc * _xlpm.Sc * _xlpm.DMc * _xlpm.Zc * _xlpm.Fc)
Name AgResidue_Equations_FieldBurning.VEERG_6_4_1_1__3__MassOfCropResidueBurnt_FunctionName: _xlfn.LAMBDA("VEERG_6_4_1_1__3__MassOfCropResidueBurnt")
Name AgResidue_Equations_FieldBurning.VEERG_6_4_1_1__3__MassOfCropResidueBurnt_LatexEquation: _xlfn.LAMBDA("M_{burn,c}=P_{c}\times R_{AGc}\times S_{c}\times DM_{c}\times Z_{c}\times F_{c}")
Name AgResidue_Equations_FieldBurning.VEERG_6_4_1_1__3__MassOfCropResidueBurnt_NIRReference: _xlfn.LAMBDA("")
Name AgResidue_Equations_FieldBurning.VEERG_6_4_1_1__3__MassOfCropResidueBurnt_Source: _xlfn.LAMBDA("VEERG 2026: 6.4.1.1, Equation (3)")
Name AgResidue_Equations_FieldBurning.VEERG_6_4_1_1__3__MassOfCropResidueBurnt_Title: _xlfn.LAMBDA("Mass of residue of crop c burnt")
Name AgResidue_Equations_FieldBurning.VEERG_6_4_1_1__3__MassOfCropResidueBurnt_Unit: _xlfn.LAMBDA("kg")
Name AgResidue_Equations_FieldBurning.VEERG_6_4_1_1__3__MassOfCropResidueBurnt_Variable: _xlfn.LAMBDA("Mburnc")
Name AgResidues_Equations_CropResidues.VEERG_6_1_1_1__1__NitrousOxideEmissionsFromCropResidues: _xlfn.LAMBDA(_xlpm.Mc,_xlpm.EFNi,_xlpm.CgN2O, _xlpm.Mc * _xlpm.EFNi * _xlpm.CgN2O * 10 ^ (-3))
Name AgResidues_Equations_CropResidues.VEERG_6_1_1_1__1__NitrousOxideEmissionsFromCropResidues_FunctionName: _xlfn.LAMBDA("VEERG_6_1_1_1__1__NitrousOxideEmissionsFromCropResidues")
Name AgResidues_Equations_CropResidues.VEERG_6_1_1_1__1__NitrousOxideEmissionsFromCropResidues_LatexEquation: _xlfn.LAMBDA("E=\sum_{c}{M_{c}\times EF_{N}\times C_{g,N2O}\times 10^{-3}}")
Name AgResidues_Equations_CropResidues.VEERG_6_1_1_1__1__NitrousOxideEmissionsFromCropResidues_NIRReference: _xlfn.LAMBDA("")
Name AgResidues_Equations_CropResidues.VEERG_6_1_1_1__1__NitrousOxideEmissionsFromCropResidues_Source: _xlfn.LAMBDA("VEERG 2026: 6.1.1.1, Equation (1)")
Name AgResidues_Equations_CropResidues.VEERG_6_1_1_1__1__NitrousOxideEmissionsFromCropResidues_Title: _xlfn.LAMBDA("Nitrous oxide emissions from the return of crop residues across all crops c to the soil")
Name AgResidues_Equations_CropResidues.VEERG_6_1_1_1__1__NitrousOxideEmissionsFromCropResidues_Unit: _xlfn.LAMBDA("t N2O")
Name AgResidues_Equations_CropResidues.VEERG_6_1_1_1__1__NitrousOxideEmissionsFromCropResidues_Variable: _xlfn.LAMBDA("E")
Name AgResidues_Equations_CropResidues.VEERG_6_1_1_1__2__MassOfNitrogenInCropResidues_LatexEquation: _xlfn.LAMBDA("M_{c}=(P_{c}\times R_{AGc}\times(1-F_{c}-FFOD_{c})\times DM_{c}\times NC_{AGc})+(P_{c}\times R_{AGc}\times R_{BGc}\times DM_{c}\times NC_{BGc})")
Name AgResidues_Equations_CropResidues.VEERG_6_1_1_1__2__MassOfNitrogenInCropResidues_NIRReference: _xlfn.LAMBDA("")
Name AgResidues_Equations_CropResidues.VEERG_6_1_1_1__2__MassOfNitrogenInCropResidues_Source: _xlfn.LAMBDA("VEERG 2026: 6.1.1.1, Equation (2)")
Name AgResidues_Equations_CropResidues.VEERG_6_1_1_1__2__MassOfNitrogenInCropResidues_Title: _xlfn.LAMBDA("Mass of nitrogen in crop residues returned to the soil")
Name AgResidues_Equations_CropResidues.VEERG_6_1_1_1__2__MassOfNitrogenInCropResidues_Unit: _xlfn.LAMBDA("kg N")
Name AgResidues_Equations_CropResidues.VEERG_6_1_1_1__2__MassOfNitrogenInCropResidues_Variable: _xlfn.LAMBDA("Mc")
Name AgResidues_Equations_CropResidues.VEERG_6_1_1_2__1__FractionOfCropResidueRemovedBaled: _xlfn.LAMBDA(_xlpm.B,_xlpm.MB,_xlpm.Pc,_xlpm.RAGc, IFERROR((_xlpm.B * _xlpm.MB) / (_xlpm.Pc * _xlpm.RAGc), 0))
Name AgResidues_Equations_CropResidues.VEERG_6_1_1_2__1__FractionOfCropResidueRemovedBaled_LatexEquation: _xlfn.LAMBDA("FFOD_{c,baled}=\frac{B\times M_{B}}{P_{c}\times R_{AG,c}}")
Name AgResidues_Equations_CropResidues.VEERG_6_1_1_2__1__FractionOfCropResidueRemovedBaled_NIRReference: _xlfn.LAMBDA("")
Name AgResidues_Equations_CropResidues.VEERG_6_1_1_2__1__FractionOfCropResidueRemovedBaled_Source: _xlfn.LAMBDA("VEERG 2026: 6.1.1.2, Equation (1)")
Name AgResidues_Equations_CropResidues.VEERG_6_1_1_2__1__FractionOfCropResidueRemovedBaled_Title: _xlfn.LAMBDA("Fraction of crop residue that is removed for crop c, calculated where residues are baled")
Name AgResidues_Equations_CropResidues.VEERG_6_1_1_2__1__FractionOfCropResidueRemovedBaled_Unit: _xlfn.LAMBDA("dimensionless")
Name AgResidues_Equations_CropResidues.VEERG_6_1_1_2__1__FractionOfCropResidueRemovedBaled_Variable: _xlfn.LAMBDA("FFODcbaled")
Name AgResidues_Equations_CropResidues.VEERG_6_1_1_2__1__FractionOfCropResidueRemovedBaled_Variation: _xlfn.LAMBDA("VARIATION FROM SOURCE: Added 'baled' to variable subscript")
Name AgResidues_Equations_CropResidues.VEERG_6_1_1_2__1a__FractionOfCropResidueRemoved: _xlfn.LAMBDA(_xlpm.FFODcbaled,_xlpm.FFODcother, _xlpm.FFODcbaled + _xlpm.FFODcother)
Name AgResidues_Equations_CropResidues.VEERG_6_1_1_2__1a__FractionOfCropResidueRemoved_LatexEquation: _xlfn.LAMBDA("FFOD_{c} = FFOD_{c,baled} + FFOD_{c,other}")
Name AgResidues_Equations_CropResidues.VEERG_6_1_1_2__1a__FractionOfCropResidueRemoved_NIRReference: _xlfn.LAMBDA("")
Name AgResidues_Equations_CropResidues.VEERG_6_1_1_2__1a__FractionOfCropResidueRemoved_Source: _xlfn.LAMBDA("")
Name AgResidues_Equations_CropResidues.VEERG_6_1_1_2__1a__FractionOfCropResidueRemoved_Title: _xlfn.LAMBDA("Fraction of crop residue that is removed for crop c")
Name AgResidues_Equations_CropResidues.VEERG_6_1_1_2__1a__FractionOfCropResidueRemoved_Unit: _xlfn.LAMBDA("dimensionless")
Name AgResidues_Equations_CropResidues.VEERG_6_1_1_2__1a__FractionOfCropResidueRemoved_Variable: _xlfn.LAMBDA("FFODc")
Name AgResidues_Equations_CropResidues.VEERG_6_1_1_2__1a__FractionOfCropResidueRemoved_Variation: _xlfn.LAMBDA("VARIATION FROM SOURCE: Added this equation to accommodate user-defined residue removal other than baling.")
Name AgResidues_Equations_Leaching.VEERG_6_3_1_1__1__LeachingAndRunoffEmissionsCropAndPastureResidue: _xlfn.LAMBDA(_xlpm.Mleachcp,_xlpm.EFleach,_xlpm.CgN2O, _xlpm.Mleachcp * _xlpm.EFleach * _xlpm.CgN2O * 10 ^ (-3))
Name AgResidues_Equations_Leaching.VEERG_6_3_1_1__1__LeachingAndRunoffEmissionsCropAndPastureResidue_LatexEquation: _xlfn.LAMBDA("E_{N2O}=\sum_{c}\sum_{p}(M_{leach,cp}\times EF_{leach}\times Cg_{N2O}\times 10^{-3})")
Name AgResidues_Equations_Leaching.VEERG_6_3_1_1__1__LeachingAndRunoffEmissionsCropAndPastureResidue_NIRReference: _xlfn.LAMBDA("")
Name AgResidues_Equations_Leaching.VEERG_6_3_1_1__1__LeachingAndRunoffEmissionsCropAndPastureResidue_Source: _xlfn.LAMBDA("VEERG 2026: 6.3.1.1, Equation (1)")

Sheet Home
A1: #VALUE!
A3: =HYPERLINK("#'Home'!A1", "Home") -> Home
A4: =HYPERLINK("#'Results - Activity period'!A1", "Results - Activity period") -> Results - Activity period
A5: =HYPERLINK("#'Results - Product EI'!A1", "Results - Product Emissions Intensity") -> Results - Product Emissions Intensity
A8: INPUTS
A9: =HYPERLINK("#'Input - Enterprise'!A1", "Enterprise") -> Enterprise
A10: =HYPERLINK("#'Input - Site'!A1", "Site") -> Site
A11: =HYPERLINK("#'Input - Poultry'!A1", "Poultry") -> Poultry
A12: =HYPERLINK("#'Input - Livestock sales'!A1", "Livestock sales") -> Livestock sales
A13: =HYPERLINK("#'Input - Poultry purchases'!A1", "Poultry purchases") -> Poultry purchases
A14: =HYPERLINK("#'Input - Fuel'!A1", "Fuel") -> Fuel
A15: =HYPERLINK("#'Input - Electricity'!A1", "Electricity") -> Electricity
A16: =HYPERLINK("#'Input - Common farm inputs'!A1", "Common farm inputs") -> Common farm inputs
A17: =HYPERLINK("#'Input - Livestock farm Inputs'!A1", "Livestock farm Inputs") -> Livestock farm Inputs
A18: =HYPERLINK("#'Input - Freight'!A1", "Freight") -> Freight
A19: =HYPERLINK("#'Input - Solid waste'!A1", "Solid waste") -> Solid waste
A20: =HYPERLINK("#'Input - Manure sent off-site'!A1", "Manure sent off-site") -> Manure sent off-site
A21: =HYPERLINK("#'Input - Data quality'!A1", "Data quality") -> Data quality
A22: =HYPERLINK("#'Input - Fert Prod System'!A1", "Fert Prod System") -> Fert Prod System
A23: =HYPERLINK("#'Input - Fertiliser'!A1", "Fertiliser") -> Fertiliser
A26: CALCULATIONS
A27: =HYPERLINK("#'4.6.1.1-2 Methane'!A1", "4.6.1.1-2 Manure Methane") -> 4.6.1.1-2 Manure Methane
A28: =HYPERLINK("#'4.6.1.3-4 Direct N20'!A1", "4.6.1.3-4 Manure Direct N2O") -> 4.6.1.3-4 Manure Direct N2O
A29: =HYPERLINK("#'4.6.1.5-6 Atmos Dep'!A1", "4.6.1.5-6 Manure Atmos Dep") -> 4.6.1.5-6 Manure Atmos Dep
A30: =HYPERLINK("#'4.6.1.7-8 Leaching and runoff'!A1", "4.6.1.7-8 Manure Leaching and runoff") -> 4.6.1.7-8 Manure Leaching and runoff
A31: =HYPERLINK("#'4.6.1.9 Manure applied to soils'!A1", "4.6.1.9 Manure applied to soils") -> 4.6.1.9 Manure applied to soils
A32: =HYPERLINK("#'4.6.1.10-11 Soil direct N2O'!A1", "4.6.1.10-11 Soil direct N2O") -> 4.6.1.10-11 Soil direct N2O
A33: =HYPERLINK("#'4.6.1.12-13 Soil atmos dep'!A1", "4.6.1.12-13 Soil atmos dep") -> 4.6.1.12-13 Soil atmos dep
A34: =HYPERLINK("#'4.6.1.14-15 Soil leach runoff'!A1", "4.6.1.14-15 Soil leach runoff") -> 4.6.1.14-15 Soil leach runoff
A35: =HYPERLINK("#'8.1.1.1-2 Transport fuel'!A1", "8.1.1.1-2 Transport fuel") -> 8.1.1.1-2 Transport fuel
A36: =HYPERLINK("#'8.2.1.1-2 Stationary fuel'!A1", "8.2.1.1-2 Stationary fuel") -> 8.2.1.1-2 Stationary fuel
A37: =HYPERLINK("#'10.1.1-2 Solid waste treatment'!A1", "10.1.1.1-2 Solid waste") -> 10.1.1.1-2 Solid waste
A38: =HYPERLINK("#'14.1.1-2 Purchased electricity'!A1", "14.1.1-2 Purchased electricity") -> 14.1.1-2 Purchased electricity
A39: =HYPERLINK("#'15 Scope 3'!A1", "15 Scope 3") -> 15 Scope 3
A40: =HYPERLINK("#'Calcs - Manure sent off-site'!A1", "Calcs - Manure sent off-site") -> Calcs - Manure sent off-site
A41: =HYPERLINK("#'5.1.1.1-2 Inorganic fert N2O'!A1", "5.1.1.1-2 Inorganic fert N2O") -> 5.1.1.1-2 Inorganic fert N2O
A42: =HYPERLINK("#'5.1.1.3-4 Inorganic fert CO2'!A1", "5.1.1.3-4 Inorganic fert CO2") -> 5.1.1.3-4 Inorganic fert CO2
A43: =HYPERLINK("#'5.2.1.1-2 Organic Fert N2O'!A1", "5.2.1.1-2 Organic Fert N2O") -> 5.2.1.1-2 Organic Fert N2O
A44: =HYPERLINK("#'5.3.1.1-2 Lime CO2'!A1", "5.3.1.1-2 Lime CO2") -> 5.3.1.1-2 Lime CO2
A45: =HYPERLINK("#'5.4.1.1-4 Atmos deposition'!A1", "5.4.1.1-4 Atmos deposition") -> 5.4.1.1-4 Atmos deposition
...

Sheet Results - Activity period
A1: #VALUE! | C1: Results - Activity period
A3: =HYPERLINK("#'Home'!A1", "Home") -> Home
A4: =HYPERLINK("#'Results - Activity period'!A1", "Results - Activity period") -> Results - Activity period | D4: ="Emissions breakdown for activities running between " & TEXT(X_Cell_Site_StartDate, "dd mmmm yyyy") & " and " & TEXT('Input - Enterprise'!E13, "dd mmmm yyyy") -> Emissions breakdown for activities running between 01 January 2025 and 31 December 2025
A5: =HYPERLINK("#'Results - Product EI'!A1", "Results - Product Emissions Intensity") -> Results - Product Emissions Intensity
D6: Scope 1
A8: INPUTS | D8: Scope 1 source | E8: GHG emissions method 1 | F8: GHG emissions method 2 | G8: GHG Unit | H8: CO2-e emissions method 1 | I8: CO2-e emissions method 2
A9: =HYPERLINK("#'Input - Enterprise'!A1", "Enterprise") -> Enterprise | D9: 4.6.1.1-2 Manure Methane | E9: =_xlfn.SINGLE(VEERG_4_6_1_1__1_TotalAnnualMethaneEmissions_Result_Method1) -> 0.019999321 | F9: =_xlfn.SINGLE(VEERG_4_6_1_1__1_TotalAnnualMethaneEmissions_Result_Method2) -> 0.019245864 | G9: t CH4 | H9: {=Common_Equations.Common_ConvertCH4ToCO2e(E9,_xlfn.XLOOKUP("CH4", Table_GWPData[Gas],Table_GWPData[CO2-e factor]))} -> 0.55998099 | I9: {=Common_Equations.Common_ConvertCH4ToCO2e(F9,_xlfn.XLOOKUP("CH4", Table_GWPData[Gas],Table_GWPData[CO2-e factor]))} -> 0.53888418 | J9: t CO2e
A10: =HYPERLINK("#'Input - Site'!A1", "Site") -> Site | D10: 4.6.1.3-4 Manure Direct N20 | E10: =_xlfn.SINGLE(VEERG_4_6_1_3__1_TotalAnnualDirectNitrousOxideEmissionsFromMMS_Result_Method1) -> 0.00057674955 | F10: =_xlfn.SINGLE(VEERG_4_6_1_3__1_TotalAnnualDirectNitrousOxideEmissionsFromMMS_Result_Method2) -> 0.00057674955 | G10: t CH4 | H10: {=Common_Equations.Common_ConvertN2OToCO2e(E10,_xlfn.XLOOKUP("N2O", Table_GWPData[Gas],Table_GWPData[CO2-e factor]))} -> 0.15283863 | I10: {=Common_Equations.Common_ConvertN2OToCO2e(F10,_xlfn.XLOOKUP("N2O", Table_GWPData[Gas],Table_GWPData[CO2-e factor]))} -> 0.15283863 | J10: t CO2e
A11: =HYPERLINK("#'Input - Poultry'!A1", "Poultry") -> Poultry | D11: 4.6.1.5-6 Manure Atmospheric Deposition | E11: =_xlfn.SINGLE(VEERG_4_6_1_5__1_TotalAnnualAtmosphericDepositionEmissionsFromMMS_Result_Method1) -> 0.00022877541 | F11: =_xlfn.SINGLE(VEERG_4_6_1_5__1_TotalAnnualAtmosphericDepositionEmissionsFromMMS_Result_Method2) -> 0.00022877541 | G11: t N2O | H11: {=Common_Equations.Common_ConvertN2OToCO2e(E11,_xlfn.XLOOKUP("N2O", Table_GWPData[Gas],Table_GWPData[CO2-e factor]))} -> 0.060625483 | I11: {=Common_Equations.Common_ConvertN2OToCO2e(F11,_xlfn.XLOOKUP("N2O", Table_GWPData[Gas],Table_GWPData[CO2-e factor]))} -> 0.060625483 | J11: t CO2e
A12: =HYPERLINK("#'Input - Livestock sales'!A1", "Livestock sales") -> Livestock sales | D12: 4.6.1.7-8 Manure Leaching and runoff | E12: =_xlfn.SINGLE(VEERG_4_6_1_7__1_AnnualEmissionsFromLeachingAndRunoffFromMMS_Result_Method1) -> 3.4753311e-06 | F12: =_xlfn.SINGLE(VEERG_4_6_1_7__1_AnnualEmissionsFromLeachingAndRunoffFromMMS_Result_Method2) -> 3.4753311e-06 | G12: t N2O | H12: {=Common_Equations.Common_ConvertN2OToCO2e(E12,_xlfn.XLOOKUP("N2O", Table_GWPData[Gas],Table_GWPData[CO2-e factor]))} -> 0.00092096274 | I12: {=Common_Equations.Common_ConvertN2OToCO2e(F12,_xlfn.XLOOKUP("N2O", Table_GWPData[Gas],Table_GWPData[CO2-e factor]))} -> 0.00092096274 | J12: t CO2e
A13: =HYPERLINK("#'Input - Poultry purchases'!A1", "Poultry purchases") -> Poultry purchases | D13: 4.6.1.10-11 Soil direct N2O | E13: =_xlfn.SINGLE(VEERG_4_6_1_10__1_DirectNitrousOxideEmissionsFromPoultryManure_Result_Method1) -> 0.00023434149 | F13: =_xlfn.SINGLE(VEERG_4_6_1_10__1_DirectNitrousOxideEmissionsFromPoultryManure_Result_Method2) -> 0.00023434149 | G13: t N2O | H13: {=Common_Equations.Common_ConvertN2OToCO2e(E13,_xlfn.XLOOKUP("N2O", Table_GWPData[Gas],Table_GWPData[CO2-e factor]))} -> 0.062100494 | I13: {=Common_Equations.Common_ConvertN2OToCO2e(F13,_xlfn.XLOOKUP("N2O", Table_GWPData[Gas],Table_GWPData[CO2-e factor]))} -> 0.062100494 | J13: t CO2e
A14: =HYPERLINK("#'Input - Fuel'!A1", "Fuel") -> Fuel | D14: 4.6.1.12-13 Soil atmos dep | E14: =_xlfn.SINGLE(VEERG_4_6_1_12__1_AtmosphericDepositionEmissionsFromPoultryManureOnPasture_Result_Method1) -> 1.7224099e-05 | F14: =_xlfn.SINGLE(VEERG_4_6_1_12__1_AtmosphericDepositionEmissionsFromPoultryManureOnPasture_Result_Method2) -> 1.7224099e-05 | G14: t N2O | H14: {=Common_Equations.Common_ConvertN2OToCO2e(E14,_xlfn.XLOOKUP("N2O", Table_GWPData[Gas],Table_GWPData[CO2-e factor]))} -> 0.0045643863 | I14: {=Common_Equations.Common_ConvertN2OToCO2e(F14,_xlfn.XLOOKUP("N2O", Table_GWPData[Gas],Table_GWPData[CO2-e factor]))} -> 0.0045643863 | J14: t CO2e
A15: =HYPERLINK("#'Input - Electricity'!A1", "Electricity") -> Electricity | D15: 4.6.1.14-15 Soil leach runoff | E15: =_xlfn.SINGLE(VEERG_4_6_1_14__1_LeachingAndRunoffEmissionsFromPoultryManureOnPasture_Result_Method1) -> 2.5777563e-06 | F15: =_xlfn.SINGLE(VEERG_4_6_1_14__1_LeachingAndRunoffEmissionsFromPoultryManureOnPasture_Result_Method2) -> 2.5777563e-06 | G15: t N2O | H15: {=Common_Equations.Common_ConvertN2OToCO2e(E15,_xlfn.XLOOKUP("N2O", Table_GWPData[Gas],Table_GWPData[CO2-e factor]))} -> 0.00068310543 | I15: {=Common_Equations.Common_ConvertN2OToCO2e(F15,_xlfn.XLOOKUP("N2O", Table_GWPData[Gas],Table_GWPData[CO2-e factor]))} -> 0.00068310543 | J15: t CO2e
A16: =HYPERLINK("#'Input - Common farm inputs'!A1", "Common farm inputs") -> Common farm inputs | D16: 8.1.1.1-2 Transport fuel CO2 | E16: {=VEERG_8_1_1_1__1_FuelCombustionTransport_Result_CO2} -> 83.182 | F16: =E16 -> 83.182 | G16: t CO2 | H16: =E17 -> 0.19906 | I16: =F17 -> 0.19906 | J16: t CO2e
A17: =HYPERLINK("#'Input - Livestock farm Inputs'!A1", "Livestock farm Inputs") -> Livestock farm Inputs | D17: 8.1.1.1-2 Transport fuel CH4 | E17: {=VEERG_8_1_1_1__1_FuelCombustionTransport_Result_CH4} -> 0.19906 | F17: =E17 -> 0.19906 | G17: t CH4 | H17: {=Common_Equations.Common_ConvertCH4ToCO2e(E18,_xlfn.XLOOKUP("CH4", Table_GWPData[Gas],Table_GWPData[CO2-e factor]))} -> 16.366 | I17: {=Common_Equations.Common_ConvertCH4ToCO2e(F18,_xlfn.XLOOKUP("CH4", Table_GWPData[Gas],Table_GWPData[CO2-e factor]))} -> 16.366 | J17: t CO2e
A18: =HYPERLINK("#'Input - Freight'!A1", "Freight") -> Freight | D18: 8.1.1.1-2 Transport fuel N2O | E18: {=VEERG_8_1_1_1__1_FuelCombustionTransport_Result_N2O} -> 0.5845 | F18: =E18 -> 0.5845 | G18: t N2O | H18: {=Common_Equations.Common_ConvertN2OToCO2e(E19,_xlfn.XLOOKUP("N2O", Table_GWPData[Gas],Table_GWPData[CO2-e factor]))} -> 7703.762 | I18: {=Common_Equations.Common_ConvertN2OToCO2e(F19,_xlfn.XLOOKUP("N2O", Table_GWPData[Gas],Table_GWPData[CO2-e factor]))} -> 7703.762 | J18: t CO2e
A19: =HYPERLINK("#'Input - Solid waste'!A1", "Solid waste") -> Solid waste | D19: 8.2.1.1-2 Stationary fuel CO2 | E19: {=VEERG_8_2_1_1__1_FuelCombustionStationary_Result_CO2} -> 29.0708 | F19: =E19 -> 29.0708 | G19: t CO2 | H19: =E20 -> 0.0724 | I19: =F20 -> 0.0724 | J19: t CO2e
A20: =HYPERLINK("#'Input - Manure sent off-site'!A1", "Manure sent off-site") -> Manure sent off-site | D20: 8.2.1.1-2 Stationary fuel CH4 | E20: {=VEERG_8_2_1_1__1_FuelCombustionStationary_Result_CH4} -> 0.0724 | F20: =E20 -> 0.0724 | G20: t CH4 | H20: {=Common_Equations.Common_ConvertCH4ToCO2e(E21,_xlfn.XLOOKUP("CH4", Table_GWPData[Gas],Table_GWPData[CO2-e factor]))} -> 1.9992 | I20: {=Common_Equations.Common_ConvertCH4ToCO2e(F21,_xlfn.XLOOKUP("CH4", Table_GWPData[Gas],Table_GWPData[CO2-e factor]))} -> 1.9992 | J20: t CO2e
A21: =HYPERLINK("#'Input - Data quality'!A1", "Data quality") -> Data quality | D21: 8.2.1.1-2 Stationary fuel N2O | E21: {=VEERG_8_2_1_1__1_FuelCombustionStationary_Result_N2O} -> 0.0714 | F21: =E21 -> 0.0714 | G21: t N2O | H21: {=Common_Equations.Common_ConvertN2OToCO2e(E22,_xlfn.XLOOKUP("N2O", Table_GWPData[Gas],Table_GWPData[CO2-e factor]))} -> 116289.43 | I21: {=Common_Equations.Common_ConvertN2OToCO2e(F22,_xlfn.XLOOKUP("N2O", Table_GWPData[Gas],Table_GWPData[CO2-e factor]))} -> 116289.43 | J21: t CO2e
A22: =HYPERLINK("#'Input - Fert Prod System'!A1", "Fert Prod System") -> Fert Prod System | D22: 10.1.1-2 Solid waste treatment | E22: {=VEERG_10_1_1_1__1_EmissionsFromWasteManagement_Scope1_Result_Method1} -> 438.82805 | F22: =E22 -> 438.82805 | G22: t CO2-e | H22: =E22 -> 438.82805 | I22: =F22 -> 438.82805 | J22: t CO2e
A23: =HYPERLINK("#'Input - Fertiliser'!A1", "Fertiliser") -> Fertiliser | D23: Total | H23: =SUM(H9:H22) -> 124451.5 | I23: =SUM(I9:I22) -> 124451.48 | J23: t CO2e
A26: CALCULATIONS | D26: Scope 2
A27: =HYPERLINK("#'4.6.1.1-2 Methane'!A1", "4.6.1.1-2 Manure Methane") -> 4.6.1.1-2 Manure Methane
A28: =HYPERLINK("#'4.6.1.3-4 Direct N20'!A1", "4.6.1.3-4 Manure Direct N2O") -> 4.6.1.3-4 Manure Direct N2O | D28: Scope 2 source | E28: GHG emissions method 1 | F28: GHG emissions method 2 | G28: GHG Unit | H28: CO2-e emissions method 1 | I28: CO2-e emissions method 2
A29: =HYPERLINK("#'4.6.1.5-6 Atmos Dep'!A1", "4.6.1.5-6 Manure Atmos Dep") -> 4.6.1.5-6 Manure Atmos Dep | D29: {="14.1.1-2 Purchased electricity " & IF(X_Cell_Electricity_CalculationMethod="Location-based (simpler)", "(Location-based)", "(Market-based)")} -> 14.1.1-2 Purchased electricity (Location-based) | E29: {=IF(X_Cell_Electricity_CalculationMethod="Location-based (simpler)", VEERG_14_1_1__1_LocationBasedScopeElectricityEmissions_Result_Method1, VEERG_14_1_2__1_MarketBasedScopeElectricityEmissionsVariation_Result_Method1)} -> 16.8 | F29: =E29 -> 16.8 | G29: t CO2e | H29: =E29 -> 16.8 | I29: =F29 -> 16.8 | J29: t CO2e
A30: =HYPERLINK("#'4.6.1.7-8 Leaching and runoff'!A1", "4.6.1.7-8 Manure Leaching and runoff") -> 4.6.1.7-8 Manure Leaching and runoff | D30: Total scope 2 | H30: =SUM(H29:H29) -> 16.8 | I30: =SUM(I29:I29) -> 16.8 | J30: t CO2e
A31: =HYPERLINK("#'4.6.1.9 Manure applied to soils'!A1", "4.6.1.9 Manure applied to soils") -> 4.6.1.9 Manure applied to soils
A32: =HYPERLINK("#'4.6.1.10-11 Soil direct N2O'!A1", "4.6.1.10-11 Soil direct N2O") -> 4.6.1.10-11 Soil direct N2O
A33: =HYPERLINK("#'4.6.1.12-13 Soil atmos dep'!A1", "4.6.1.12-13 Soil atmos dep") -> 4.6.1.12-13 Soil atmos dep | D33: Scope 3
A34: =HYPERLINK("#'4.6.1.14-15 Soil leach runoff'!A1", "4.6.1.14-15 Soil leach runoff") -> 4.6.1.14-15 Soil leach runoff
A35: =HYPERLINK("#'8.1.1.1-2 Transport fuel'!A1", "8.1.1.1-2 Transport fuel") -> 8.1.1.1-2 Transport fuel | D35: Scope 3 source | E35: GHG emissions method 1 | F35: GHG emissions method 2 | G35: GHG Unit | H35: CO2-e emissions method 1 | I35: CO2-e emissions method 2
A36: =HYPERLINK("#'8.2.1.1-2 Stationary fuel'!A1", "8.2.1.1-2 Stationary fuel") -> 8.2.1.1-2 Stationary fuel | D36: 15.1.1.1 Total emissions from purchased livestock - Pigs | E36: {=VEERG_15_1_1_1__1_EmissionsFromPurchasedLivestock_Pigs_Result_Method1} -> 0 | F36: {=VEERG_15_1_1_1__1_EmissionsFromPurchasedLivestock_Pigs_Result_Method2} -> 0 | G36: t CO2e | H36: =E36 -> 0 | I36: =F36 -> 0 | J36: t CO2e
A37: =HYPERLINK("#'10.1.1-2 Solid waste treatment'!A1", "10.1.1.1-2 Solid waste") -> 10.1.1.1-2 Solid waste | D37: 15.2.1.1 Emissions from purchased feed | E37: {=VEERG_15_2_1_1__1_EmissionsFromPurchasedFeed_Result_Method1} -> 0.785052 | F37: {=VEERG_15_2_1_1__1_EmissionsFromPurchasedFeed_Result_Method1} -> 0.785052 | G37: t CO2e | H37: =E37 -> 0.785052 | I37: =F37 -> 0.785052 | J37: t CO2e
A38: =HYPERLINK("#'14.1.1-2 Purchased electricity'!A1", "14.1.1-2 Purchased electricity") -> 14.1.1-2 Purchased electricity | D38: 15.7.1.1 Services and contractor operations | E38: {=VEERG_15_7_1_1__1_EmissionsFromPurchasedServices_Result_Method1} -> No data | F38: {=VEERG_15_7_1_1__1_EmissionsFromPurchasedServices_Result_Method2} -> 42 | G38: t CO2e | H38: =E38 -> No data | I38: =F38 -> 42 | J38: t CO2e
A39: =HYPERLINK("#'15 Scope 3'!A1", "15 Scope 3") -> 15 Scope 3 | D39: 15.10.1.1 Other: Cleaning chemicals | E39: {=VEERG_15_10_1_1__1_OtherPurchasedGoodsAndServices_CleaningChemicals_Result_Method1} -> 0.5051 | F39: {=VEERG_15_10_1_1__1_OtherPurchasedGoodsAndServices_CleaningChemicals_Result_Method2} -> 2.73 | G39: t CO2e | H39: =E39 -> 0.5051 | I39: =F39 -> 2.73 | J39: t CO2e
A40: =HYPERLINK("#'Calcs - Manure sent off-site'!A1", "Calcs - Manure sent off-site") -> Calcs - Manure sent off-site | D40: 15.10.1.1 Other: Pharmacy chemicals | E40: {=VEERG_15_10_1_1__1_OtherPurchasedGoodsAndServices_PharmacyChemicals_Result_Method1} -> 0.015636 | F40: {=VEERG_15_10_1_1__1_OtherPurchasedGoodsAndServices_PharmacyChemicals_Result_Method1} -> 0.015636 | G40: t CO2e | H40: =E40 -> 0.015636 | I40: =F40 -> 0.015636 | J40: t CO2e
A41: =HYPERLINK("#'5.1.1.1-2 Inorganic fert N2O'!A1", "5.1.1.1-2 Inorganic fert N2O") -> 5.1.1.1-2 Inorganic fert N2O | D41: 15.10.1.1 Other: Uncategorised | E41: {=VEERG_15_10_1_1__1_OtherPurchasedGoodsAndServices_Uncategorised_Result_Method1} -> No data | F41: {=VEERG_15_10_1_1__1_OtherPurchasedGoodsAndServices_Uncategorised_Result_Method2} -> 4000 | G41: t CO2e | H41: =E41 -> No data | I41: =F41 -> 4000 | J41: t CO2e
A42: =HYPERLINK("#'5.1.1.3-4 Inorganic fert CO2'!A1", "5.1.1.3-4 Inorganic fert CO2") -> 5.1.1.3-4 Inorganic fert CO2 | D42: 15.11.1.1 Fuel | E42: {=VEERG_15_11_1_1__1_TotalUpstreamEmissionsFromFuel_Result} -> 26.794 | F42: =E42 -> 26.794 | G42: t CO2e | H42: =E42 -> 26.794 | I42: =F42 -> 26.794 | J42: t CO2e
A43: =HYPERLINK("#'5.2.1.1-2 Organic Fert N2O'!A1", "5.2.1.1-2 Organic Fert N2O") -> 5.2.1.1-2 Organic Fert N2O | D43: {="15.12.1.1 Purchased electricity " & IF(X_Cell_Electricity_CalculationMethod="Location-based (simpler)", "(Location-based)", "(Market-based)")} -> 15.12.1.1 Purchased electricity (Location-based) | E43: {=IF(X_Cell_Electricity_CalculationMethod="Location-based (simpler)", VEERG_15_12_1_1__1_UpstreamPurchasedElectricityLocationBased_Result, VEERG_15_12_1_1__1_UpstreamPurchasedElectricityMarketBased_Result)} -> 2.7 | F43: =E43 -> 2.7 | G43: t CO2e | H43: =E43 -> 2.7 | I43: =F43 -> 2.7 | J43: t CO2e
A44: =HYPERLINK("#'5.3.1.1-2 Lime CO2'!A1", "5.3.1.1-2 Lime CO2") -> 5.3.1.1-2 Lime CO2 | D44: 15.13.1.1 Waste sent to treatment facility | E44: {=VEERG_10_1_1_1__1_EmissionsFromWasteManagement_Scope3_Result_Method1} -> 441.15 | F44: =E44 -> 441.15 | G44: t CO2e | H44: =E44 -> 441.15 | I44: =F44 -> 441.15 | J44: t CO2e
...

Sheet Results - Product EI
A1: #VALUE! | C1: Results - Product emissions intensity
A3: =HYPERLINK("#'Home'!A1", "Home") -> Home
A4: =HYPERLINK("#'Results - Activity period'!A1", "Results - Activity period") -> Results - Activity period
A5: =HYPERLINK("#'Results - Product EI'!A1", "Results - Product Emissions Intensity") -> Results - Product Emissions Intensity
A8: INPUTS
A9: =HYPERLINK("#'Input - Enterprise'!A1", "Enterprise") -> Enterprise
A10: =HYPERLINK("#'Input - Site'!A1", "Site") -> Site
A11: =HYPERLINK("#'Input - Poultry'!A1", "Poultry") -> Poultry
A12: =HYPERLINK("#'Input - Livestock sales'!A1", "Livestock sales") -> Livestock sales
A13: =HYPERLINK("#'Input - Poultry purchases'!A1", "Poultry purchases") -> Poultry purchases
A14: =HYPERLINK("#'Input - Fuel'!A1", "Fuel") -> Fuel
A15: =HYPERLINK("#'Input - Electricity'!A1", "Electricity") -> Electricity
A16: =HYPERLINK("#'Input - Common farm inputs'!A1", "Common farm inputs") -> Common farm inputs
A17: =HYPERLINK("#'Input - Livestock farm Inputs'!A1", "Livestock farm Inputs") -> Livestock farm Inputs
A18: =HYPERLINK("#'Input - Freight'!A1", "Freight") -> Freight
A19: =HYPERLINK("#'Input - Solid waste'!A1", "Solid waste") -> Solid waste
A20: =HYPERLINK("#'Input - Manure sent off-site'!A1", "Manure sent off-site") -> Manure sent off-site
A21: =HYPERLINK("#'Input - Data quality'!A1", "Data quality") -> Data quality
A22: =HYPERLINK("#'Input - Fert Prod System'!A1", "Fert Prod System") -> Fert Prod System
A23: =HYPERLINK("#'Input - Fertiliser'!A1", "Fertiliser") -> Fertiliser
A26: CALCULATIONS
A27: =HYPERLINK("#'4.6.1.1-2 Methane'!A1", "4.6.1.1-2 Manure Methane") -> 4.6.1.1-2 Manure Methane
A28: =HYPERLINK("#'4.6.1.3-4 Direct N20'!A1", "4.6.1.3-4 Manure Direct N2O") -> 4.6.1.3-4 Manure Direct N2O
A29: =HYPERLINK("#'4.6.1.5-6 Atmos Dep'!A1", "4.6.1.5-6 Manure Atmos Dep") -> 4.6.1.5-6 Manure Atmos Dep
A30: =HYPERLINK("#'4.6.1.7-8 Leaching and runoff'!A1", "4.6.1.7-8 Manure Leaching and runoff") -> 4.6.1.7-8 Manure Leaching and runoff
A31: =HYPERLINK("#'4.6.1.9 Manure applied to soils'!A1", "4.6.1.9 Manure applied to soils") -> 4.6.1.9 Manure applied to soils
A32: =HYPERLINK("#'4.6.1.10-11 Soil direct N2O'!A1", "4.6.1.10-11 Soil direct N2O") -> 4.6.1.10-11 Soil direct N2O | D32: ="Emissions for whole production cycle running between " & TEXT(X_Cell_Enterprise_ProductionTimeframeStart, "d mmmm yyyy") & " and " & TEXT(X_Cell_Enterprise_ProductionTimeframeEnd, "d mmmm yyyy") -> Emissions for whole production cycle running between 1 November 2025 and 31 March 2026
A33: =HYPERLINK("#'4.6.1.12-13 Soil atmos dep'!A1", "4.6.1.12-13 Soil atmos dep") -> 4.6.1.12-13 Soil atmos dep
A34: =HYPERLINK("#'4.6.1.14-15 Soil leach runoff'!A1", "4.6.1.14-15 Soil leach runoff") -> 4.6.1.14-15 Soil leach runoff
A35: =HYPERLINK("#'8.1.1.1-2 Transport fuel'!A1", "8.1.1.1-2 Transport fuel") -> 8.1.1.1-2 Transport fuel | E35: Method 1 | F35: Method 2
A36: =HYPERLINK("#'8.2.1.1-2 Stationary fuel'!A1", "8.2.1.1-2 Stationary fuel") -> 8.2.1.1-2 Stationary fuel | D36: Emissions for production cycle excluding removals | E36: =Result_EmissionsForWholeProductionCycle_Gross_Method1 -> 124940.25 | F36: =Result_EmissionsForWholeProductionCycle_Gross_Method2 -> 5708324.5 | G36: t CO2e
A37: =HYPERLINK("#'10.1.1-2 Solid waste treatment'!A1", "10.1.1.1-2 Solid waste") -> 10.1.1.1-2 Solid waste | D37: Net emissions for production cycle | E37: =Result_EmissionsForWholeProductionCycle_Net_Method1 -> 124940.25 | F37: =Result_EmissionsForWholeProductionCycle_Net_Method2 -> 5708324.5 | G37: t CO2e
A38: =HYPERLINK("#'14.1.1-2 Purchased electricity'!A1", "14.1.1-2 Purchased electricity") -> 14.1.1-2 Purchased electricity
A39: =HYPERLINK("#'15 Scope 3'!A1", "15 Scope 3") -> 15 Scope 3
A40: =HYPERLINK("#'Calcs - Manure sent off-site'!A1", "Calcs - Manure sent off-site") -> Calcs - Manure sent off-site | D40: ="Product emissions intensity for whole production cycle running between " & TEXT(X_Cell_Enterprise_ProductionTimeframeStart, "d mmmm yyyy") & " and " & TEXT(X_Cell_Enterprise_ProductionTimeframeEnd, "d mmmm yyyy") -> Product emissions intensity for whole production cycle running between 1 November 2025 and 31 March 2026
A41: =HYPERLINK("#'5.1.1.1-2 Inorganic fert N2O'!A1", "5.1.1.1-2 Inorganic fert N2O") -> 5.1.1.1-2 Inorganic fert N2O
A42: =HYPERLINK("#'5.1.1.3-4 Inorganic fert CO2'!A1", "5.1.1.3-4 Inorganic fert CO2") -> 5.1.1.3-4 Inorganic fert CO2 | D42: Product emissions - Mass
A43: =HYPERLINK("#'5.2.1.1-2 Organic Fert N2O'!A1", "5.2.1.1-2 Organic Fert N2O") -> 5.2.1.1-2 Organic Fert N2O | D43: Product | E43: Product type | F43: Amount (tonnnes) | G43: Mass emissions assignment | H43: Emissions intensity (Method 1) | I43: Emissions intensity (Method 2) | J43: Unit
A44: =HYPERLINK("#'5.3.1.1-2 Lime CO2'!A1", "5.3.1.1-2 Lime CO2") -> 5.3.1.1-2 Lime CO2 | D44: Liveweight sold - excluding removals | E44: Main product | F44: =X_Cell_Enterprise_BirdsSold -> 500 | G44: =F44/(F44+F46+F48) -> 0.97847358 | H44: =($E$36/F44)*G44 -> 244.50147 | I44: =($F$36/F44)*G44 -> 11170.889 | J44: t co2e/t birds sold
A45: =HYPERLINK("#'5.4.1.1-4 Atmos deposition'!A1", "5.4.1.1-4 Atmos deposition") -> 5.4.1.1-4 Atmos deposition | D45: Liveweight sold - net emissions | E45: Main product | F45: =F44 -> 500 | G45: =G44 -> 0.97847358 | H45: =($E$37/F45)*G45 -> 244.50147 | I45: =($F$37/F45)*G45 -> 11170.889 | J45: t co2e/t birds sold
...

Sheet Input - Enterprise
A1: #VALUE! | C1: Input - Enterprise
A3: =HYPERLINK("#'Home'!A1", "Home") -> Home
A4: =HYPERLINK("#'Results - Activity period'!A1", "Results - Activity period") -> Results - Activity period
A5: =HYPERLINK("#'Results - Product EI'!A1", "Results - Product Emissions Intensity") -> Results - Product Emissions Intensity | D5: Your business
D7: Farm name | E7: Test Farms
A8: INPUTS | D8: Reporting entity name | E8: Test Farms Pty Ltd
A9: =HYPERLINK("#'Input - Enterprise'!A1", "Enterprise") -> Enterprise
A10: =HYPERLINK("#'Input - Site'!A1", "Site") -> Site | D10: 💡An 'Emissions accounting period' is a 12 month period where the business can report on the emissions, and is typically the same as the business' financial accounting period.
A11: =HYPERLINK("#'Input - Poultry'!A1", "Poultry") -> Poultry
A12: =HYPERLINK("#'Input - Livestock sales'!A1", "Livestock sales") -> Livestock sales | D12: Emissions calculation period start date | E12: 45658 | F12: ← DD/MM/YYYY or DD Month YYYY
A13: =HYPERLINK("#'Input - Poultry purchases'!A1", "Poultry purchases") -> Poultry purchases | D13: Emissions calculation period end date | E13: =DATE(YEAR(E12)+1,MONTH(E12),DAY(E12))-1 -> 46022 | F13: ← Automatically calculated, 12 months after start date
A14: =HYPERLINK("#'Input - Fuel'!A1", "Fuel") -> Fuel
A15: =HYPERLINK("#'Input - Electricity'!A1", "Electricity") -> Electricity
A16: =HYPERLINK("#'Input - Common farm inputs'!A1", "Common farm inputs") -> Common farm inputs | D16: Production
A17: =HYPERLINK("#'Input - Livestock farm Inputs'!A1", "Livestock farm Inputs") -> Livestock farm Inputs
A18: =HYPERLINK("#'Input - Freight'!A1", "Freight") -> Freight | D18: Production timeframe start | E18: 45962 | F18: ← DD/MM/YYYY or DD Month YYYY
A19: =HYPERLINK("#'Input - Solid waste'!A1", "Solid waste") -> Solid waste | D19: Production timeframe end | E19: 46112 | F19: ← DD/MM/YYYY or DD Month YYYY
A20: =HYPERLINK("#'Input - Manure sent off-site'!A1", "Manure sent off-site") -> Manure sent off-site | D20: Production timeframe length | E20: =DATEDIF(E18,E19+1,"m") -> 5 | F20: Months
A21: =HYPERLINK("#'Input - Data quality'!A1", "Data quality") -> Data quality
A22: =HYPERLINK("#'Input - Fert Prod System'!A1", "Fert Prod System") -> Fert Prod System | D22: Birds sold | E22: =SUM(Table_Input_LivestockSales[Total liveweight sold])*10^-3 -> 500 | F22: tonnes
A23: =HYPERLINK("#'Input - Fertiliser'!A1", "Fertiliser") -> Fertiliser | D23: Eggs sold | E23: 10 | F23: tonnes
D24: Manure produced | E24: 10 | F24: tonnes
D25: Percent manure sold | E25: 0.1 | F25: percent
A26: CALCULATIONS | D26: Percent manure used as fertiliser on own farm | E26: 0.1 | F26: percent
A27: =HYPERLINK("#'4.6.1.1-2 Methane'!A1", "4.6.1.1-2 Manure Methane") -> 4.6.1.1-2 Manure Methane
A28: =HYPERLINK("#'4.6.1.3-4 Direct N20'!A1", "4.6.1.3-4 Manure Direct N2O") -> 4.6.1.3-4 Manure Direct N2O | D28: Percentage of income from birds sold | E28: 0.8 | F28: percent
A29: =HYPERLINK("#'4.6.1.5-6 Atmos Dep'!A1", "4.6.1.5-6 Manure Atmos Dep") -> 4.6.1.5-6 Manure Atmos Dep | D29: Percentage of income from eggs sold | E29: 0.8 | F29: percent
A30: =HYPERLINK("#'4.6.1.7-8 Leaching and runoff'!A1", "4.6.1.7-8 Manure Leaching and runoff") -> 4.6.1.7-8 Manure Leaching and runoff | D30: Percentage of income from manure sold | E30: 0.2 | F30: percent
A31: =HYPERLINK("#'4.6.1.9 Manure applied to soils'!A1", "4.6.1.9 Manure applied to soils") -> 4.6.1.9 Manure applied to soils
A32: =HYPERLINK("#'4.6.1.10-11 Soil direct N2O'!A1", "4.6.1.10-11 Soil direct N2O") -> 4.6.1.10-11 Soil direct N2O
A33: =HYPERLINK("#'4.6.1.12-13 Soil atmos dep'!A1", "4.6.1.12-13 Soil atmos dep") -> 4.6.1.12-13 Soil atmos dep | D33: Carbon removals
A34: =HYPERLINK("#'4.6.1.14-15 Soil leach runoff'!A1", "4.6.1.14-15 Soil leach runoff") -> 4.6.1.14-15 Soil leach runoff
A35: =HYPERLINK("#'8.1.1.1-2 Transport fuel'!A1", "8.1.1.1-2 Transport fuel") -> 8.1.1.1-2 Transport fuel
A36: =HYPERLINK("#'8.2.1.1-2 Stationary fuel'!A1", "8.2.1.1-2 Stationary fuel") -> 8.2.1.1-2 Stationary fuel | D36: ="Carbon captured from " & TEXT(X_Cell_Site_StartDate, "d mmmm yyyy") & " to " & TEXT(X_Cell_Site_EndDate, "d, mmmm, yyyy") & " from environmental plantings" -> Carbon captured from 1 January 2025 to 31, December, 2025 from environmental plantings
A37: =HYPERLINK("#'10.1.1-2 Solid waste treatment'!A1", "10.1.1.1-2 Solid waste") -> 10.1.1.1-2 Solid waste
A38: =HYPERLINK("#'14.1.1-2 Purchased electricity'!A1", "14.1.1-2 Purchased electricity") -> 14.1.1-2 Purchased electricity | D38: Planting name | E38: Total removed CO2 | F38: Percent allocated to this enterprise | G38: Removal allocated to this enterprise
A39: =HYPERLINK("#'15 Scope 3'!A1", "15 Scope 3") -> 15 Scope 3 | G39: =Table_Input_Enterprise_PlantingRemovals[[#This Row],[Total removed CO2]]*Table_Input_Enterprise_PlantingRemovals[[#This Row],[Percent allocated to this enterprise]] -> 0
A40: =HYPERLINK("#'Calcs - Manure sent off-site'!A1", "Calcs - Manure sent off-site") -> Calcs - Manure sent off-site
A41: =HYPERLINK("#'5.1.1.1-2 Inorganic fert N2O'!A1", "5.1.1.1-2 Inorganic fert N2O") -> 5.1.1.1-2 Inorganic fert N2O
A42: =HYPERLINK("#'5.1.1.3-4 Inorganic fert CO2'!A1", "5.1.1.3-4 Inorganic fert CO2") -> 5.1.1.3-4 Inorganic fert CO2
...

Sheet Input - Site
A1: #VALUE! | C1: Input - Site
A3: =HYPERLINK("#'Home'!A1", "Home") -> Home
A4: =HYPERLINK("#'Results - Activity period'!A1", "Results - Activity period") -> Results - Activity period
A5: =HYPERLINK("#'Results - Product EI'!A1", "Results - Product Emissions Intensity") -> Results - Product Emissions Intensity | D5: Location and climate
D7: Location information is used to reference some region and climate-specific emission factors
A8: INPUTS | D8: Tip: Use the web-based GAF Location Helper tool to easily get region and climate information. You will need an internet connection to use the GAF Location Helper.
A9: =HYPERLINK("#'Input - Enterprise'!A1", "Enterprise") -> Enterprise
A10: =HYPERLINK("#'Input - Site'!A1", "Site") -> Site | D10: State | E10: Western Australia | F10: ← Please select
A11: =HYPERLINK("#'Input - Poultry'!A1", "Poultry") -> Poultry | D11: Region (ABS Statistical area level 4) if state is WA | E11: Western Australia - Outback (South) | F11: ← Please select
A12: =HYPERLINK("#'Input - Livestock sales'!A1", "Livestock sales") -> Livestock sales | D12: Leaching zone | E12: NO - Not in leaching zone | F12: ← Please select
A13: =HYPERLINK("#'Input - Poultry purchases'!A1", "Poultry purchases") -> Poultry purchases | D13: Elevation | E13: 307.7 | F13: Meters
A14: =HYPERLINK("#'Input - Fuel'!A1", "Fuel") -> Fuel | D14: Average temperature for reporting period | E14: 18 | F14: Degrees celsius
A15: =HYPERLINK("#'Input - Electricity'!A1", "Electricity") -> Electricity | D15: Total rainfall for reporting period | E15: 601 | F15: Millimetres
A16: =HYPERLINK("#'Input - Common farm inputs'!A1", "Common farm inputs") -> Common farm inputs | D16: Potential evapotranspiration for reporting period | E16: 1326 | F16: Millimetres
A17: =HYPERLINK("#'Input - Livestock farm Inputs'!A1", "Livestock farm Inputs") -> Livestock farm Inputs | D17: Number of frost days for reporting period | E17: 7 | F17: Days
A18: =HYPERLINK("#'Input - Freight'!A1", "Freight") -> Freight | D18: MAP:PET ratio | E18: =E15/E16 -> 0.45324284
A19: =HYPERLINK("#'Input - Solid waste'!A1", "Solid waste") -> Solid waste | D19: Rainfall zone | E19: =Common_InputFunctions.Utility_LookupItemFromMinMax(E15,Table_SourceData_RainfallZones[Min rainfall],Table_SourceData_RainfallZones[Max rainfall],Table_SourceData_RainfallZones[Rainfall Zone]) -> High rainfall
A20: =HYPERLINK("#'Input - Manure sent off-site'!A1", "Manure sent off-site") -> Manure sent off-site | D20: Climate zone | E20: =Common_InputFunctions.Utility_GetClimateZone(E14,E15,E17,E13,E18,Table_SourceData_ClimateZones[Min temp],Table_SourceData_ClimateZones[Max temp],Table_SourceData_ClimateZones[Min rainfall],Table_SourceData_ClimateZones[Max rainfall],Table_SourceData_ClimateZones[Min frost days],Table_SourceData_ClimateZones[Max frost days],Table_SourceData_ClimateZones[Min elevation],Table_SourceData_ClimateZones[Max elevation],Table_SourceData_ClimateZones[Min MAP:PET],Table_SourceData_ClimateZones[Max MAP:PET],Table_SourceData_ClimateZones[Climate zone]) -> Warm temperate dry
A21: =HYPERLINK("#'Input - Data quality'!A1", "Data quality") -> Data quality | D21: Wet or dry climate zone | E21: =Common_InputFunctions.Utility_LookupValueInTable($E$20,Table_SourceData_WetDryZones[Climate zone],Table_SourceData_WetDryZones[Wet or Dry Zone]) -> Dry climate zone
A22: =HYPERLINK("#'Input - Fert Prod System'!A1", "Fert Prod System") -> Fert Prod System | D22: Temperature zone | E22: =Common_InputFunctions.Utility_LookupItemFromMinMax(E14,Table_SourceData_TemperatureZones[Min MAT],Table_SourceData_TemperatureZones[Max MAT],Table_SourceData_TemperatureZones[Temperature Zone]) -> Temperate
A23: =HYPERLINK("#'Input - Fertiliser'!A1", "Fertiliser") -> Fertiliser
A26: CALCULATIONS
A27: =HYPERLINK("#'4.6.1.1-2 Methane'!A1", "4.6.1.1-2 Manure Methane") -> 4.6.1.1-2 Manure Methane
A28: =HYPERLINK("#'4.6.1.3-4 Direct N20'!A1", "4.6.1.3-4 Manure Direct N2O") -> 4.6.1.3-4 Manure Direct N2O
A29: =HYPERLINK("#'4.6.1.5-6 Atmos Dep'!A1", "4.6.1.5-6 Manure Atmos Dep") -> 4.6.1.5-6 Manure Atmos Dep
A30: =HYPERLINK("#'4.6.1.7-8 Leaching and runoff'!A1", "4.6.1.7-8 Manure Leaching and runoff") -> 4.6.1.7-8 Manure Leaching and runoff
A31: =HYPERLINK("#'4.6.1.9 Manure applied to soils'!A1", "4.6.1.9 Manure applied to soils") -> 4.6.1.9 Manure applied to soils
A32: =HYPERLINK("#'4.6.1.10-11 Soil direct N2O'!A1", "4.6.1.10-11 Soil direct N2O") -> 4.6.1.10-11 Soil direct N2O
A33: =HYPERLINK("#'4.6.1.12-13 Soil atmos dep'!A1", "4.6.1.12-13 Soil atmos dep") -> 4.6.1.12-13 Soil atmos dep
A34: =HYPERLINK("#'4.6.1.14-15 Soil leach runoff'!A1", "4.6.1.14-15 Soil leach runoff") -> 4.6.1.14-15 Soil leach runoff
A35: =HYPERLINK("#'8.1.1.1-2 Transport fuel'!A1", "8.1.1.1-2 Transport fuel") -> 8.1.1.1-2 Transport fuel
A36: =HYPERLINK("#'8.2.1.1-2 Stationary fuel'!A1", "8.2.1.1-2 Stationary fuel") -> 8.2.1.1-2 Stationary fuel
A37: =HYPERLINK("#'10.1.1-2 Solid waste treatment'!A1", "10.1.1.1-2 Solid waste") -> 10.1.1.1-2 Solid waste
A38: =HYPERLINK("#'14.1.1-2 Purchased electricity'!A1", "14.1.1-2 Purchased electricity") -> 14.1.1-2 Purchased electricity
A39: =HYPERLINK("#'15 Scope 3'!A1", "15 Scope 3") -> 15 Scope 3
A40: =HYPERLINK("#'Calcs - Manure sent off-site'!A1", "Calcs - Manure sent off-site") -> Calcs - Manure sent off-site
A41: =HYPERLINK("#'5.1.1.1-2 Inorganic fert N2O'!A1", "5.1.1.1-2 Inorganic fert N2O") -> 5.1.1.1-2 Inorganic fert N2O
A42: =HYPERLINK("#'5.1.1.3-4 Inorganic fert CO2'!A1", "5.1.1.3-4 Inorganic fert CO2") -> 5.1.1.3-4 Inorganic fert CO2
A43: =HYPERLINK("#'5.2.1.1-2 Organic Fert N2O'!A1", "5.2.1.1-2 Organic Fert N2O") -> 5.2.1.1-2 Organic Fert N2O
A44: =HYPERLINK("#'5.3.1.1-2 Lime CO2'!A1", "5.3.1.1-2 Lime CO2") -> 5.3.1.1-2 Lime CO2
...

Sheet Input - Poultry
A1: #VALUE! | C1: Input -Poultry
A3: =HYPERLINK("#'Home'!A1", "Home") -> Home
A4: =HYPERLINK("#'Results - Activity period'!A1", "Results - Activity period") -> Results - Activity period
A5: =HYPERLINK("#'Results - Product EI'!A1", "Results - Product Emissions Intensity") -> Results - Product Emissions Intensity | D5: This tool demostrates inputs for one production system.
A8: INPUTS
A9: =HYPERLINK("#'Input - Enterprise'!A1", "Enterprise") -> Enterprise | E9: Layers | F9: Meat chicken growers | G9: Meat chicken breeders | H9: Other
A10: =HYPERLINK("#'Input - Site'!A1", "Site") -> Site | D10: ="Average duration of stay between " & TEXT(X_Cell_Site_StartDate, "dd mmm yy") & " and " & TEXT(X_Cell_Site_EndDate, "dd mmm yy") -> Average duration of stay between 01 Jan 25 and 31 Dec 25 | E10: 365 | F10: 365 | G10: 365 | H10: 365 | I10: Days
A11: =HYPERLINK("#'Input - Poultry'!A1", "Poultry") -> Poultry | D11: ="Average number of birds between " & TEXT(X_Cell_Site_StartDate, "dd mmm yy") & " and " & TEXT(X_Cell_Site_EndDate, "dd mmm yy") -> Average number of birds between 01 Jan 25 and 31 Dec 25 | E11: 100 | F11: 100 | G11: 100 | H11: 100 | I11: Head
A12: =HYPERLINK("#'Input - Livestock sales'!A1", "Livestock sales") -> Livestock sales
A13: =HYPERLINK("#'Input - Poultry purchases'!A1", "Poultry purchases") -> Poultry purchases | D13: Manure production
A14: =HYPERLINK("#'Input - Fuel'!A1", "Fuel") -> Fuel
A15: =HYPERLINK("#'Input - Electricity'!A1", "Electricity") -> Electricity | D15: Method 1 default values (Do not edit) | E15: Layers | F15: Meat chicken growers | G15: Meat chicken breeders | H15: Other
A16: =HYPERLINK("#'Input - Common farm inputs'!A1", "Common farm inputs") -> Common farm inputs | D16: Dry matter intake | E16: ='Constants - Poultry'!E9 -> 0.086 | F16: ='Constants - Poultry'!F9 -> 0.093 | G16: ='Constants - Poultry'!G9 -> 0.103 | H16: ='Constants - Poultry'!H9 -> 0.093 | I16: kg/DM/bird/day
A17: =HYPERLINK("#'Input - Livestock farm Inputs'!A1", "Livestock farm Inputs") -> Livestock farm Inputs | D17: Dry matter digestibility (DMD) | E17: ='Constants - Poultry'!E10 -> 0.8 | F17: ='Constants - Poultry'!F10 -> 0.8 | G17: ='Constants - Poultry'!G10 -> 0.8 | H17: ='Constants - Poultry'!H10 -> 0.8 | I17: fraction
A18: =HYPERLINK("#'Input - Freight'!A1", "Freight") -> Freight | D18: Crude protein (CP) | E18: ='Constants - Poultry'!E11 -> 0.19 | F18: ='Constants - Poultry'!F11 -> 0.23 | G18: ='Constants - Poultry'!G11 -> 0.19 | H18: ='Constants - Poultry'!H11 -> 0.23 | I18: fraction
A19: =HYPERLINK("#'Input - Solid waste'!A1", "Solid waste") -> Solid waste
A20: =HYPERLINK("#'Input - Manure sent off-site'!A1", "Manure sent off-site") -> Manure sent off-site | D20: Method 2 custom values (Edit if known) | E20: Layers | F20: Meat chicken growers | G20: Meat chicken breeders | H20: Other
A21: =HYPERLINK("#'Input - Data quality'!A1", "Data quality") -> Data quality | D21: Dry matter intake | E21: ='Constants - Poultry'!E9 -> 0.086 | F21: ='Constants - Poultry'!F9 -> 0.093 | G21: ='Constants - Poultry'!G9 -> 0.103 | H21: ='Constants - Poultry'!H9 -> 0.093 | I21: kg/DM/bird/day
A22: =HYPERLINK("#'Input - Fert Prod System'!A1", "Fert Prod System") -> Fert Prod System | D22: Dry matter digestibility (DMD) | E22: ='Constants - Poultry'!E10 -> 0.8 | F22: ='Constants - Poultry'!F10 -> 0.8 | G22: ='Constants - Poultry'!G10 -> 0.8 | H22: ='Constants - Poultry'!H10 -> 0.8 | I22: fraction
A23: =HYPERLINK("#'Input - Fertiliser'!A1", "Fertiliser") -> Fertiliser | D23: Crude protein (CP) | E23: ='Constants - Poultry'!E11 -> 0.19 | F23: ='Constants - Poultry'!F11 -> 0.23 | G23: ='Constants - Poultry'!G11 -> 0.19 | H23: ='Constants - Poultry'!H11 -> 0.23 | I23: fraction
D25: Manure management systems
A26: CALCULATIONS
A27: =HYPERLINK("#'4.6.1.1-2 Methane'!A1", "4.6.1.1-2 Manure Methane") -> 4.6.1.1-2 Manure Methane | D27: Production system | E27: Cage | F27: ← Please select
A28: =HYPERLINK("#'4.6.1.3-4 Direct N20'!A1", "4.6.1.3-4 Manure Direct N2O") -> 4.6.1.3-4 Manure Direct N2O
A29: =HYPERLINK("#'4.6.1.5-6 Atmos Dep'!A1", "4.6.1.5-6 Manure Atmos Dep") -> 4.6.1.5-6 Manure Atmos Dep | D29: Stage 1 MMS | E29: Layers | F29: Meat chicken growers | G29: Meat chicken breeders | H29: Other
A30: =HYPERLINK("#'4.6.1.7-8 Leaching and runoff'!A1", "4.6.1.7-8 Manure Leaching and runoff") -> 4.6.1.7-8 Manure Leaching and runoff | D30: ='Constants - Poultry'!G29 -> Poultry manure with bedding | E30: 0.3 | F30: 0.3 | G30: 0.3 | H30: 0.3 | I30: Percent
A31: =HYPERLINK("#'4.6.1.9 Manure applied to soils'!A1", "4.6.1.9 Manure applied to soils") -> 4.6.1.9 Manure applied to soils | D31: ='Constants - Poultry'!G30 -> Belt manure removal | E31: 0.3 | F31: 0.3 | G31: 0.3 | H31: 0.3 | I31: Percent
A32: =HYPERLINK("#'4.6.1.10-11 Soil direct N2O'!A1", "4.6.1.10-11 Soil direct N2O") -> 4.6.1.10-11 Soil direct N2O | D32: ='Constants - Poultry'!G31 -> Manure stored in house | E32: 0.3 | F32: 0.3 | G32: 0.3 | H32: 0.3 | I32: Percent
A33: =HYPERLINK("#'4.6.1.12-13 Soil atmos dep'!A1", "4.6.1.12-13 Soil atmos dep") -> 4.6.1.12-13 Soil atmos dep | D33: ='Constants - Poultry'!G32 -> Pasture range and paddock | E33: 0.1 | F33: 0.1 | G33: 0.1 | H33: 0.1 | I33: Percent
A34: =HYPERLINK("#'4.6.1.14-15 Soil leach runoff'!A1", "4.6.1.14-15 Soil leach runoff") -> 4.6.1.14-15 Soil leach runoff | D34: Total sent to all MMS (Must equal 100%) | E34: =SUM(E30,E31,E32,E33) -> 1 | F34: =SUM(F30,F31,F32,F33) -> 1 | G34: =SUM(G30,G31,G32,G33) -> 1 | H34: =SUM(H30,H31,H32,H33) -> 1
A35: =HYPERLINK("#'8.1.1.1-2 Transport fuel'!A1", "8.1.1.1-2 Transport fuel") -> 8.1.1.1-2 Transport fuel | D35: ▼
A36: =HYPERLINK("#'8.2.1.1-2 Stationary fuel'!A1", "8.2.1.1-2 Stationary fuel") -> 8.2.1.1-2 Stationary fuel | D36: Stage 2 MMS | E36: Layers | F36: Meat chicken growers | G36: Meat chicken breeders | H36: Other | I36: ► | K36: Destination after stage 2 MMS (Percent)
A37: =HYPERLINK("#'10.1.1-2 Solid waste treatment'!A1", "10.1.1.1-2 Solid waste") -> 10.1.1.1-2 Solid waste | D37: ="From stage 1: " & $D$30 -> From stage 1: Poultry manure with bedding | E37: =IF(SUM(E30:H30)>0,"Manure was sent to this MMS, please complete this section.","No manure was sent to this MMS. Leave this section blank.") -> Manure was sent to this MMS, please complete this section. | K37: Sold | L37: Fert for own farm (eg crop) | M37: Direct application to soil
A38: =HYPERLINK("#'14.1.1-2 Purchased electricity'!A1", "14.1.1-2 Purchased electricity") -> 14.1.1-2 Purchased electricity | D38: ='Constants - Poultry'!$J$29 -> Solid storage | E38: 0.2 | F38: 0.2 | G38: 0.2 | H38: 0.2 | I38: Percent | K38: 0.25 | L38: 0.25 | M38: =1-SUM(K38:L38) -> 0.5
A39: =HYPERLINK("#'15 Scope 3'!A1", "15 Scope 3") -> 15 Scope 3 | D39: ='Constants - Poultry'!$J$30 -> Composting (passive windrow) | E39: 0.2 | F39: 0.2 | G39: 0.2 | H39: 0.2 | I39: Percent | K39: 0.25 | L39: 0.25 | M39: =1-SUM(K39:L39) -> 0.5
A40: =HYPERLINK("#'Calcs - Manure sent off-site'!A1", "Calcs - Manure sent off-site") -> Calcs - Manure sent off-site | D40: ='Constants - Poultry'!$J$31 -> Digester / covered lagoons | E40: 0.2 | F40: 0.2 | G40: 0.2 | H40: 0.2 | I40: Percent | K40: 0.25 | L40: 0.25 | M40: =1-SUM(K40:L40) -> 0.5
A41: =HYPERLINK("#'5.1.1.1-2 Inorganic fert N2O'!A1", "5.1.1.1-2 Inorganic fert N2O") -> 5.1.1.1-2 Inorganic fert N2O | D41: ='Constants - Poultry'!$J$32 -> Direct processing | E41: 0.2 | F41: 0.2 | G41: 0.2 | H41: 0.2 | I41: Percent | K41: 0.25 | L41: 0.25 | M41: =1-SUM(K41:L41) -> 0.5
A42: =HYPERLINK("#'5.1.1.3-4 Inorganic fert CO2'!A1", "5.1.1.3-4 Inorganic fert CO2") -> 5.1.1.3-4 Inorganic fert CO2 | D42: ='Constants - Poultry'!$J$33 -> Direct application | E42: =1-SUM(E38:E41) -> 0.2 | F42: =1-SUM(F38:F41) -> 0.2 | G42: =1-SUM(G38:G41) -> 0.2 | H42: =1-SUM(H38:H41) -> 0.2 | I42: Percent | K42: 0 | L42: 0 | M42: =1-SUM(K42:L42) -> 1
A43: =HYPERLINK("#'5.2.1.1-2 Organic Fert N2O'!A1", "5.2.1.1-2 Organic Fert N2O") -> 5.2.1.1-2 Organic Fert N2O
A44: =HYPERLINK("#'5.3.1.1-2 Lime CO2'!A1", "5.3.1.1-2 Lime CO2") -> 5.3.1.1-2 Lime CO2 | D44: ="From stage 1: " & $D$31 -> From stage 1: Belt manure removal | E44: =IF(SUM(E31:H31)>0,"Manure was sent to this MMS, please complete this section.","No manure was sent to this MMS. Leave this section blank.") -> Manure was sent to this MMS, please complete this section. | K44: Sold | L44: Fert for own farm (eg crop) | M44: Direct application to soil
...

Sheet Input - Livestock sales
C1: Input - Livestock sales
A3: =HYPERLINK("#'Home'!A1", "Home") -> Home
A4: =HYPERLINK("#'Results - Activity period'!A1", "Results - Activity period") -> Results - Activity period
A5: =HYPERLINK("#'Results - Product EI'!A1", "Results - Product Emissions Intensity") -> Results - Product Emissions Intensity | D5: ⚠️ Livestock sales are not automatically reflected in the duration and head tables - you will need to manually adjust head count and average liveweight
D6: Transaction name | E6: Class (select) | F6: Sale date | G6: Head sold | H6: Average weight per head (kg) | I6: Total liveweight sold
F7: 45566 | G7: 1000 | H7: 500 | I7: =G7*H7 -> 500000
A8: INPUTS | I8: =G8*H8 -> 0
A9: =HYPERLINK("#'Input - Enterprise'!A1", "Enterprise") -> Enterprise | I9: =G9*H9 -> 0
A10: =HYPERLINK("#'Input - Site'!A1", "Site") -> Site | I10: =G10*H10 -> 0
A11: =HYPERLINK("#'Input - Poultry'!A1", "Poultry") -> Poultry | I11: =G11*H11 -> 0
A12: =HYPERLINK("#'Input - Livestock sales'!A1", "Livestock sales") -> Livestock sales | I12: =G12*H12 -> 0
A13: =HYPERLINK("#'Input - Poultry purchases'!A1", "Poultry purchases") -> Poultry purchases | I13: =G13*H13 -> 0
A14: =HYPERLINK("#'Input - Fuel'!A1", "Fuel") -> Fuel | I14: =G14*H14 -> 0
A15: =HYPERLINK("#'Input - Electricity'!A1", "Electricity") -> Electricity | I15: =G15*H15 -> 0
A16: =HYPERLINK("#'Input - Common farm inputs'!A1", "Common farm inputs") -> Common farm inputs | I16: =G16*H16 -> 0
A17: =HYPERLINK("#'Input - Livestock farm Inputs'!A1", "Livestock farm Inputs") -> Livestock farm Inputs
A18: =HYPERLINK("#'Input - Freight'!A1", "Freight") -> Freight
A19: =HYPERLINK("#'Input - Solid waste'!A1", "Solid waste") -> Solid waste
A20: =HYPERLINK("#'Input - Manure sent off-site'!A1", "Manure sent off-site") -> Manure sent off-site
A21: =HYPERLINK("#'Input - Data quality'!A1", "Data quality") -> Data quality
A22: =HYPERLINK("#'Input - Fert Prod System'!A1", "Fert Prod System") -> Fert Prod System
A23: =HYPERLINK("#'Input - Fertiliser'!A1", "Fertiliser") -> Fertiliser
A26: CALCULATIONS
A27: =HYPERLINK("#'4.6.1.1-2 Methane'!A1", "4.6.1.1-2 Manure Methane") -> 4.6.1.1-2 Manure Methane
A28: =HYPERLINK("#'4.6.1.3-4 Direct N20'!A1", "4.6.1.3-4 Manure Direct N2O") -> 4.6.1.3-4 Manure Direct N2O
A29: =HYPERLINK("#'4.6.1.5-6 Atmos Dep'!A1", "4.6.1.5-6 Manure Atmos Dep") -> 4.6.1.5-6 Manure Atmos Dep
A30: =HYPERLINK("#'4.6.1.7-8 Leaching and runoff'!A1", "4.6.1.7-8 Manure Leaching and runoff") -> 4.6.1.7-8 Manure Leaching and runoff
A31: =HYPERLINK("#'4.6.1.9 Manure applied to soils'!A1", "4.6.1.9 Manure applied to soils") -> 4.6.1.9 Manure applied to soils
A32: =HYPERLINK("#'4.6.1.10-11 Soil direct N2O'!A1", "4.6.1.10-11 Soil direct N2O") -> 4.6.1.10-11 Soil direct N2O
A33: =HYPERLINK("#'4.6.1.12-13 Soil atmos dep'!A1", "4.6.1.12-13 Soil atmos dep") -> 4.6.1.12-13 Soil atmos dep
A34: =HYPERLINK("#'4.6.1.14-15 Soil leach runoff'!A1", "4.6.1.14-15 Soil leach runoff") -> 4.6.1.14-15 Soil leach runoff
A35: =HYPERLINK("#'8.1.1.1-2 Transport fuel'!A1", "8.1.1.1-2 Transport fuel") -> 8.1.1.1-2 Transport fuel
A36: =HYPERLINK("#'8.2.1.1-2 Stationary fuel'!A1", "8.2.1.1-2 Stationary fuel") -> 8.2.1.1-2 Stationary fuel
A37: =HYPERLINK("#'10.1.1-2 Solid waste treatment'!A1", "10.1.1.1-2 Solid waste") -> 10.1.1.1-2 Solid waste
A38: =HYPERLINK("#'14.1.1-2 Purchased electricity'!A1", "14.1.1-2 Purchased electricity") -> 14.1.1-2 Purchased electricity
A39: =HYPERLINK("#'15 Scope 3'!A1", "15 Scope 3") -> 15 Scope 3
A40: =HYPERLINK("#'Calcs - Manure sent off-site'!A1", "Calcs - Manure sent off-site") -> Calcs - Manure sent off-site
A41: =HYPERLINK("#'5.1.1.1-2 Inorganic fert N2O'!A1", "5.1.1.1-2 Inorganic fert N2O") -> 5.1.1.1-2 Inorganic fert N2O
A42: =HYPERLINK("#'5.1.1.3-4 Inorganic fert CO2'!A1", "5.1.1.3-4 Inorganic fert CO2") -> 5.1.1.3-4 Inorganic fert CO2
A43: =HYPERLINK("#'5.2.1.1-2 Organic Fert N2O'!A1", "5.2.1.1-2 Organic Fert N2O") -> 5.2.1.1-2 Organic Fert N2O
...

Sheet Input - Poultry purchases
A1: #VALUE! | C1: Input - Poultry Purchases
A3: =HYPERLINK("#'Home'!A1", "Home") -> Home
A4: =HYPERLINK("#'Results - Activity period'!A1", "Results - Activity period") -> Results - Activity period
A5: =HYPERLINK("#'Results - Product EI'!A1", "Results - Product Emissions Intensity") -> Results - Product Emissions Intensity | D5: ⚠️ Livestock sales and purchases are not automatically reflected in the duration and head count tables - you will need to manually adjust head count, duration and average liveweight
D6: Transaction name | E6: Class (select) | F6: Quantity (head) | G6: Liveweight (kg/head) Method 1 | H6: Liveweight (kg/head) Method 2
D7: Chooks from Carolyn | E7: Chicken | F7: 100 | G7: {=Common_InputFunctions.Utility_LookupValueInTableNumber(Table_Input_LivestockPurchases_Poultry[[#This Row],[Class (select)]], Table_SourceData_Poultry_Liveweights[Livestock class j],Table_SourceData_Poultry_Liveweights[Average liveweight (kg)])} -> 1.3 | H7: 1.3
A8: INPUTS | D8: Roosters from Raj | E8: Pullets | F8: 100 | G8: {=Common_InputFunctions.Utility_LookupValueInTableNumber(Table_Input_LivestockPurchases_Poultry[[#This Row],[Class (select)]], Table_SourceData_Poultry_Liveweights[Livestock class j],Table_SourceData_Poultry_Liveweights[Average liveweight (kg)])} -> 1.4 | H8: 1.4
A9: =HYPERLINK("#'Input - Enterprise'!A1", "Enterprise") -> Enterprise | G9: {=Common_InputFunctions.Utility_LookupValueInTableNumber(Table_Input_LivestockPurchases_Poultry[[#This Row],[Class (select)]], Table_SourceData_Poultry_Liveweights[Livestock class j],Table_SourceData_Poultry_Liveweights[Average liveweight (kg)])} -> 0
A10: =HYPERLINK("#'Input - Site'!A1", "Site") -> Site | G10: {=Common_InputFunctions.Utility_LookupValueInTableNumber(Table_Input_LivestockPurchases_Poultry[[#This Row],[Class (select)]], Table_SourceData_Poultry_Liveweights[Livestock class j],Table_SourceData_Poultry_Liveweights[Average liveweight (kg)])} -> 0
A11: =HYPERLINK("#'Input - Poultry'!A1", "Poultry") -> Poultry | G11: {=Common_InputFunctions.Utility_LookupValueInTableNumber(Table_Input_LivestockPurchases_Poultry[[#This Row],[Class (select)]], Table_SourceData_Poultry_Liveweights[Livestock class j],Table_SourceData_Poultry_Liveweights[Average liveweight (kg)])} -> 0
A12: =HYPERLINK("#'Input - Livestock sales'!A1", "Livestock sales") -> Livestock sales | G12: {=Common_InputFunctions.Utility_LookupValueInTableNumber(Table_Input_LivestockPurchases_Poultry[[#This Row],[Class (select)]], Table_SourceData_Poultry_Liveweights[Livestock class j],Table_SourceData_Poultry_Liveweights[Average liveweight (kg)])} -> 0
A13: =HYPERLINK("#'Input - Poultry purchases'!A1", "Poultry purchases") -> Poultry purchases | G13: {=Common_InputFunctions.Utility_LookupValueInTableNumber(Table_Input_LivestockPurchases_Poultry[[#This Row],[Class (select)]], Table_SourceData_Poultry_Liveweights[Livestock class j],Table_SourceData_Poultry_Liveweights[Average liveweight (kg)])} -> 0
A14: =HYPERLINK("#'Input - Fuel'!A1", "Fuel") -> Fuel | G14: {=Common_InputFunctions.Utility_LookupValueInTableNumber(Table_Input_LivestockPurchases_Poultry[[#This Row],[Class (select)]], Table_SourceData_Poultry_Liveweights[Livestock class j],Table_SourceData_Poultry_Liveweights[Average liveweight (kg)])} -> 0
A15: =HYPERLINK("#'Input - Electricity'!A1", "Electricity") -> Electricity | G15: {=Common_InputFunctions.Utility_LookupValueInTableNumber(Table_Input_LivestockPurchases_Poultry[[#This Row],[Class (select)]], Table_SourceData_Poultry_Liveweights[Livestock class j],Table_SourceData_Poultry_Liveweights[Average liveweight (kg)])} -> 0
