Workbook
Name _Toc225350871: '5.4.1.1-4 Atmos deposition'!$C$1
Name _Toc225350871: '5.5.1.1-2 Leaching and runoff'!$C$1
Name AgResidue_Equations_CropResidue.VEERG_6_1_1_1__1__NitrousOxideEmissionsFromCropResidues: _xlfn.LAMBDA(_xlpm.M_c,_xlpm.EF_Ni,_xlpm.C_N2O, _xlpm.M_c * _xlpm.EF_Ni * _xlpm.C_N2O * 10 ^ (-3))
Name AgResidue_Equations_CropResidue.VEERG_6_1_1_1__1__NitrousOxideEmissionsFromCropResidues_FunctionName: _xlfn.LAMBDA("VEERG_6_1_1_1__1__NitrousOxideEmissionsFromCropResidues")
Name AgResidue_Equations_CropResidue.VEERG_6_1_1_1__1__NitrousOxideEmissionsFromCropResidues_LatexEquation: _xlfn.LAMBDA("E=\sum\nolimits_c\left(M_{c}\times EF_{N}\right)\times C_{g,N2O}\times 10^{-3}")
Name AgResidue_Equations_CropResidue.VEERG_6_1_1_1__1__NitrousOxideEmissionsFromCropResidues_NIRReference: _xlfn.LAMBDA("")
Name AgResidue_Equations_CropResidue.VEERG_6_1_1_1__1__NitrousOxideEmissionsFromCropResidues_Source: _xlfn.LAMBDA("VEERG 2026: 6.1.1.1, Equation (1)")
Name AgResidue_Equations_CropResidue.VEERG_6_1_1_1__1__NitrousOxideEmissionsFromCropResidues_Title: _xlfn.LAMBDA("Nitrous oxide emissions from the return of crop residues across all crops c to the soil")
Name AgResidue_Equations_CropResidue.VEERG_6_1_1_1__1__NitrousOxideEmissionsFromCropResidues_Unit: _xlfn.LAMBDA("t N2O")
Name AgResidue_Equations_CropResidue.VEERG_6_1_1_1__1__NitrousOxideEmissionsFromCropResidues_Variable: _xlfn.LAMBDA("E")
Name AgResidue_Equations_CropResidue.VEERG_6_1_1_1__2__MassOfNitrogenInCropResidues_LatexEquation: _xlfn.LAMBDA("M_{c}=(P_{c}\times R_{AGc}\times(1-F_{c}-FFOD_{c})\times DM_{c}\times NC_{AGc})+(P_{c}\times R_{AGc}\times R_{BGc}\times DM_{c}\times NC_{BGc})")
Name AgResidue_Equations_CropResidue.VEERG_6_1_1_1__2__MassOfNitrogenInCropResidues_NIRReference: _xlfn.LAMBDA("")
Name AgResidue_Equations_CropResidue.VEERG_6_1_1_1__2__MassOfNitrogenInCropResidues_Source: _xlfn.LAMBDA("VEERG 2026: 6.1.1.1, Equation (2)")
Name AgResidue_Equations_CropResidue.VEERG_6_1_1_1__2__MassOfNitrogenInCropResidues_Title: _xlfn.LAMBDA("Mass of nitrogen in crop residues returned to the soil")
Name AgResidue_Equations_CropResidue.VEERG_6_1_1_1__2__MassOfNitrogenInCropResidues_Unit: _xlfn.LAMBDA("kg N")
Name AgResidue_Equations_CropResidue.VEERG_6_1_1_1__2__MassOfNitrogenInCropResidues_Variable: _xlfn.LAMBDA("M_c")
Name AgResidue_Equations_CropResidue.VEERG_6_1_1_2__1__FractionOfCropResidueRemovedBaled: _xlfn.LAMBDA(_xlpm.B,_xlpm.M_B,_xlpm.P_c,_xlpm.R_AGc, IFERROR((_xlpm.B * _xlpm.M_B) / (_xlpm.P_c * _xlpm.R_AGc), 0))
Name AgResidue_Equations_CropResidue.VEERG_6_1_1_2__1__FractionOfCropResidueRemovedBaled_LatexEquation: _xlfn.LAMBDA("FFOD_{c}=\frac{B\times M_{B}}{P_{c}\times R_{AG,c}}")
Name AgResidue_Equations_CropResidue.VEERG_6_1_1_2__1__FractionOfCropResidueRemovedBaled_NIRReference: _xlfn.LAMBDA("")
Name AgResidue_Equations_CropResidue.VEERG_6_1_1_2__1__FractionOfCropResidueRemovedBaled_Source: _xlfn.LAMBDA("VEERG 2026: 6.1.1.2, Equation (1)")
Name AgResidue_Equations_CropResidue.VEERG_6_1_1_2__1__FractionOfCropResidueRemovedBaled_Title: _xlfn.LAMBDA("Fraction of crop residue that is removed for crop c, calculated where residues are baled")
Name AgResidue_Equations_CropResidue.VEERG_6_1_1_2__1__FractionOfCropResidueRemovedBaled_Unit: _xlfn.LAMBDA("fraction")
Name AgResidue_Equations_CropResidue.VEERG_6_1_1_2__1__FractionOfCropResidueRemovedBaled_Variable: _xlfn.LAMBDA("FFOD_c")
Name AgResidue_Equations_CropResidue.VEERG_6_1_1_2__1__FractionOfCropResidueRemovedBaled_Variation: _xlfn.LAMBDA("")
Name AgResidue_Equations_FieldBurning.VEERG_6_4_1_1__1__MethaneEmissionsFromBurningOfCropResidues: _xlfn.LAMBDA(_xlpm.M_burnc,_xlpm.CC_c,_xlpm.EF_CH4,_xlpm.C_CH4, (_xlpm.M_burnc * _xlpm.CC_c) * _xlpm.EF_CH4 * _xlpm.C_CH4 * 10 ^ (-3))
Name AgResidue_Equations_FieldBurning.VEERG_6_4_1_1__1__MethaneEmissionsFromBurningOfCropResidues_FunctionName: _xlfn.LAMBDA("VEERG_6_4_1_1__1__MethaneEmissionsFromBurningOfCropResidues")
Name AgResidue_Equations_FieldBurning.VEERG_6_4_1_1__1__MethaneEmissionsFromBurningOfCropResidues_LatexEquation: _xlfn.LAMBDA("E_{CH4}=\sum\nolimits_c(M_{burn,c}\times CC_{c})\times EF_{CH4}\times C_{CH4}\times 10^{-3}")
Name AgResidue_Equations_FieldBurning.VEERG_6_4_1_1__1__MethaneEmissionsFromBurningOfCropResidues_NIRReference: _xlfn.LAMBDA("")
Name AgResidue_Equations_FieldBurning.VEERG_6_4_1_1__1__MethaneEmissionsFromBurningOfCropResidues_Source: _xlfn.LAMBDA("VEERG 2026: 6.4.1.1, Equation (1)")
Name AgResidue_Equations_FieldBurning.VEERG_6_4_1_1__1__MethaneEmissionsFromBurningOfCropResidues_Title: _xlfn.LAMBDA("Methane emissions from the burning of crop residues")
Name AgResidue_Equations_FieldBurning.VEERG_6_4_1_1__1__MethaneEmissionsFromBurningOfCropResidues_Unit: _xlfn.LAMBDA("t CH4")
Name AgResidue_Equations_FieldBurning.VEERG_6_4_1_1__1__MethaneEmissionsFromBurningOfCropResidues_Variable: _xlfn.LAMBDA("ECH4")
Name AgResidue_Equations_FieldBurning.VEERG_6_4_1_1__2__NitrousOxideEmissionsFromBurningOfCropResidues: _xlfn.LAMBDA(_xlpm.M_burnc,_xlpm.NC_AGc,_xlpm.EF_N2O,_xlpm.C_N2O, (_xlpm.M_burnc * _xlpm.NC_AGc) * _xlpm.EF_N2O * _xlpm.C_N2O * 10 ^ (-3))
Name AgResidue_Equations_FieldBurning.VEERG_6_4_1_1__2__NitrousOxideEmissionsFromBurningOfCropResidues_FunctionName: _xlfn.LAMBDA("VEERG_6_4_1_1__2__NitrousOxideEmissionsFromBurningOfCropResidues")
Name AgResidue_Equations_FieldBurning.VEERG_6_4_1_1__2__NitrousOxideEmissionsFromBurningOfCropResidues_LatexEquation: _xlfn.LAMBDA("E_{N2O}=\sum\nolimits_c(M_{burn,c}\times NC_{AGc})\times EF_{N2O}\times C_{N2O}\times 10^{-3}")
Name AgResidue_Equations_FieldBurning.VEERG_6_4_1_1__2__NitrousOxideEmissionsFromBurningOfCropResidues_NIRReference: _xlfn.LAMBDA("")
Name AgResidue_Equations_FieldBurning.VEERG_6_4_1_1__2__NitrousOxideEmissionsFromBurningOfCropResidues_Source: _xlfn.LAMBDA("VEERG 2026: 6.4.1.1, Equation (2)")
Name AgResidue_Equations_FieldBurning.VEERG_6_4_1_1__2__NitrousOxideEmissionsFromBurningOfCropResidues_Title: _xlfn.LAMBDA("Nitrous oxide emissions from the burning of crop residues")
Name AgResidue_Equations_FieldBurning.VEERG_6_4_1_1__2__NitrousOxideEmissionsFromBurningOfCropResidues_Unit: _xlfn.LAMBDA("t N2O")
Name AgResidue_Equations_FieldBurning.VEERG_6_4_1_1__2__NitrousOxideEmissionsFromBurningOfCropResidues_Variable: _xlfn.LAMBDA("EN2O")
Name AgResidue_Equations_FieldBurning.VEERG_6_4_1_1__3__MassOfCropResidueBurnt: _xlfn.LAMBDA(_xlpm.P_c,_xlpm.R_AGc,_xlpm.S_c,_xlpm.DM_c,_xlpm.Z_c,_xlpm.F_c, _xlpm.P_c * _xlpm.R_AGc * _xlpm.S_c * _xlpm.DM_c * _xlpm.Z_c * _xlpm.F_c)
Name AgResidue_Equations_FieldBurning.VEERG_6_4_1_1__3__MassOfCropResidueBurnt_FunctionName: _xlfn.LAMBDA("VEERG_6_4_1_1__3__MassOfCropResidueBurnt")
Name AgResidue_Equations_FieldBurning.VEERG_6_4_1_1__3__MassOfCropResidueBurnt_LatexEquation: _xlfn.LAMBDA("M_{burn,c}=P_{c}\times R_{AGc}\times S_{c}\times DM_{c}\times Z_{c}\times F_{c}")
Name AgResidue_Equations_FieldBurning.VEERG_6_4_1_1__3__MassOfCropResidueBurnt_NIRReference: _xlfn.LAMBDA("")
Name AgResidue_Equations_FieldBurning.VEERG_6_4_1_1__3__MassOfCropResidueBurnt_Source: _xlfn.LAMBDA("VEERG 2026: 6.4.1.1, Equation (3)")
Name AgResidue_Equations_FieldBurning.VEERG_6_4_1_1__3__MassOfCropResidueBurnt_Title: _xlfn.LAMBDA("Mass of residue of crop c burnt")
Name AgResidue_Equations_FieldBurning.VEERG_6_4_1_1__3__MassOfCropResidueBurnt_Unit: _xlfn.LAMBDA("kg")
Name AgResidue_Equations_FieldBurning.VEERG_6_4_1_1__3__MassOfCropResidueBurnt_Variable: _xlfn.LAMBDA("M_burnc")
Name AgResidue_Equations_Leaching.VEERG_6_3_1_1__1__LeachingAndRunoffEmissionsCropAndPastureResidue: _xlfn.LAMBDA(_xlpm.M_leachcp,_xlpm.EF_leach,_xlpm.C_N2O, (_xlpm.M_leachcp * _xlpm.EF_leach) * _xlpm.C_N2O * 10 ^ (-3))
Name AgResidue_Equations_Leaching.VEERG_6_3_1_1__1__LeachingAndRunoffEmissionsCropAndPastureResidue_LatexEquation: _xlfn.LAMBDA("E_{N2O}=\sum\nolimits_c\sum\nolimits_p(M_{leach,cp}\times EF_{leach}\times C_{N2O}\times 10^{-3})")
Name AgResidue_Equations_Leaching.VEERG_6_3_1_1__1__LeachingAndRunoffEmissionsCropAndPastureResidue_NIRReference: _xlfn.LAMBDA("")
Name AgResidue_Equations_Leaching.VEERG_6_3_1_1__1__LeachingAndRunoffEmissionsCropAndPastureResidue_Source: _xlfn.LAMBDA("VEERG 2026: 6.3.1.1, Equation (1)")
Name AgResidue_Equations_Leaching.VEERG_6_3_1_1__1__LeachingAndRunoffEmissionsCropAndPastureResidue_Title: _xlfn.LAMBDA("Nitrous oxide leaching and runoff emissions from crop and pasture residues returned to the soil")
Name AgResidue_Equations_Leaching.VEERG_6_3_1_1__1__LeachingAndRunoffEmissionsCropAndPastureResidue_Unit: _xlfn.LAMBDA("t N2O")
Name AgResidue_Equations_Leaching.VEERG_6_3_1_1__1__LeachingAndRunoffEmissionsCropAndPastureResidue_Variable: _xlfn.LAMBDA("EN2O")
Name AgResidue_Equations_Leaching.VEERG_6_3_1_1__2__MassOfNitrogenLostThroughLeachingAndRunoff: _xlfn.LAMBDA(_xlpm.M_cp,_xlpm.FracWET_j,_xlpm.FracLEACH, _xlpm.M_cp * _xlpm.FracWET_j * _xlpm.FracLEACH)
Name AgResidue_Equations_Leaching.VEERG_6_3_1_1__2__MassOfNitrogenLostThroughLeachingAndRunoff_LatexEquation: _xlfn.LAMBDA("M_{leach,cp}=M_{cp}\times FracWET_{j}\times FracLEACH")
Name AgResidue_Equations_Leaching.VEERG_6_3_1_1__2__MassOfNitrogenLostThroughLeachingAndRunoff_NIRReference: _xlfn.LAMBDA("")
Name AgResidue_Equations_Leaching.VEERG_6_3_1_1__2__MassOfNitrogenLostThroughLeachingAndRunoff_Source: _xlfn.LAMBDA("VEERG 2026: 6.3.1.1, Equation (2)")
Name AgResidue_Equations_Leaching.VEERG_6_3_1_1__2__MassOfNitrogenLostThroughLeachingAndRunoff_Title: _xlfn.LAMBDA("Mass of nitrogen lost through leaching and runoff")

Sheet Home
A1: #VALUE!
A3: =HYPERLINK("#'Home'!A1", "Home") -> Home
A4: =HYPERLINK("#'Results - Activity period'!A1", "Results - Activity period") -> Results - Activity period
A5: =HYPERLINK("#'Results - Product EI'!A1", "Results - Product Emissions Intensity") -> Results - Product Emissions Intensity
A6: =HYPERLINK("#'Results'!A1", "Results") -> Results
A9: INPUTS
A10: =HYPERLINK("#'Input - Enterprise'!A1", "Enterprise") -> Enterprise
A11: =HYPERLINK("#'Input - Site'!A1", "Site") -> Site
A12: =HYPERLINK("#'Input - Dairy'!A1", "Dairy") -> Dairy
A13: =HYPERLINK("#'Input - Livestock sales'!A1", "Livestock sales") -> Livestock sales
A14: =HYPERLINK("#'Input - Dairy cattle purchases'!A1", "Dairy cattle purchases") -> Dairy cattle purchases
A15: =HYPERLINK("#'Input - Pasture'!A1", "Pasture") -> Pasture
A16: =HYPERLINK("#'Input - Fert Prod System'!A1", "Fert Prod System") -> Fert Prod System
A17: =HYPERLINK("#'Input - Fertiliser'!A1", "Fertiliser") -> Fertiliser
A18: =HYPERLINK("#'Input - Fuel'!A1", "Fuel") -> Fuel
A19: =HYPERLINK("#'Input - Electricity'!A1", "Electricity") -> Electricity
A20: =HYPERLINK("#'Input - Common farm inputs'!A1", "Common farm inputs") -> Common farm inputs
A21: =HYPERLINK("#'Input - Crop pasture farm input'!A1", "Crop pasture farm input") -> Crop pasture farm input
A22: =HYPERLINK("#'Input - Livestock farm Inputs'!A1", "Livestock farm Inputs") -> Livestock farm Inputs
A23: =HYPERLINK("#'Input - Freight'!A1", "Freight") -> Freight
A24: =HYPERLINK("#'Input - Solid waste'!A1", "Solid waste") -> Solid waste
A25: =HYPERLINK("#'Input - Manure sent off-site'!A1", "Manure sent off-site") -> Manure sent off-site
A26: =HYPERLINK("#'Input - Refrigerants'!A1", "Refrigerants") -> Refrigerants
A27: =HYPERLINK("#'Input - Data quality'!A1", "Data quality") -> Data quality
A30: CALCULATIONS
A31: =HYPERLINK("#'3.3.1.1-2 Enteric Methane'!A1", "3.3.1.1-2 Enteric methane") -> 3.3.1.1-2 Enteric methane
A32: =HYPERLINK("#'4.3.1.1-2 Methane'!A1", "4.3.1.1-2 Manure methane") -> 4.3.1.1-2 Manure methane
A33: =HYPERLINK("#'4.3.1.3-4 Direct N20'!A1", "4.3.1.3-4 Direct N20") -> 4.3.1.3-4 Direct N20
A34: =HYPERLINK("#'4.3.1.5 Atmos deposition'!A1", "4.3.1.5 Atmos deposition") -> 4.3.1.5 Atmos deposition
A35: =HYPERLINK("#'4.3.1.6-7 Leaching and runoff'!A1", "4.3.1.6-7 Leaching & runoff") -> 4.3.1.6-7 Leaching & runoff
A36: =HYPERLINK("#'4.3.1.8 Manure applied to soils'!A1", "4.3.1.8 Manure applied to soils") -> 4.3.1.8 Manure applied to soils
A37: =HYPERLINK("#'4.3.1.9 Soil direct N2O'!A1", "4.3.1.9 Soil direct N2O") -> 4.3.1.9 Soil direct N2O
A38: =HYPERLINK("#'4.3.1.10-11 Soil Atmos Dep'!A1", "4.3.1.10-11 Soil Atmos Deposition") -> 4.3.1.10-11 Soil Atmos Deposition
A39: =HYPERLINK("#'4.3.1.12-13 Soil leach runoff'!A1", "4.3.1.12-13 Soil leach & runoff") -> 4.3.1.12-13 Soil leach & runoff
A40: =HYPERLINK("#'5.1.1.1-2 Inorganic fert N2O'!A1", "5.1.1.1-2 Inorganic fert N2O") -> 5.1.1.1-2 Inorganic fert N2O
A41: =HYPERLINK("#'5.1.1.3-4 Inorganic fert CO2'!A1", "5.1.1.3-4 Inorganic fert CO2") -> 5.1.1.3-4 Inorganic fert CO2
A42: =HYPERLINK("#'5.2.1.1-2 Organic Fert N2O'!A1", "5.2.1.1-2 Organic fert N2O") -> 5.2.1.1-2 Organic fert N2O
A43: =HYPERLINK("#'5.3.1.1-2 Lime CO2'!A1", "5.3.1.1-2 Lime CO2") -> 5.3.1.1-2 Lime CO2
A44: =HYPERLINK("#'5.4.1.1-4 Atmos deposition'!A1", "5.4.1.1-4 Atmos. deposition") -> 5.4.1.1-4 Atmos. deposition
A45: =HYPERLINK("#'5.5.1.1-2 Leaching and runoff'!A1", "5.5.1.1-2 Leaching & runoff") -> 5.5.1.1-2 Leaching & runoff
...

Sheet Results - Activity period
A1: #VALUE! | C1: Results - Activity period
A3: =HYPERLINK("#'Home'!A1", "Home") -> Home
A4: =HYPERLINK("#'Results - Activity period'!A1", "Results - Activity period") -> Results - Activity period
A5: =HYPERLINK("#'Results - Product EI'!A1", "Results - Product Emissions Intensity") -> Results - Product Emissions Intensity | D5: ="Emissions breakdown for activities running between " & TEXT(X_Cell_Site_StartDate, "dd mmmm yyyy") & " and " & TEXT('Input - Enterprise'!E13, "dd mmmm yyyy") -> Emissions breakdown for activities running between 01 January 2024 and 31 December 2024
A6: =HYPERLINK("#'Results'!A1", "Results") -> Results
D7: Scope 1
A9: INPUTS | D9: Scope 1 source | E9: GHG emissions method 1 | F9: GHG emissions method 2 | G9: GHG Unit | H9: CO2-e emissions method 1 | I9: CO2-e emissions method 2
A10: =HYPERLINK("#'Input - Enterprise'!A1", "Enterprise") -> Enterprise | D10: 3.3.1.1-2 Enteric methane | E10: {=VEERG_3_3_1_1__1_TotalAnnualMethaneFromEntericFermentationVariation_Result_Method1} -> 32.464683 | F10: {=VEERG_3_3_1_1__1_TotalAnnualMethaneFromEntericFermentationVariation_Result_Method2} -> 32.464683 | G10: t CH4 | H10: {=Common_Equations.Common_ConvertCH4ToCO2e(E10,_xlfn.XLOOKUP("CH4", Table_GWPData[Gas],Table_GWPData[CO2-e factor]))} -> 909.01112 | I10: {=Common_Equations.Common_ConvertCH4ToCO2e(F10,_xlfn.XLOOKUP("CH4", Table_GWPData[Gas],Table_GWPData[CO2-e factor]))} -> 909.01112 | J10: t CO2e
A11: =HYPERLINK("#'Input - Site'!A1", "Site") -> Site | D11: 4.3.1.1-2 Manure methane | E11: {=VEERG_4_3_1_1__1_TotalAnnualMethaneFromManureManagement_Result_Method1} -> 10.314346 | F11: {=VEERG_4_3_1_1__1_TotalAnnualMethaneFromManureManagement_Result_Method2} -> 10.640707 | G11: t CH4 | H11: {=Common_Equations.Common_ConvertCH4ToCO2e(E11,_xlfn.XLOOKUP("CH4", Table_GWPData[Gas],Table_GWPData[CO2-e factor]))} -> 288.80168 | I11: {=Common_Equations.Common_ConvertCH4ToCO2e(F11,_xlfn.XLOOKUP("CH4", Table_GWPData[Gas],Table_GWPData[CO2-e factor]))} -> 297.93979 | J11: t CO2e
A12: =HYPERLINK("#'Input - Dairy'!A1", "Dairy") -> Dairy | D12: 4.3.1.3-4 Manure direct N2O | E12: {=VEERG_4_3_1_3__1_TotalAnnualDirectNitrousOxideEmissionsFromMMS_Result_Method1} -> 0.058975626 | F12: {=VEERG_4_3_1_3__1_TotalAnnualDirectNitrousOxideEmissionsFromMMS_Result_Method2} -> 0.058975626 | G12: t N2O | H12: {=Common_Equations.Common_ConvertN2OToCO2e(E12,_xlfn.XLOOKUP("N2O", Table_GWPData[Gas],Table_GWPData[CO2-e factor]))} -> 15.628541 | I12: {=Common_Equations.Common_ConvertN2OToCO2e(F12,_xlfn.XLOOKUP("N2O", Table_GWPData[Gas],Table_GWPData[CO2-e factor]))} -> 15.628541 | J12: t CO2e
A13: =HYPERLINK("#'Input - Livestock sales'!A1", "Livestock sales") -> Livestock sales | D13: 4.3.1.5 Manure atmospheric deposition | E13: {=VEERG_4_3_1_5__1_AnnualAtmosphericDepositionEmissionsFromMMS_Result_Method1} -> 0.047299753 | F13: {=VEERG_4_3_1_5__1_AnnualAtmosphericDepositionEmissionsFromMMS_Result_Method2} -> 0.047299753 | G13: t N2O | H13: {=Common_Equations.Common_ConvertN2OToCO2e(E13,_xlfn.XLOOKUP("N2O", Table_GWPData[Gas],Table_GWPData[CO2-e factor]))} -> 12.534435 | I13: {=Common_Equations.Common_ConvertN2OToCO2e(F13,_xlfn.XLOOKUP("N2O", Table_GWPData[Gas],Table_GWPData[CO2-e factor]))} -> 12.534435 | J13: t CO2e
A14: =HYPERLINK("#'Input - Dairy cattle purchases'!A1", "Dairy cattle purchases") -> Dairy cattle purchases | D14: 4.3.1.6-7 Manure leaching and runoff | E14: {=VEERG_4_3_1_6__1_AnnualEmissionsFromLeachingAndRunoffFromMMS_Result_Method1} -> 0.0025949275 | F14: {=VEERG_4_3_1_6__1_AnnualEmissionsFromLeachingAndRunoffFromMMS_Result_Method2} -> 0.0025949275 | G14: t N2O | H14: {=Common_Equations.Common_ConvertN2OToCO2e(E14,_xlfn.XLOOKUP("N2O", Table_GWPData[Gas],Table_GWPData[CO2-e factor]))} -> 0.6876558 | I14: {=Common_Equations.Common_ConvertN2OToCO2e(F14,_xlfn.XLOOKUP("N2O", Table_GWPData[Gas],Table_GWPData[CO2-e factor]))} -> 0.6876558 | J14: t CO2e
A15: =HYPERLINK("#'Input - Pasture'!A1", "Pasture") -> Pasture | D15: 4.3.1.9 Soil direct N2O | E15: {=VEERG_4_3_1_9__1_DirectNitrousOxideEmissionsOnPasture_Result_Method1} -> 0.074716451 | F15: {=VEERG_4_3_1_9__1_DirectNitrousOxideEmissionsOnPasture_Result_Method2} -> 0.074716451 | G15: t N2O | H15: {=Common_Equations.Common_ConvertN2OToCO2e(E15,_xlfn.XLOOKUP("N2O", Table_GWPData[Gas],Table_GWPData[CO2-e factor]))} -> 19.79986 | I15: {=Common_Equations.Common_ConvertN2OToCO2e(F15,_xlfn.XLOOKUP("N2O", Table_GWPData[Gas],Table_GWPData[CO2-e factor]))} -> 19.79986 | J15: t CO2e
A16: =HYPERLINK("#'Input - Fert Prod System'!A1", "Fert Prod System") -> Fert Prod System | D16: 4.3.1.10-11 Soil atmospheric deposition | E16: {=VEERG_4_3_1_10__1_AtmosphericDepositionEmissionsFromUrineAndDungOnPasture_Result_Method1} -> 0.046286842 | F16: {=VEERG_4_3_1_10__1_AtmosphericDepositionEmissionsFromUrineAndDungOnPasture_Result_Method2} -> 0.046286842 | G16: t N2O | H16: {=Common_Equations.Common_ConvertN2OToCO2e(E16,_xlfn.XLOOKUP("N2O", Table_GWPData[Gas],Table_GWPData[CO2-e factor]))} -> 12.266013 | I16: {=Common_Equations.Common_ConvertN2OToCO2e(F16,_xlfn.XLOOKUP("N2O", Table_GWPData[Gas],Table_GWPData[CO2-e factor]))} -> 12.266013 | J16: t CO2e
A17: =HYPERLINK("#'Input - Fertiliser'!A1", "Fertiliser") -> Fertiliser | D17: 4.3.1.12-13 Soil leaching and runoff | E17: {=VEERG_4_3_1_12__1_LeachingAndRunoffEmissionsFromUrineAndDungOnPasture_Result_Method1} -> 0.098625716 | F17: {=VEERG_4_3_1_12__1_LeachingAndRunoffEmissionsFromUrineAndDungOnPasture_Result_Method2} -> 0.098625716 | G17: t N2O | H17: {=Common_Equations.Common_ConvertN2OToCO2e(E17,_xlfn.XLOOKUP("N2O", Table_GWPData[Gas],Table_GWPData[CO2-e factor]))} -> 26.135815 | I17: {=Common_Equations.Common_ConvertN2OToCO2e(F17,_xlfn.XLOOKUP("N2O", Table_GWPData[Gas],Table_GWPData[CO2-e factor]))} -> 26.135815 | J17: t CO2e
A18: =HYPERLINK("#'Input - Fuel'!A1", "Fuel") -> Fuel | D18: 5.1.1.1-2 Inorganic fert N2O | E18: {=VEERG_5_1_1_1__1_InorganicFertiliserApplicationN2OEmissions_Result_Method1} -> 1.6950489 | F18: {=VEERG_5_1_1_1__1_InorganicFertiliserApplicationN2OEmissions_Result_Method2} -> 1.6950489 | G18: t N2O | H18: {=Common_Equations.Common_ConvertN2OToCO2e(E18,_xlfn.XLOOKUP("N2O", Table_GWPData[Gas],Table_GWPData[CO2-e factor]))} -> 449.18795 | I18: {=Common_Equations.Common_ConvertN2OToCO2e(F18,_xlfn.XLOOKUP("N2O", Table_GWPData[Gas],Table_GWPData[CO2-e factor]))} -> 449.18797 | J18: t CO2e
A19: =HYPERLINK("#'Input - Electricity'!A1", "Electricity") -> Electricity | D19: 5.1.1.3-4 Inorganic fert CO2 | E19: {=VEERG_5_1_1_3__1_InorganicFertiliserApplicationCO2Emissions_Result_Method1} -> 184.92753 | F19: =E19 -> 184.92753 | G19: t CO2 | H19: =E19 -> 184.92753 | I19: =F19 -> 184.92753 | J19: t CO2e
A20: =HYPERLINK("#'Input - Common farm inputs'!A1", "Common farm inputs") -> Common farm inputs | D20: 5.2.1.1-2 Organic fert N2O | E20: {=VEERG_5_2_1_1__2_MassOfNitrogenInOrganicFertiliser_Result_Method1} -> 0.055785714 | F20: =E20 -> 0.055785714 | G20: t N2O | H20: {=Common_Equations.Common_ConvertN2OToCO2e(E20,_xlfn.XLOOKUP("N2O", Table_GWPData[Gas],Table_GWPData[CO2-e factor]))} -> 14.783214 | I20: {=Common_Equations.Common_ConvertN2OToCO2e(F20,_xlfn.XLOOKUP("N2O", Table_GWPData[Gas],Table_GWPData[CO2-e factor]))} -> 14.783214 | J20: t CO2e
A21: =HYPERLINK("#'Input - Crop pasture farm input'!A1", "Crop pasture farm input") -> Crop pasture farm input | D21: 5.3.1.1-2 Lime CO2 | E21: {=VEERG_5_3_1_1__1_LimeApplicationCO2Emissions_Result_Method1} -> 758.08333 | F21: =E21 -> 758.08333 | G21: t CO2 | H21: =E21 -> 758.08333 | I21: =F21 -> 758.08333 | J21: t CO2e
A22: =HYPERLINK("#'Input - Livestock farm Inputs'!A1", "Livestock farm Inputs") -> Livestock farm Inputs | D22: 5.4.1.1-4 Atmos. deposition | E22: {=VEERG_5_4_1_3__1_OrganicFertiliserAtmosphericDepositionN2OEmissions_Result_Method1} -> 0.0138237 | F22: =E22 -> 0.0138237 | G22: t N2O | H22: {=Common_Equations.Common_ConvertN2OToCO2e(E22,_xlfn.XLOOKUP("N2O", Table_GWPData[Gas],Table_GWPData[CO2-e factor]))} -> 3.6632805 | I22: {=Common_Equations.Common_ConvertN2OToCO2e(F22,_xlfn.XLOOKUP("N2O", Table_GWPData[Gas],Table_GWPData[CO2-e factor]))} -> 3.6632805 | J22: t CO2e
A23: =HYPERLINK("#'Input - Freight'!A1", "Freight") -> Freight | D23: 5.5.1.1-2 Leaching & runoff | E23: {=VEERG_5_5_1_1__1_FertiliserLeachingAndRunoffN2OEmissions_result_Method1} -> 0.7879174 | F23: =E23 -> 0.7879174 | G23: t N2O | H23: {=Common_Equations.Common_ConvertN2OToCO2e(E23,_xlfn.XLOOKUP("N2O", Table_GWPData[Gas],Table_GWPData[CO2-e factor]))} -> 208.79811 | I23: {=Common_Equations.Common_ConvertN2OToCO2e(F23,_xlfn.XLOOKUP("N2O", Table_GWPData[Gas],Table_GWPData[CO2-e factor]))} -> 208.79811 | J23: t CO2e
A24: =HYPERLINK("#'Input - Solid waste'!A1", "Solid waste") -> Solid waste | D24: 6.2.1.1-2 Pasture residue N2O | E24: {=VEERG_6_2_1_1__1__NitrousOxideEmissionsFromPastureResidues_Result_Method1} -> 5.8320429e-07 | F24: {=VEERG_6_2_1_1__1__NitrousOxideEmissionsFromPastureResidues_Result_Method2} -> 5.8320429e-07 | G24: t N2O | H24: {=Common_Equations.Common_ConvertN2OToCO2e(E24,_xlfn.XLOOKUP("N2O", Table_GWPData[Gas],Table_GWPData[CO2-e factor]))} -> 0.00015454914 | I24: {=Common_Equations.Common_ConvertN2OToCO2e(F24,_xlfn.XLOOKUP("N2O", Table_GWPData[Gas],Table_GWPData[CO2-e factor]))} -> 0.00015454914 | J24: t CO2e
A25: =HYPERLINK("#'Input - Manure sent off-site'!A1", "Manure sent off-site") -> Manure sent off-site | D25: 6.3.1.1-2 Leach & runoff (pasture) | E25: {=VEERG_6_3_1_1__1__LeachingAndRunoffEmissionsCropAndPastureResidue_PastureOnly_Result_Method1} -> 3.0793186e-07 | F25: {=VEERG_6_3_1_1__1__LeachingAndRunoffEmissionsCropAndPastureResidue_PastureOnly_Result_Method2} -> 3.0793186e-07 | G25: t N2O | H25: {=Common_Equations.Common_ConvertN2OToCO2e(E25,_xlfn.XLOOKUP("N2O", Table_GWPData[Gas],Table_GWPData[CO2-e factor]))} -> 8.1601944e-05 | I25: {=Common_Equations.Common_ConvertN2OToCO2e(F25,_xlfn.XLOOKUP("N2O", Table_GWPData[Gas],Table_GWPData[CO2-e factor]))} -> 8.1601944e-05 | J25: t CO2e
A26: =HYPERLINK("#'Input - Refrigerants'!A1", "Refrigerants") -> Refrigerants | D26: 8.1.1.1-2 Transport fuel CO2 | E26: {=VEERG_8_1_1_1__1_FuelCombustionTransport_Result_CO2} -> 83.182 | F26: =E26 -> 83.182 | G26: t CO2 | H26: =E26 -> 83.182 | I26: =F26 -> 83.182 | J26: t CO2e
A27: =HYPERLINK("#'Input - Data quality'!A1", "Data quality") -> Data quality | D27: 8.1.1.1-2 Transport fuel CH4 | E27: {=VEERG_8_1_1_1__1_FuelCombustionTransport_Result_CH4} -> 0.19906 | F27: =E27 -> 0.19906 | G27: t CH4 | H27: {=Common_Equations.Common_ConvertCH4ToCO2e(E27,_xlfn.XLOOKUP("CH4", Table_GWPData[Gas],Table_GWPData[CO2-e factor]))} -> 5.57368 | I27: {=Common_Equations.Common_ConvertCH4ToCO2e(F27,_xlfn.XLOOKUP("CH4", Table_GWPData[Gas],Table_GWPData[CO2-e factor]))} -> 5.57368 | J27: t CO2e
D28: 8.1.1.1-2 Transport fuel N2O | E28: {=VEERG_8_1_1_1__1_FuelCombustionTransport_Result_N2O} -> 0.5845 | F28: =E28 -> 0.5845 | G28: t N2O | H28: {=Common_Equations.Common_ConvertN2OToCO2e(E28,_xlfn.XLOOKUP("N2O", Table_GWPData[Gas],Table_GWPData[CO2-e factor]))} -> 154.8925 | I28: {=Common_Equations.Common_ConvertN2OToCO2e(F28,_xlfn.XLOOKUP("N2O", Table_GWPData[Gas],Table_GWPData[CO2-e factor]))} -> 154.8925 | J28: t CO2e
D29: 8.2.1.1-2 Stationary fuel CO2 | E29: {=VEERG_8_2_1_1__1_FuelCombustionStationary_Result_CO2} -> 29.0708 | F29: =E29 -> 29.0708 | G29: t CO2 | H29: =E29 -> 29.0708 | I29: =F29 -> 29.0708 | J29: t CO2e
A30: CALCULATIONS | D30: 8.2.1.1-2 Stationary fuel CH4 | E30: {=VEERG_8_2_1_1__1_FuelCombustionStationary_Result_CH4} -> 0.0724 | F30: =E30 -> 0.0724 | G30: t CH4 | H30: {=Common_Equations.Common_ConvertCH4ToCO2e(E30,_xlfn.XLOOKUP("CH4", Table_GWPData[Gas],Table_GWPData[CO2-e factor]))} -> 2.0272 | I30: {=Common_Equations.Common_ConvertCH4ToCO2e(F30,_xlfn.XLOOKUP("CH4", Table_GWPData[Gas],Table_GWPData[CO2-e factor]))} -> 2.0272 | J30: t CO2e
A31: =HYPERLINK("#'3.3.1.1-2 Enteric Methane'!A1", "3.3.1.1-2 Enteric methane") -> 3.3.1.1-2 Enteric methane | D31: 8.2.1.1-2 Stationary fuel N2O | E31: {=VEERG_8_2_1_1__1_FuelCombustionStationary_Result_N2O} -> 0.0714 | F31: =E31 -> 0.0714 | G31: t N2O | H31: {=Common_Equations.Common_ConvertN2OToCO2e(E31,_xlfn.XLOOKUP("N2O", Table_GWPData[Gas],Table_GWPData[CO2-e factor]))} -> 18.921 | I31: {=Common_Equations.Common_ConvertN2OToCO2e(F31,_xlfn.XLOOKUP("N2O", Table_GWPData[Gas],Table_GWPData[CO2-e factor]))} -> 18.921 | J31: t CO2e
A32: =HYPERLINK("#'4.3.1.1-2 Methane'!A1", "4.3.1.1-2 Manure methane") -> 4.3.1.1-2 Manure methane | D32: 9.1.1.1-2 Refrigerant leakage - Gas 1 | E32: {=VEERG_9_1_1__1_RefrigerantLeaking_Result_Blend1_Value_Method1} -> 0.00085 | F32: =E32 -> 0.00085 | G32: {=IF(ISBLANK(VEERG_9_1_1__1_RefrigerantLeaking_Result_Blend1_Name_Method1), "", "t " & VEERG_9_1_1__1_RefrigerantLeaking_Result_Blend1_Name_Method1)} -> t R-402A | H32: =INDEX(Table_E_CO2e,2,4) -> 1.1860424 | I32: =H32 -> 1.1860424 | J32: t CO2e
A33: =HYPERLINK("#'4.3.1.3-4 Direct N20'!A1", "4.3.1.3-4 Direct N20") -> 4.3.1.3-4 Direct N20 | D33: 9.1.1.1-2 Refrigerant leakage - Gas 2 | E33: {=VEERG_9_1_1__1_RefrigerantLeaking_Result_Blend2_Value_Method1} -> 0.00175 | F33: =E33 -> 0.00175 | G33: {=IF(ISBLANK(VEERG_9_1_1__1_RefrigerantLeaking_Result_Blend2_Name_Method1), "", "t " & VEERG_9_1_1__1_RefrigerantLeaking_Result_Blend2_Name_Method1)} -> t R-422B | H33: =INDEX(Table_E_CO2e,3,4) -> 2.0794288 | I33: =H33 -> 2.0794288 | J33: t CO2e
A34: =HYPERLINK("#'4.3.1.5 Atmos deposition'!A1", "4.3.1.5 Atmos deposition") -> 4.3.1.5 Atmos deposition | D34: 9.1.1.1-2 Refrigerant leakage - Gas 3 | E34: {=VEERG_9_1_1__1_RefrigerantLeaking_Result_Blend3_Value_Method1} -> 0.01221 | F34: =E34 -> 0.01221 | G34: {=IF(ISBLANK(VEERG_9_1_1__1_RefrigerantLeaking_Result_Blend3_Name_Method1), "", "t " & VEERG_9_1_1__1_RefrigerantLeaking_Result_Blend3_Name_Method1)} -> t R-400 60/40 | H34: =INDEX(Table_E_CO2e,4,4) -> 70.007256 | I34: =H34 -> 70.007256 | J34: t CO2e
A35: =HYPERLINK("#'4.3.1.6-7 Leaching and runoff'!A1", "4.3.1.6-7 Leaching & runoff") -> 4.3.1.6-7 Leaching & runoff | D35: 9.1.1.1-2 Refrigerant leakage - Gas 4 | E35: {=VEERG_9_1_1__1_RefrigerantLeaking_Result_Blend4_Value_Method1} -> 0.0157 | F35: =E35 -> 0.0157 | G35: {=IF(ISBLANK(VEERG_9_1_1__1_RefrigerantLeaking_Result_Blend4_Name_Method1), "", "t " & VEERG_9_1_1__1_RefrigerantLeaking_Result_Blend4_Name_Method1)} -> t R-504 | H35: =INDEX(Table_E_CO2e,5,4) -> 34.780656 | I35: =H35 -> 34.780656 | J35: t CO2e
A36: =HYPERLINK("#'4.3.1.8 Manure applied to soils'!A1", "4.3.1.8 Manure applied to soils") -> 4.3.1.8 Manure applied to soils | D36: 9.1.1.1-2 Refrigerant leakage - Gas 5 | E36: {=VEERG_9_1_1__1_RefrigerantLeaking_Result_Blend5_Value_Method1} -> 0 | F36: =E36 -> 0 | G36: {=IF(ISBLANK(VEERG_9_1_1__1_RefrigerantLeaking_Result_Blend5_Name_Method1), "", "t " & VEERG_9_1_1__1_RefrigerantLeaking_Result_Blend5_Name_Method1)} | H36: =INDEX(Table_E_CO2e,6,4) -> 0 | I36: =H36 -> 0 | J36: t CO2e
A37: =HYPERLINK("#'4.3.1.9 Soil direct N2O'!A1", "4.3.1.9 Soil direct N2O") -> 4.3.1.9 Soil direct N2O | D37: 9.1.1.1-2 Refrigerant leakage - Gas 6 | E37: {=VEERG_9_1_1__1_RefrigerantLeaking_Result_Blend6_Value_Method1} -> 0 | F37: =E37 -> 0 | G37: {=IF(ISBLANK(VEERG_9_1_1__1_RefrigerantLeaking_Result_Blend6_Name_Method1), "", "t " & VEERG_9_1_1__1_RefrigerantLeaking_Result_Blend6_Name_Method1)} | H37: =INDEX(Table_E_CO2e,7,4) -> 0 | I37: =H37 -> 0 | J37: t CO2e
A38: =HYPERLINK("#'4.3.1.10-11 Soil Atmos Dep'!A1", "4.3.1.10-11 Soil Atmos Deposition") -> 4.3.1.10-11 Soil Atmos Deposition | D38: 9.1.1.1-2 Refrigerant leakage - Gas 7 | E38: {=VEERG_9_1_1__1_RefrigerantLeaking_Result_Blend7_Value_Method1} -> 0 | F38: =E38 -> 0 | G38: {=IF(ISBLANK(VEERG_9_1_1__1_RefrigerantLeaking_Result_Blend7_Name_Method1), "", "t " & VEERG_9_1_1__1_RefrigerantLeaking_Result_Blend7_Name_Method1)} | H38: =INDEX(Table_E_CO2e,8,4) -> 0 | I38: =H38 -> 0 | J38: t CO2e
A39: =HYPERLINK("#'4.3.1.12-13 Soil leach runoff'!A1", "4.3.1.12-13 Soil leach & runoff") -> 4.3.1.12-13 Soil leach & runoff | D39: 9.1.1.1-2 Refrigerant leakage - Gas 8 | E39: {=VEERG_9_1_1__1_RefrigerantLeaking_Result_Blend8_Value_Method1} -> 0 | F39: =E39 -> 0 | G39: {=IF(ISBLANK(VEERG_9_1_1__1_RefrigerantLeaking_Result_Blend8_Name_Method1), "", "t " & VEERG_9_1_1__1_RefrigerantLeaking_Result_Blend8_Name_Method1)} | H39: =INDEX(Table_E_CO2e,9,4) -> 0 | I39: =H39 -> 0 | J39: t CO2e
A40: =HYPERLINK("#'5.1.1.1-2 Inorganic fert N2O'!A1", "5.1.1.1-2 Inorganic fert N2O") -> 5.1.1.1-2 Inorganic fert N2O | D40: 9.1.1.1-2 Refrigerant leakage - Gas 9 | E40: {=VEERG_9_1_1__1_RefrigerantLeaking_Result_Blend9_Value_Method1} -> 0 | F40: =E40 -> 0 | G40: {=IF(ISBLANK(VEERG_9_1_1__1_RefrigerantLeaking_Result_Blend9_Name_Method1), "", "t " & VEERG_9_1_1__1_RefrigerantLeaking_Result_Blend9_Name_Method1)} | H40: =INDEX(Table_E_CO2e,10,4) -> 0 | I40: =H40 -> 0 | J40: t CO2e
A41: =HYPERLINK("#'5.1.1.3-4 Inorganic fert CO2'!A1", "5.1.1.3-4 Inorganic fert CO2") -> 5.1.1.3-4 Inorganic fert CO2 | D41: 9.1.1.1-2 Refrigerant leakage - Gas 10 | E41: {=VEERG_9_1_1__1_RefrigerantLeaking_Result_Blend10_Value_Method1} -> 0 | F41: =E41 -> 0 | G41: {=IF(ISBLANK(VEERG_9_1_1__1_RefrigerantLeaking_Result_Blend10_Name_Method1), "", "t " & VEERG_9_1_1__1_RefrigerantLeaking_Result_Blend10_Name_Method1)} | H41: =INDEX(Table_E_CO2e,11,4) -> 0 | I41: =H41 -> 0 | J41: t CO2e
A42: =HYPERLINK("#'5.2.1.1-2 Organic Fert N2O'!A1", "5.2.1.1-2 Organic fert N2O") -> 5.2.1.1-2 Organic fert N2O | D42: 10.1.1-2 Solid waste treatment | E42: {=VEERG_10_1_1_1__1_EmissionsFromWasteManagement_Scope1_Result_Method1} -> 438.82805 | F42: =E42 -> 438.82805 | G42: t CO2-e | H42: =E42 -> 438.82805 | I42: =F42 -> 438.82805 | J42: t CO2e
...

Sheet Results - Product EI
A1: #VALUE! | C1: Results - Product emissions intensity
A3: =HYPERLINK("#'Home'!A1", "Home") -> Home
A4: =HYPERLINK("#'Results - Activity period'!A1", "Results - Activity period") -> Results - Activity period
A5: =HYPERLINK("#'Results - Product EI'!A1", "Results - Product Emissions Intensity") -> Results - Product Emissions Intensity
A6: =HYPERLINK("#'Results'!A1", "Results") -> Results
A9: INPUTS
A10: =HYPERLINK("#'Input - Enterprise'!A1", "Enterprise") -> Enterprise
A11: =HYPERLINK("#'Input - Site'!A1", "Site") -> Site
A12: =HYPERLINK("#'Input - Dairy'!A1", "Dairy") -> Dairy
A13: =HYPERLINK("#'Input - Livestock sales'!A1", "Livestock sales") -> Livestock sales
A14: =HYPERLINK("#'Input - Dairy cattle purchases'!A1", "Dairy cattle purchases") -> Dairy cattle purchases
A15: =HYPERLINK("#'Input - Pasture'!A1", "Pasture") -> Pasture
A16: =HYPERLINK("#'Input - Fert Prod System'!A1", "Fert Prod System") -> Fert Prod System
A17: =HYPERLINK("#'Input - Fertiliser'!A1", "Fertiliser") -> Fertiliser
A18: =HYPERLINK("#'Input - Fuel'!A1", "Fuel") -> Fuel
A19: =HYPERLINK("#'Input - Electricity'!A1", "Electricity") -> Electricity
A20: =HYPERLINK("#'Input - Common farm inputs'!A1", "Common farm inputs") -> Common farm inputs
A21: =HYPERLINK("#'Input - Crop pasture farm input'!A1", "Crop pasture farm input") -> Crop pasture farm input
A22: =HYPERLINK("#'Input - Livestock farm Inputs'!A1", "Livestock farm Inputs") -> Livestock farm Inputs
A23: =HYPERLINK("#'Input - Freight'!A1", "Freight") -> Freight
A24: =HYPERLINK("#'Input - Solid waste'!A1", "Solid waste") -> Solid waste
A25: =HYPERLINK("#'Input - Manure sent off-site'!A1", "Manure sent off-site") -> Manure sent off-site
A26: =HYPERLINK("#'Input - Refrigerants'!A1", "Refrigerants") -> Refrigerants
A27: =HYPERLINK("#'Input - Data quality'!A1", "Data quality") -> Data quality
A30: CALCULATIONS
A31: =HYPERLINK("#'3.3.1.1-2 Enteric Methane'!A1", "3.3.1.1-2 Enteric methane") -> 3.3.1.1-2 Enteric methane
A32: =HYPERLINK("#'4.3.1.1-2 Methane'!A1", "4.3.1.1-2 Manure methane") -> 4.3.1.1-2 Manure methane | D32: ="Emissions for whole production cycle running between " & TEXT(X_Cell_Enterprise_ProductionTimeframeStart, "d mmmm yyyy") & " and " & TEXT(X_Cell_Enterprise_ProductionTimeframeEnd, "d mmmm yyyy") -> Emissions for whole production cycle running between 1 November 2023 and 31 March 2025
A33: =HYPERLINK("#'4.3.1.3-4 Direct N20'!A1", "4.3.1.3-4 Direct N20") -> 4.3.1.3-4 Direct N20
A34: =HYPERLINK("#'4.3.1.5 Atmos deposition'!A1", "4.3.1.5 Atmos deposition") -> 4.3.1.5 Atmos deposition
A35: =HYPERLINK("#'4.3.1.6-7 Leaching and runoff'!A1", "4.3.1.6-7 Leaching & runoff") -> 4.3.1.6-7 Leaching & runoff | E35: Method 1 | F35: Method 2
A36: =HYPERLINK("#'4.3.1.8 Manure applied to soils'!A1", "4.3.1.8 Manure applied to soils") -> 4.3.1.8 Manure applied to soils | D36: Emissions for production cycle excluding removals | E36: =Result_EmissionsForWholeProductionCycle_Gross_Method1 -> 5038.9537 | F36: =Result_EmissionsForWholeProductionCycle_Gross_Method2 -> 7753.9955 | G36: t CO2e
A37: =HYPERLINK("#'4.3.1.9 Soil direct N2O'!A1", "4.3.1.9 Soil direct N2O") -> 4.3.1.9 Soil direct N2O | D37: Net emissions for production cycle | E37: =Result_EmissionsForWholeProductionCycle_Net_Method1 -> 5038.9537 | F37: =Result_EmissionsForWholeProductionCycle_Net_Method2 -> 7753.9955 | G37: t CO2e
A38: =HYPERLINK("#'4.3.1.10-11 Soil Atmos Dep'!A1", "4.3.1.10-11 Soil Atmos Deposition") -> 4.3.1.10-11 Soil Atmos Deposition
A39: =HYPERLINK("#'4.3.1.12-13 Soil leach runoff'!A1", "4.3.1.12-13 Soil leach & runoff") -> 4.3.1.12-13 Soil leach & runoff | D39: ="Product emissions intensity for whole production cycle running between " & TEXT(X_Cell_Enterprise_ProductionTimeframeStart, "d mmmm yyyy") & " and " & TEXT(X_Cell_Enterprise_ProductionTimeframeEnd, "d mmmm yyyy") -> Product emissions intensity for whole production cycle running between 1 November 2023 and 31 March 2025
A40: =HYPERLINK("#'5.1.1.1-2 Inorganic fert N2O'!A1", "5.1.1.1-2 Inorganic fert N2O") -> 5.1.1.1-2 Inorganic fert N2O
A41: =HYPERLINK("#'5.1.1.3-4 Inorganic fert CO2'!A1", "5.1.1.3-4 Inorganic fert CO2") -> 5.1.1.3-4 Inorganic fert CO2
A42: =HYPERLINK("#'5.2.1.1-2 Organic Fert N2O'!A1", "5.2.1.1-2 Organic fert N2O") -> 5.2.1.1-2 Organic fert N2O | D42: Product emissions - Mass
A43: =HYPERLINK("#'5.3.1.1-2 Lime CO2'!A1", "5.3.1.1-2 Lime CO2") -> 5.3.1.1-2 Lime CO2 | D43: Product | E43: Product type | F43: Amount (tonnnes) | G43: Mass emissions assignment | H43: Emissions intensity (Method 1) | I43: Emissions intensity (Method 2) | J43: Unit
A44: =HYPERLINK("#'5.4.1.1-4 Atmos deposition'!A1", "5.4.1.1-4 Atmos. deposition") -> 5.4.1.1-4 Atmos. deposition | D44: Milk sold - excluding removals | E44: Main product | F44: =X_Cell_Enterprise_MilkProduced*(IF(X_Cell_Enterprise_MilkProducedUnit="Litres of milk", 1.03, 1))*10^-3 -> 7.74457 | G44: =F44/(F44+F46+F48) -> 0.56346397 | H44: =(E36/F44)*G44 -> 366.61414 | I44: =(F36/F44)*G44 -> 564.14973 | J44: t co2e/t milk sold
A45: =HYPERLINK("#'5.5.1.1-2 Leaching and runoff'!A1", "5.5.1.1-2 Leaching & runoff") -> 5.5.1.1-2 Leaching & runoff | D45: Milk sold - net emissions | E45: Main product | F45: =F44 -> 7.74457 | G45: =G44 -> 0.56346397 | H45: =(E37/F45)*G45 -> 366.61414 | I45: =(F37/F45)*G45 -> 564.14973 | J45: t co2e/t milk sold
...

Sheet Input - Enterprise
A1: #VALUE! | C1: Input - Enterprise
A3: =HYPERLINK("#'Home'!A1", "Home") -> Home
A4: =HYPERLINK("#'Results - Activity period'!A1", "Results - Activity period") -> Results - Activity period
A5: =HYPERLINK("#'Results - Product EI'!A1", "Results - Product Emissions Intensity") -> Results - Product Emissions Intensity | D5: Your business
A6: =HYPERLINK("#'Results'!A1", "Results") -> Results
D7: Farm name | E7: Test Farms
D8: Reporting entity name | E8: Test Farms Pty Ltd
A9: INPUTS
A10: =HYPERLINK("#'Input - Enterprise'!A1", "Enterprise") -> Enterprise | D10: 💡An 'Emissions accounting period' is a 12 month period where the business can report on the emissions, and is typically the same as the business' financial accounting period.
A11: =HYPERLINK("#'Input - Site'!A1", "Site") -> Site
A12: =HYPERLINK("#'Input - Dairy'!A1", "Dairy") -> Dairy | D12: Emissions calculation period start date | E12: 45292 | F12: ← DD/MM/YYYY or DD Month YYYY
A13: =HYPERLINK("#'Input - Livestock sales'!A1", "Livestock sales") -> Livestock sales | D13: Emissions calculation period end date | E13: =DATE(YEAR(E12)+1,MONTH(E12),DAY(E12))-1 -> 45657 | F13: ← Automatically calculated, 12 months after start date
A14: =HYPERLINK("#'Input - Dairy cattle purchases'!A1", "Dairy cattle purchases") -> Dairy cattle purchases
A15: =HYPERLINK("#'Input - Pasture'!A1", "Pasture") -> Pasture
A16: =HYPERLINK("#'Input - Fert Prod System'!A1", "Fert Prod System") -> Fert Prod System | D16: Production
A17: =HYPERLINK("#'Input - Fertiliser'!A1", "Fertiliser") -> Fertiliser
A18: =HYPERLINK("#'Input - Fuel'!A1", "Fuel") -> Fuel | D18: Production timeframe start | E18: 45231 | F18: ← DD/MM/YYYY or DD Month YYYY
A19: =HYPERLINK("#'Input - Electricity'!A1", "Electricity") -> Electricity | D19: Production timeframe end | E19: 45747 | F19: ← DD/MM/YYYY or DD Month YYYY
A20: =HYPERLINK("#'Input - Common farm inputs'!A1", "Common farm inputs") -> Common farm inputs | D20: Production timeframe length | E20: =DATEDIF(E18,E19+1,"m") -> 17 | F20: Months
A21: =HYPERLINK("#'Input - Crop pasture farm input'!A1", "Crop pasture farm input") -> Crop pasture farm input
A22: =HYPERLINK("#'Input - Livestock farm Inputs'!A1", "Livestock farm Inputs") -> Livestock farm Inputs | D22: Liveweight sold | E22: =SUM(Table_Input_LivestockSales[Total liveweight sold])*10^-3 -> 5 | F22: tonnes
A23: =HYPERLINK("#'Input - Freight'!A1", "Freight") -> Freight | D23: Milk produced unit | E23: {=X_Cell_Dairy_MilkProductionUnit} -> Litres of milk
A24: =HYPERLINK("#'Input - Solid waste'!A1", "Solid waste") -> Solid waste | D24: Milk produced | E24: {=X_Cell_Dairy_MilkProductionAmount*365*IF(E23="Milk solds", 1, 1.03)} -> 7519 | F24: =E23 -> Litres of milk
A25: =HYPERLINK("#'Input - Manure sent off-site'!A1", "Manure sent off-site") -> Manure sent off-site | D25: Manure sold | E25: 1 | F25: tonnes
A26: =HYPERLINK("#'Input - Refrigerants'!A1", "Refrigerants") -> Refrigerants | D26: Manure used as fertiliser on own farm | E26: 1 | F26: tonnes
A27: =HYPERLINK("#'Input - Data quality'!A1", "Data quality") -> Data quality
D28: Percentage of income from milk sold | E28: 0.8 | F28: percent
D29: Percentage of income from liveweight sold | E29: 0.15 | F29: percent
A30: CALCULATIONS | D30: Percentage of income from manure sold | E30: 0.05 | F30: percent
A31: =HYPERLINK("#'3.3.1.1-2 Enteric Methane'!A1", "3.3.1.1-2 Enteric methane") -> 3.3.1.1-2 Enteric methane
A32: =HYPERLINK("#'4.3.1.1-2 Methane'!A1", "4.3.1.1-2 Manure methane") -> 4.3.1.1-2 Manure methane
A33: =HYPERLINK("#'4.3.1.3-4 Direct N20'!A1", "4.3.1.3-4 Direct N20") -> 4.3.1.3-4 Direct N20
A34: =HYPERLINK("#'4.3.1.5 Atmos deposition'!A1", "4.3.1.5 Atmos deposition") -> 4.3.1.5 Atmos deposition | D34: Carbon removals
A35: =HYPERLINK("#'4.3.1.6-7 Leaching and runoff'!A1", "4.3.1.6-7 Leaching & runoff") -> 4.3.1.6-7 Leaching & runoff
A36: =HYPERLINK("#'4.3.1.8 Manure applied to soils'!A1", "4.3.1.8 Manure applied to soils") -> 4.3.1.8 Manure applied to soils
A37: =HYPERLINK("#'4.3.1.9 Soil direct N2O'!A1", "4.3.1.9 Soil direct N2O") -> 4.3.1.9 Soil direct N2O | D37: ="Carbon captured from " & TEXT(X_Cell_Site_StartDate, "d mmmm yyyy") & " to " & TEXT(X_Cell_Site_EndDate, "d, mmmm, yyyy") & " from environmental plantings" -> Carbon captured from 1 January 2024 to 31, December, 2024 from environmental plantings
A38: =HYPERLINK("#'4.3.1.10-11 Soil Atmos Dep'!A1", "4.3.1.10-11 Soil Atmos Deposition") -> 4.3.1.10-11 Soil Atmos Deposition
A39: =HYPERLINK("#'4.3.1.12-13 Soil leach runoff'!A1", "4.3.1.12-13 Soil leach & runoff") -> 4.3.1.12-13 Soil leach & runoff | D39: Planting name | E39: Total removed CO2 | F39: Percent allocated to this enterprise | G39: Removal allocated to this enterprise
A40: =HYPERLINK("#'5.1.1.1-2 Inorganic fert N2O'!A1", "5.1.1.1-2 Inorganic fert N2O") -> 5.1.1.1-2 Inorganic fert N2O | G40: =Table_Input_Enterprise_PlantingRemovals[[#This Row],[Total removed CO2]]*Table_Input_Enterprise_PlantingRemovals[[#This Row],[Percent allocated to this enterprise]] -> 0
A41: =HYPERLINK("#'5.1.1.3-4 Inorganic fert CO2'!A1", "5.1.1.3-4 Inorganic fert CO2") -> 5.1.1.3-4 Inorganic fert CO2
...

Sheet Input - Site
A1: #VALUE! | C1: Input - Site
A3: =HYPERLINK("#'Home'!A1", "Home") -> Home
A4: =HYPERLINK("#'Results - Activity period'!A1", "Results - Activity period") -> Results - Activity period
A5: =HYPERLINK("#'Results - Product EI'!A1", "Results - Product Emissions Intensity") -> Results - Product Emissions Intensity | D5: Location and climate
A6: =HYPERLINK("#'Results'!A1", "Results") -> Results
D7: Location information is used to reference some region and climate-specific emission factors
D8: Tip: Use the web-based GAF Location Helper tool to easily get region and climate information. You will need an internet connection to use the GAF Location Helper.
A9: INPUTS
A10: =HYPERLINK("#'Input - Enterprise'!A1", "Enterprise") -> Enterprise | D10: State | E10: Western Australia | F10: ← Please select
A11: =HYPERLINK("#'Input - Site'!A1", "Site") -> Site | D11: Region (ABS Statistical area level 4) if state is WA | E11: Western Australia - Outback (South) | F11: ← Please select
A12: =HYPERLINK("#'Input - Dairy'!A1", "Dairy") -> Dairy | D12: Leaching zone | E12: NO - Not in leaching zone | F12: ← Please select
A13: =HYPERLINK("#'Input - Livestock sales'!A1", "Livestock sales") -> Livestock sales | D13: Elevation | E13: 307.7 | F13: Meters
A14: =HYPERLINK("#'Input - Dairy cattle purchases'!A1", "Dairy cattle purchases") -> Dairy cattle purchases | D14: Average temperature for reporting period | E14: 18 | F14: Degrees celsius
A15: =HYPERLINK("#'Input - Pasture'!A1", "Pasture") -> Pasture | D15: Total rainfall for reporting period | E15: 601 | F15: Millimetres
A16: =HYPERLINK("#'Input - Fert Prod System'!A1", "Fert Prod System") -> Fert Prod System | D16: Potential evapotranspiration for reporting period | E16: 1326 | F16: Millimetres
A17: =HYPERLINK("#'Input - Fertiliser'!A1", "Fertiliser") -> Fertiliser | D17: Number of frost days for reporting period | E17: 7 | F17: Days
A18: =HYPERLINK("#'Input - Fuel'!A1", "Fuel") -> Fuel | D18: MAP:PET ratio | E18: =E15/E16 -> 0.45324284
A19: =HYPERLINK("#'Input - Electricity'!A1", "Electricity") -> Electricity | D19: Rainfall zone | E19: =Common_InputFunctions.Utility_LookupItemFromMinMax(E15,Table_SourceData_RainfallZones[Min rainfall],Table_SourceData_RainfallZones[Max rainfall],Table_SourceData_RainfallZones[Rainfall Zone]) -> High rainfall
A20: =HYPERLINK("#'Input - Common farm inputs'!A1", "Common farm inputs") -> Common farm inputs | D20: Climate zone | E20: =Common_InputFunctions.Utility_GetClimateZone(E14,E15,E17,E13,E18,Table_SourceData_ClimateZones[Min temp],Table_SourceData_ClimateZones[Max temp],Table_SourceData_ClimateZones[Min rainfall],Table_SourceData_ClimateZones[Max rainfall],Table_SourceData_ClimateZones[Min frost days],Table_SourceData_ClimateZones[Max frost days],Table_SourceData_ClimateZones[Min elevation],Table_SourceData_ClimateZones[Max elevation],Table_SourceData_ClimateZones[Min MAP:PET],Table_SourceData_ClimateZones[Max MAP:PET],Table_SourceData_ClimateZones[Climate zone]) -> Warm temperate dry
A21: =HYPERLINK("#'Input - Crop pasture farm input'!A1", "Crop pasture farm input") -> Crop pasture farm input | D21: Wet or dry climate zone | E21: =Common_InputFunctions.Utility_LookupValueInTable($E$20,Table_SourceData_WetDryZones[Climate zone],Table_SourceData_WetDryZones[Wet or Dry Zone]) -> Dry climate zone
A22: =HYPERLINK("#'Input - Livestock farm Inputs'!A1", "Livestock farm Inputs") -> Livestock farm Inputs | D22: Temperature zone | E22: =Common_InputFunctions.Utility_LookupItemFromMinMax(E14,Table_SourceData_TemperatureZones[Min MAT],Table_SourceData_TemperatureZones[Max MAT],Table_SourceData_TemperatureZones[Temperature Zone]) -> Temperate
A23: =HYPERLINK("#'Input - Freight'!A1", "Freight") -> Freight
A24: =HYPERLINK("#'Input - Solid waste'!A1", "Solid waste") -> Solid waste
A25: =HYPERLINK("#'Input - Manure sent off-site'!A1", "Manure sent off-site") -> Manure sent off-site
A26: =HYPERLINK("#'Input - Refrigerants'!A1", "Refrigerants") -> Refrigerants
A27: =HYPERLINK("#'Input - Data quality'!A1", "Data quality") -> Data quality
A30: CALCULATIONS
A31: =HYPERLINK("#'3.3.1.1-2 Enteric Methane'!A1", "3.3.1.1-2 Enteric methane") -> 3.3.1.1-2 Enteric methane
A32: =HYPERLINK("#'4.3.1.1-2 Methane'!A1", "4.3.1.1-2 Manure methane") -> 4.3.1.1-2 Manure methane
A33: =HYPERLINK("#'4.3.1.3-4 Direct N20'!A1", "4.3.1.3-4 Direct N20") -> 4.3.1.3-4 Direct N20
A34: =HYPERLINK("#'4.3.1.5 Atmos deposition'!A1", "4.3.1.5 Atmos deposition") -> 4.3.1.5 Atmos deposition
A35: =HYPERLINK("#'4.3.1.6-7 Leaching and runoff'!A1", "4.3.1.6-7 Leaching & runoff") -> 4.3.1.6-7 Leaching & runoff
A36: =HYPERLINK("#'4.3.1.8 Manure applied to soils'!A1", "4.3.1.8 Manure applied to soils") -> 4.3.1.8 Manure applied to soils
A37: =HYPERLINK("#'4.3.1.9 Soil direct N2O'!A1", "4.3.1.9 Soil direct N2O") -> 4.3.1.9 Soil direct N2O
A38: =HYPERLINK("#'4.3.1.10-11 Soil Atmos Dep'!A1", "4.3.1.10-11 Soil Atmos Deposition") -> 4.3.1.10-11 Soil Atmos Deposition
A39: =HYPERLINK("#'4.3.1.12-13 Soil leach runoff'!A1", "4.3.1.12-13 Soil leach & runoff") -> 4.3.1.12-13 Soil leach & runoff
A40: =HYPERLINK("#'5.1.1.1-2 Inorganic fert N2O'!A1", "5.1.1.1-2 Inorganic fert N2O") -> 5.1.1.1-2 Inorganic fert N2O
A41: =HYPERLINK("#'5.1.1.3-4 Inorganic fert CO2'!A1", "5.1.1.3-4 Inorganic fert CO2") -> 5.1.1.3-4 Inorganic fert CO2
A42: =HYPERLINK("#'5.2.1.1-2 Organic Fert N2O'!A1", "5.2.1.1-2 Organic fert N2O") -> 5.2.1.1-2 Organic fert N2O
A43: =HYPERLINK("#'5.3.1.1-2 Lime CO2'!A1", "5.3.1.1-2 Lime CO2") -> 5.3.1.1-2 Lime CO2
...

Sheet Input - Dairy
A1: #VALUE! | C1: Input -Dairy
A3: =HYPERLINK("#'Home'!A1", "Home") -> Home
A4: =HYPERLINK("#'Results - Activity period'!A1", "Results - Activity period") -> Results - Activity period
A5: =HYPERLINK("#'Results - Product EI'!A1", "Results - Product Emissions Intensity") -> Results - Product Emissions Intensity | D5: Herd movement
A6: =HYPERLINK("#'Results'!A1", "Results") -> Results
D7: Breed | E7: Medium Friesian | F7: ← Please select
A9: INPUTS | E9: Milking cows | F9: Heifers > 1 year | G9: Heifers < 1 year | H9: Bulls > 1 year | I9: Bulls < 1 year
A10: =HYPERLINK("#'Input - Enterprise'!A1", "Enterprise") -> Enterprise | D10: ="Average number of head between " & TEXT(X_Cell_Site_StartDate, "dd mmm yy") & " and " & TEXT(X_Cell_Site_EndDate, "dd mmm yy") -> Average number of head between 01 Jan 24 and 31 Dec 24 | E10: 100 | F10: 100 | G10: 100 | H10: 100 | I10: 100 | J10: head
A11: =HYPERLINK("#'Input - Site'!A1", "Site") -> Site
A12: =HYPERLINK("#'Input - Dairy'!A1", "Dairy") -> Dairy | D12: Liveweight
A13: =HYPERLINK("#'Input - Livestock sales'!A1", "Livestock sales") -> Livestock sales | D13: Method 1 default values (Do not edit) | E13: Milking cows | F13: Heifers > 1 year | G13: Heifers < 1 year | H13: Bulls > 1 year | I13: Bulls < 1 year
A14: =HYPERLINK("#'Input - Dairy cattle purchases'!A1", "Dairy cattle purchases") -> Dairy cattle purchases | D14: Average liveweight | E14: =Common_InputFunctions.Utility_LookupValueInTableNumber(X_Cell_Dairy_Breed, Table_SourceData_Dairy_WjCowsHeifers[Breed],Table_SourceData_Dairy_WjCowsHeifers[Milking cows]) -> 550 | F14: =Common_InputFunctions.Utility_LookupValueInTableNumber(X_Cell_Dairy_Breed, Table_SourceData_Dairy_WjCowsHeifers[Breed],Table_SourceData_Dairy_WjCowsHeifers[Heifers > 1]) -> 380 | G14: =Common_InputFunctions.Utility_LookupValueInTableNumber(X_Cell_Dairy_Breed, Table_SourceData_Dairy_WjCowsHeifers[Breed],Table_SourceData_Dairy_WjCowsHeifers[Heifers < 1 (weaned)]) -> 155 | H14: {=Table_SourceData_Dairy_WjBulls[Bulls > 1]} -> 600 | I14: {=Table_SourceData_Dairy_WjBulls[Bulls < 1 (weaned)]} -> 225 | J14: kg/head
A15: =HYPERLINK("#'Input - Pasture'!A1", "Pasture") -> Pasture | D15: Average liveweight gain | E15: {=Table_SourceData_Dairy_LWGj[Milking cows]} -> 0.016 | F15: {=Table_SourceData_Dairy_LWGj[Heifers > 1]} -> 0.6 | G15: {=Table_SourceData_Dairy_LWGj[Heifers < 1 (weaned)]} -> 0.57 | H15: {=Table_SourceData_Dairy_LWGj[Bulls > 1]} -> 0.1 | I15: {=Table_SourceData_Dairy_LWGj[Bulls < 1 (weaned)]} -> 0.8 | J15: kg/head/day
A16: =HYPERLINK("#'Input - Fert Prod System'!A1", "Fert Prod System") -> Fert Prod System
A17: =HYPERLINK("#'Input - Fertiliser'!A1", "Fertiliser") -> Fertiliser | D17: Method 2 custom values (Edit if known) | E17: Milking cows | F17: Heifers > 1 year | G17: Heifers < 1 year | H17: Bulls > 1 year | I17: Bulls < 1 year
A18: =HYPERLINK("#'Input - Fuel'!A1", "Fuel") -> Fuel | D18: Average liveweight | E18: =Common_InputFunctions.Utility_LookupValueInTableNumber(X_Cell_Dairy_Breed, Table_SourceData_Dairy_WjCowsHeifers[Breed],Table_SourceData_Dairy_WjCowsHeifers[Milking cows]) -> 550 | F18: =Common_InputFunctions.Utility_LookupValueInTableNumber(X_Cell_Dairy_Breed, Table_SourceData_Dairy_WjCowsHeifers[Breed],Table_SourceData_Dairy_WjCowsHeifers[Heifers > 1]) -> 380 | G18: =Common_InputFunctions.Utility_LookupValueInTableNumber(X_Cell_Dairy_Breed, Table_SourceData_Dairy_WjCowsHeifers[Breed],Table_SourceData_Dairy_WjCowsHeifers[Heifers < 1 (weaned)]) -> 155 | H18: {=Table_SourceData_Dairy_WjBulls[Bulls > 1]} -> 600 | I18: {=Table_SourceData_Dairy_WjBulls[Bulls < 1 (weaned)]} -> 225 | J18: kg/head
A19: =HYPERLINK("#'Input - Electricity'!A1", "Electricity") -> Electricity | D19: Average liveweight gain | E19: {=Table_SourceData_Dairy_LWGj[Milking cows]} -> 0.016 | F19: {=Table_SourceData_Dairy_LWGj[Heifers > 1]} -> 0.6 | G19: {=Table_SourceData_Dairy_LWGj[Heifers < 1 (weaned)]} -> 0.57 | H19: {=Table_SourceData_Dairy_LWGj[Bulls > 1]} -> 0.1 | I19: {=Table_SourceData_Dairy_LWGj[Bulls < 1 (weaned)]} -> 0.8 | J19: kg/head/day
A20: =HYPERLINK("#'Input - Common farm inputs'!A1", "Common farm inputs") -> Common farm inputs
A21: =HYPERLINK("#'Input - Crop pasture farm input'!A1", "Crop pasture farm input") -> Crop pasture farm input | D21: Duration of stay
A22: =HYPERLINK("#'Input - Livestock farm Inputs'!A1", "Livestock farm Inputs") -> Livestock farm Inputs
A23: =HYPERLINK("#'Input - Freight'!A1", "Freight") -> Freight | D23: Method 1 default values (Do not edit) | E23: Milking cows | F23: Heifers > 1 year | G23: Heifers < 1 year | H23: Bulls > 1 year | I23: Bulls < 1 year
A24: =HYPERLINK("#'Input - Solid waste'!A1", "Solid waste") -> Solid waste | D24: ="Average duration of stay between " & TEXT(X_Cell_Site_StartDate, "dd mmm yy") & " and " & TEXT(X_Cell_Site_EndDate, "dd mmm yy") & " weaned livestock" -> Average duration of stay between 01 Jan 24 and 31 Dec 24 weaned livestock | E24: {=Common_InputFunctions.Utility_LookupValueInTableNumber(E23,Table_SourceData_Dairy_Duration[Animal class j],Table_SourceData_Dairy_Duration[Duration (weaned)])} -> 365 | F24: {=Common_InputFunctions.Utility_LookupValueInTableNumber(F23,Table_SourceData_Dairy_Duration[Animal class j],Table_SourceData_Dairy_Duration[Duration (weaned)])} -> 365 | G24: {=Common_InputFunctions.Utility_LookupValueInTableNumber(G23,Table_SourceData_Dairy_Duration[Animal class j],Table_SourceData_Dairy_Duration[Duration (weaned)])} -> 281 | H24: {=Common_InputFunctions.Utility_LookupValueInTableNumber(H23,Table_SourceData_Dairy_Duration[Animal class j],Table_SourceData_Dairy_Duration[Duration (weaned)])} -> 365 | I24: {=Common_InputFunctions.Utility_LookupValueInTableNumber(I23,Table_SourceData_Dairy_Duration[Animal class j],Table_SourceData_Dairy_Duration[Duration (weaned)])} -> 281 | J24: Days
A25: =HYPERLINK("#'Input - Manure sent off-site'!A1", "Manure sent off-site") -> Manure sent off-site | D25: ="Average duration of stay between " & TEXT(X_Cell_Site_StartDate, "dd mmm yy") & " and " & TEXT(X_Cell_Site_EndDate, "dd mmm yy") & " pre-weaned livestock" -> Average duration of stay between 01 Jan 24 and 31 Dec 24 pre-weaned livestock | E25: {=Common_InputFunctions.Utility_LookupValueInTableNumber(E23,Table_SourceData_Dairy_Duration[Animal class j],Table_SourceData_Dairy_Duration[Duration (pre-weaned)])} -> 0 | F25: {=Common_InputFunctions.Utility_LookupValueInTableNumber(F23,Table_SourceData_Dairy_Duration[Animal class j],Table_SourceData_Dairy_Duration[Duration (pre-weaned)])} -> 0 | G25: {=Common_InputFunctions.Utility_LookupValueInTableNumber(G23,Table_SourceData_Dairy_Duration[Animal class j],Table_SourceData_Dairy_Duration[Duration (pre-weaned)])} -> 84 | H25: {=Common_InputFunctions.Utility_LookupValueInTableNumber(H23,Table_SourceData_Dairy_Duration[Animal class j],Table_SourceData_Dairy_Duration[Duration (pre-weaned)])} -> 0 | I25: {=Common_InputFunctions.Utility_LookupValueInTableNumber(I23,Table_SourceData_Dairy_Duration[Animal class j],Table_SourceData_Dairy_Duration[Duration (pre-weaned)])} -> 84 | J25: Days
A26: =HYPERLINK("#'Input - Refrigerants'!A1", "Refrigerants") -> Refrigerants
A27: =HYPERLINK("#'Input - Data quality'!A1", "Data quality") -> Data quality | D27: Method 2 custom values (Edit if known) | E27: Milking cows | F27: Heifers > 1 year | G27: Heifers < 1 year | H27: Bulls > 1 year | I27: Bulls < 1 year
D28: ="Average duration of stay between " & TEXT(X_Cell_Site_StartDate, "dd mmm yy") & " and " & TEXT(X_Cell_Site_EndDate, "dd mmm yy") & " weaned livestock" -> Average duration of stay between 01 Jan 24 and 31 Dec 24 weaned livestock | E28: {=Common_InputFunctions.Utility_LookupValueInTableNumber(E27,Table_SourceData_Dairy_Duration[Animal class j],Table_SourceData_Dairy_Duration[Duration (weaned)])} -> 365 | F28: {=Common_InputFunctions.Utility_LookupValueInTableNumber(F27,Table_SourceData_Dairy_Duration[Animal class j],Table_SourceData_Dairy_Duration[Duration (weaned)])} -> 365 | G28: {=Common_InputFunctions.Utility_LookupValueInTableNumber(G27,Table_SourceData_Dairy_Duration[Animal class j],Table_SourceData_Dairy_Duration[Duration (weaned)])} -> 281 | H28: {=Common_InputFunctions.Utility_LookupValueInTableNumber(H27,Table_SourceData_Dairy_Duration[Animal class j],Table_SourceData_Dairy_Duration[Duration (weaned)])} -> 365 | I28: {=Common_InputFunctions.Utility_LookupValueInTableNumber(I27,Table_SourceData_Dairy_Duration[Animal class j],Table_SourceData_Dairy_Duration[Duration (weaned)])} -> 281 | J28: Days
D29: ="Average duration of stay between " & TEXT(X_Cell_Site_StartDate, "dd mmm yy") & " and " & TEXT(X_Cell_Site_EndDate, "dd mmm yy") & " pre-weaned livestock" -> Average duration of stay between 01 Jan 24 and 31 Dec 24 pre-weaned livestock | E29: =365-E28 -> 0 | F29: =365-F28 -> 0 | G29: =365-G28 -> 84 | H29: =365-H28 -> 0 | I29: =365-I28 -> 84 | J29: Days
A30: CALCULATIONS
A31: =HYPERLINK("#'3.3.1.1-2 Enteric Methane'!A1", "3.3.1.1-2 Enteric methane") -> 3.3.1.1-2 Enteric methane
A32: =HYPERLINK("#'4.3.1.1-2 Methane'!A1", "4.3.1.1-2 Manure methane") -> 4.3.1.1-2 Manure methane
A33: =HYPERLINK("#'4.3.1.3-4 Direct N20'!A1", "4.3.1.3-4 Direct N20") -> 4.3.1.3-4 Direct N20 | D33: Diet
A34: =HYPERLINK("#'4.3.1.5 Atmos deposition'!A1", "4.3.1.5 Atmos deposition") -> 4.3.1.5 Atmos deposition
A35: =HYPERLINK("#'4.3.1.6-7 Leaching and runoff'!A1", "4.3.1.6-7 Leaching & runoff") -> 4.3.1.6-7 Leaching & runoff | D35: Method 1 default values (Do not edit) | E35: Milking cows | F35: Heifers > 1 year | G35: Heifers < 1 year | H35: Bulls > 1 year | I35: Bulls < 1 year
A36: =HYPERLINK("#'4.3.1.8 Manure applied to soils'!A1", "4.3.1.8 Manure applied to soils") -> 4.3.1.8 Manure applied to soils | D36: Dry matter digestibility | E36: =SourceData_Dairy_DryMatterDigestibility_Data -> 0.75 | F36: =SourceData_Dairy_DryMatterDigestibility_Data -> 0.75 | G36: =SourceData_Dairy_DryMatterDigestibility_Data -> 0.75 | H36: =SourceData_Dairy_DryMatterDigestibility_Data -> 0.75 | I36: =SourceData_Dairy_DryMatterDigestibility_Data -> 0.75 | J36: Fraction
A37: =HYPERLINK("#'4.3.1.9 Soil direct N2O'!A1", "4.3.1.9 Soil direct N2O") -> 4.3.1.9 Soil direct N2O | D37: Crude protein | E37: =SourceData_Dairy_CrudeProtein_Data -> 0.2 | F37: =SourceData_Dairy_CrudeProtein_Data -> 0.2 | G37: =SourceData_Dairy_CrudeProtein_Data -> 0.2 | H37: =SourceData_Dairy_CrudeProtein_Data -> 0.2 | I37: =SourceData_Dairy_CrudeProtein_Data -> 0.2 | J37: Fraction
A38: =HYPERLINK("#'4.3.1.10-11 Soil Atmos Dep'!A1", "4.3.1.10-11 Soil Atmos Deposition") -> 4.3.1.10-11 Soil Atmos Deposition
A39: =HYPERLINK("#'4.3.1.12-13 Soil leach runoff'!A1", "4.3.1.12-13 Soil leach & runoff") -> 4.3.1.12-13 Soil leach & runoff | D39: Method 2 custom values (Edit if known) | E39: Milking cows | F39: Heifers > 1 year | G39: Heifers < 1 year | H39: Bulls > 1 year | I39: Bulls < 1 year
A40: =HYPERLINK("#'5.1.1.1-2 Inorganic fert N2O'!A1", "5.1.1.1-2 Inorganic fert N2O") -> 5.1.1.1-2 Inorganic fert N2O | D40: Dry matter digestibility | E40: =SourceData_Dairy_DryMatterDigestibility_Data -> 0.75 | F40: =SourceData_Dairy_DryMatterDigestibility_Data -> 0.75 | G40: =SourceData_Dairy_DryMatterDigestibility_Data -> 0.75 | H40: =SourceData_Dairy_DryMatterDigestibility_Data -> 0.75 | I40: =SourceData_Dairy_DryMatterDigestibility_Data -> 0.75 | J40: Fraction
A41: =HYPERLINK("#'5.1.1.3-4 Inorganic fert CO2'!A1", "5.1.1.3-4 Inorganic fert CO2") -> 5.1.1.3-4 Inorganic fert CO2 | D41: Crude protein | E41: =SourceData_Dairy_CrudeProtein_Data -> 0.2 | F41: =SourceData_Dairy_CrudeProtein_Data -> 0.2 | G41: =SourceData_Dairy_CrudeProtein_Data -> 0.2 | H41: =SourceData_Dairy_CrudeProtein_Data -> 0.2 | I41: =SourceData_Dairy_CrudeProtein_Data -> 0.2 | J41: Fraction
A42: =HYPERLINK("#'5.2.1.1-2 Organic Fert N2O'!A1", "5.2.1.1-2 Organic fert N2O") -> 5.2.1.1-2 Organic fert N2O
...

Sheet Input - Livestock sales
A1: #VALUE! | C1: Input - Livestock sales
A3: =HYPERLINK("#'Home'!A1", "Home") -> Home
A4: =HYPERLINK("#'Results - Activity period'!A1", "Results - Activity period") -> Results - Activity period
A5: =HYPERLINK("#'Results - Product EI'!A1", "Results - Product Emissions Intensity") -> Results - Product Emissions Intensity | D5: ⚠️ Livestock sales are not automatically reflected in the duration and head tables - you will need to manually adjust head count and average liveweight
A6: =HYPERLINK("#'Results'!A1", "Results") -> Results | D6: Transaction name | E6: Class (select) | F6: Sale date | G6: Head sold | H6: Average weight per head (kg) | I6: Total liveweight sold
F7: 45566 | G7: 10 | H7: 500 | I7: =G7*H7 -> 5000
I8: =G8*H8 -> 0
A9: INPUTS | I9: =G9*H9 -> 0
A10: =HYPERLINK("#'Input - Enterprise'!A1", "Enterprise") -> Enterprise | I10: =G10*H10 -> 0
A11: =HYPERLINK("#'Input - Site'!A1", "Site") -> Site | I11: =G11*H11 -> 0
A12: =HYPERLINK("#'Input - Dairy'!A1", "Dairy") -> Dairy | I12: =G12*H12 -> 0
A13: =HYPERLINK("#'Input - Livestock sales'!A1", "Livestock sales") -> Livestock sales | I13: =G13*H13 -> 0
A14: =HYPERLINK("#'Input - Dairy cattle purchases'!A1", "Dairy cattle purchases") -> Dairy cattle purchases | I14: =G14*H14 -> 0
