Workbook
Name _Toc225350871: '5.4.1.1-4 Atmos deposition'!$C$1
Name _Toc225350871: '5.5.1.1-2 Leaching and runoff'!$C$1
Name Common_Equations.Common_ConvertCH4ToCO2e: _xlfn.LAMBDA(_xlpm.E_CH4,_xlpm.GWP_CH4, _xlpm.E_CH4 * _xlpm.GWP_CH4)
Name Common_Equations.Common_ConvertCH4ToCO2e_Arguments: _xlfn.LAMBDA(_xlfn.MAKEARRAY(2, 2, _xlfn.LAMBDA(_xlpm.r,_xlpm.c, INDEX({"ECH4","Methane emissions (t CH4)";"GWPCH4","Global warming potential for methane (t CO2-e / t CH4)"}, _xlpm.r, _xlpm.c))))
Name Common_Equations.Common_ConvertCH4ToCO2e_LatexEquation: _xlfn.LAMBDA("CO2_e = E_{CH4} \times GWP_{CH4}")
Name Common_Equations.Common_ConvertCH4ToCO2e_NIRReference: _xlfn.LAMBDA("")
Name Common_Equations.Common_ConvertCH4ToCO2e_Title: _xlfn.LAMBDA("Convert methane emissions to carbon dioxide equivalent emissions")
Name Common_Equations.Common_ConvertCH4ToCO2e_Unit: _xlfn.LAMBDA("t CO2e")
Name Common_Equations.Common_ConvertCH4ToCO2e_Variable: _xlfn.LAMBDA("ECH4 CO2e")
Name Common_Equations.Common_ConvertN2OToCO2e: _xlfn.LAMBDA(_xlpm.E_N2O,_xlpm.GWP_N2O, _xlpm.E_N2O * _xlpm.GWP_N2O)
Name Common_Equations.Common_ConvertN2OToCO2e_LatexEquation: _xlfn.LAMBDA("CO2_e = E_{N2O} \times GWP_{N2O}")
Name Common_Equations.Common_ConvertN2OToCO2e_NIRReference: _xlfn.LAMBDA("")
Name Common_Equations.Common_ConvertN2OToCO2e_Title: _xlfn.LAMBDA("Convert nitrous oxide emissions to carbon dioxide equivalent emissions")
Name Common_Equations.Common_ConvertN2OToCO2e_Unit: _xlfn.LAMBDA("t CO2e")
Name Common_Equations.Common_ConvertN2OToCO2e_Variable: _xlfn.LAMBDA("EN2O CO2e")
Name Common_InputFunctions.Utility_ConvertStateCommonNameToAbbreviation: _xlfn.LAMBDA(_xlpm.StateCommonName,_xlpm.StateCommonNameArray,_xlpm.StateAbbreviationArray, _xlfn.XLOOKUP(_xlpm.StateCommonName, _xlpm.StateCommonNameArray, _xlpm.StateAbbreviationArray, ""))
Name Common_InputFunctions.Utility_DisplayArguments_1_2: _xlfn.LAMBDA(_xlpm.ArgumentsArray, _xlfn.CHOOSECOLS(_xlpm.ArgumentsArray, 1, 2))
Name Common_InputFunctions.Utility_DisplayArguments_3_4: _xlfn.LAMBDA(_xlpm.ArgumentsArray, _xlfn.CHOOSECOLS(_xlpm.ArgumentsArray, 3, 4))
Name Common_InputFunctions.Utility_DisplayFunctionName: _xlfn.LAMBDA(_xlpm.Function, _xlfn.TEXTBEFORE(_xlfn.FORMULATEXT(_xlpm.Function), "("))
Name Common_InputFunctions.Utility_GetArrayTableColumnStartNumber: _xlfn.LAMBDA(_xlpm.TableHeaderCell, COLUMN(_xlpm.TableHeaderCell))
Name Common_InputFunctions.Utility_GetArrayTableRowStartNumber: _xlfn.LAMBDA(_xlpm.TableheaderCell,_xlpm.RowsBetweenHeaderandArray, ROW(_xlpm.TableheaderCell) + _xlpm.RowsBetweenHeaderandArray - 1)
Name Common_InputFunctions.Utility_LookupValueInTable: _xlfn.LAMBDA(_xlpm.LookupValue,_xlpm.LookupArray,_xlpm.ReturnArray, _xlfn.XLOOKUP(_xlpm.LookupValue, _xlpm.LookupArray, _xlpm.ReturnArray, ""))
Name Common_InputFunctions.Utility_ResultsItemFromEquationTitleAndSource: _xlfn.LAMBDA(_xlpm.TitleCell,_xlpm.SourceCell, SUBSTITUTE(LEFT(_xlpm.SourceCell, FIND(",", _xlpm.SourceCell) - 1), "VEERG 2026: ", "") & " " & _xlpm.TitleCell)
Name Common_InputFunctions.Utility_SourceHyperlink: _xlfn.LAMBDA(_xlpm.TargetCell, _xlfn.LET(_xlpm.sh, _xlfn.TEXTAFTER(CELL("filename", _xlpm.TargetCell), "]"), _xlpm.addr, CELL("address", _xlpm.TargetCell), "#'" & _xlpm.sh & "'!" & _xlpm.addr))
Name Common_InputFunctions.Utility_SourceHyperlinkDifferentSheet: _xlfn.LAMBDA(_xlpm.TargetCell, _xlfn.LET(_xlpm.sh, _xlfn.TEXTAFTER(CELL("filename", _xlpm.TargetCell), "]"), _xlpm.addr, CELL("address", _xlpm.TargetCell), "#" & _xlpm.addr))
Name Common_SourceData.Common_SourceData_AustralianStatesTerritories_Source: _xlfn.LAMBDA("")
Name Common_SourceData.Common_SourceData_AustralianStatesTerritories_Title: _xlfn.LAMBDA("Australian states and territories")
Name Common_SourceData.Common_SourceData_AustralianStatesTerritories_Unit: _xlfn.LAMBDA("")
Name Common_SourceData.Common_SourceData_AustralianStatesTerritories_Variable: _xlfn.LAMBDA("")
Name Common_SourceData.Common_SourceData_ClimateZones_Source: _xlfn.LAMBDA("VEERG 2026: Table 1.3: Climate and Rainfall zone classifications and definitions")
Name Common_SourceData.Common_SourceData_ClimateZones_Title: _xlfn.LAMBDA("VEERG Australian climate zones")
Name Common_SourceData.Common_SourceData_ClimateZones_Unit: _xlfn.LAMBDA("")
Name Common_SourceData.Common_SourceData_ClimateZones_Variable: _xlfn.LAMBDA("")
Name Common_SourceData.Common_SourceData_ConvertGasElementalToMolecular_Source: _xlfn.LAMBDA("XXXXXXX")
Name Common_SourceData.Common_SourceData_ConvertGasElementalToMolecular_Title: _xlfn.LAMBDA("Factor to convert elemental mass of gas to molecular mass")
Name Common_SourceData.Common_SourceData_ConvertGasElementalToMolecular_Unit: _xlfn.LAMBDA("factor")
Name Common_SourceData.Common_SourceData_ConvertGasElementalToMolecular_Variable: _xlfn.LAMBDA("Cg")
Name Common_SourceData.Common_SourceData_ConvertN2oElementalToMolecularCg_Data: _xlfn.LAMBDA(44 / 28)
Name Common_SourceData.Common_SourceData_ConvertN2oElementalToMolecularCg_Source: _xlfn.LAMBDA("National Inventory Report 2023 Volume 1")
Name Common_SourceData.Common_SourceData_ConvertN2oElementalToMolecularCg_Title: _xlfn.LAMBDA("Factor to convert elemental mass of N2O to molecular mass")
Name Common_SourceData.Common_SourceData_ConvertN2oElementalToMolecularCg_Unit: _xlfn.LAMBDA("factor")
Name Common_SourceData.Common_SourceData_ConvertN2oElementalToMolecularCg_Variable: _xlfn.LAMBDA("CgN2O")
Name Common_SourceData.Common_SourceData_DataScores_Scope3_Source: _xlfn.LAMBDA("VEERG 2026: XXXXXXXX")
Name Common_SourceData.Common_SourceData_DataScores_Scope3_Title: _xlfn.LAMBDA("Australian data scores for scope 3")
Name Common_SourceData.Common_SourceData_DataScores_Scope3_Unit: _xlfn.LAMBDA("")
Name Common_SourceData.Common_SourceData_DataScores_Scope3_Variable: _xlfn.LAMBDA("")
Name Common_SourceData.Common_SourceData_DataScores_Scope3_Variation: _xlfn.LAMBDA("")
Name Common_SourceData.Common_SourceData_DensityOfMethane_Data: _xlfn.LAMBDA(0.6784)
Name Common_SourceData.Common_SourceData_DensityOfMethane_Source: _xlfn.LAMBDA("National Inventory Report 2023 Volume 1: Equations 3.B.1a_2, 3.B.1c_2, 3.B.3_1, 3.B.4g_2")
Name Common_SourceData.Common_SourceData_DensityOfMethane_Title: _xlfn.LAMBDA("p = density of methane")
Name Common_SourceData.Common_SourceData_DensityOfMethane_Unit: _xlfn.LAMBDA("kg/m3")
Name Common_SourceData.Common_SourceData_EFleach_Data: _xlfn.LAMBDA(_xlfn.MAKEARRAY(1, 2, _xlfn.LAMBDA(_xlpm.r,_xlpm.c, INDEX({"EFleach",0.011}, _xlpm.r, _xlpm.c))))
Name Common_SourceData.Common_SourceData_EFleach_NIRReference: _xlfn.LAMBDA("National Inventory Report Volume 1: Equation 3.D.B_10")
Name Common_SourceData.Common_SourceData_EFleach_Source: _xlfn.LAMBDA("VEERG 2026:5.5.2.3 Constant Parameters")
Name Common_SourceData.Common_SourceData_EFleach_Title: _xlfn.LAMBDA("Emission factor for nitrogen leaching and runoff")
Name Common_SourceData.Common_SourceData_EFleach_Unit: _xlfn.LAMBDA("(kg N2O-N / kg N")
Name Common_SourceData.Common_SourceData_EFleach_Variation: _xlfn.LAMBDA((""))
Name Common_SourceData.Common_SourceData_EFN2O_NIRReference: _xlfn.LAMBDA("")
Name Common_SourceData.Common_SourceData_EFN2O_Source: _xlfn.LAMBDA("VEERG 2026: Table A.2.2.1")
Name Common_SourceData.Common_SourceData_EFN2O_Title: _xlfn.LAMBDA("Nitrous oxide emission factors for inorganic fertiliser application")

Sheet Home
A1: #VALUE!
A3: =HYPERLINK("#'Home'!A1", "Home") -> Home
A6: INPUTS
A7: =HYPERLINK("#'Input - Planting'!A1", "Planting") -> Planting
A8: =HYPERLINK("#'Input - Fertiliser'!A1", "Fertiliser") -> Fertiliser
A9: =HYPERLINK("#'Input - Fuel'!A1", "Fuel") -> Fuel
A10: =HYPERLINK("#'Input - Fert Prod System'!A1", "Fert Prod System") -> Fert Prod System
A11: =HYPERLINK("#'Input - Site'!A1", "Site") -> Site
A12: =HYPERLINK("#'Input - Data quality'!A1", "Data quality") -> Data quality
A15: CALCULATIONS
A16: =HYPERLINK("#'5.1.1.1-2 Inorganic fert N2O'!A1", "5.1.1.1-2 Inorganic fert N2O") -> 5.1.1.1-2 Inorganic fert N2O
A17: =HYPERLINK("#'5.1.1.3-4 Inorganic fert CO2'!A1", "5.1.1.3-4 Inorganic fert CO2") -> 5.1.1.3-4 Inorganic fert CO2
A18: =HYPERLINK("#'5.2.1.1-2 Organic Fert N2O'!A1", "5.2.1.1-2 Organic fert N2O") -> 5.2.1.1-2 Organic fert N2O
A19: =HYPERLINK("#'5.3.1.1-2 Lime CO2'!A1", "5.3.1.1-2 Lime CO2") -> 5.3.1.1-2 Lime CO2
A20: =HYPERLINK("#'5.4.1.1-4 Atmos deposition'!A1", "5.4.1.1-4 Atmos. deposition") -> 5.4.1.1-4 Atmos. deposition
A21: =HYPERLINK("#'5.5.1.1-2 Leaching and runoff'!A1", "5.5.1.1-2 Leaching & runoff") -> 5.5.1.1-2 Leaching & runoff
A22: =HYPERLINK("#'8.1.1.1-2 Transport fuel'!A1", "8.1.1.1-2 Transport fuel") -> 8.1.1.1-2 Transport fuel
A23: =HYPERLINK("#'8.2.1.1-2 Stationary fuel'!A1", "8.2.1.1-2 Stationary fuel") -> 8.2.1.1-2 Stationary fuel
A26: APPENDICES
A27: =HYPERLINK("#'Constants - Fertiliser'!A1", "Constants - Fertiliser") -> Constants - Fertiliser
A28: =HYPERLINK("#'Constants - Fuel'!A1", "Constants - Fuel") -> Constants - Fuel
A29: =HYPERLINK("#'Constants - Common'!A1", "Constants - Common") -> Constants - Common

Sheet Input - Planting
A1: #VALUE!
A3: =HYPERLINK("#'Home'!A1", "Home") -> Home | B3: Latitude | C3: -33.8688
B4: Longitude | C4: 151.2093
B5: Date planted | C5: 43831
A6: INPUTS | B6: Planting name | C6: My cool thing
A7: =HYPERLINK("#'Input - Planting'!A1", "Planting") -> Planting
A8: =HYPERLINK("#'Input - Fertiliser'!A1", "Fertiliser") -> Fertiliser | B8: Planting area in hectares | C8: 100
A9: =HYPERLINK("#'Input - Fuel'!A1", "Fuel") -> Fuel
A10: =HYPERLINK("#'Input - Fert Prod System'!A1", "Fert Prod System") -> Fert Prod System
A11: =HYPERLINK("#'Input - Site'!A1", "Site") -> Site | B11: Emissions calculation period start date | C11: 45292
A12: =HYPERLINK("#'Input - Data quality'!A1", "Data quality") -> Data quality | B12: Emissions calculation period end date | C12: =DATE(YEAR(C11)+1,MONTH(C11),DAY(C11))-1 -> 45657
B14: FullCAM simulation results
A15: CALCULATIONS | B15: Carbon captured per hectare | C15: 123 | D15: tonnes CO2/hectare
A16: =HYPERLINK("#'5.1.1.1-2 Inorganic fert N2O'!A1", "5.1.1.1-2 Inorganic fert N2O") -> 5.1.1.1-2 Inorganic fert N2O | B16: Total carbon captured | C16: =C8*X_Result_Planting_CarbonCapturedPerHectare -> 12300 | D16: tonnes CO2
A17: =HYPERLINK("#'5.1.1.3-4 Inorganic fert CO2'!A1", "5.1.1.3-4 Inorganic fert CO2") -> 5.1.1.3-4 Inorganic fert CO2
A18: =HYPERLINK("#'5.2.1.1-2 Organic Fert N2O'!A1", "5.2.1.1-2 Organic fert N2O") -> 5.2.1.1-2 Organic fert N2O
A19: =HYPERLINK("#'5.3.1.1-2 Lime CO2'!A1", "5.3.1.1-2 Lime CO2") -> 5.3.1.1-2 Lime CO2
A20: =HYPERLINK("#'5.4.1.1-4 Atmos deposition'!A1", "5.4.1.1-4 Atmos. deposition") -> 5.4.1.1-4 Atmos. deposition
A21: =HYPERLINK("#'5.5.1.1-2 Leaching and runoff'!A1", "5.5.1.1-2 Leaching & runoff") -> 5.5.1.1-2 Leaching & runoff
A22: =HYPERLINK("#'8.1.1.1-2 Transport fuel'!A1", "8.1.1.1-2 Transport fuel") -> 8.1.1.1-2 Transport fuel
A23: =HYPERLINK("#'8.2.1.1-2 Stationary fuel'!A1", "8.2.1.1-2 Stationary fuel") -> 8.2.1.1-2 Stationary fuel
A26: APPENDICES
A27: =HYPERLINK("#'Constants - Fertiliser'!A1", "Constants - Fertiliser") -> Constants - Fertiliser
A28: =HYPERLINK("#'Constants - Fuel'!A1", "Constants - Fuel") -> Constants - Fuel
A29: =HYPERLINK("#'Constants - Common'!A1", "Constants - Common") -> Constants - Common

Sheet Input - Fertiliser
A1: #VALUE! | C1: Input - Fertiliser
A3: =HYPERLINK("#'Home'!A1", "Home") -> Home
D5: Inorganic fertiliser applied
A6: INPUTS
A7: =HYPERLINK("#'Input - Planting'!A1", "Planting") -> Planting | D7: 💡You can add more rows to tables by right-clicking on the table and selecting "Insert > Table rows above/below".
A8: =HYPERLINK("#'Input - Fertiliser'!A1", "Fertiliser") -> Fertiliser | D8: 💡The application area is the same as the area under pasture / cropping by default. You can edit it if the application area is different.
A9: =HYPERLINK("#'Input - Fuel'!A1", "Fuel") -> Fuel
A10: =HYPERLINK("#'Input - Fert Prod System'!A1", "Fert Prod System") -> Fert Prod System | D10: Branded fertiliser products
A11: =HYPERLINK("#'Input - Site'!A1", "Site") -> Site | D11: Product (select) | E11: Amount applied per hectare | F11: Application unit | G11: Application area (ha) | H11: Density | I11: Total applied (kg) | J11: Ingredient 1 | K11: Ingredient 1 percent | L11: Ingredient 2 | M11: Ingredient 2 percent | N11: Ingredient 3 | O11: Ingredient 3 percent | P11: Ingredient 4 | Q11: Ingredient 4 percent | R11: Ingredient 5 | S11: Ingredient 5 percent | T11: Ingredient 6 | U11: Ingredient 6 percent | V11: % N (Ingredients) | W11: % N (declared) | X11: N application rate (kg/ha) | Y11: Urea source | Z11: Ammonia source
A12: =HYPERLINK("#'Input - Data quality'!A1", "Data quality") -> Data quality | D12: Urea | E12: 100 | F12: =IFERROR(_xlfn.XLOOKUP(Table_Input_InorganicFertiliser_Brands[[#This Row],[Product (select)]],FertiliserProducts[Product],FertiliserProducts[Unit]), "kg") -> kg | G12: =X_Cell_Fertiliser_AreaUnderCropping -> 100 | H12: =IFERROR(_xlfn.XLOOKUP(Table_Input_InorganicFertiliser_Brands[[#This Row],[Product (select)]],FertiliserProducts[Product],FertiliserProducts[Density]), 1) -> 1 | I12: =(Table_Input_InorganicFertiliser_Brands[[#This Row],[Amount applied per hectare]]*Table_Input_InorganicFertiliser_Brands[[#This Row],[Density]])*Table_Input_InorganicFertiliser_Brands[[#This Row],[Application area (ha)]] -> 10000 | J12: {=Fertiliser_InputFunctions.Fertiliser_FertiliserProductLookup(Table_Input_InorganicFertiliser_Brands[[#This Row],[Product (select)]], Table_Input_InorganicFertiliser_Brands[[#Headers],[Ingredient 1]], FertiliserProducts[#Data], FertiliserProducts[Product], FertiliserProducts[#Headers])} -> Urea | K12: {=Fertiliser_InputFunctions.Fertiliser_FertiliserProductLookup(Table_Input_InorganicFertiliser_Brands[[#This Row],[Product (select)]], Table_Input_InorganicFertiliser_Brands[[#Headers],[Ingredient 1 percent]], FertiliserProducts[#Data], FertiliserProducts[Product], FertiliserProducts[#Headers])} -> 1 | L12: {=Fertiliser_InputFunctions.Fertiliser_FertiliserProductLookup(Table_Input_InorganicFertiliser_Brands[[#This Row],[Product (select)]], Table_Input_InorganicFertiliser_Brands[[#Headers],[Ingredient 2]], FertiliserProducts[#Data], FertiliserProducts[Product], FertiliserProducts[#Headers])} -> 0 | M12: {=Fertiliser_InputFunctions.Fertiliser_FertiliserProductLookup(Table_Input_InorganicFertiliser_Brands[[#This Row],[Product (select)]], Table_Input_InorganicFertiliser_Brands[[#Headers],[Ingredient 2 percent]], FertiliserProducts[#Data], FertiliserProducts[Product], FertiliserProducts[#Headers])} -> 0 | N12: {=Fertiliser_InputFunctions.Fertiliser_FertiliserProductLookup(Table_Input_InorganicFertiliser_Brands[[#This Row],[Product (select)]], Table_Input_InorganicFertiliser_Brands[[#Headers],[Ingredient 3]], FertiliserProducts[#Data], FertiliserProducts[Product], FertiliserProducts[#Headers])} -> 0 | O12: {=Fertiliser_InputFunctions.Fertiliser_FertiliserProductLookup(Table_Input_InorganicFertiliser_Brands[[#This Row],[Product (select)]], Table_Input_InorganicFertiliser_Brands[[#Headers],[Ingredient 3 percent]], FertiliserProducts[#Data], FertiliserProducts[Product], FertiliserProducts[#Headers])} -> 0 | P12: {=Fertiliser_InputFunctions.Fertiliser_FertiliserProductLookup(Table_Input_InorganicFertiliser_Brands[[#This Row],[Product (select)]], Table_Input_InorganicFertiliser_Brands[[#Headers],[Ingredient 4]], FertiliserProducts[#Data], FertiliserProducts[Product], FertiliserProducts[#Headers])} -> 0 | Q12: {=Fertiliser_InputFunctions.Fertiliser_FertiliserProductLookup(Table_Input_InorganicFertiliser_Brands[[#This Row],[Product (select)]], Table_Input_InorganicFertiliser_Brands[[#Headers],[Ingredient 4 percent]], FertiliserProducts[#Data], FertiliserProducts[Product], FertiliserProducts[#Headers])} -> 0 | R12: {=Fertiliser_InputFunctions.Fertiliser_FertiliserProductLookup(Table_Input_InorganicFertiliser_Brands[[#This Row],[Product (select)]], Table_Input_InorganicFertiliser_Brands[[#Headers],[Ingredient 5]], FertiliserProducts[#Data], FertiliserProducts[Product], FertiliserProducts[#Headers])} -> 0 | S12: {=Fertiliser_InputFunctions.Fertiliser_FertiliserProductLookup(Table_Input_InorganicFertiliser_Brands[[#This Row],[Product (select)]], Table_Input_InorganicFertiliser_Brands[[#Headers],[Ingredient 5 percent]], FertiliserProducts[#Data], FertiliserProducts[Product], FertiliserProducts[#Headers])} -> 0 | T12: {=Fertiliser_InputFunctions.Fertiliser_FertiliserProductLookup(Table_Input_InorganicFertiliser_Brands[[#This Row],[Product (select)]], Table_Input_InorganicFertiliser_Brands[[#Headers],[Ingredient 6]], FertiliserProducts[#Data], FertiliserProducts[Product], FertiliserProducts[#Headers])} -> 0 | U12: {=Fertiliser_InputFunctions.Fertiliser_FertiliserProductLookup(Table_Input_InorganicFertiliser_Brands[[#This Row],[Product (select)]], Table_Input_InorganicFertiliser_Brands[[#Headers],[Ingredient 6 percent]], FertiliserProducts[#Data], FertiliserProducts[Product], FertiliserProducts[#Headers])} -> 0 | V12: =IFERROR((_xlfn.XLOOKUP(Table_Input_InorganicFertiliser_Brands[[#This Row],[Ingredient 1]], Table_Fertiliser_ChemicalCompounds[Fertiliser type f],Table_Fertiliser_ChemicalCompounds[FNinorganic f])*Table_Input_InorganicFertiliser_Brands[[#This Row],[Ingredient 1 percent]]), 0)+ IFERROR((_xlfn.XLOOKUP(Table_Input_InorganicFertiliser_Brands[[#This Row],[Ingredient 2]],Table_Fertiliser_ChemicalCompounds[Fertiliser type f],Table_Fertiliser_ChemicalCompounds[FNinorganic f])*Table_Input_InorganicFertiliser_Brands[[#This Row],[Ingredient 2 percent]]), 0)+ IFERROR((_xlfn.XLOOKUP(Table_Input_InorganicFertiliser_Brands[[#This Row],[Ingredient 3]],Table_Fertiliser_ChemicalCompounds[Fertiliser type f],Table_Fertiliser_ChemicalCompounds[FNinorganic f])*Table_Input_InorganicFertiliser_Brands[[#This Row],[Ingredient 3 percent]]), 0)+ IFERROR((_xlfn.XLOOKUP(Table_Input_InorganicFertiliser_Brands[[#This Row],[Ingredient 4]],Table_Fertiliser_ChemicalCompounds[Fertiliser type f],Table_Fertiliser_ChemicalCompounds[FNinorganic f])*Table_Input_InorganicFertiliser_Brands[[#This Row],[Ingredient 4 percent]]), 0)+ IFERROR((_xlfn.XLOOKUP(Table_Input_InorganicFertiliser_Brands[[#This Row],[Ingredient 5]],Table_Fertiliser_ChemicalCompounds[Fertiliser type f],Table_Fertiliser_ChemicalCompounds[FNinorganic f])*Table_Input_InorganicFertiliser_Brands[[#This Row],[Ingredient 5 percent]]), 0)+ IFERROR((_xlfn.XLOOKUP(Table_Input_InorganicFertiliser_Brands[[#This Row],[Ingredient 6]],Table_Fertiliser_ChemicalCompounds[Fertiliser type f],Table_Fertiliser_ChemicalCompounds[FNinorganic f])*Table_Input_InorganicFertiliser_Brands[[#This Row],[Ingredient 6 percent]]), 0) -> 0.46 | W12: {=IFERROR(Fertiliser_InputFunctions.Fertiliser_FertiliserProductLookup(Table_Input_InorganicFertiliser_Brands[[#This Row],[Product (select)]], "N declared", FertiliserProducts[#Data], FertiliserProducts[Product], FertiliserProducts[#Headers])*0.01, 0)} -> 0.46 | X12: =(Table_Input_InorganicFertiliser_Brands[[#This Row],[Amount applied per hectare]]*Table_Input_InorganicFertiliser_Brands[[#This Row],[Density]])*(IF(Table_Input_InorganicFertiliser_Brands[[#This Row],[% N (declared)]], Table_Input_InorganicFertiliser_Brands[[#This Row],[% N (declared)]], Table_Input_InorganicFertiliser_Brands[[#This Row],[% N (Ingredients)]])) -> 46 | Y12: =IFERROR(_xlfn.XLOOKUP(Table_Input_InorganicFertiliser_Brands[[#This Row],[Product (select)]],FertiliserProducts[Product],FertiliserProducts[Urea source]), "") -> 0 | Z12: =IFERROR(_xlfn.XLOOKUP(Table_Input_InorganicFertiliser_Brands[[#This Row],[Product (select)]],FertiliserProducts[Product],FertiliserProducts[Ammonia source]), "") -> 0
D13: Boost-It | E13: 100 | F13: =IFERROR(_xlfn.XLOOKUP(Table_Input_InorganicFertiliser_Brands[[#This Row],[Product (select)]],FertiliserProducts[Product],FertiliserProducts[Unit]), "kg") -> kg | G13: =X_Cell_Fertiliser_AreaUnderCropping -> 100 | H13: =IFERROR(_xlfn.XLOOKUP(Table_Input_InorganicFertiliser_Brands[[#This Row],[Product (select)]],FertiliserProducts[Product],FertiliserProducts[Density]), 1) -> 1 | I13: =(Table_Input_InorganicFertiliser_Brands[[#This Row],[Amount applied per hectare]]*Table_Input_InorganicFertiliser_Brands[[#This Row],[Density]])*Table_Input_InorganicFertiliser_Brands[[#This Row],[Application area (ha)]] -> 10000 | J13: {=Fertiliser_InputFunctions.Fertiliser_FertiliserProductLookup(Table_Input_InorganicFertiliser_Brands[[#This Row],[Product (select)]], Table_Input_InorganicFertiliser_Brands[[#Headers],[Ingredient 1]], FertiliserProducts[#Data], FertiliserProducts[Product], FertiliserProducts[#Headers])} -> Urea | K13: {=Fertiliser_InputFunctions.Fertiliser_FertiliserProductLookup(Table_Input_InorganicFertiliser_Brands[[#This Row],[Product (select)]], Table_Input_InorganicFertiliser_Brands[[#Headers],[Ingredient 1 percent]], FertiliserProducts[#Data], FertiliserProducts[Product], FertiliserProducts[#Headers])} -> 0.521739 | L13: {=Fertiliser_InputFunctions.Fertiliser_FertiliserProductLookup(Table_Input_InorganicFertiliser_Brands[[#This Row],[Product (select)]], Table_Input_InorganicFertiliser_Brands[[#Headers],[Ingredient 2]], FertiliserProducts[#Data], FertiliserProducts[Product], FertiliserProducts[#Headers])} -> Potassium - Generic | M13: {=Fertiliser_InputFunctions.Fertiliser_FertiliserProductLookup(Table_Input_InorganicFertiliser_Brands[[#This Row],[Product (select)]], Table_Input_InorganicFertiliser_Brands[[#Headers],[Ingredient 2 percent]], FertiliserProducts[#Data], FertiliserProducts[Product], FertiliserProducts[#Headers])} -> 0.08 | N13: {=Fertiliser_InputFunctions.Fertiliser_FertiliserProductLookup(Table_Input_InorganicFertiliser_Brands[[#This Row],[Product (select)]], Table_Input_InorganicFertiliser_Brands[[#Headers],[Ingredient 3]], FertiliserProducts[#Data], FertiliserProducts[Product], FertiliserProducts[#Headers])} -> Sulfur - Generic | O13: {=Fertiliser_InputFunctions.Fertiliser_FertiliserProductLookup(Table_Input_InorganicFertiliser_Brands[[#This Row],[Product (select)]], Table_Input_InorganicFertiliser_Brands[[#Headers],[Ingredient 3 percent]], FertiliserProducts[#Data], FertiliserProducts[Product], FertiliserProducts[#Headers])} -> 0.053 | P13: {=Fertiliser_InputFunctions.Fertiliser_FertiliserProductLookup(Table_Input_InorganicFertiliser_Brands[[#This Row],[Product (select)]], Table_Input_InorganicFertiliser_Brands[[#Headers],[Ingredient 4]], FertiliserProducts[#Data], FertiliserProducts[Product], FertiliserProducts[#Headers])} -> Phosphorus - Generic | Q13: {=Fertiliser_InputFunctions.Fertiliser_FertiliserProductLookup(Table_Input_InorganicFertiliser_Brands[[#This Row],[Product (select)]], Table_Input_InorganicFertiliser_Brands[[#Headers],[Ingredient 4 percent]], FertiliserProducts[#Data], FertiliserProducts[Product], FertiliserProducts[#Headers])} -> 0.052 | R13: {=Fertiliser_InputFunctions.Fertiliser_FertiliserProductLookup(Table_Input_InorganicFertiliser_Brands[[#This Row],[Product (select)]], Table_Input_InorganicFertiliser_Brands[[#Headers],[Ingredient 5]], FertiliserProducts[#Data], FertiliserProducts[Product], FertiliserProducts[#Headers])} -> Magnesium | S13: {=Fertiliser_InputFunctions.Fertiliser_FertiliserProductLookup(Table_Input_InorganicFertiliser_Brands[[#This Row],[Product (select)]], Table_Input_InorganicFertiliser_Brands[[#Headers],[Ingredient 5 percent]], FertiliserProducts[#Data], FertiliserProducts[Product], FertiliserProducts[#Headers])} -> 0.013 | T13: {=Fertiliser_InputFunctions.Fertiliser_FertiliserProductLookup(Table_Input_InorganicFertiliser_Brands[[#This Row],[Product (select)]], Table_Input_InorganicFertiliser_Brands[[#Headers],[Ingredient 6]], FertiliserProducts[#Data], FertiliserProducts[Product], FertiliserProducts[#Headers])} -> Zinc | U13: {=Fertiliser_InputFunctions.Fertiliser_FertiliserProductLookup(Table_Input_InorganicFertiliser_Brands[[#This Row],[Product (select)]], Table_Input_InorganicFertiliser_Brands[[#Headers],[Ingredient 6 percent]], FertiliserProducts[#Data], FertiliserProducts[Product], FertiliserProducts[#Headers])} -> 0.002 | V13: =IFERROR((_xlfn.XLOOKUP(Table_Input_InorganicFertiliser_Brands[[#This Row],[Ingredient 1]], Table_Fertiliser_ChemicalCompounds[Fertiliser type f],Table_Fertiliser_ChemicalCompounds[FNinorganic f])*Table_Input_InorganicFertiliser_Brands[[#This Row],[Ingredient 1 percent]]), 0)+ IFERROR((_xlfn.XLOOKUP(Table_Input_InorganicFertiliser_Brands[[#This Row],[Ingredient 2]],Table_Fertiliser_ChemicalCompounds[Fertiliser type f],Table_Fertiliser_ChemicalCompounds[FNinorganic f])*Table_Input_InorganicFertiliser_Brands[[#This Row],[Ingredient 2 percent]]), 0)+ IFERROR((_xlfn.XLOOKUP(Table_Input_InorganicFertiliser_Brands[[#This Row],[Ingredient 3]],Table_Fertiliser_ChemicalCompounds[Fertiliser type f],Table_Fertiliser_ChemicalCompounds[FNinorganic f])*Table_Input_InorganicFertiliser_Brands[[#This Row],[Ingredient 3 percent]]), 0)+ IFERROR((_xlfn.XLOOKUP(Table_Input_InorganicFertiliser_Brands[[#This Row],[Ingredient 4]],Table_Fertiliser_ChemicalCompounds[Fertiliser type f],Table_Fertiliser_ChemicalCompounds[FNinorganic f])*Table_Input_InorganicFertiliser_Brands[[#This Row],[Ingredient 4 percent]]), 0)+ IFERROR((_xlfn.XLOOKUP(Table_Input_InorganicFertiliser_Brands[[#This Row],[Ingredient 5]],Table_Fertiliser_ChemicalCompounds[Fertiliser type f],Table_Fertiliser_ChemicalCompounds[FNinorganic f])*Table_Input_InorganicFertiliser_Brands[[#This Row],[Ingredient 5 percent]]), 0)+ IFERROR((_xlfn.XLOOKUP(Table_Input_InorganicFertiliser_Brands[[#This Row],[Ingredient 6]],Table_Fertiliser_ChemicalCompounds[Fertiliser type f],Table_Fertiliser_ChemicalCompounds[FNinorganic f])*Table_Input_InorganicFertiliser_Brands[[#This Row],[Ingredient 6 percent]]), 0) -> 0.23999994 | W13: {=IFERROR(Fertiliser_InputFunctions.Fertiliser_FertiliserProductLookup(Table_Input_InorganicFertiliser_Brands[[#This Row],[Product (select)]], "N declared", FertiliserProducts[#Data], FertiliserProducts[Product], FertiliserProducts[#Headers])*0.01, 0)} -> 0.24 | X13: =(Table_Input_InorganicFertiliser_Brands[[#This Row],[Amount applied per hectare]]*Table_Input_InorganicFertiliser_Brands[[#This Row],[Density]])*(IF(Table_Input_InorganicFertiliser_Brands[[#This Row],[% N (declared)]], Table_Input_InorganicFertiliser_Brands[[#This Row],[% N (declared)]], Table_Input_InorganicFertiliser_Brands[[#This Row],[% N (Ingredients)]])) -> 24 | Y13: =IFERROR(_xlfn.XLOOKUP(Table_Input_InorganicFertiliser_Brands[[#This Row],[Product (select)]],FertiliserProducts[Product],FertiliserProducts[Urea source]), "") -> 0 | Z13: =IFERROR(_xlfn.XLOOKUP(Table_Input_InorganicFertiliser_Brands[[#This Row],[Product (select)]],FertiliserProducts[Product],FertiliserProducts[Ammonia source]), "") -> 0
D14: Cal-Gran 50/50 | E14: 100 | F14: =IFERROR(_xlfn.XLOOKUP(Table_Input_InorganicFertiliser_Brands[[#This Row],[Product (select)]],FertiliserProducts[Product],FertiliserProducts[Unit]), "kg") -> kg | G14: =X_Cell_Fertiliser_AreaUnderCropping -> 100 | H14: =IFERROR(_xlfn.XLOOKUP(Table_Input_InorganicFertiliser_Brands[[#This Row],[Product (select)]],FertiliserProducts[Product],FertiliserProducts[Density]), 1) -> 1 | I14: =(Table_Input_InorganicFertiliser_Brands[[#This Row],[Amount applied per hectare]]*Table_Input_InorganicFertiliser_Brands[[#This Row],[Density]])*Table_Input_InorganicFertiliser_Brands[[#This Row],[Application area (ha)]] -> 10000 | J14: {=Fertiliser_InputFunctions.Fertiliser_FertiliserProductLookup(Table_Input_InorganicFertiliser_Brands[[#This Row],[Product (select)]], Table_Input_InorganicFertiliser_Brands[[#Headers],[Ingredient 1]], FertiliserProducts[#Data], FertiliserProducts[Product], FertiliserProducts[#Headers])} -> Nitrogen - Nitrate | K14: {=Fertiliser_InputFunctions.Fertiliser_FertiliserProductLookup(Table_Input_InorganicFertiliser_Brands[[#This Row],[Product (select)]], Table_Input_InorganicFertiliser_Brands[[#Headers],[Ingredient 1 percent]], FertiliserProducts[#Data], FertiliserProducts[Product], FertiliserProducts[#Headers])} -> 0.055 | L14: {=Fertiliser_InputFunctions.Fertiliser_FertiliserProductLookup(Table_Input_InorganicFertiliser_Brands[[#This Row],[Product (select)]], Table_Input_InorganicFertiliser_Brands[[#Headers],[Ingredient 2]], FertiliserProducts[#Data], FertiliserProducts[Product], FertiliserProducts[#Headers])} -> Nitrogen - Ammoniacal | M14: {=Fertiliser_InputFunctions.Fertiliser_FertiliserProductLookup(Table_Input_InorganicFertiliser_Brands[[#This Row],[Product (select)]], Table_Input_InorganicFertiliser_Brands[[#Headers],[Ingredient 2 percent]], FertiliserProducts[#Data], FertiliserProducts[Product], FertiliserProducts[#Headers])} -> 0.124 | N14: {=Fertiliser_InputFunctions.Fertiliser_FertiliserProductLookup(Table_Input_InorganicFertiliser_Brands[[#This Row],[Product (select)]], Table_Input_InorganicFertiliser_Brands[[#Headers],[Ingredient 3]], FertiliserProducts[#Data], FertiliserProducts[Product], FertiliserProducts[#Headers])} -> Potassium - Generic | O14: {=Fertiliser_InputFunctions.Fertiliser_FertiliserProductLookup(Table_Input_InorganicFertiliser_Brands[[#This Row],[Product (select)]], Table_Input_InorganicFertiliser_Brands[[#Headers],[Ingredient 3 percent]], FertiliserProducts[#Data], FertiliserProducts[Product], FertiliserProducts[#Headers])} -> 0.15 | P14: {=Fertiliser_InputFunctions.Fertiliser_FertiliserProductLookup(Table_Input_InorganicFertiliser_Brands[[#This Row],[Product (select)]], Table_Input_InorganicFertiliser_Brands[[#Headers],[Ingredient 4]], FertiliserProducts[#Data], FertiliserProducts[Product], FertiliserProducts[#Headers])} -> Sulfur - Generic | Q14: {=Fertiliser_InputFunctions.Fertiliser_FertiliserProductLookup(Table_Input_InorganicFertiliser_Brands[[#This Row],[Product (select)]], Table_Input_InorganicFertiliser_Brands[[#Headers],[Ingredient 4 percent]], FertiliserProducts[#Data], FertiliserProducts[Product], FertiliserProducts[#Headers])} -> 0.036 | R14: {=Fertiliser_InputFunctions.Fertiliser_FertiliserProductLookup(Table_Input_InorganicFertiliser_Brands[[#This Row],[Product (select)]], Table_Input_InorganicFertiliser_Brands[[#Headers],[Ingredient 5]], FertiliserProducts[#Data], FertiliserProducts[Product], FertiliserProducts[#Headers])} -> Calcium | S14: {=Fertiliser_InputFunctions.Fertiliser_FertiliserProductLookup(Table_Input_InorganicFertiliser_Brands[[#This Row],[Product (select)]], Table_Input_InorganicFertiliser_Brands[[#Headers],[Ingredient 5 percent]], FertiliserProducts[#Data], FertiliserProducts[Product], FertiliserProducts[#Headers])} -> 0.044 | T14: {=Fertiliser_InputFunctions.Fertiliser_FertiliserProductLookup(Table_Input_InorganicFertiliser_Brands[[#This Row],[Product (select)]], Table_Input_InorganicFertiliser_Brands[[#Headers],[Ingredient 6]], FertiliserProducts[#Data], FertiliserProducts[Product], FertiliserProducts[#Headers])} -> 0 | U14: {=Fertiliser_InputFunctions.Fertiliser_FertiliserProductLookup(Table_Input_InorganicFertiliser_Brands[[#This Row],[Product (select)]], Table_Input_InorganicFertiliser_Brands[[#Headers],[Ingredient 6 percent]], FertiliserProducts[#Data], FertiliserProducts[Product], FertiliserProducts[#Headers])} -> 0 | V14: =IFERROR((_xlfn.XLOOKUP(Table_Input_InorganicFertiliser_Brands[[#This Row],[Ingredient 1]], Table_Fertiliser_ChemicalCompounds[Fertiliser type f],Table_Fertiliser_ChemicalCompounds[FNinorganic f])*Table_Input_InorganicFertiliser_Brands[[#This Row],[Ingredient 1 percent]]), 0)+ IFERROR((_xlfn.XLOOKUP(Table_Input_InorganicFertiliser_Brands[[#This Row],[Ingredient 2]],Table_Fertiliser_ChemicalCompounds[Fertiliser type f],Table_Fertiliser_ChemicalCompounds[FNinorganic f])*Table_Input_InorganicFertiliser_Brands[[#This Row],[Ingredient 2 percent]]), 0)+ IFERROR((_xlfn.XLOOKUP(Table_Input_InorganicFertiliser_Brands[[#This Row],[Ingredient 3]],Table_Fertiliser_ChemicalCompounds[Fertiliser type f],Table_Fertiliser_ChemicalCompounds[FNinorganic f])*Table_Input_InorganicFertiliser_Brands[[#This Row],[Ingredient 3 percent]]), 0)+ IFERROR((_xlfn.XLOOKUP(Table_Input_InorganicFertiliser_Brands[[#This Row],[Ingredient 4]],Table_Fertiliser_ChemicalCompounds[Fertiliser type f],Table_Fertiliser_ChemicalCompounds[FNinorganic f])*Table_Input_InorganicFertiliser_Brands[[#This Row],[Ingredient 4 percent]]), 0)+ IFERROR((_xlfn.XLOOKUP(Table_Input_InorganicFertiliser_Brands[[#This Row],[Ingredient 5]],Table_Fertiliser_ChemicalCompounds[Fertiliser type f],Table_Fertiliser_ChemicalCompounds[FNinorganic f])*Table_Input_InorganicFertiliser_Brands[[#This Row],[Ingredient 5 percent]]), 0)+ IFERROR((_xlfn.XLOOKUP(Table_Input_InorganicFertiliser_Brands[[#This Row],[Ingredient 6]],Table_Fertiliser_ChemicalCompounds[Fertiliser type f],Table_Fertiliser_ChemicalCompounds[FNinorganic f])*Table_Input_InorganicFertiliser_Brands[[#This Row],[Ingredient 6 percent]]), 0) -> 0.179 | W14: {=IFERROR(Fertiliser_InputFunctions.Fertiliser_FertiliserProductLookup(Table_Input_InorganicFertiliser_Brands[[#This Row],[Product (select)]], "N declared", FertiliserProducts[#Data], FertiliserProducts[Product], FertiliserProducts[#Headers])*0.01, 0)} -> 0.179 | X14: =(Table_Input_InorganicFertiliser_Brands[[#This Row],[Amount applied per hectare]]*Table_Input_InorganicFertiliser_Brands[[#This Row],[Density]])*(IF(Table_Input_InorganicFertiliser_Brands[[#This Row],[% N (declared)]], Table_Input_InorganicFertiliser_Brands[[#This Row],[% N (declared)]], Table_Input_InorganicFertiliser_Brands[[#This Row],[% N (Ingredients)]])) -> 17.9 | Y14: =IFERROR(_xlfn.XLOOKUP(Table_Input_InorganicFertiliser_Brands[[#This Row],[Product (select)]],FertiliserProducts[Product],FertiliserProducts[Urea source]), "") -> 0 | Z14: =IFERROR(_xlfn.XLOOKUP(Table_Input_InorganicFertiliser_Brands[[#This Row],[Product (select)]],FertiliserProducts[Product],FertiliserProducts[Ammonia source]), "") -> 0
A15: CALCULATIONS | F15: =IFERROR(_xlfn.XLOOKUP(Table_Input_InorganicFertiliser_Brands[[#This Row],[Product (select)]],FertiliserProducts[Product],FertiliserProducts[Unit]), "kg") -> kg | G15: =X_Cell_Fertiliser_AreaUnderCropping -> 100 | H15: =IFERROR(_xlfn.XLOOKUP(Table_Input_InorganicFertiliser_Brands[[#This Row],[Product (select)]],FertiliserProducts[Product],FertiliserProducts[Density]), 1) -> 1 | I15: =(Table_Input_InorganicFertiliser_Brands[[#This Row],[Amount applied per hectare]]*Table_Input_InorganicFertiliser_Brands[[#This Row],[Density]])*Table_Input_InorganicFertiliser_Brands[[#This Row],[Application area (ha)]] -> 0 | J15: {=Fertiliser_InputFunctions.Fertiliser_FertiliserProductLookup(Table_Input_InorganicFertiliser_Brands[[#This Row],[Product (select)]], Table_Input_InorganicFertiliser_Brands[[#Headers],[Ingredient 1]], FertiliserProducts[#Data], FertiliserProducts[Product], FertiliserProducts[#Headers])} | K15: {=Fertiliser_InputFunctions.Fertiliser_FertiliserProductLookup(Table_Input_InorganicFertiliser_Brands[[#This Row],[Product (select)]], Table_Input_InorganicFertiliser_Brands[[#Headers],[Ingredient 1 percent]], FertiliserProducts[#Data], FertiliserProducts[Product], FertiliserProducts[#Headers])} | L15: {=Fertiliser_InputFunctions.Fertiliser_FertiliserProductLookup(Table_Input_InorganicFertiliser_Brands[[#This Row],[Product (select)]], Table_Input_InorganicFertiliser_Brands[[#Headers],[Ingredient 2]], FertiliserProducts[#Data], FertiliserProducts[Product], FertiliserProducts[#Headers])} | M15: {=Fertiliser_InputFunctions.Fertiliser_FertiliserProductLookup(Table_Input_InorganicFertiliser_Brands[[#This Row],[Product (select)]], Table_Input_InorganicFertiliser_Brands[[#Headers],[Ingredient 2 percent]], FertiliserProducts[#Data], FertiliserProducts[Product], FertiliserProducts[#Headers])} | N15: {=Fertiliser_InputFunctions.Fertiliser_FertiliserProductLookup(Table_Input_InorganicFertiliser_Brands[[#This Row],[Product (select)]], Table_Input_InorganicFertiliser_Brands[[#Headers],[Ingredient 3]], FertiliserProducts[#Data], FertiliserProducts[Product], FertiliserProducts[#Headers])} | O15: {=Fertiliser_InputFunctions.Fertiliser_FertiliserProductLookup(Table_Input_InorganicFertiliser_Brands[[#This Row],[Product (select)]], Table_Input_InorganicFertiliser_Brands[[#Headers],[Ingredient 3 percent]], FertiliserProducts[#Data], FertiliserProducts[Product], FertiliserProducts[#Headers])} | P15: {=Fertiliser_InputFunctions.Fertiliser_FertiliserProductLookup(Table_Input_InorganicFertiliser_Brands[[#This Row],[Product (select)]], Table_Input_InorganicFertiliser_Brands[[#Headers],[Ingredient 4]], FertiliserProducts[#Data], FertiliserProducts[Product], FertiliserProducts[#Headers])} | Q15: {=Fertiliser_InputFunctions.Fertiliser_FertiliserProductLookup(Table_Input_InorganicFertiliser_Brands[[#This Row],[Product (select)]], Table_Input_InorganicFertiliser_Brands[[#Headers],[Ingredient 4 percent]], FertiliserProducts[#Data], FertiliserProducts[Product], FertiliserProducts[#Headers])} | R15: {=Fertiliser_InputFunctions.Fertiliser_FertiliserProductLookup(Table_Input_InorganicFertiliser_Brands[[#This Row],[Product (select)]], Table_Input_InorganicFertiliser_Brands[[#Headers],[Ingredient 5]], FertiliserProducts[#Data], FertiliserProducts[Product], FertiliserProducts[#Headers])} | S15: {=Fertiliser_InputFunctions.Fertiliser_FertiliserProductLookup(Table_Input_InorganicFertiliser_Brands[[#This Row],[Product (select)]], Table_Input_InorganicFertiliser_Brands[[#Headers],[Ingredient 5 percent]], FertiliserProducts[#Data], FertiliserProducts[Product], FertiliserProducts[#Headers])} | T15: {=Fertiliser_InputFunctions.Fertiliser_FertiliserProductLookup(Table_Input_InorganicFertiliser_Brands[[#This Row],[Product (select)]], Table_Input_InorganicFertiliser_Brands[[#Headers],[Ingredient 6]], FertiliserProducts[#Data], FertiliserProducts[Product], FertiliserProducts[#Headers])} | U15: {=Fertiliser_InputFunctions.Fertiliser_FertiliserProductLookup(Table_Input_InorganicFertiliser_Brands[[#This Row],[Product (select)]], Table_Input_InorganicFertiliser_Brands[[#Headers],[Ingredient 6 percent]], FertiliserProducts[#Data], FertiliserProducts[Product], FertiliserProducts[#Headers])} | V15: =IFERROR((_xlfn.XLOOKUP(Table_Input_InorganicFertiliser_Brands[[#This Row],[Ingredient 1]], Table_Fertiliser_ChemicalCompounds[Fertiliser type f],Table_Fertiliser_ChemicalCompounds[FNinorganic f])*Table_Input_InorganicFertiliser_Brands[[#This Row],[Ingredient 1 percent]]), 0)+ IFERROR((_xlfn.XLOOKUP(Table_Input_InorganicFertiliser_Brands[[#This Row],[Ingredient 2]],Table_Fertiliser_ChemicalCompounds[Fertiliser type f],Table_Fertiliser_ChemicalCompounds[FNinorganic f])*Table_Input_InorganicFertiliser_Brands[[#This Row],[Ingredient 2 percent]]), 0)+ IFERROR((_xlfn.XLOOKUP(Table_Input_InorganicFertiliser_Brands[[#This Row],[Ingredient 3]],Table_Fertiliser_ChemicalCompounds[Fertiliser type f],Table_Fertiliser_ChemicalCompounds[FNinorganic f])*Table_Input_InorganicFertiliser_Brands[[#This Row],[Ingredient 3 percent]]), 0)+ IFERROR((_xlfn.XLOOKUP(Table_Input_InorganicFertiliser_Brands[[#This Row],[Ingredient 4]],Table_Fertiliser_ChemicalCompounds[Fertiliser type f],Table_Fertiliser_ChemicalCompounds[FNinorganic f])*Table_Input_InorganicFertiliser_Brands[[#This Row],[Ingredient 4 percent]]), 0)+ IFERROR((_xlfn.XLOOKUP(Table_Input_InorganicFertiliser_Brands[[#This Row],[Ingredient 5]],Table_Fertiliser_ChemicalCompounds[Fertiliser type f],Table_Fertiliser_ChemicalCompounds[FNinorganic f])*Table_Input_InorganicFertiliser_Brands[[#This Row],[Ingredient 5 percent]]), 0)+ IFERROR((_xlfn.XLOOKUP(Table_Input_InorganicFertiliser_Brands[[#This Row],[Ingredient 6]],Table_Fertiliser_ChemicalCompounds[Fertiliser type f],Table_Fertiliser_ChemicalCompounds[FNinorganic f])*Table_Input_InorganicFertiliser_Brands[[#This Row],[Ingredient 6 percent]]), 0) -> 0 | W15: {=IFERROR(Fertiliser_InputFunctions.Fertiliser_FertiliserProductLookup(Table_Input_InorganicFertiliser_Brands[[#This Row],[Product (select)]], "N declared", FertiliserProducts[#Data], FertiliserProducts[Product], FertiliserProducts[#Headers])*0.01, 0)} -> 0 | X15: =(Table_Input_InorganicFertiliser_Brands[[#This Row],[Amount applied per hectare]]*Table_Input_InorganicFertiliser_Brands[[#This Row],[Density]])*(IF(Table_Input_InorganicFertiliser_Brands[[#This Row],[% N (declared)]], Table_Input_InorganicFertiliser_Brands[[#This Row],[% N (declared)]], Table_Input_InorganicFertiliser_Brands[[#This Row],[% N (Ingredients)]])) -> 0 | Y15: =IFERROR(_xlfn.XLOOKUP(Table_Input_InorganicFertiliser_Brands[[#This Row],[Product (select)]],FertiliserProducts[Product],FertiliserProducts[Urea source]), "") | Z15: =IFERROR(_xlfn.XLOOKUP(Table_Input_InorganicFertiliser_Brands[[#This Row],[Product (select)]],FertiliserProducts[Product],FertiliserProducts[Ammonia source]), "")
A16: =HYPERLINK("#'5.1.1.1-2 Inorganic fert N2O'!A1", "5.1.1.1-2 Inorganic fert N2O") -> 5.1.1.1-2 Inorganic fert N2O | F16: =IFERROR(_xlfn.XLOOKUP(Table_Input_InorganicFertiliser_Brands[[#This Row],[Product (select)]],FertiliserProducts[Product],FertiliserProducts[Unit]), "kg") -> kg | G16: =X_Cell_Fertiliser_AreaUnderCropping -> 100 | H16: =IFERROR(_xlfn.XLOOKUP(Table_Input_InorganicFertiliser_Brands[[#This Row],[Product (select)]],FertiliserProducts[Product],FertiliserProducts[Density]), 1) -> 1 | I16: =(Table_Input_InorganicFertiliser_Brands[[#This Row],[Amount applied per hectare]]*Table_Input_InorganicFertiliser_Brands[[#This Row],[Density]])*Table_Input_InorganicFertiliser_Brands[[#This Row],[Application area (ha)]] -> 0 | J16: {=Fertiliser_InputFunctions.Fertiliser_FertiliserProductLookup(Table_Input_InorganicFertiliser_Brands[[#This Row],[Product (select)]], Table_Input_InorganicFertiliser_Brands[[#Headers],[Ingredient 1]], FertiliserProducts[#Data], FertiliserProducts[Product], FertiliserProducts[#Headers])} | K16: {=Fertiliser_InputFunctions.Fertiliser_FertiliserProductLookup(Table_Input_InorganicFertiliser_Brands[[#This Row],[Product (select)]], Table_Input_InorganicFertiliser_Brands[[#Headers],[Ingredient 1 percent]], FertiliserProducts[#Data], FertiliserProducts[Product], FertiliserProducts[#Headers])} | L16: {=Fertiliser_InputFunctions.Fertiliser_FertiliserProductLookup(Table_Input_InorganicFertiliser_Brands[[#This Row],[Product (select)]], Table_Input_InorganicFertiliser_Brands[[#Headers],[Ingredient 2]], FertiliserProducts[#Data], FertiliserProducts[Product], FertiliserProducts[#Headers])} | M16: {=Fertiliser_InputFunctions.Fertiliser_FertiliserProductLookup(Table_Input_InorganicFertiliser_Brands[[#This Row],[Product (select)]], Table_Input_InorganicFertiliser_Brands[[#Headers],[Ingredient 2 percent]], FertiliserProducts[#Data], FertiliserProducts[Product], FertiliserProducts[#Headers])} | N16: {=Fertiliser_InputFunctions.Fertiliser_FertiliserProductLookup(Table_Input_InorganicFertiliser_Brands[[#This Row],[Product (select)]], Table_Input_InorganicFertiliser_Brands[[#Headers],[Ingredient 3]], FertiliserProducts[#Data], FertiliserProducts[Product], FertiliserProducts[#Headers])} | O16: {=Fertiliser_InputFunctions.Fertiliser_FertiliserProductLookup(Table_Input_InorganicFertiliser_Brands[[#This Row],[Product (select)]], Table_Input_InorganicFertiliser_Brands[[#Headers],[Ingredient 3 percent]], FertiliserProducts[#Data], FertiliserProducts[Product], FertiliserProducts[#Headers])} | P16: {=Fertiliser_InputFunctions.Fertiliser_FertiliserProductLookup(Table_Input_InorganicFertiliser_Brands[[#This Row],[Product (select)]], Table_Input_InorganicFertiliser_Brands[[#Headers],[Ingredient 4]], FertiliserProducts[#Data], FertiliserProducts[Product], FertiliserProducts[#Headers])} | Q16: {=Fertiliser_InputFunctions.Fertiliser_FertiliserProductLookup(Table_Input_InorganicFertiliser_Brands[[#This Row],[Product (select)]], Table_Input_InorganicFertiliser_Brands[[#Headers],[Ingredient 4 percent]], FertiliserProducts[#Data], FertiliserProducts[Product], FertiliserProducts[#Headers])} | R16: {=Fertiliser_InputFunctions.Fertiliser_FertiliserProductLookup(Table_Input_InorganicFertiliser_Brands[[#This Row],[Product (select)]], Table_Input_InorganicFertiliser_Brands[[#Headers],[Ingredient 5]], FertiliserProducts[#Data], FertiliserProducts[Product], FertiliserProducts[#Headers])} | S16: {=Fertiliser_InputFunctions.Fertiliser_FertiliserProductLookup(Table_Input_InorganicFertiliser_Brands[[#This Row],[Product (select)]], Table_Input_InorganicFertiliser_Brands[[#Headers],[Ingredient 5 percent]], FertiliserProducts[#Data], FertiliserProducts[Product], FertiliserProducts[#Headers])} | T16: {=Fertiliser_InputFunctions.Fertiliser_FertiliserProductLookup(Table_Input_InorganicFertiliser_Brands[[#This Row],[Product (select)]], Table_Input_InorganicFertiliser_Brands[[#Headers],[Ingredient 6]], FertiliserProducts[#Data], FertiliserProducts[Product], FertiliserProducts[#Headers])} | U16: {=Fertiliser_InputFunctions.Fertiliser_FertiliserProductLookup(Table_Input_InorganicFertiliser_Brands[[#This Row],[Product (select)]], Table_Input_InorganicFertiliser_Brands[[#Headers],[Ingredient 6 percent]], FertiliserProducts[#Data], FertiliserProducts[Product], FertiliserProducts[#Headers])} | V16: =IFERROR((_xlfn.XLOOKUP(Table_Input_InorganicFertiliser_Brands[[#This Row],[Ingredient 1]], Table_Fertiliser_ChemicalCompounds[Fertiliser type f],Table_Fertiliser_ChemicalCompounds[FNinorganic f])*Table_Input_InorganicFertiliser_Brands[[#This Row],[Ingredient 1 percent]]), 0)+ IFERROR((_xlfn.XLOOKUP(Table_Input_InorganicFertiliser_Brands[[#This Row],[Ingredient 2]],Table_Fertiliser_ChemicalCompounds[Fertiliser type f],Table_Fertiliser_ChemicalCompounds[FNinorganic f])*Table_Input_InorganicFertiliser_Brands[[#This Row],[Ingredient 2 percent]]), 0)+ IFERROR((_xlfn.XLOOKUP(Table_Input_InorganicFertiliser_Brands[[#This Row],[Ingredient 3]],Table_Fertiliser_ChemicalCompounds[Fertiliser type f],Table_Fertiliser_ChemicalCompounds[FNinorganic f])*Table_Input_InorganicFertiliser_Brands[[#This Row],[Ingredient 3 percent]]), 0)+ IFERROR((_xlfn.XLOOKUP(Table_Input_InorganicFertiliser_Brands[[#This Row],[Ingredient 4]],Table_Fertiliser_ChemicalCompounds[Fertiliser type f],Table_Fertiliser_ChemicalCompounds[FNinorganic f])*Table_Input_InorganicFertiliser_Brands[[#This Row],[Ingredient 4 percent]]), 0)+ IFERROR((_xlfn.XLOOKUP(Table_Input_InorganicFertiliser_Brands[[#This Row],[Ingredient 5]],Table_Fertiliser_ChemicalCompounds[Fertiliser type f],Table_Fertiliser_ChemicalCompounds[FNinorganic f])*Table_Input_InorganicFertiliser_Brands[[#This Row],[Ingredient 5 percent]]), 0)+ IFERROR((_xlfn.XLOOKUP(Table_Input_InorganicFertiliser_Brands[[#This Row],[Ingredient 6]],Table_Fertiliser_ChemicalCompounds[Fertiliser type f],Table_Fertiliser_ChemicalCompounds[FNinorganic f])*Table_Input_InorganicFertiliser_Brands[[#This Row],[Ingredient 6 percent]]), 0) -> 0 | W16: {=IFERROR(Fertiliser_InputFunctions.Fertiliser_FertiliserProductLookup(Table_Input_InorganicFertiliser_Brands[[#This Row],[Product (select)]], "N declared", FertiliserProducts[#Data], FertiliserProducts[Product], FertiliserProducts[#Headers])*0.01, 0)} -> 0 | X16: =(Table_Input_InorganicFertiliser_Brands[[#This Row],[Amount applied per hectare]]*Table_Input_InorganicFertiliser_Brands[[#This Row],[Density]])*(IF(Table_Input_InorganicFertiliser_Brands[[#This Row],[% N (declared)]], Table_Input_InorganicFertiliser_Brands[[#This Row],[% N (declared)]], Table_Input_InorganicFertiliser_Brands[[#This Row],[% N (Ingredients)]])) -> 0 | Y16: =IFERROR(_xlfn.XLOOKUP(Table_Input_InorganicFertiliser_Brands[[#This Row],[Product (select)]],FertiliserProducts[Product],FertiliserProducts[Urea source]), "") | Z16: =IFERROR(_xlfn.XLOOKUP(Table_Input_InorganicFertiliser_Brands[[#This Row],[Product (select)]],FertiliserProducts[Product],FertiliserProducts[Ammonia source]), "")
A17: =HYPERLINK("#'5.1.1.3-4 Inorganic fert CO2'!A1", "5.1.1.3-4 Inorganic fert CO2") -> 5.1.1.3-4 Inorganic fert CO2 | F17: =IFERROR(_xlfn.XLOOKUP(Table_Input_InorganicFertiliser_Brands[[#This Row],[Product (select)]],FertiliserProducts[Product],FertiliserProducts[Unit]), "kg") -> kg | G17: =X_Cell_Fertiliser_AreaUnderCropping -> 100 | H17: =IFERROR(_xlfn.XLOOKUP(Table_Input_InorganicFertiliser_Brands[[#This Row],[Product (select)]],FertiliserProducts[Product],FertiliserProducts[Density]), 1) -> 1 | I17: =(Table_Input_InorganicFertiliser_Brands[[#This Row],[Amount applied per hectare]]*Table_Input_InorganicFertiliser_Brands[[#This Row],[Density]])*Table_Input_InorganicFertiliser_Brands[[#This Row],[Application area (ha)]] -> 0 | J17: {=Fertiliser_InputFunctions.Fertiliser_FertiliserProductLookup(Table_Input_InorganicFertiliser_Brands[[#This Row],[Product (select)]], Table_Input_InorganicFertiliser_Brands[[#Headers],[Ingredient 1]], FertiliserProducts[#Data], FertiliserProducts[Product], FertiliserProducts[#Headers])} | K17: {=Fertiliser_InputFunctions.Fertiliser_FertiliserProductLookup(Table_Input_InorganicFertiliser_Brands[[#This Row],[Product (select)]], Table_Input_InorganicFertiliser_Brands[[#Headers],[Ingredient 1 percent]], FertiliserProducts[#Data], FertiliserProducts[Product], FertiliserProducts[#Headers])} | L17: {=Fertiliser_InputFunctions.Fertiliser_FertiliserProductLookup(Table_Input_InorganicFertiliser_Brands[[#This Row],[Product (select)]], Table_Input_InorganicFertiliser_Brands[[#Headers],[Ingredient 2]], FertiliserProducts[#Data], FertiliserProducts[Product], FertiliserProducts[#Headers])} | M17: {=Fertiliser_InputFunctions.Fertiliser_FertiliserProductLookup(Table_Input_InorganicFertiliser_Brands[[#This Row],[Product (select)]], Table_Input_InorganicFertiliser_Brands[[#Headers],[Ingredient 2 percent]], FertiliserProducts[#Data], FertiliserProducts[Product], FertiliserProducts[#Headers])} | N17: {=Fertiliser_InputFunctions.Fertiliser_FertiliserProductLookup(Table_Input_InorganicFertiliser_Brands[[#This Row],[Product (select)]], Table_Input_InorganicFertiliser_Brands[[#Headers],[Ingredient 3]], FertiliserProducts[#Data], FertiliserProducts[Product], FertiliserProducts[#Headers])} | O17: {=Fertiliser_InputFunctions.Fertiliser_FertiliserProductLookup(Table_Input_InorganicFertiliser_Brands[[#This Row],[Product (select)]], Table_Input_InorganicFertiliser_Brands[[#Headers],[Ingredient 3 percent]], FertiliserProducts[#Data], FertiliserProducts[Product], FertiliserProducts[#Headers])} | P17: {=Fertiliser_InputFunctions.Fertiliser_FertiliserProductLookup(Table_Input_InorganicFertiliser_Brands[[#This Row],[Product (select)]], Table_Input_InorganicFertiliser_Brands[[#Headers],[Ingredient 4]], FertiliserProducts[#Data], FertiliserProducts[Product], FertiliserProducts[#Headers])} | Q17: {=Fertiliser_InputFunctions.Fertiliser_FertiliserProductLookup(Table_Input_InorganicFertiliser_Brands[[#This Row],[Product (select)]], Table_Input_InorganicFertiliser_Brands[[#Headers],[Ingredient 4 percent]], FertiliserProducts[#Data], FertiliserProducts[Product], FertiliserProducts[#Headers])} | R17: {=Fertiliser_InputFunctions.Fertiliser_FertiliserProductLookup(Table_Input_InorganicFertiliser_Brands[[#This Row],[Product (select)]], Table_Input_InorganicFertiliser_Brands[[#Headers],[Ingredient 5]], FertiliserProducts[#Data], FertiliserProducts[Product], FertiliserProducts[#Headers])} | S17: {=Fertiliser_InputFunctions.Fertiliser_FertiliserProductLookup(Table_Input_InorganicFertiliser_Brands[[#This Row],[Product (select)]], Table_Input_InorganicFertiliser_Brands[[#Headers],[Ingredient 5 percent]], FertiliserProducts[#Data], FertiliserProducts[Product], FertiliserProducts[#Headers])} | T17: {=Fertiliser_InputFunctions.Fertiliser_FertiliserProductLookup(Table_Input_InorganicFertiliser_Brands[[#This Row],[Product (select)]], Table_Input_InorganicFertiliser_Brands[[#Headers],[Ingredient 6]], FertiliserProducts[#Data], FertiliserProducts[Product], FertiliserProducts[#Headers])} | U17: {=Fertiliser_InputFunctions.Fertiliser_FertiliserProductLookup(Table_Input_InorganicFertiliser_Brands[[#This Row],[Product (select)]], Table_Input_InorganicFertiliser_Brands[[#Headers],[Ingredient 6 percent]], FertiliserProducts[#Data], FertiliserProducts[Product], FertiliserProducts[#Headers])} | V17: =IFERROR((_xlfn.XLOOKUP(Table_Input_InorganicFertiliser_Brands[[#This Row],[Ingredient 1]], Table_Fertiliser_ChemicalCompounds[Fertiliser type f],Table_Fertiliser_ChemicalCompounds[FNinorganic f])*Table_Input_InorganicFertiliser_Brands[[#This Row],[Ingredient 1 percent]]), 0)+ IFERROR((_xlfn.XLOOKUP(Table_Input_InorganicFertiliser_Brands[[#This Row],[Ingredient 2]],Table_Fertiliser_ChemicalCompounds[Fertiliser type f],Table_Fertiliser_ChemicalCompounds[FNinorganic f])*Table_Input_InorganicFertiliser_Brands[[#This Row],[Ingredient 2 percent]]), 0)+ IFERROR((_xlfn.XLOOKUP(Table_Input_InorganicFertiliser_Brands[[#This Row],[Ingredient 3]],Table_Fertiliser_ChemicalCompounds[Fertiliser type f],Table_Fertiliser_ChemicalCompounds[FNinorganic f])*Table_Input_InorganicFertiliser_Brands[[#This Row],[Ingredient 3 percent]]), 0)+ IFERROR((_xlfn.XLOOKUP(Table_Input_InorganicFertiliser_Brands[[#This Row],[Ingredient 4]],Table_Fertiliser_ChemicalCompounds[Fertiliser type f],Table_Fertiliser_ChemicalCompounds[FNinorganic f])*Table_Input_InorganicFertiliser_Brands[[#This Row],[Ingredient 4 percent]]), 0)+ IFERROR((_xlfn.XLOOKUP(Table_Input_InorganicFertiliser_Brands[[#This Row],[Ingredient 5]],Table_Fertiliser_ChemicalCompounds[Fertiliser type f],Table_Fertiliser_ChemicalCompounds[FNinorganic f])*Table_Input_InorganicFertiliser_Brands[[#This Row],[Ingredient 5 percent]]), 0)+ IFERROR((_xlfn.XLOOKUP(Table_Input_InorganicFertiliser_Brands[[#This Row],[Ingredient 6]],Table_Fertiliser_ChemicalCompounds[Fertiliser type f],Table_Fertiliser_ChemicalCompounds[FNinorganic f])*Table_Input_InorganicFertiliser_Brands[[#This Row],[Ingredient 6 percent]]), 0) -> 0 | W17: {=IFERROR(Fertiliser_InputFunctions.Fertiliser_FertiliserProductLookup(Table_Input_InorganicFertiliser_Brands[[#This Row],[Product (select)]], "N declared", FertiliserProducts[#Data], FertiliserProducts[Product], FertiliserProducts[#Headers])*0.01, 0)} -> 0 | X17: =(Table_Input_InorganicFertiliser_Brands[[#This Row],[Amount applied per hectare]]*Table_Input_InorganicFertiliser_Brands[[#This Row],[Density]])*(IF(Table_Input_InorganicFertiliser_Brands[[#This Row],[% N (declared)]], Table_Input_InorganicFertiliser_Brands[[#This Row],[% N (declared)]], Table_Input_InorganicFertiliser_Brands[[#This Row],[% N (Ingredients)]])) -> 0 | Y17: =IFERROR(_xlfn.XLOOKUP(Table_Input_InorganicFertiliser_Brands[[#This Row],[Product (select)]],FertiliserProducts[Product],FertiliserProducts[Urea source]), "") | Z17: =IFERROR(_xlfn.XLOOKUP(Table_Input_InorganicFertiliser_Brands[[#This Row],[Product (select)]],FertiliserProducts[Product],FertiliserProducts[Ammonia source]), "")
