Workbook
Name _Toc225350871: '5.4.1.1-4 Atmos deposition'!$C$1
Name _Toc225350871: '5.5.1.1-2 Leaching and runoff'!$C$1
Name AgResidue_Equations_CropResidue.VEERG_6_1_1_1__1__NitrousOxideEmissionsFromCropResidues: _xlfn.LAMBDA(_xlpm.M_c,_xlpm.EF_Ni,_xlpm.C_N2O, _xlpm.M_c * _xlpm.EF_Ni * _xlpm.C_N2O * 10 ^ (-3))
Name AgResidue_Equations_CropResidue.VEERG_6_1_1_1__1__NitrousOxideEmissionsFromCropResidues_FunctionName: _xlfn.LAMBDA("VEERG_6_1_1_1__1__NitrousOxideEmissionsFromCropResidues")
Name AgResidue_Equations_CropResidue.VEERG_6_1_1_1__1__NitrousOxideEmissionsFromCropResidues_LatexEquation: _xlfn.LAMBDA("E=\sum\nolimits_c\left(M_{c}\times EF_{N}\right)\times C_{g,N2O}\times 10^{-3}")
Name AgResidue_Equations_CropResidue.VEERG_6_1_1_1__1__NitrousOxideEmissionsFromCropResidues_NIRReference: _xlfn.LAMBDA("")
Name AgResidue_Equations_CropResidue.VEERG_6_1_1_1__1__NitrousOxideEmissionsFromCropResidues_Source: _xlfn.LAMBDA("VEERG 2026: 6.1.1.1, Equation (1)")
Name AgResidue_Equations_CropResidue.VEERG_6_1_1_1__1__NitrousOxideEmissionsFromCropResidues_Title: _xlfn.LAMBDA("Nitrous oxide emissions from the return of crop residues across all crops c to the soil")
Name AgResidue_Equations_CropResidue.VEERG_6_1_1_1__1__NitrousOxideEmissionsFromCropResidues_Unit: _xlfn.LAMBDA("t N2O")
Name AgResidue_Equations_CropResidue.VEERG_6_1_1_1__1__NitrousOxideEmissionsFromCropResidues_Variable: _xlfn.LAMBDA("E")
Name AgResidue_Equations_CropResidue.VEERG_6_1_1_1__2__MassOfNitrogenInCropResidues_LatexEquation: _xlfn.LAMBDA("M_{c}=(P_{c}\times R_{AGc}\times(1-F_{c}-FFOD_{c})\times DM_{c}\times NC_{AGc})+(P_{c}\times R_{AGc}\times R_{BGc}\times DM_{c}\times NC_{BGc})")
Name AgResidue_Equations_CropResidue.VEERG_6_1_1_1__2__MassOfNitrogenInCropResidues_NIRReference: _xlfn.LAMBDA("")
Name AgResidue_Equations_CropResidue.VEERG_6_1_1_1__2__MassOfNitrogenInCropResidues_Source: _xlfn.LAMBDA("VEERG 2026: 6.1.1.1, Equation (2)")
Name AgResidue_Equations_CropResidue.VEERG_6_1_1_1__2__MassOfNitrogenInCropResidues_Title: _xlfn.LAMBDA("Mass of nitrogen in crop residues returned to the soil")
Name AgResidue_Equations_CropResidue.VEERG_6_1_1_1__2__MassOfNitrogenInCropResidues_Unit: _xlfn.LAMBDA("kg N")
Name AgResidue_Equations_CropResidue.VEERG_6_1_1_1__2__MassOfNitrogenInCropResidues_Variable: _xlfn.LAMBDA("M_c")
Name AgResidue_Equations_CropResidue.VEERG_6_1_1_2__1__FractionOfCropResidueRemovedBaled: _xlfn.LAMBDA(_xlpm.B,_xlpm.M_B,_xlpm.P_c,_xlpm.R_AGc, IFERROR((_xlpm.B * _xlpm.M_B) / (_xlpm.P_c * _xlpm.R_AGc), 0))
Name AgResidue_Equations_CropResidue.VEERG_6_1_1_2__1__FractionOfCropResidueRemovedBaled_LatexEquation: _xlfn.LAMBDA("FFOD_{c}=\frac{B\times M_{B}}{P_{c}\times R_{AG,c}}")
Name AgResidue_Equations_CropResidue.VEERG_6_1_1_2__1__FractionOfCropResidueRemovedBaled_NIRReference: _xlfn.LAMBDA("")
Name AgResidue_Equations_CropResidue.VEERG_6_1_1_2__1__FractionOfCropResidueRemovedBaled_Source: _xlfn.LAMBDA("VEERG 2026: 6.1.1.2, Equation (1)")
Name AgResidue_Equations_CropResidue.VEERG_6_1_1_2__1__FractionOfCropResidueRemovedBaled_Title: _xlfn.LAMBDA("Fraction of crop residue that is removed for crop c, calculated where residues are baled")
Name AgResidue_Equations_CropResidue.VEERG_6_1_1_2__1__FractionOfCropResidueRemovedBaled_Unit: _xlfn.LAMBDA("fraction")
Name AgResidue_Equations_CropResidue.VEERG_6_1_1_2__1__FractionOfCropResidueRemovedBaled_Variable: _xlfn.LAMBDA("FFOD_c")
Name AgResidue_Equations_CropResidue.VEERG_6_1_1_2__1__FractionOfCropResidueRemovedBaled_Variation: _xlfn.LAMBDA("")
Name AgResidue_Equations_FieldBurning.VEERG_6_4_1_1__1__MethaneEmissionsFromBurningOfCropResidues: _xlfn.LAMBDA(_xlpm.M_burnc,_xlpm.CC_c,_xlpm.EF_CH4,_xlpm.C_CH4, (_xlpm.M_burnc * _xlpm.CC_c) * _xlpm.EF_CH4 * _xlpm.C_CH4 * 10 ^ (-3))
Name AgResidue_Equations_FieldBurning.VEERG_6_4_1_1__1__MethaneEmissionsFromBurningOfCropResidues_FunctionName: _xlfn.LAMBDA("VEERG_6_4_1_1__1__MethaneEmissionsFromBurningOfCropResidues")
Name AgResidue_Equations_FieldBurning.VEERG_6_4_1_1__1__MethaneEmissionsFromBurningOfCropResidues_LatexEquation: _xlfn.LAMBDA("E_{CH4}=\sum\nolimits_c(M_{burn,c}\times CC_{c})\times EF_{CH4}\times C_{CH4}\times 10^{-3}")
Name AgResidue_Equations_FieldBurning.VEERG_6_4_1_1__1__MethaneEmissionsFromBurningOfCropResidues_NIRReference: _xlfn.LAMBDA("")
Name AgResidue_Equations_FieldBurning.VEERG_6_4_1_1__1__MethaneEmissionsFromBurningOfCropResidues_Source: _xlfn.LAMBDA("VEERG 2026: 6.4.1.1, Equation (1)")
Name AgResidue_Equations_FieldBurning.VEERG_6_4_1_1__1__MethaneEmissionsFromBurningOfCropResidues_Title: _xlfn.LAMBDA("Methane emissions from the burning of crop residues")
Name AgResidue_Equations_FieldBurning.VEERG_6_4_1_1__1__MethaneEmissionsFromBurningOfCropResidues_Unit: _xlfn.LAMBDA("t CH4")
Name AgResidue_Equations_FieldBurning.VEERG_6_4_1_1__1__MethaneEmissionsFromBurningOfCropResidues_Variable: _xlfn.LAMBDA("ECH4")
Name AgResidue_Equations_FieldBurning.VEERG_6_4_1_1__2__NitrousOxideEmissionsFromBurningOfCropResidues: _xlfn.LAMBDA(_xlpm.M_burnc,_xlpm.NC_AGc,_xlpm.EF_N2O,_xlpm.C_N2O, (_xlpm.M_burnc * _xlpm.NC_AGc) * _xlpm.EF_N2O * _xlpm.C_N2O * 10 ^ (-3))
Name AgResidue_Equations_FieldBurning.VEERG_6_4_1_1__2__NitrousOxideEmissionsFromBurningOfCropResidues_FunctionName: _xlfn.LAMBDA("VEERG_6_4_1_1__2__NitrousOxideEmissionsFromBurningOfCropResidues")
Name AgResidue_Equations_FieldBurning.VEERG_6_4_1_1__2__NitrousOxideEmissionsFromBurningOfCropResidues_LatexEquation: _xlfn.LAMBDA("E_{N2O}=\sum\nolimits_c(M_{burn,c}\times NC_{AGc})\times EF_{N2O}\times C_{N2O}\times 10^{-3}")
Name AgResidue_Equations_FieldBurning.VEERG_6_4_1_1__2__NitrousOxideEmissionsFromBurningOfCropResidues_NIRReference: _xlfn.LAMBDA("")
Name AgResidue_Equations_FieldBurning.VEERG_6_4_1_1__2__NitrousOxideEmissionsFromBurningOfCropResidues_Source: _xlfn.LAMBDA("VEERG 2026: 6.4.1.1, Equation (2)")
Name AgResidue_Equations_FieldBurning.VEERG_6_4_1_1__2__NitrousOxideEmissionsFromBurningOfCropResidues_Title: _xlfn.LAMBDA("Nitrous oxide emissions from the burning of crop residues")
Name AgResidue_Equations_FieldBurning.VEERG_6_4_1_1__2__NitrousOxideEmissionsFromBurningOfCropResidues_Unit: _xlfn.LAMBDA("t N2O")
Name AgResidue_Equations_FieldBurning.VEERG_6_4_1_1__2__NitrousOxideEmissionsFromBurningOfCropResidues_Variable: _xlfn.LAMBDA("EN2O")
Name AgResidue_Equations_FieldBurning.VEERG_6_4_1_1__3__MassOfCropResidueBurnt: _xlfn.LAMBDA(_xlpm.P_c,_xlpm.R_AGc,_xlpm.S_c,_xlpm.DM_c,_xlpm.Z_c,_xlpm.F_c, _xlpm.P_c * _xlpm.R_AGc * _xlpm.S_c * _xlpm.DM_c * _xlpm.Z_c * _xlpm.F_c)
Name AgResidue_Equations_FieldBurning.VEERG_6_4_1_1__3__MassOfCropResidueBurnt_FunctionName: _xlfn.LAMBDA("VEERG_6_4_1_1__3__MassOfCropResidueBurnt")
Name AgResidue_Equations_FieldBurning.VEERG_6_4_1_1__3__MassOfCropResidueBurnt_LatexEquation: _xlfn.LAMBDA("M_{burn,c}=P_{c}\times R_{AGc}\times S_{c}\times DM_{c}\times Z_{c}\times F_{c}")
Name AgResidue_Equations_FieldBurning.VEERG_6_4_1_1__3__MassOfCropResidueBurnt_NIRReference: _xlfn.LAMBDA("")
Name AgResidue_Equations_FieldBurning.VEERG_6_4_1_1__3__MassOfCropResidueBurnt_Source: _xlfn.LAMBDA("VEERG 2026: 6.4.1.1, Equation (3)")
Name AgResidue_Equations_FieldBurning.VEERG_6_4_1_1__3__MassOfCropResidueBurnt_Title: _xlfn.LAMBDA("Mass of residue of crop c burnt")
Name AgResidue_Equations_FieldBurning.VEERG_6_4_1_1__3__MassOfCropResidueBurnt_Unit: _xlfn.LAMBDA("kg")
Name AgResidue_Equations_FieldBurning.VEERG_6_4_1_1__3__MassOfCropResidueBurnt_Variable: _xlfn.LAMBDA("M_burnc")
Name AgResidue_Equations_Leaching.VEERG_6_3_1_1__1__LeachingAndRunoffEmissionsCropAndPastureResidue: _xlfn.LAMBDA(_xlpm.M_leachcp,_xlpm.EF_leach,_xlpm.C_N2O, (_xlpm.M_leachcp * _xlpm.EF_leach) * _xlpm.C_N2O * 10 ^ (-3))
Name AgResidue_Equations_Leaching.VEERG_6_3_1_1__1__LeachingAndRunoffEmissionsCropAndPastureResidue_LatexEquation: _xlfn.LAMBDA("E_{N2O}=\sum\nolimits_c\sum\nolimits_p(M_{leach,cp}\times EF_{leach}\times C_{N2O}\times 10^{-3})")
Name AgResidue_Equations_Leaching.VEERG_6_3_1_1__1__LeachingAndRunoffEmissionsCropAndPastureResidue_NIRReference: _xlfn.LAMBDA("")
Name AgResidue_Equations_Leaching.VEERG_6_3_1_1__1__LeachingAndRunoffEmissionsCropAndPastureResidue_Source: _xlfn.LAMBDA("VEERG 2026: 6.3.1.1, Equation (1)")
Name AgResidue_Equations_Leaching.VEERG_6_3_1_1__1__LeachingAndRunoffEmissionsCropAndPastureResidue_Title: _xlfn.LAMBDA("Nitrous oxide leaching and runoff emissions from crop and pasture residues returned to the soil")
Name AgResidue_Equations_Leaching.VEERG_6_3_1_1__1__LeachingAndRunoffEmissionsCropAndPastureResidue_Unit: _xlfn.LAMBDA("t N2O")
Name AgResidue_Equations_Leaching.VEERG_6_3_1_1__1__LeachingAndRunoffEmissionsCropAndPastureResidue_Variable: _xlfn.LAMBDA("EN2O")
Name AgResidue_Equations_Leaching.VEERG_6_3_1_1__2__MassOfNitrogenLostThroughLeachingAndRunoff: _xlfn.LAMBDA(_xlpm.M_cp,_xlpm.FracWET_j,_xlpm.FracLEACH, _xlpm.M_cp * _xlpm.FracWET_j * _xlpm.FracLEACH)
Name AgResidue_Equations_Leaching.VEERG_6_3_1_1__2__MassOfNitrogenLostThroughLeachingAndRunoff_LatexEquation: _xlfn.LAMBDA("M_{leach,cp}=M_{cp}\times FracWET_{j}\times FracLEACH")
Name AgResidue_Equations_Leaching.VEERG_6_3_1_1__2__MassOfNitrogenLostThroughLeachingAndRunoff_NIRReference: _xlfn.LAMBDA("")
Name AgResidue_Equations_Leaching.VEERG_6_3_1_1__2__MassOfNitrogenLostThroughLeachingAndRunoff_Source: _xlfn.LAMBDA("VEERG 2026: 6.3.1.1, Equation (2)")
Name AgResidue_Equations_Leaching.VEERG_6_3_1_1__2__MassOfNitrogenLostThroughLeachingAndRunoff_Title: _xlfn.LAMBDA("Mass of nitrogen lost through leaching and runoff")

Sheet Home
A1: #VALUE!
A3: =HYPERLINK("#'Home'!A1", "Home") -> Home
A4: =HYPERLINK("#'Results - Activity period'!A1", "Results - Activity period") -> Results - Activity period
A5: =HYPERLINK("#'Results - Product EI'!A1", "Results - Product EI") -> Results - Product EI
A8: INPUTS
A9: =HYPERLINK("#'Input - Enterprise'!A1", "Enterprise") -> Enterprise
A10: =HYPERLINK("#'Input - Site'!A1", "Site") -> Site
A11: =HYPERLINK("#'Input - Crop'!A1", "Crop") -> Crop
A12: =HYPERLINK("#'Input - Fert Prod System'!A1", "Fert Prod System") -> Fert Prod System
A13: =HYPERLINK("#'Input - Fertiliser'!A1", "Fertiliser") -> Fertiliser
A14: =HYPERLINK("#'Input - Fuel'!A1", "Fuel") -> Fuel
A15: =HYPERLINK("#'Input - Electricity'!A1", "Electricity") -> Electricity
A16: =HYPERLINK("#'Input - Common farm inputs'!A1", "Common farm inputs") -> Common farm inputs
A17: =HYPERLINK("#'Input - Crop pasture farm input'!A1", "Crop pasture farm input") -> Crop pasture farm input
A18: =HYPERLINK("#'Input - Freight'!A1", "Freight") -> Freight
A19: =HYPERLINK("#'Input - Solid waste'!A1", "Solid waste") -> Solid waste
A20: =HYPERLINK("#'Input - Data quality'!A1", "Data quality") -> Data quality
A23: CALCULATIONS
A24: =HYPERLINK("#'5.1.1.1-2 Inorganic fert N2O'!A1", "5.1.1.1-2 Inorganic fert N2O") -> 5.1.1.1-2 Inorganic fert N2O
A25: =HYPERLINK("#'5.1.1.3-4 Inorganic fert CO2'!A1", "5.1.1.3-4 Inorganic fert CO2") -> 5.1.1.3-4 Inorganic fert CO2
A26: =HYPERLINK("#'5.2.1.1-2 Organic Fert N2O'!A1", "5.2.1.1-2 Organic fert N2O") -> 5.2.1.1-2 Organic fert N2O
A27: =HYPERLINK("#'5.3.1.1-2 Lime CO2'!A1", "5.3.1.1-2 Lime CO2") -> 5.3.1.1-2 Lime CO2
A28: =HYPERLINK("#'5.4.1.1-4 Atmos deposition'!A1", "5.4.1.1-4 Atmos. deposition") -> 5.4.1.1-4 Atmos. deposition
A29: =HYPERLINK("#'5.5.1.1-2 Leaching and runoff'!A1", "5.5.1.1-2 Leaching & runoff") -> 5.5.1.1-2 Leaching & runoff
A30: =HYPERLINK("#'6.1.1.1-2 Crop residue N2O'!A1", "6.1.1.1-2 Crop residue N2O") -> 6.1.1.1-2 Crop residue N2O
A31: =HYPERLINK("#'6.3.1.1-2 Leach runoff crop'!A1", "6.3.1.1-2 Leach & runoff (crop)") -> 6.3.1.1-2 Leach & runoff (crop)
A32: =HYPERLINK("#'6.4.1.1-2 Residue burning'!A1", "6.4.1.1-2 Residue burning") -> 6.4.1.1-2 Residue burning
A33: =HYPERLINK("#'8.1.1.1-2 Transport fuel'!A1", "8.1.1.1-2 Transport fuel") -> 8.1.1.1-2 Transport fuel
A34: =HYPERLINK("#'8.2.1.1-2 Stationary fuel'!A1", "8.2.1.1-2 Stationary fuel") -> 8.2.1.1-2 Stationary fuel
A35: =HYPERLINK("#'10.1.1-2 Solid waste treatment'!A1", "10.1.1.1-2 Solid waste") -> 10.1.1.1-2 Solid waste
A36: =HYPERLINK("#'14.1.1-2 Purchased electricity'!A1", "14.1.1-2 Purchased electricity") -> 14.1.1-2 Purchased electricity
A37: =HYPERLINK("#'15 Scope 3'!A1", "15 Scope 3") -> 15 Scope 3
A40: APPENDICES
A41: =HYPERLINK("#'Constants - Ag Residue'!A1", "Constants - Ag residue") -> Constants - Ag residue
A42: =HYPERLINK("#'Constants - Electricity'!A1", "Constants - Electricity") -> Constants - Electricity
A43: =HYPERLINK("#'Constants - Fertiliser'!A1", "Constants - Fertiliser") -> Constants - Fertiliser
A44: =HYPERLINK("#'Constants - Fuel'!A1", "Constants - Fuel") -> Constants - Fuel
A45: =HYPERLINK("#'Constants - Scope 3'!A1", "Constants - Scope 3") -> Constants - Scope 3
A46: =HYPERLINK("#'Constants - Solid Waste'!A1", "Constants - Solid Waste") -> Constants - Solid Waste
A47: =HYPERLINK("#'Constants - Common'!A1", "Constants - Common") -> Constants - Common
...

Sheet Results - Activity period
A1: #VALUE! | C1: Results - Activity period
A3: =HYPERLINK("#'Home'!A1", "Home") -> Home
A4: =HYPERLINK("#'Results - Activity period'!A1", "Results - Activity period") -> Results - Activity period | D4: ="Emissions breakdown for activities running between " & TEXT(X_Cell_Site_StartDate, "dd mmmm yyyy") & " and " & TEXT('Input - Enterprise'!E13, "dd mmmm yyyy") -> Emissions breakdown for activities running between 01 January 2025 and 31 December 2025
A5: =HYPERLINK("#'Results - Product EI'!A1", "Results - Product EI") -> Results - Product EI
D6: Scope 1
A8: INPUTS | D8: Scope 1 source | E8: GHG emissions method 1 | F8: GHG emissions method 2 | G8: GHG Unit | H8: CO2-e emissions method 1 | I8: CO2-e emissions method 2
A9: =HYPERLINK("#'Input - Enterprise'!A1", "Enterprise") -> Enterprise | D9: 5.1.1.1-2 Inorganic fert N2O | E9: {=VEERG_5_1_1_1__1_InorganicFertiliserApplicationN2OEmissions_Result_Method1} -> 2.0110749 | F9: {=VEERG_5_1_1_1__1_InorganicFertiliserApplicationN2OEmissions_Result_Method2} -> 2.011075 | G9: t N2O | H9: {=Common_Equations.Common_ConvertN2OToCO2e(E9,_xlfn.XLOOKUP("N2O", Table_GWPData[Gas],Table_GWPData[CO2-e factor]))} -> 532.93486 | I9: {=Common_Equations.Common_ConvertN2OToCO2e(F9,_xlfn.XLOOKUP("N2O", Table_GWPData[Gas],Table_GWPData[CO2-e factor]))} -> 532.93488 | J9: t CO2e
A10: =HYPERLINK("#'Input - Site'!A1", "Site") -> Site | D10: 5.1.1.3-4 Inorganic fert CO2 | E10: {=VEERG_5_1_1_3__1_InorganicFertiliserApplicationCO2Emissions_Result_Method1} -> 184.92753 | F10: =E10 -> 184.92753 | G10: t CO2 | H10: =E10 -> 184.92753 | I10: =F10 -> 184.92753 | J10: t CO2e
A11: =HYPERLINK("#'Input - Crop'!A1", "Crop") -> Crop | D11: 5.2.1.1-2 Organic fert N2O | E11: {=VEERG_5_2_1_1__2_MassOfNitrogenInOrganicFertiliser_Result_Method1} -> 0.055785714 | F11: =E11 -> 0.055785714 | G11: t N2O | H11: {=Common_Equations.Common_ConvertN2OToCO2e(E11,_xlfn.XLOOKUP("N2O", Table_GWPData[Gas],Table_GWPData[CO2-e factor]))} -> 14.783214 | I11: {=Common_Equations.Common_ConvertN2OToCO2e(F11,_xlfn.XLOOKUP("N2O", Table_GWPData[Gas],Table_GWPData[CO2-e factor]))} -> 14.783214 | J11: t CO2e
A12: =HYPERLINK("#'Input - Fert Prod System'!A1", "Fert Prod System") -> Fert Prod System | D12: 5.3.1.1-2 Lime CO2 | E12: {=VEERG_5_3_1_1__1_LimeApplicationCO2Emissions_Result_Method1} -> 758.08333 | F12: =E12 -> 758.08333 | G12: t CO2 | H12: =E12 -> 758.08333 | I12: =F12 -> 758.08333 | J12: t CO2e
A13: =HYPERLINK("#'Input - Fertiliser'!A1", "Fertiliser") -> Fertiliser | D13: 5.4.1.1-4 Atmos. deposition | E13: 0.0016401 | F13: =E13 -> 0.0016401 | G13: t N2O | H13: {=Common_Equations.Common_ConvertN2OToCO2e(E13,_xlfn.XLOOKUP("N2O", Table_GWPData[Gas],Table_GWPData[CO2-e factor]))} -> 0.4346265 | I13: {=Common_Equations.Common_ConvertN2OToCO2e(F13,_xlfn.XLOOKUP("N2O", Table_GWPData[Gas],Table_GWPData[CO2-e factor]))} -> 0.4346265 | J13: t CO2e
A14: =HYPERLINK("#'Input - Fuel'!A1", "Fuel") -> Fuel | D14: 5.5.1.1-2 Leaching & runoff | E14: 0.07879174 | F14: =E14 -> 0.07879174 | G14: t N2O | H14: {=Common_Equations.Common_ConvertN2OToCO2e(E14,_xlfn.XLOOKUP("N2O", Table_GWPData[Gas],Table_GWPData[CO2-e factor]))} -> 20.879811 | I14: {=Common_Equations.Common_ConvertN2OToCO2e(F14,_xlfn.XLOOKUP("N2O", Table_GWPData[Gas],Table_GWPData[CO2-e factor]))} -> 20.879811 | J14: t CO2e
A15: =HYPERLINK("#'Input - Electricity'!A1", "Electricity") -> Electricity | D15: 6.1.1.1-2 Crop residue N2O | E15: {=VEERG_6_1_1_1__1__NitrousOxideEmissionsFromCropResidues_Result_Method1} -> 0.66792 | F15: {=VEERG_6_1_1_1__1__NitrousOxideEmissionsFromCropResidues_Result_Method2} -> 0.66792 | G15: t N2O | H15: {=Common_Equations.Common_ConvertN2OToCO2e(E15,_xlfn.XLOOKUP("N2O", Table_GWPData[Gas],Table_GWPData[CO2-e factor]))} -> 176.9988 | I15: {=Common_Equations.Common_ConvertN2OToCO2e(F15,_xlfn.XLOOKUP("N2O", Table_GWPData[Gas],Table_GWPData[CO2-e factor]))} -> 176.9988 | J15: t CO2e
A16: =HYPERLINK("#'Input - Common farm inputs'!A1", "Common farm inputs") -> Common farm inputs | D16: 6.3.1.1-2 Leach & runoff (crop) | E16: {=VEERG_6_3_1_1__1__LeachingAndRunoffEmissionsCropAndPastureResidue_CropOnly_Result_Method1} -> 0.35266176 | F16: {=VEERG_6_3_1_1__1__LeachingAndRunoffEmissionsCropAndPastureResidue_CropOnly_Result_Method2} -> 0.35266176 | G16: t N2O | H16: {=Common_Equations.Common_ConvertN2OToCO2e(E16,_xlfn.XLOOKUP("N2O", Table_GWPData[Gas],Table_GWPData[CO2-e factor]))} -> 93.455366 | I16: {=Common_Equations.Common_ConvertN2OToCO2e(F16,_xlfn.XLOOKUP("N2O", Table_GWPData[Gas],Table_GWPData[CO2-e factor]))} -> 93.455366 | J16: t CO2e
A17: =HYPERLINK("#'Input - Crop pasture farm input'!A1", "Crop pasture farm input") -> Crop pasture farm input | D17: 6.4.1.1-2 Residue burning N2O | E17: {=VEERG_6_4_1_1__2__NitrousOxideEmissionsFromBurningOfCropResidues_Result_Method1} -> 0.12769303 | F17: =E17 -> 0.12769303 | G17: t N2O | H17: {=Common_Equations.Common_ConvertN2OToCO2e(E17,_xlfn.XLOOKUP("N2O", Table_GWPData[Gas],Table_GWPData[CO2-e factor]))} -> 33.838653 | I17: {=Common_Equations.Common_ConvertN2OToCO2e(F17,_xlfn.XLOOKUP("N2O", Table_GWPData[Gas],Table_GWPData[CO2-e factor]))} -> 33.838653 | J17: t CO2e
A18: =HYPERLINK("#'Input - Freight'!A1", "Freight") -> Freight | D18: 6.4.1.1-2 Residue burning CH4 | E18: {=VEERG_6_4_1_1__1__MethaneEmissionsFromBurningOfCropResidues_Result_Method1} -> 3.3264 | F18: =E18 -> 3.3264 | G18: t CH4 | H18: {=Common_Equations.Common_ConvertCH4ToCO2e(E18,_xlfn.XLOOKUP("CH4", Table_GWPData[Gas],Table_GWPData[CO2-e factor]))} -> 93.1392 | I18: {=Common_Equations.Common_ConvertCH4ToCO2e(F18,_xlfn.XLOOKUP("CH4", Table_GWPData[Gas],Table_GWPData[CO2-e factor]))} -> 93.1392 | J18: t CO2e
A19: =HYPERLINK("#'Input - Solid waste'!A1", "Solid waste") -> Solid waste | D19: 8.1.1.1-2 Transport fuel CO2 | E19: {=VEERG_8_1_1_1__1_FuelCombustionTransport_Result_CO2} -> 83.182 | F19: =E19 -> 83.182 | G19: t CO2 | H19: =E19 -> 83.182 | I19: =F19 -> 83.182 | J19: t CO2e
A20: =HYPERLINK("#'Input - Data quality'!A1", "Data quality") -> Data quality | D20: 8.1.1.1-2 Transport fuel CH4 | E20: {=VEERG_8_1_1_1__1_FuelCombustionTransport_Result_CH4} -> 0.19906 | F20: =E20 -> 0.19906 | G20: t CH4 | H20: {=Common_Equations.Common_ConvertCH4ToCO2e(E20,_xlfn.XLOOKUP("CH4", Table_GWPData[Gas],Table_GWPData[CO2-e factor]))} -> 5.57368 | I20: {=Common_Equations.Common_ConvertCH4ToCO2e(F20,_xlfn.XLOOKUP("CH4", Table_GWPData[Gas],Table_GWPData[CO2-e factor]))} -> 5.57368 | J20: t CO2e
D21: 8.1.1.1-2 Transport fuel N2O | E21: {=VEERG_8_1_1_1__1_FuelCombustionTransport_Result_N2O} -> 0.5845 | F21: =E21 -> 0.5845 | G21: t N2O | H21: {=Common_Equations.Common_ConvertN2OToCO2e(E21,_xlfn.XLOOKUP("N2O", Table_GWPData[Gas],Table_GWPData[CO2-e factor]))} -> 154.8925 | I21: {=Common_Equations.Common_ConvertN2OToCO2e(F21,_xlfn.XLOOKUP("N2O", Table_GWPData[Gas],Table_GWPData[CO2-e factor]))} -> 154.8925 | J21: t CO2e
D22: 8.2.1.1-2 Stationary fuel CO2 | E22: {=VEERG_8_2_1_1__1_FuelCombustionStationary_Result_CO2} -> 29.0708 | F22: =E22 -> 29.0708 | G22: t CO2 | H22: =E22 -> 29.0708 | I22: =F22 -> 29.0708 | J22: t CO2e
A23: CALCULATIONS | D23: 8.2.1.1-2 Stationary fuel CH4 | E23: {=VEERG_8_2_1_1__1_FuelCombustionStationary_Result_CH4} -> 0.0724 | F23: =E23 -> 0.0724 | G23: t CH4 | H23: {=Common_Equations.Common_ConvertCH4ToCO2e(E23,_xlfn.XLOOKUP("CH4", Table_GWPData[Gas],Table_GWPData[CO2-e factor]))} -> 2.0272 | I23: {=Common_Equations.Common_ConvertCH4ToCO2e(F23,_xlfn.XLOOKUP("CH4", Table_GWPData[Gas],Table_GWPData[CO2-e factor]))} -> 2.0272 | J23: t CO2e
A24: =HYPERLINK("#'5.1.1.1-2 Inorganic fert N2O'!A1", "5.1.1.1-2 Inorganic fert N2O") -> 5.1.1.1-2 Inorganic fert N2O | D24: 8.2.1.1-2 Stationary fuel N2O | E24: {=VEERG_8_2_1_1__1_FuelCombustionStationary_Result_N2O} -> 0.0714 | F24: =E24 -> 0.0714 | G24: t N2O | H24: {=Common_Equations.Common_ConvertN2OToCO2e(E24,_xlfn.XLOOKUP("N2O", Table_GWPData[Gas],Table_GWPData[CO2-e factor]))} -> 18.921 | I24: {=Common_Equations.Common_ConvertN2OToCO2e(F24,_xlfn.XLOOKUP("N2O", Table_GWPData[Gas],Table_GWPData[CO2-e factor]))} -> 18.921 | J24: t CO2e
A25: =HYPERLINK("#'5.1.1.3-4 Inorganic fert CO2'!A1", "5.1.1.3-4 Inorganic fert CO2") -> 5.1.1.3-4 Inorganic fert CO2 | D25: 14.1.1-2 Purchased electricity (Location-based) | E25: {=VEERG_14_1_1__1_LocationBasedScopeElectricityEmissions_Result_Method1} -> 16.8 | F25: =E25 -> 16.8 | G25: t CO2e | H25: =E25 -> 16.8 | I25: =F25 -> 16.8 | J25: t CO2e
A26: =HYPERLINK("#'5.2.1.1-2 Organic Fert N2O'!A1", "5.2.1.1-2 Organic fert N2O") -> 5.2.1.1-2 Organic fert N2O | D26: 14.1.1-2 Purchased electricity (Market-based) | E26: {=VEERG_14_1_2__1_MarketBasedScopeElectricityEmissionsVariation_Result_Method1} -> 9.72 | F26: =E26 -> 9.72 | G26: t CO2e | H26: =E26 -> 9.72 | I26: =F26 -> 9.72 | J26: t CO2e
A27: =HYPERLINK("#'5.3.1.1-2 Lime CO2'!A1", "5.3.1.1-2 Lime CO2") -> 5.3.1.1-2 Lime CO2 | D27: Total | H27: =SUM(H9:H26) -> 2229.6626 | I27: =SUM(I9:I26) -> 2229.6626 | J27: t CO2e
A28: =HYPERLINK("#'5.4.1.1-4 Atmos deposition'!A1", "5.4.1.1-4 Atmos. deposition") -> 5.4.1.1-4 Atmos. deposition
A29: =HYPERLINK("#'5.5.1.1-2 Leaching and runoff'!A1", "5.5.1.1-2 Leaching & runoff") -> 5.5.1.1-2 Leaching & runoff
A30: =HYPERLINK("#'6.1.1.1-2 Crop residue N2O'!A1", "6.1.1.1-2 Crop residue N2O") -> 6.1.1.1-2 Crop residue N2O | D30: Scope 2
A31: =HYPERLINK("#'6.3.1.1-2 Leach runoff crop'!A1", "6.3.1.1-2 Leach & runoff (crop)") -> 6.3.1.1-2 Leach & runoff (crop)
A32: =HYPERLINK("#'6.4.1.1-2 Residue burning'!A1", "6.4.1.1-2 Residue burning") -> 6.4.1.1-2 Residue burning | D32: Scope 2 source | E32: GHG emissions method 1 | F32: GHG emissions method 2 | G32: GHG Unit | H32: CO2-e emissions method 1 | I32: CO2-e emissions method 2
A33: =HYPERLINK("#'8.1.1.1-2 Transport fuel'!A1", "8.1.1.1-2 Transport fuel") -> 8.1.1.1-2 Transport fuel | D33: {="14.1.1-2 Purchased electricity " & IF(X_Cell_Electricity_CalculationMethod="Location-based (simpler)", "(Location-based)", "(Market-based)")} -> 14.1.1-2 Purchased electricity (Location-based) | E33: {=IF(X_Cell_Electricity_CalculationMethod="Location-based (simpler)", VEERG_14_1_1__1_LocationBasedScopeElectricityEmissions_Result_Method1, VEERG_14_1_2__1_MarketBasedScopeElectricityEmissionsVariation_Result_Method1)} -> 16.8 | F33: =E33 -> 16.8 | G33: t CO2e | H33: =E33 -> 16.8 | I33: =F33 -> 16.8 | J33: t CO2e
A34: =HYPERLINK("#'8.2.1.1-2 Stationary fuel'!A1", "8.2.1.1-2 Stationary fuel") -> 8.2.1.1-2 Stationary fuel | D34: Total scope 2 | H34: =SUM(H33:H33) -> 16.8 | I34: =SUM(I33:I33) -> 16.8 | J34: t CO2e
A35: =HYPERLINK("#'10.1.1-2 Solid waste treatment'!A1", "10.1.1.1-2 Solid waste") -> 10.1.1.1-2 Solid waste
A36: =HYPERLINK("#'14.1.1-2 Purchased electricity'!A1", "14.1.1-2 Purchased electricity") -> 14.1.1-2 Purchased electricity
A37: =HYPERLINK("#'15 Scope 3'!A1", "15 Scope 3") -> 15 Scope 3 | D37: Scope 3
D39: Scope 3 source | E39: GHG emissions method 1 | F39: GHG emissions method 2 | G39: GHG Unit | H39: CO2-e emissions method 1 | I39: CO2-e emissions method 2
A40: APPENDICES | D40: 15.4.1.1 Fertiliser | E40: {=VEERG_15_4_1_1__2_EmissionsFromPurchasedFertiliserComponentsVariation_Result_Method1} -> 518.806 | F40: {=VEERG_15_4_1_1__2_EmissionsFromPurchasedFertiliserComponentsVariation_Result_Method2} -> 599.726 | G40: t CO2e | H40: =E40 -> 518.806 | I40: =F40 -> 599.726 | J40: t CO2e
A41: =HYPERLINK("#'Constants - Ag Residue'!A1", "Constants - Ag residue") -> Constants - Ag residue | D41: 15.5.1.1 Agrichemicals | E41: {=VEERG_15_5_1_1__1_EmissionsFromPurchasedAgrichemicals_Result_Method1} -> 7.516 | F41: {=VEERG_15_5_1_1__1_EmissionsFromPurchasedAgrichemicals_Result_Method2} -> 7.496 | G41: t CO2e | H41: =E41 -> 7.516 | I41: =F41 -> 7.496 | J41: t CO2e
A42: =HYPERLINK("#'Constants - Electricity'!A1", "Constants - Electricity") -> Constants - Electricity | D42: 15.6.1.1 Lime | E42: {=VEERG_15_6_1_1__1_EmissionsFromPurchasedLime_Result_Method1} -> 0.16554 | F42: {=VEERG_15_6_1_1__1_EmissionsFromPurchasedLime_Result_Method2} -> 0.144 | G42: t CO2e | H42: =E42 -> 0.16554 | I42: =F42 -> 0.144 | J42: t CO2e
A43: =HYPERLINK("#'Constants - Fertiliser'!A1", "Constants - Fertiliser") -> Constants - Fertiliser | D43: 15.7.1.1 Services and contractor operations | E43: {=VEERG_15_7_1_1__1_EmissionsFromPurchasedServices_Result_Method1} -> No data | F43: {=VEERG_15_7_1_1__1_EmissionsFromPurchasedServices_Result_Method2} -> 1.1 | G43: t CO2e | H43: =E43 -> No data | I43: =F43 -> 1.1 | J43: t CO2e
...

Sheet Results - Product EI
A1: #VALUE! | C1: Results - Product emissions intensity
A3: =HYPERLINK("#'Home'!A1", "Home") -> Home
A4: =HYPERLINK("#'Results - Activity period'!A1", "Results - Activity period") -> Results - Activity period
A5: =HYPERLINK("#'Results - Product EI'!A1", "Results - Product EI") -> Results - Product EI
A8: INPUTS
A9: =HYPERLINK("#'Input - Enterprise'!A1", "Enterprise") -> Enterprise
A10: =HYPERLINK("#'Input - Site'!A1", "Site") -> Site
A11: =HYPERLINK("#'Input - Crop'!A1", "Crop") -> Crop
A12: =HYPERLINK("#'Input - Fert Prod System'!A1", "Fert Prod System") -> Fert Prod System
A13: =HYPERLINK("#'Input - Fertiliser'!A1", "Fertiliser") -> Fertiliser
A14: =HYPERLINK("#'Input - Fuel'!A1", "Fuel") -> Fuel
A15: =HYPERLINK("#'Input - Electricity'!A1", "Electricity") -> Electricity
A16: =HYPERLINK("#'Input - Common farm inputs'!A1", "Common farm inputs") -> Common farm inputs
A17: =HYPERLINK("#'Input - Crop pasture farm input'!A1", "Crop pasture farm input") -> Crop pasture farm input
A18: =HYPERLINK("#'Input - Freight'!A1", "Freight") -> Freight
A19: =HYPERLINK("#'Input - Solid waste'!A1", "Solid waste") -> Solid waste
A20: =HYPERLINK("#'Input - Data quality'!A1", "Data quality") -> Data quality
A23: CALCULATIONS
A24: =HYPERLINK("#'5.1.1.1-2 Inorganic fert N2O'!A1", "5.1.1.1-2 Inorganic fert N2O") -> 5.1.1.1-2 Inorganic fert N2O
A25: =HYPERLINK("#'5.1.1.3-4 Inorganic fert CO2'!A1", "5.1.1.3-4 Inorganic fert CO2") -> 5.1.1.3-4 Inorganic fert CO2
A26: =HYPERLINK("#'5.2.1.1-2 Organic Fert N2O'!A1", "5.2.1.1-2 Organic fert N2O") -> 5.2.1.1-2 Organic fert N2O
A27: =HYPERLINK("#'5.3.1.1-2 Lime CO2'!A1", "5.3.1.1-2 Lime CO2") -> 5.3.1.1-2 Lime CO2
A28: =HYPERLINK("#'5.4.1.1-4 Atmos deposition'!A1", "5.4.1.1-4 Atmos. deposition") -> 5.4.1.1-4 Atmos. deposition
A29: =HYPERLINK("#'5.5.1.1-2 Leaching and runoff'!A1", "5.5.1.1-2 Leaching & runoff") -> 5.5.1.1-2 Leaching & runoff
A30: =HYPERLINK("#'6.1.1.1-2 Crop residue N2O'!A1", "6.1.1.1-2 Crop residue N2O") -> 6.1.1.1-2 Crop residue N2O
A31: =HYPERLINK("#'6.3.1.1-2 Leach runoff crop'!A1", "6.3.1.1-2 Leach & runoff (crop)") -> 6.3.1.1-2 Leach & runoff (crop)
A32: =HYPERLINK("#'6.4.1.1-2 Residue burning'!A1", "6.4.1.1-2 Residue burning") -> 6.4.1.1-2 Residue burning | D32: ="Emissions for whole production cycle running between " & TEXT(X_Cell_Enterprise_ProductionTimeframeStart, "d mmmm yyyy") & " and " & TEXT(X_Cell_Enterprise_ProductionTimeframeEnd, "d mmmm yyyy") -> Emissions for whole production cycle running between 1 November 2025 and 31 March 2026
A33: =HYPERLINK("#'8.1.1.1-2 Transport fuel'!A1", "8.1.1.1-2 Transport fuel") -> 8.1.1.1-2 Transport fuel
A34: =HYPERLINK("#'8.2.1.1-2 Stationary fuel'!A1", "8.2.1.1-2 Stationary fuel") -> 8.2.1.1-2 Stationary fuel
A35: =HYPERLINK("#'10.1.1-2 Solid waste treatment'!A1", "10.1.1.1-2 Solid waste") -> 10.1.1.1-2 Solid waste | E35: Method 1 | F35: Method 2
A36: =HYPERLINK("#'14.1.1-2 Purchased electricity'!A1", "14.1.1-2 Purchased electricity") -> 14.1.1-2 Purchased electricity | D36: Emissions for production cycle excluding removals | E36: =Result_EmissionsForWholeProductionCycle_Gross_Method1 -> 3244.0992 | F36: =Result_EmissionsForWholeProductionCycle_Gross_Method2 -> 13168.273 | G36: t CO2e
A37: =HYPERLINK("#'15 Scope 3'!A1", "15 Scope 3") -> 15 Scope 3 | D37: Net emissions for production cycle | E37: =Result_EmissionsForWholeProductionCycle_Net_Method1 -> 3244.0992 | F37: =Result_EmissionsForWholeProductionCycle_Net_Method2 -> 13168.273 | G37: t CO2e
D39: ="Product emissions intensity for whole production cycle running between " & TEXT(X_Cell_Enterprise_ProductionTimeframeStart, "d mmmm yyyy") & " and " & TEXT(X_Cell_Enterprise_ProductionTimeframeEnd, "d mmmm yyyy") -> Product emissions intensity for whole production cycle running between 1 November 2025 and 31 March 2026
A40: APPENDICES
A41: =HYPERLINK("#'Constants - Ag Residue'!A1", "Constants - Ag residue") -> Constants - Ag residue
A42: =HYPERLINK("#'Constants - Electricity'!A1", "Constants - Electricity") -> Constants - Electricity | D42: Product emissions - Mass
A43: =HYPERLINK("#'Constants - Fertiliser'!A1", "Constants - Fertiliser") -> Constants - Fertiliser | D43: Product | E43: Product type | F43: Amount (tonnnes) | G43: Mass emissions assignment | H43: Emissions intensity (Method 1) | I43: Emissions intensity (Method 2) | J43: Unit
A44: =HYPERLINK("#'Constants - Fuel'!A1", "Constants - Fuel") -> Constants - Fuel | D44: Grain sold - excluding removals | E44: Main product | F44: =X_Cell_Enterprise_GrainYield*X_Cell_Enterprise_PercentGrainSold -> 1000 | G44: =F44/(F44+F47) -> 0.7518797 | H44: =(E36/F44)*G44 -> 2.4391723 | I44: =(F36/F44)*G44 -> 9.9009568 | J44: t co2e/t grain sold
A45: =HYPERLINK("#'Constants - Scope 3'!A1", "Constants - Scope 3") -> Constants - Scope 3 | D45: Grain sold - net emissions | E45: Main product | F45: =F44 -> 1000 | G45: =G44 -> 0.7518797 | H45: =(E37/F45)*G45 -> 2.4391723 | I45: =(F37/F45)*G45 -> 9.9009568 | J45: t co2e/t grain sold
A46: =HYPERLINK("#'Constants - Solid Waste'!A1", "Constants - Solid Waste") -> Constants - Solid Waste | D46: Grain used as feed on own farm | E46: Residual product | F46: =X_Cell_Enterprise_GrainYield*X_Cell_Enterprise_PercentGrainUsedAsFeed -> 1000 | G46: N/A | H46: N/A | I46: N/A
...

Sheet Input - Enterprise
A1: #VALUE! | C1: Input - Enterprise
A3: =HYPERLINK("#'Home'!A1", "Home") -> Home
A4: =HYPERLINK("#'Results - Activity period'!A1", "Results - Activity period") -> Results - Activity period
A5: =HYPERLINK("#'Results - Product EI'!A1", "Results - Product EI") -> Results - Product EI | D5: Your business
D7: Farm name | E7: Test Farms
A8: INPUTS | D8: Reporting entity name | E8: Test Farms Pty Ltd
A9: =HYPERLINK("#'Input - Enterprise'!A1", "Enterprise") -> Enterprise
A10: =HYPERLINK("#'Input - Site'!A1", "Site") -> Site | D10: 💡An 'Emissions accounting period' is a 12 month period where the business can report on the emissions, and is typically the same as the business' financial accounting period.
A11: =HYPERLINK("#'Input - Crop'!A1", "Crop") -> Crop
A12: =HYPERLINK("#'Input - Fert Prod System'!A1", "Fert Prod System") -> Fert Prod System | D12: Emissions calculation period start date | E12: 45658 | F12: ← DD/MM/YYYY or DD Month YYYY
A13: =HYPERLINK("#'Input - Fertiliser'!A1", "Fertiliser") -> Fertiliser | D13: Emissions calculation period end date | E13: =DATE(YEAR(E12)+1,MONTH(E12),DAY(E12))-1 -> 46022 | F13: ← Automatically calculated, 12 months after start date
A14: =HYPERLINK("#'Input - Fuel'!A1", "Fuel") -> Fuel
A15: =HYPERLINK("#'Input - Electricity'!A1", "Electricity") -> Electricity
A16: =HYPERLINK("#'Input - Common farm inputs'!A1", "Common farm inputs") -> Common farm inputs | D16: Production
A17: =HYPERLINK("#'Input - Crop pasture farm input'!A1", "Crop pasture farm input") -> Crop pasture farm input
A18: =HYPERLINK("#'Input - Freight'!A1", "Freight") -> Freight | D18: Production timeframe start | E18: 45962 | F18: ← DD/MM/YYYY or DD Month YYYY
A19: =HYPERLINK("#'Input - Solid waste'!A1", "Solid waste") -> Solid waste | D19: Production timeframe end | E19: 46112 | F19: ← DD/MM/YYYY or DD Month YYYY
A20: =HYPERLINK("#'Input - Data quality'!A1", "Data quality") -> Data quality | D20: Production timeframe length | E20: =DATEDIF(E18,E19+1,"m") -> 5 | F20: Months
D22: Grain yield | E22: {=IF(X_Cell_Crop_CropPurpose = "Cash grain crop", X_Cell_Crop_TotalProductionOfCrop, 0)} -> 10000 | F22: tonnes
A23: CALCULATIONS | D23: Percent grain sold | E23: 0.1 | F23: percent
A24: =HYPERLINK("#'5.1.1.1-2 Inorganic fert N2O'!A1", "5.1.1.1-2 Inorganic fert N2O") -> 5.1.1.1-2 Inorganic fert N2O | D24: Percent grain used as feed on own farm | E24: 0.1 | F24: percent
A25: =HYPERLINK("#'5.1.1.3-4 Inorganic fert CO2'!A1", "5.1.1.3-4 Inorganic fert CO2") -> 5.1.1.3-4 Inorganic fert CO2 | D25: Percent grain stored and not sold or used | E25: =100%-E23-E24 -> 0.8 | F25: percent
A26: =HYPERLINK("#'5.2.1.1-2 Organic Fert N2O'!A1", "5.2.1.1-2 Organic fert N2O") -> 5.2.1.1-2 Organic fert N2O
A27: =HYPERLINK("#'5.3.1.1-2 Lime CO2'!A1", "5.3.1.1-2 Lime CO2") -> 5.3.1.1-2 Lime CO2 | D27: Baled hay/silage yield | E27: {=X_Cell_Crop_TotalResidueBaled} -> 1650 | F27: tonnes
A28: =HYPERLINK("#'5.4.1.1-4 Atmos deposition'!A1", "5.4.1.1-4 Atmos. deposition") -> 5.4.1.1-4 Atmos. deposition | D28: Percent baled hay/silage sold | E28: 0.2 | F28: percent
A29: =HYPERLINK("#'5.5.1.1-2 Leaching and runoff'!A1", "5.5.1.1-2 Leaching & runoff") -> 5.5.1.1-2 Leaching & runoff | D29: Percent baled hay/silage used as feed on own farm | E29: 0.1 | F29: percent
A30: =HYPERLINK("#'6.1.1.1-2 Crop residue N2O'!A1", "6.1.1.1-2 Crop residue N2O") -> 6.1.1.1-2 Crop residue N2O | D30: Percent grain stored and not sold or used | E30: =100%-E28-E29 -> 0.7 | F30: percent
A31: =HYPERLINK("#'6.3.1.1-2 Leach runoff crop'!A1", "6.3.1.1-2 Leach & runoff (crop)") -> 6.3.1.1-2 Leach & runoff (crop)
A32: =HYPERLINK("#'6.4.1.1-2 Residue burning'!A1", "6.4.1.1-2 Residue burning") -> 6.4.1.1-2 Residue burning | D32: Percentage of income from grain sold | E32: 0.8 | F32: percent
A33: =HYPERLINK("#'8.1.1.1-2 Transport fuel'!A1", "8.1.1.1-2 Transport fuel") -> 8.1.1.1-2 Transport fuel | D33: Percentage of income from baled hay/silage sold | E33: 0.2 | F33: percent
A34: =HYPERLINK("#'8.2.1.1-2 Stationary fuel'!A1", "8.2.1.1-2 Stationary fuel") -> 8.2.1.1-2 Stationary fuel
A35: =HYPERLINK("#'10.1.1-2 Solid waste treatment'!A1", "10.1.1.1-2 Solid waste") -> 10.1.1.1-2 Solid waste
A36: =HYPERLINK("#'14.1.1-2 Purchased electricity'!A1", "14.1.1-2 Purchased electricity") -> 14.1.1-2 Purchased electricity | D36: Carbon removals
A37: =HYPERLINK("#'15 Scope 3'!A1", "15 Scope 3") -> 15 Scope 3
D39: ="Carbon captured from " & TEXT(X_Cell_Site_StartDate, "d mmmm yyyy") & " to " & TEXT(X_Cell_Site_EndDate, "d, mmmm, yyyy") & " from environmental plantings" -> Carbon captured from 1 January 2025 to 31, December, 2025 from environmental plantings
A40: APPENDICES
A41: =HYPERLINK("#'Constants - Ag Residue'!A1", "Constants - Ag residue") -> Constants - Ag residue | D41: Planting name | E41: Total removed CO2 | F41: Percent allocated to this enterprise | G41: Removal allocated to this enterprise
A42: =HYPERLINK("#'Constants - Electricity'!A1", "Constants - Electricity") -> Constants - Electricity | G42: =Table_Input_Enterprise_PlantingRemovals[[#This Row],[Total removed CO2]]*Table_Input_Enterprise_PlantingRemovals[[#This Row],[Percent allocated to this enterprise]] -> 0
A43: =HYPERLINK("#'Constants - Fertiliser'!A1", "Constants - Fertiliser") -> Constants - Fertiliser
A44: =HYPERLINK("#'Constants - Fuel'!A1", "Constants - Fuel") -> Constants - Fuel
...

Sheet Input - Site
A1: #VALUE! | C1: Input - Site
A3: =HYPERLINK("#'Home'!A1", "Home") -> Home
A4: =HYPERLINK("#'Results - Activity period'!A1", "Results - Activity period") -> Results - Activity period
A5: =HYPERLINK("#'Results - Product EI'!A1", "Results - Product EI") -> Results - Product EI | D5: Location and climate
D7: Location information is used to reference some region and climate-specific emission factors
A8: INPUTS | D8: Tip: Use the web-based GAF Location Helper tool to easily get region and climate information. You will need an internet connection to use the GAF Location Helper.
A9: =HYPERLINK("#'Input - Enterprise'!A1", "Enterprise") -> Enterprise
A10: =HYPERLINK("#'Input - Site'!A1", "Site") -> Site | D10: State | E10: Western Australia | F10: ← Please select
A11: =HYPERLINK("#'Input - Crop'!A1", "Crop") -> Crop | D11: Region (ABS Statistical area level 4) if state is WA | E11: Western Australia - Outback (South) | F11: ← Please select
A12: =HYPERLINK("#'Input - Fert Prod System'!A1", "Fert Prod System") -> Fert Prod System | D12: Leaching zone | E12: NO - Not in leaching zone | F12: ← Please select
A13: =HYPERLINK("#'Input - Fertiliser'!A1", "Fertiliser") -> Fertiliser | D13: Elevation | E13: 307.7 | F13: Meters
A14: =HYPERLINK("#'Input - Fuel'!A1", "Fuel") -> Fuel | D14: Average temperature for reporting period | E14: 18 | F14: Degrees celsius
A15: =HYPERLINK("#'Input - Electricity'!A1", "Electricity") -> Electricity | D15: Total rainfall for reporting period | E15: 601 | F15: Millimetres
A16: =HYPERLINK("#'Input - Common farm inputs'!A1", "Common farm inputs") -> Common farm inputs | D16: Potential evapotranspiration for reporting period | E16: 1326 | F16: Millimetres
A17: =HYPERLINK("#'Input - Crop pasture farm input'!A1", "Crop pasture farm input") -> Crop pasture farm input | D17: Number of frost days for reporting period | E17: 7 | F17: Days
A18: =HYPERLINK("#'Input - Freight'!A1", "Freight") -> Freight | D18: MAP:PET ratio | E18: =E15/E16 -> 0.45324284
A19: =HYPERLINK("#'Input - Solid waste'!A1", "Solid waste") -> Solid waste | D19: Rainfall zone | E19: =Common_InputFunctions.Utility_LookupItemFromMinMax(E15,Table_SourceData_RainfallZones[Min rainfall],Table_SourceData_RainfallZones[Max rainfall],Table_SourceData_RainfallZones[Rainfall Zone]) -> High rainfall
A20: =HYPERLINK("#'Input - Data quality'!A1", "Data quality") -> Data quality | D20: Climate zone | E20: =Common_InputFunctions.Utility_GetClimateZone(E14,E15,E17,E13,E18,Table_SourceData_ClimateZones[Min temp],Table_SourceData_ClimateZones[Max temp],Table_SourceData_ClimateZones[Min rainfall],Table_SourceData_ClimateZones[Max rainfall],Table_SourceData_ClimateZones[Min frost days],Table_SourceData_ClimateZones[Max frost days],Table_SourceData_ClimateZones[Min elevation],Table_SourceData_ClimateZones[Max elevation],Table_SourceData_ClimateZones[Min MAP:PET],Table_SourceData_ClimateZones[Max MAP:PET],Table_SourceData_ClimateZones[Climate zone]) -> Warm temperate dry
D21: Wet or dry climate zone | E21: =Common_InputFunctions.Utility_LookupValueInTable($E$20,Table_SourceData_WetDryZones[Climate zone],Table_SourceData_WetDryZones[Wet or Dry Zone]) -> Dry climate zone
D22: Temperature zone | E22: =Common_InputFunctions.Utility_LookupItemFromMinMax(E14,Table_SourceData_TemperatureZones[Min MAT],Table_SourceData_TemperatureZones[Max MAT],Table_SourceData_TemperatureZones[Temperature Zone]) -> Temperate
A23: CALCULATIONS
A24: =HYPERLINK("#'5.1.1.1-2 Inorganic fert N2O'!A1", "5.1.1.1-2 Inorganic fert N2O") -> 5.1.1.1-2 Inorganic fert N2O
A25: =HYPERLINK("#'5.1.1.3-4 Inorganic fert CO2'!A1", "5.1.1.3-4 Inorganic fert CO2") -> 5.1.1.3-4 Inorganic fert CO2
A26: =HYPERLINK("#'5.2.1.1-2 Organic Fert N2O'!A1", "5.2.1.1-2 Organic fert N2O") -> 5.2.1.1-2 Organic fert N2O
A27: =HYPERLINK("#'5.3.1.1-2 Lime CO2'!A1", "5.3.1.1-2 Lime CO2") -> 5.3.1.1-2 Lime CO2
A28: =HYPERLINK("#'5.4.1.1-4 Atmos deposition'!A1", "5.4.1.1-4 Atmos. deposition") -> 5.4.1.1-4 Atmos. deposition
A29: =HYPERLINK("#'5.5.1.1-2 Leaching and runoff'!A1", "5.5.1.1-2 Leaching & runoff") -> 5.5.1.1-2 Leaching & runoff
A30: =HYPERLINK("#'6.1.1.1-2 Crop residue N2O'!A1", "6.1.1.1-2 Crop residue N2O") -> 6.1.1.1-2 Crop residue N2O
A31: =HYPERLINK("#'6.3.1.1-2 Leach runoff crop'!A1", "6.3.1.1-2 Leach & runoff (crop)") -> 6.3.1.1-2 Leach & runoff (crop)
A32: =HYPERLINK("#'6.4.1.1-2 Residue burning'!A1", "6.4.1.1-2 Residue burning") -> 6.4.1.1-2 Residue burning
A33: =HYPERLINK("#'8.1.1.1-2 Transport fuel'!A1", "8.1.1.1-2 Transport fuel") -> 8.1.1.1-2 Transport fuel
A34: =HYPERLINK("#'8.2.1.1-2 Stationary fuel'!A1", "8.2.1.1-2 Stationary fuel") -> 8.2.1.1-2 Stationary fuel
A35: =HYPERLINK("#'10.1.1-2 Solid waste treatment'!A1", "10.1.1.1-2 Solid waste") -> 10.1.1.1-2 Solid waste
A36: =HYPERLINK("#'14.1.1-2 Purchased electricity'!A1", "14.1.1-2 Purchased electricity") -> 14.1.1-2 Purchased electricity
A37: =HYPERLINK("#'15 Scope 3'!A1", "15 Scope 3") -> 15 Scope 3
A40: APPENDICES
A41: =HYPERLINK("#'Constants - Ag Residue'!A1", "Constants - Ag residue") -> Constants - Ag residue
A42: =HYPERLINK("#'Constants - Electricity'!A1", "Constants - Electricity") -> Constants - Electricity
A43: =HYPERLINK("#'Constants - Fertiliser'!A1", "Constants - Fertiliser") -> Constants - Fertiliser
A44: =HYPERLINK("#'Constants - Fuel'!A1", "Constants - Fuel") -> Constants - Fuel
...

Sheet Input - Crop
A1: #VALUE! | C1: Input - Crop
A3: =HYPERLINK("#'Home'!A1", "Home") -> Home
A4: =HYPERLINK("#'Results - Activity period'!A1", "Results - Activity period") -> Results - Activity period
A5: =HYPERLINK("#'Results - Product EI'!A1", "Results - Product EI") -> Results - Product EI | D5: Area
D7: If multiple paddocks were managed in the same way at the same time, you can enter information for them all together.
A8: INPUTS
A9: =HYPERLINK("#'Input - Enterprise'!A1", "Enterprise") -> Enterprise | D9: Crop type | E9: Wheat | F9: ← Please select
A10: =HYPERLINK("#'Input - Site'!A1", "Site") -> Site | D10: Crop purpose | E10: Cash grain crop | F10: ← Please select
A11: =HYPERLINK("#'Input - Crop'!A1", "Crop") -> Crop | D11: Irrigation method | E11: Sprinkler irrigation | F11: ← Please select
A12: =HYPERLINK("#'Input - Fert Prod System'!A1", "Fert Prod System") -> Fert Prod System
A13: =HYPERLINK("#'Input - Fertiliser'!A1", "Fertiliser") -> Fertiliser | D13: Area under cropping | E13: 1000 | F13: Hectares
A14: =HYPERLINK("#'Input - Fuel'!A1", "Fuel") -> Fuel
A15: =HYPERLINK("#'Input - Electricity'!A1", "Electricity") -> Electricity | D15: Yield
A16: =HYPERLINK("#'Input - Common farm inputs'!A1", "Common farm inputs") -> Common farm inputs
A17: =HYPERLINK("#'Input - Crop pasture farm input'!A1", "Crop pasture farm input") -> Crop pasture farm input | D17: =X_Cell_Crop_CropPurpose & " " & _xlfn.XLOOKUP(X_Cell_Crop_CropPurpose,Table_SourceData_CropPurposeAndYields[Purpose], Table_SourceData_CropPurposeAndYields[harvest term]) & " per hectare¹" -> Cash grain crop yield per hectare¹ | E17: 10 | F17: ="Tonnes " & _xlfn.XLOOKUP(X_Cell_Crop_CropPurpose, Table_SourceData_CropPurposeAndYields[Purpose], Table_SourceData_CropPurposeAndYields[Per hectare unit], FALSE) & " per hectare" -> Tonnes grain per hectare
A18: =HYPERLINK("#'Input - Freight'!A1", "Freight") -> Freight | D18: Residue:crop ratio² | E18: =_xlfn.IFS(X_Cell_Crop_CropPurpose="Cash grain crop", Common_InputFunctions.Utility_LookupValueInTableNumber(X_Cell_Crop_CropType, Table_SourceData_CropAttributes[Crop type],Table_SourceData_CropAttributes[Residue: Crop ratio]), X_Cell_Crop_CropPurpose="Cash crop for hay/silage", 0, X_Cell_Crop_CropPurpose="Cover crop", 1) -> 1.5
A19: =HYPERLINK("#'Input - Solid waste'!A1", "Solid waste") -> Solid waste | D19: Crop residue biomass | E19: =X_Cell_Crop_YieldPerHectare*E18 -> 15 | F19: Tonnes per hectare
A20: =HYPERLINK("#'Input - Data quality'!A1", "Data quality") -> Data quality | D20: Whole plant above ground biomass | E20: =X_Cell_Crop_YieldPerHectare+E19 -> 25 | F20: Tonnes per hectare
D22: Total production of crop³ | E22: =X_Cell_Crop_YieldPerHectare*X_Cell_Crop_AreaUnderCropping -> 10000 | F22: ="Tonnes " & _xlfn.XLOOKUP(X_Cell_Crop_CropPurpose, Table_SourceData_CropPurposeAndYields[Purpose], Table_SourceData_CropPurposeAndYields[Harvest uit], FALSE) -> Tonnes grain
A23: CALCULATIONS
A24: =HYPERLINK("#'5.1.1.1-2 Inorganic fert N2O'!A1", "5.1.1.1-2 Inorganic fert N2O") -> 5.1.1.1-2 Inorganic fert N2O | D24: ="¹ " & _xlfn.XLOOKUP(X_Cell_Crop_CropPurpose, Table_SourceData_CropPurposeAndYields[Purpose],Table_SourceData_CropPurposeAndYields[Yield note]) -> ¹ Yield is the grain harvested from the plant
A25: =HYPERLINK("#'5.1.1.3-4 Inorganic fert CO2'!A1", "5.1.1.3-4 Inorganic fert CO2") -> 5.1.1.3-4 Inorganic fert CO2 | D25: ="² " & _xlfn.XLOOKUP(X_Cell_Crop_CropPurpose, Table_SourceData_CropPurposeAndYields[Purpose],Table_SourceData_CropPurposeAndYields[Residue crop ratio note]) -> ² Residue to crop ratio is provided from default values
A26: =HYPERLINK("#'5.2.1.1-2 Organic Fert N2O'!A1", "5.2.1.1-2 Organic fert N2O") -> 5.2.1.1-2 Organic fert N2O | D26: ="³ " & _xlfn.XLOOKUP(X_Cell_Crop_CropPurpose,Table_SourceData_CropPurposeAndYields[Purpose],Table_SourceData_CropPurposeAndYields[Total production note]) -> ³ Total production is the total grain harvested
A27: =HYPERLINK("#'5.3.1.1-2 Lime CO2'!A1", "5.3.1.1-2 Lime CO2") -> 5.3.1.1-2 Lime CO2
A28: =HYPERLINK("#'5.4.1.1-4 Atmos deposition'!A1", "5.4.1.1-4 Atmos. deposition") -> 5.4.1.1-4 Atmos. deposition | D28: Residue management
A29: =HYPERLINK("#'5.5.1.1-2 Leaching and runoff'!A1", "5.5.1.1-2 Leaching & runoff") -> 5.5.1.1-2 Leaching & runoff
A30: =HYPERLINK("#'6.1.1.1-2 Crop residue N2O'!A1", "6.1.1.1-2 Crop residue N2O") -> 6.1.1.1-2 Crop residue N2O | D30: ="Residue after " & VLOOKUP(X_Cell_Crop_CropPurpose,'Constants - Ag Residue'!D8:G10, 4, FALSE) -> Residue after harvest | E30: =E19*X_Cell_Crop_AreaUnderCropping -> 15000 | F30: Tonnes
A31: =HYPERLINK("#'6.3.1.1-2 Leach runoff crop'!A1", "6.3.1.1-2 Leach & runoff (crop)") -> 6.3.1.1-2 Leach & runoff (crop)
A32: =HYPERLINK("#'6.4.1.1-2 Residue burning'!A1", "6.4.1.1-2 Residue burning") -> 6.4.1.1-2 Residue burning | D32: Baled residue
A33: =HYPERLINK("#'8.1.1.1-2 Transport fuel'!A1", "8.1.1.1-2 Transport fuel") -> 8.1.1.1-2 Transport fuel | D33: Percentage of residue that was baled | E33: 0.11 | F33: Percent
A34: =HYPERLINK("#'8.2.1.1-2 Stationary fuel'!A1", "8.2.1.1-2 Stationary fuel") -> 8.2.1.1-2 Stationary fuel | D34: Average weight per bale | E34: 60 | F34: Kilograms
A35: =HYPERLINK("#'10.1.1-2 Solid waste treatment'!A1", "10.1.1.1-2 Solid waste") -> 10.1.1.1-2 Solid waste | D35: Number of bales | E35: =IFERROR((X_Cell_Crop_TotalResidueBaled*10^3)/X_Cell_Crop_AverageWeightPerBale, 0) -> 27500 | F35: Bales
A36: =HYPERLINK("#'14.1.1-2 Purchased electricity'!A1", "14.1.1-2 Purchased electricity") -> 14.1.1-2 Purchased electricity | D36: Total residue baled | E36: =E30*X_Cell_Crop_PercentResidueBaled -> 1650 | F36: Tonnes
A37: =HYPERLINK("#'15 Scope 3'!A1", "15 Scope 3") -> 15 Scope 3
D38: Burned residue
D39: Percentage of residue that was burned | E39: 0.3 | F39: Percent
A40: APPENDICES | D40: Total residue burned | E40: =E30*X_Cell_Crop_PercentResidueBurned -> 4500 | F40: Tonnes
A41: =HYPERLINK("#'Constants - Ag Residue'!A1", "Constants - Ag residue") -> Constants - Ag residue
A42: =HYPERLINK("#'Constants - Electricity'!A1", "Constants - Electricity") -> Constants - Electricity | D42: Residue retained on paddocks | E42: =E30-X_Cell_Crop_TotalResidueBaled-E40 -> 8850 | F42: Tonnes
A43: =HYPERLINK("#'Constants - Fertiliser'!A1", "Constants - Fertiliser") -> Constants - Fertiliser
...

Sheet Input - Fert Prod System
A1: #VALUE! | C1: Input - Fertiliser Production System
A3: =HYPERLINK("#'Home'!A1", "Home") -> Home
A4: =HYPERLINK("#'Results - Activity period'!A1", "Results - Activity period") -> Results - Activity period
A5: =HYPERLINK("#'Results - Product EI'!A1", "Results - Product EI") -> Results - Product EI | D5: These inputs are used for fertiliser calculations, and they take their values from the "Input - Crop" sheet. Do not edit these cells.
D7: Production system | E7: Crop
A8: INPUTS | D8: Crop type | E8: {=_xlfn.IFS(X_Cell_Crop_CropType="Maize", "Maize", X_Cell_Crop_CropType="Cotton", "Cotton", TRUE, "Grains")} -> Grains
A9: =HYPERLINK("#'Input - Enterprise'!A1", "Enterprise") -> Enterprise | D9: Irrigation method | E9: {=X_Cell_Crop_IrrigationMethod} -> Sprinkler irrigation
A10: =HYPERLINK("#'Input - Site'!A1", "Site") -> Site | D10: Area under cropping | E10: {=X_Cell_Crop_AreaUnderCropping} -> 1000
A11: =HYPERLINK("#'Input - Crop'!A1", "Crop") -> Crop
A12: =HYPERLINK("#'Input - Fert Prod System'!A1", "Fert Prod System") -> Fert Prod System
A13: =HYPERLINK("#'Input - Fertiliser'!A1", "Fertiliser") -> Fertiliser
A14: =HYPERLINK("#'Input - Fuel'!A1", "Fuel") -> Fuel
A15: =HYPERLINK("#'Input - Electricity'!A1", "Electricity") -> Electricity
A16: =HYPERLINK("#'Input - Common farm inputs'!A1", "Common farm inputs") -> Common farm inputs
A17: =HYPERLINK("#'Input - Crop pasture farm input'!A1", "Crop pasture farm input") -> Crop pasture farm input
A18: =HYPERLINK("#'Input - Freight'!A1", "Freight") -> Freight
A19: =HYPERLINK("#'Input - Solid waste'!A1", "Solid waste") -> Solid waste
A20: =HYPERLINK("#'Input - Data quality'!A1", "Data quality") -> Data quality
A23: CALCULATIONS
A24: =HYPERLINK("#'5.1.1.1-2 Inorganic fert N2O'!A1", "5.1.1.1-2 Inorganic fert N2O") -> 5.1.1.1-2 Inorganic fert N2O
A25: =HYPERLINK("#'5.1.1.3-4 Inorganic fert CO2'!A1", "5.1.1.3-4 Inorganic fert CO2") -> 5.1.1.3-4 Inorganic fert CO2
A26: =HYPERLINK("#'5.2.1.1-2 Organic Fert N2O'!A1", "5.2.1.1-2 Organic fert N2O") -> 5.2.1.1-2 Organic fert N2O
A27: =HYPERLINK("#'5.3.1.1-2 Lime CO2'!A1", "5.3.1.1-2 Lime CO2") -> 5.3.1.1-2 Lime CO2
A28: =HYPERLINK("#'5.4.1.1-4 Atmos deposition'!A1", "5.4.1.1-4 Atmos. deposition") -> 5.4.1.1-4 Atmos. deposition
A29: =HYPERLINK("#'5.5.1.1-2 Leaching and runoff'!A1", "5.5.1.1-2 Leaching & runoff") -> 5.5.1.1-2 Leaching & runoff
A30: =HYPERLINK("#'6.1.1.1-2 Crop residue N2O'!A1", "6.1.1.1-2 Crop residue N2O") -> 6.1.1.1-2 Crop residue N2O
A31: =HYPERLINK("#'6.3.1.1-2 Leach runoff crop'!A1", "6.3.1.1-2 Leach & runoff (crop)") -> 6.3.1.1-2 Leach & runoff (crop)
A32: =HYPERLINK("#'6.4.1.1-2 Residue burning'!A1", "6.4.1.1-2 Residue burning") -> 6.4.1.1-2 Residue burning
A33: =HYPERLINK("#'8.1.1.1-2 Transport fuel'!A1", "8.1.1.1-2 Transport fuel") -> 8.1.1.1-2 Transport fuel
A34: =HYPERLINK("#'8.2.1.1-2 Stationary fuel'!A1", "8.2.1.1-2 Stationary fuel") -> 8.2.1.1-2 Stationary fuel
A35: =HYPERLINK("#'10.1.1-2 Solid waste treatment'!A1", "10.1.1.1-2 Solid waste") -> 10.1.1.1-2 Solid waste
A36: =HYPERLINK("#'14.1.1-2 Purchased electricity'!A1", "14.1.1-2 Purchased electricity") -> 14.1.1-2 Purchased electricity
A37: =HYPERLINK("#'15 Scope 3'!A1", "15 Scope 3") -> 15 Scope 3
A40: APPENDICES
A41: =HYPERLINK("#'Constants - Ag Residue'!A1", "Constants - Ag residue") -> Constants - Ag residue
A42: =HYPERLINK("#'Constants - Electricity'!A1", "Constants - Electricity") -> Constants - Electricity
A43: =HYPERLINK("#'Constants - Fertiliser'!A1", "Constants - Fertiliser") -> Constants - Fertiliser
A44: =HYPERLINK("#'Constants - Fuel'!A1", "Constants - Fuel") -> Constants - Fuel
A45: =HYPERLINK("#'Constants - Scope 3'!A1", "Constants - Scope 3") -> Constants - Scope 3
A46: =HYPERLINK("#'Constants - Solid Waste'!A1", "Constants - Solid Waste") -> Constants - Solid Waste
...

Sheet Input - Fertiliser
A1: #VALUE! | C1: Input - Fertiliser
A3: =HYPERLINK("#'Home'!A1", "Home") -> Home
A4: =HYPERLINK("#'Results - Activity period'!A1", "Results - Activity period") -> Results - Activity period
A5: =HYPERLINK("#'Results - Product EI'!A1", "Results - Product EI") -> Results - Product EI | D5: Inorganic fertiliser applied
D7: 💡You can add more rows to tables by right-clicking on the table and selecting "Insert > Table rows above/below".
A8: INPUTS | D8: 💡The application area is the same as the area under pasture / cropping by default. You can edit it if the application area is different.
A9: =HYPERLINK("#'Input - Enterprise'!A1", "Enterprise") -> Enterprise
A10: =HYPERLINK("#'Input - Site'!A1", "Site") -> Site | D10: Branded fertiliser products
A11: =HYPERLINK("#'Input - Crop'!A1", "Crop") -> Crop | D11: Product (select) | E11: Amount applied per hectare | F11: Application unit | G11: Application area (ha) | H11: Density | I11: Total applied (kg) | J11: Ingredient 1 | K11: Ingredient 1 percent | L11: Ingredient 2 | M11: Ingredient 2 percent | N11: Ingredient 3 | O11: Ingredient 3 percent | P11: Ingredient 4 | Q11: Ingredient 4 percent | R11: Ingredient 5 | S11: Ingredient 5 percent | T11: Ingredient 6 | U11: Ingredient 6 percent | V11: % N (Ingredients) | W11: % N (declared) | X11: N application rate (kg/ha) | Y11: Urea source | Z11: Ammonia source
