Workbook
Name _Toc225350871: '5.4.1.1-4 Atmos deposition'!$C$1
Name _Toc225350871: '5.5.1.1-2 Leaching and runoff'!$C$1
Name AgResidue_Equations_CropResidue.VEERG_6_1_1_1__1__NitrousOxideEmissionsFromCropResidues: _xlfn.LAMBDA(_xlpm.M_c,_xlpm.EF_Ni,_xlpm.C_N2O, _xlpm.M_c * _xlpm.EF_Ni * _xlpm.C_N2O * 10 ^ (-3))
Name AgResidue_Equations_CropResidue.VEERG_6_1_1_1__1__NitrousOxideEmissionsFromCropResidues_FunctionName: _xlfn.LAMBDA("VEERG_6_1_1_1__1__NitrousOxideEmissionsFromCropResidues")
Name AgResidue_Equations_CropResidue.VEERG_6_1_1_1__1__NitrousOxideEmissionsFromCropResidues_LatexEquation: _xlfn.LAMBDA("E=\sum\nolimits_c\left(M_{c}\times EF_{N}\right)\times C_{g,N2O}\times 10^{-3}")
Name AgResidue_Equations_CropResidue.VEERG_6_1_1_1__1__NitrousOxideEmissionsFromCropResidues_NIRReference: _xlfn.LAMBDA("")
Name AgResidue_Equations_CropResidue.VEERG_6_1_1_1__1__NitrousOxideEmissionsFromCropResidues_Source: _xlfn.LAMBDA("VEERG 2026: 6.1.1.1, Equation (1)")
Name AgResidue_Equations_CropResidue.VEERG_6_1_1_1__1__NitrousOxideEmissionsFromCropResidues_Title: _xlfn.LAMBDA("Nitrous oxide emissions from the return of crop residues across all crops c to the soil")
Name AgResidue_Equations_CropResidue.VEERG_6_1_1_1__1__NitrousOxideEmissionsFromCropResidues_Unit: _xlfn.LAMBDA("t N2O")
Name AgResidue_Equations_CropResidue.VEERG_6_1_1_1__1__NitrousOxideEmissionsFromCropResidues_Variable: _xlfn.LAMBDA("E")
Name AgResidue_Equations_CropResidue.VEERG_6_1_1_1__2__MassOfNitrogenInCropResidues_LatexEquation: _xlfn.LAMBDA("M_{c}=(P_{c}\times R_{AGc}\times(1-F_{c}-FFOD_{c})\times DM_{c}\times NC_{AGc})+(P_{c}\times R_{AGc}\times R_{BGc}\times DM_{c}\times NC_{BGc})")
Name AgResidue_Equations_CropResidue.VEERG_6_1_1_1__2__MassOfNitrogenInCropResidues_NIRReference: _xlfn.LAMBDA("")
Name AgResidue_Equations_CropResidue.VEERG_6_1_1_1__2__MassOfNitrogenInCropResidues_Source: _xlfn.LAMBDA("VEERG 2026: 6.1.1.1, Equation (2)")
Name AgResidue_Equations_CropResidue.VEERG_6_1_1_1__2__MassOfNitrogenInCropResidues_Title: _xlfn.LAMBDA("Mass of nitrogen in crop residues returned to the soil")
Name AgResidue_Equations_CropResidue.VEERG_6_1_1_1__2__MassOfNitrogenInCropResidues_Unit: _xlfn.LAMBDA("kg N")
Name AgResidue_Equations_CropResidue.VEERG_6_1_1_1__2__MassOfNitrogenInCropResidues_Variable: _xlfn.LAMBDA("M_c")
Name AgResidue_Equations_CropResidue.VEERG_6_1_1_2__1__FractionOfCropResidueRemovedBaled: _xlfn.LAMBDA(_xlpm.B,_xlpm.M_B,_xlpm.P_c,_xlpm.R_AGc, IFERROR((_xlpm.B * _xlpm.M_B) / (_xlpm.P_c * _xlpm.R_AGc), 0))
Name AgResidue_Equations_CropResidue.VEERG_6_1_1_2__1__FractionOfCropResidueRemovedBaled_LatexEquation: _xlfn.LAMBDA("FFOD_{c}=\frac{B\times M_{B}}{P_{c}\times R_{AG,c}}")
Name AgResidue_Equations_CropResidue.VEERG_6_1_1_2__1__FractionOfCropResidueRemovedBaled_NIRReference: _xlfn.LAMBDA("")
Name AgResidue_Equations_CropResidue.VEERG_6_1_1_2__1__FractionOfCropResidueRemovedBaled_Source: _xlfn.LAMBDA("VEERG 2026: 6.1.1.2, Equation (1)")
Name AgResidue_Equations_CropResidue.VEERG_6_1_1_2__1__FractionOfCropResidueRemovedBaled_Title: _xlfn.LAMBDA("Fraction of crop residue that is removed for crop c, calculated where residues are baled")
Name AgResidue_Equations_CropResidue.VEERG_6_1_1_2__1__FractionOfCropResidueRemovedBaled_Unit: _xlfn.LAMBDA("fraction")
Name AgResidue_Equations_CropResidue.VEERG_6_1_1_2__1__FractionOfCropResidueRemovedBaled_Variable: _xlfn.LAMBDA("FFOD_c")
Name AgResidue_Equations_CropResidue.VEERG_6_1_1_2__1__FractionOfCropResidueRemovedBaled_Variation: _xlfn.LAMBDA("")
Name AgResidue_Equations_FieldBurning.VEERG_6_4_1_1__1__MethaneEmissionsFromBurningOfCropResidues: _xlfn.LAMBDA(_xlpm.M_burnc,_xlpm.CC_c,_xlpm.EF_CH4,_xlpm.C_CH4, (_xlpm.M_burnc * _xlpm.CC_c) * _xlpm.EF_CH4 * _xlpm.C_CH4 * 10 ^ (-3))
Name AgResidue_Equations_FieldBurning.VEERG_6_4_1_1__1__MethaneEmissionsFromBurningOfCropResidues_FunctionName: _xlfn.LAMBDA("VEERG_6_4_1_1__1__MethaneEmissionsFromBurningOfCropResidues")
Name AgResidue_Equations_FieldBurning.VEERG_6_4_1_1__1__MethaneEmissionsFromBurningOfCropResidues_LatexEquation: _xlfn.LAMBDA("E_{CH4}=\sum\nolimits_c(M_{burn,c}\times CC_{c})\times EF_{CH4}\times C_{CH4}\times 10^{-3}")
Name AgResidue_Equations_FieldBurning.VEERG_6_4_1_1__1__MethaneEmissionsFromBurningOfCropResidues_NIRReference: _xlfn.LAMBDA("")
Name AgResidue_Equations_FieldBurning.VEERG_6_4_1_1__1__MethaneEmissionsFromBurningOfCropResidues_Source: _xlfn.LAMBDA("VEERG 2026: 6.4.1.1, Equation (1)")
Name AgResidue_Equations_FieldBurning.VEERG_6_4_1_1__1__MethaneEmissionsFromBurningOfCropResidues_Title: _xlfn.LAMBDA("Methane emissions from the burning of crop residues")
Name AgResidue_Equations_FieldBurning.VEERG_6_4_1_1__1__MethaneEmissionsFromBurningOfCropResidues_Unit: _xlfn.LAMBDA("t CH4")
Name AgResidue_Equations_FieldBurning.VEERG_6_4_1_1__1__MethaneEmissionsFromBurningOfCropResidues_Variable: _xlfn.LAMBDA("ECH4")
Name AgResidue_Equations_FieldBurning.VEERG_6_4_1_1__2__NitrousOxideEmissionsFromBurningOfCropResidues: _xlfn.LAMBDA(_xlpm.M_burnc,_xlpm.NC_AGc,_xlpm.EF_N2O,_xlpm.C_N2O, (_xlpm.M_burnc * _xlpm.NC_AGc) * _xlpm.EF_N2O * _xlpm.C_N2O * 10 ^ (-3))
Name AgResidue_Equations_FieldBurning.VEERG_6_4_1_1__2__NitrousOxideEmissionsFromBurningOfCropResidues_FunctionName: _xlfn.LAMBDA("VEERG_6_4_1_1__2__NitrousOxideEmissionsFromBurningOfCropResidues")
Name AgResidue_Equations_FieldBurning.VEERG_6_4_1_1__2__NitrousOxideEmissionsFromBurningOfCropResidues_LatexEquation: _xlfn.LAMBDA("E_{N2O}=\sum\nolimits_c(M_{burn,c}\times NC_{AGc})\times EF_{N2O}\times C_{N2O}\times 10^{-3}")
Name AgResidue_Equations_FieldBurning.VEERG_6_4_1_1__2__NitrousOxideEmissionsFromBurningOfCropResidues_NIRReference: _xlfn.LAMBDA("")
Name AgResidue_Equations_FieldBurning.VEERG_6_4_1_1__2__NitrousOxideEmissionsFromBurningOfCropResidues_Source: _xlfn.LAMBDA("VEERG 2026: 6.4.1.1, Equation (2)")
Name AgResidue_Equations_FieldBurning.VEERG_6_4_1_1__2__NitrousOxideEmissionsFromBurningOfCropResidues_Title: _xlfn.LAMBDA("Nitrous oxide emissions from the burning of crop residues")
Name AgResidue_Equations_FieldBurning.VEERG_6_4_1_1__2__NitrousOxideEmissionsFromBurningOfCropResidues_Unit: _xlfn.LAMBDA("t N2O")
Name AgResidue_Equations_FieldBurning.VEERG_6_4_1_1__2__NitrousOxideEmissionsFromBurningOfCropResidues_Variable: _xlfn.LAMBDA("EN2O")
Name AgResidue_Equations_FieldBurning.VEERG_6_4_1_1__3__MassOfCropResidueBurnt: _xlfn.LAMBDA(_xlpm.P_c,_xlpm.R_AGc,_xlpm.S_c,_xlpm.DM_c,_xlpm.Z_c,_xlpm.F_c, _xlpm.P_c * _xlpm.R_AGc * _xlpm.S_c * _xlpm.DM_c * _xlpm.Z_c * _xlpm.F_c)
Name AgResidue_Equations_FieldBurning.VEERG_6_4_1_1__3__MassOfCropResidueBurnt_FunctionName: _xlfn.LAMBDA("VEERG_6_4_1_1__3__MassOfCropResidueBurnt")
Name AgResidue_Equations_FieldBurning.VEERG_6_4_1_1__3__MassOfCropResidueBurnt_LatexEquation: _xlfn.LAMBDA("M_{burn,c}=P_{c}\times R_{AGc}\times S_{c}\times DM_{c}\times Z_{c}\times F_{c}")
Name AgResidue_Equations_FieldBurning.VEERG_6_4_1_1__3__MassOfCropResidueBurnt_NIRReference: _xlfn.LAMBDA("")
Name AgResidue_Equations_FieldBurning.VEERG_6_4_1_1__3__MassOfCropResidueBurnt_Source: _xlfn.LAMBDA("VEERG 2026: 6.4.1.1, Equation (3)")
Name AgResidue_Equations_FieldBurning.VEERG_6_4_1_1__3__MassOfCropResidueBurnt_Title: _xlfn.LAMBDA("Mass of residue of crop c burnt")
Name AgResidue_Equations_FieldBurning.VEERG_6_4_1_1__3__MassOfCropResidueBurnt_Unit: _xlfn.LAMBDA("kg")
Name AgResidue_Equations_FieldBurning.VEERG_6_4_1_1__3__MassOfCropResidueBurnt_Variable: _xlfn.LAMBDA("M_burnc")
Name AgResidue_Equations_Leaching.VEERG_6_3_1_1__1__LeachingAndRunoffEmissionsCropAndPastureResidue: _xlfn.LAMBDA(_xlpm.M_leachcp,_xlpm.EF_leach,_xlpm.C_N2O, (_xlpm.M_leachcp * _xlpm.EF_leach) * _xlpm.C_N2O * 10 ^ (-3))
Name AgResidue_Equations_Leaching.VEERG_6_3_1_1__1__LeachingAndRunoffEmissionsCropAndPastureResidue_LatexEquation: _xlfn.LAMBDA("E_{N2O}=\sum\nolimits_c\sum\nolimits_p(M_{leach,cp}\times EF_{leach}\times C_{N2O}\times 10^{-3})")
Name AgResidue_Equations_Leaching.VEERG_6_3_1_1__1__LeachingAndRunoffEmissionsCropAndPastureResidue_NIRReference: _xlfn.LAMBDA("")
Name AgResidue_Equations_Leaching.VEERG_6_3_1_1__1__LeachingAndRunoffEmissionsCropAndPastureResidue_Source: _xlfn.LAMBDA("VEERG 2026: 6.3.1.1, Equation (1)")
Name AgResidue_Equations_Leaching.VEERG_6_3_1_1__1__LeachingAndRunoffEmissionsCropAndPastureResidue_Title: _xlfn.LAMBDA("Nitrous oxide leaching and runoff emissions from crop and pasture residues returned to the soil")
Name AgResidue_Equations_Leaching.VEERG_6_3_1_1__1__LeachingAndRunoffEmissionsCropAndPastureResidue_Unit: _xlfn.LAMBDA("t N2O")
Name AgResidue_Equations_Leaching.VEERG_6_3_1_1__1__LeachingAndRunoffEmissionsCropAndPastureResidue_Variable: _xlfn.LAMBDA("EN2O")
Name AgResidue_Equations_Leaching.VEERG_6_3_1_1__2__MassOfNitrogenLostThroughLeachingAndRunoff: _xlfn.LAMBDA(_xlpm.M_cp,_xlpm.FracWET_j,_xlpm.FracLEACH, _xlpm.M_cp * _xlpm.FracWET_j * _xlpm.FracLEACH)
Name AgResidue_Equations_Leaching.VEERG_6_3_1_1__2__MassOfNitrogenLostThroughLeachingAndRunoff_LatexEquation: _xlfn.LAMBDA("M_{leach,cp}=M_{cp}\times FracWET_{j}\times FracLEACH")
Name AgResidue_Equations_Leaching.VEERG_6_3_1_1__2__MassOfNitrogenLostThroughLeachingAndRunoff_NIRReference: _xlfn.LAMBDA("")
Name AgResidue_Equations_Leaching.VEERG_6_3_1_1__2__MassOfNitrogenLostThroughLeachingAndRunoff_Source: _xlfn.LAMBDA("VEERG 2026: 6.3.1.1, Equation (2)")
Name AgResidue_Equations_Leaching.VEERG_6_3_1_1__2__MassOfNitrogenLostThroughLeachingAndRunoff_Title: _xlfn.LAMBDA("Mass of nitrogen lost through leaching and runoff")

Sheet Home
A1: #VALUE!
A3: =HYPERLINK("#'Home'!A1", "Home") -> Home
A4: =HYPERLINK("#'Results - Activity period'!A1", "Results - Activity period") -> Results - Activity period
A5: =HYPERLINK("#'Results - Product EI'!A1", "Results - Product EI") -> Results - Product EI
A8: INPUTS
A9: =HYPERLINK("#'Input - Enterprise'!A1", "Enterprise") -> Enterprise
A10: =HYPERLINK("#'Input - Site'!A1", "Site") -> Site
A11: =HYPERLINK("#'Input - Crop'!A1", "Crop") -> Crop
A12: =HYPERLINK("#'Input - Fert Prod System'!A1", "Fert Prod System") -> Fert Prod System
A13: =HYPERLINK("#'Input - Fertiliser'!A1", "Fertiliser") -> Fertiliser
A14: =HYPERLINK("#'Input - Fuel'!A1", "Fuel") -> Fuel
A15: =HYPERLINK("#'Input - Electricity'!A1", "Electricity") -> Electricity
A16: =HYPERLINK("#'Input - Common farm inputs'!A1", "Common farm inputs") -> Common farm inputs
A17: =HYPERLINK("#'Input - Crop pasture farm input'!A1", "Crop pasture farm input") -> Crop pasture farm input
A18: =HYPERLINK("#'Input - Freight'!A1", "Freight") -> Freight
A19: =HYPERLINK("#'Input - Solid waste'!A1", "Solid waste") -> Solid waste
A20: =HYPERLINK("#'Input - Data quality'!A1", "Data quality") -> Data quality
A23: CALCULATIONS
A24: =HYPERLINK("#'5.1.1.1-2 Inorganic fert N2O'!A1", "5.1.1.1-2 Inorganic fert N2O") -> 5.1.1.1-2 Inorganic fert N2O
A25: =HYPERLINK("#'5.1.1.3-4 Inorganic fert CO2'!A1", "5.1.1.3-4 Inorganic fert CO2") -> 5.1.1.3-4 Inorganic fert CO2
A26: =HYPERLINK("#'5.2.1.1-2 Organic Fert N2O'!A1", "5.2.1.1-2 Organic fert N2O") -> 5.2.1.1-2 Organic fert N2O
A27: =HYPERLINK("#'5.3.1.1-2 Lime CO2'!A1", "5.3.1.1-2 Lime CO2") -> 5.3.1.1-2 Lime CO2
A28: =HYPERLINK("#'5.4.1.1-4 Atmos deposition'!A1", "5.4.1.1-4 Atmos. deposition") -> 5.4.1.1-4 Atmos. deposition
A29: =HYPERLINK("#'5.5.1.1-2 Leaching and runoff'!A1", "5.5.1.1-2 Leaching & runoff") -> 5.5.1.1-2 Leaching & runoff
A30: =HYPERLINK("#'6.1.1.1-2 Crop residue N2O'!A1", "6.1.1.1-2 Crop residue N2O") -> 6.1.1.1-2 Crop residue N2O
A31: =HYPERLINK("#'6.3.1.1-2 Leach runoff crop'!A1", "6.3.1.1-2 Leach & runoff (crop)") -> 6.3.1.1-2 Leach & runoff (crop)
A32: =HYPERLINK("#'8.1.1.1-2 Transport fuel'!A1", "8.1.1.1-2 Transport fuel") -> 8.1.1.1-2 Transport fuel
A33: =HYPERLINK("#'8.2.1.1-2 Stationary fuel'!A1", "8.2.1.1-2 Stationary fuel") -> 8.2.1.1-2 Stationary fuel
A34: =HYPERLINK("#'10.1.1-2 Solid waste treatment'!A1", "10.1.1.1-2 Solid waste") -> 10.1.1.1-2 Solid waste
A35: =HYPERLINK("#'14.1.1-2 Purchased electricity'!A1", "14.1.1-2 Purchased electricity") -> 14.1.1-2 Purchased electricity
A36: =HYPERLINK("#'15 Scope 3'!A1", "15 Scope 3") -> 15 Scope 3
A39: APPENDICES
A40: =HYPERLINK("#'Constants - Ag Residue'!A1", "Constants - Ag residue") -> Constants - Ag residue
A41: =HYPERLINK("#'Constants - Electricity'!A1", "Constants - Electricity") -> Constants - Electricity
A42: =HYPERLINK("#'Constants - Fertiliser'!A1", "Constants - Fertiliser") -> Constants - Fertiliser
A43: =HYPERLINK("#'Constants - Fuel'!A1", "Constants - Fuel") -> Constants - Fuel
A44: =HYPERLINK("#'Constants - Scope 3'!A1", "Constants - Scope 3") -> Constants - Scope 3
A45: =HYPERLINK("#'Constants - Solid Waste'!A1", "Constants - Solid Waste") -> Constants - Solid Waste
A46: =HYPERLINK("#'Constants - Common'!A1", "Constants - Common") -> Constants - Common
A47: =HYPERLINK("#'Constants - Common Livestock'!A1", "Constants - Common Livestock") -> Constants - Common Livestock

Sheet Results - Activity period
A1: #VALUE! | C1: Results - Activity period
A3: =HYPERLINK("#'Home'!A1", "Home") -> Home
A4: =HYPERLINK("#'Results - Activity period'!A1", "Results - Activity period") -> Results - Activity period | D4: ="Emissions breakdown for activities running between " & TEXT(X_Cell_Site_StartDate, "dd mmmm yyyy") & " and " & TEXT('Input - Enterprise'!E13, "dd mmmm yyyy") -> Emissions breakdown for activities running between 01 January 2025 and 31 December 2025
A5: =HYPERLINK("#'Results - Product EI'!A1", "Results - Product EI") -> Results - Product EI
D6: Scope 1
A8: INPUTS | D8: Scope 1 source | E8: GHG emissions method 1 | F8: GHG emissions method 2 | G8: GHG Unit | H8: CO2-e emissions method 1 | I8: CO2-e emissions method 2
A9: =HYPERLINK("#'Input - Enterprise'!A1", "Enterprise") -> Enterprise | D9: 5.1.1.1-2 Inorganic fert N2O | E9: {=VEERG_5_1_1_1__1_InorganicFertiliserApplicationN2OEmissions_Result_Method1} -> 2.0110749 | F9: {=VEERG_5_1_1_1__1_InorganicFertiliserApplicationN2OEmissions_Result_Method2} -> 0.0092837064 | G9: t N2O | H9: {=Common_Equations.Common_ConvertN2OToCO2e(E9,_xlfn.XLOOKUP("N2O", Table_GWPData[Gas],Table_GWPData[CO2-e factor]))} -> 532.93486 | I9: {=Common_Equations.Common_ConvertN2OToCO2e(F9,_xlfn.XLOOKUP("N2O", Table_GWPData[Gas],Table_GWPData[CO2-e factor]))} -> 2.4601822 | J9: t CO2e
A10: =HYPERLINK("#'Input - Site'!A1", "Site") -> Site | D10: 5.1.1.3-4 Inorganic fert CO2 | E10: {=VEERG_5_1_1_3__1_InorganicFertiliserApplicationCO2Emissions_Result_Method1} -> 184.92753 | F10: =E10 -> 184.92753 | G10: t CO2 | H10: =E10 -> 184.92753 | I10: =F10 -> 184.92753 | J10: t CO2e
A11: =HYPERLINK("#'Input - Crop'!A1", "Crop") -> Crop | D11: 5.2.1.1-2 Organic fert N2O | E11: {=VEERG_5_2_1_1__2_MassOfNitrogenInOrganicFertiliser_Result_Method1} -> 0.055785714 | F11: =E11 -> 0.055785714 | G11: t N2O | H11: {=Common_Equations.Common_ConvertN2OToCO2e(E11,_xlfn.XLOOKUP("N2O", Table_GWPData[Gas],Table_GWPData[CO2-e factor]))} -> 14.783214 | I11: {=Common_Equations.Common_ConvertN2OToCO2e(F11,_xlfn.XLOOKUP("N2O", Table_GWPData[Gas],Table_GWPData[CO2-e factor]))} -> 14.783214 | J11: t CO2e
A12: =HYPERLINK("#'Input - Fert Prod System'!A1", "Fert Prod System") -> Fert Prod System | D12: 5.3.1.1-2 Lime CO2 | E12: {=VEERG_5_3_1_1__1_LimeApplicationCO2Emissions_Result_Method1} -> 758.08333 | F12: =E12 -> 758.08333 | G12: t CO2 | H12: =E12 -> 758.08333 | I12: =F12 -> 758.08333 | J12: t CO2e
A13: =HYPERLINK("#'Input - Fertiliser'!A1", "Fertiliser") -> Fertiliser | D13: 5.4.1.1-4 Atmos. deposition | E13: 0.0016401 | F13: =E13 -> 0.0016401 | G13: t N2O | H13: {=Common_Equations.Common_ConvertN2OToCO2e(E13,_xlfn.XLOOKUP("N2O", Table_GWPData[Gas],Table_GWPData[CO2-e factor]))} -> 0.4346265 | I13: {=Common_Equations.Common_ConvertN2OToCO2e(F13,_xlfn.XLOOKUP("N2O", Table_GWPData[Gas],Table_GWPData[CO2-e factor]))} -> 0.4346265 | J13: t CO2e
A14: =HYPERLINK("#'Input - Fuel'!A1", "Fuel") -> Fuel | D14: 5.5.1.1-2 Leaching & runoff | E14: 0.07879174 | F14: =E14 -> 0.07879174 | G14: t N2O | H14: {=Common_Equations.Common_ConvertN2OToCO2e(E14,_xlfn.XLOOKUP("N2O", Table_GWPData[Gas],Table_GWPData[CO2-e factor]))} -> 20.879811 | I14: {=Common_Equations.Common_ConvertN2OToCO2e(F14,_xlfn.XLOOKUP("N2O", Table_GWPData[Gas],Table_GWPData[CO2-e factor]))} -> 20.879811 | J14: t CO2e
A15: =HYPERLINK("#'Input - Electricity'!A1", "Electricity") -> Electricity | D15: 6.1.1.1-2 Crop residue N2O | E15: {=VEERG_6_1_1_1__1__NitrousOxideEmissionsFromCropResidues_Result_Method1} -> 0.23531611 | F15: {=VEERG_6_1_1_1__1__NitrousOxideEmissionsFromCropResidues_Result_Method2} -> 0.23531611 | G15: t N2O | H15: {=Common_Equations.Common_ConvertN2OToCO2e(E15,_xlfn.XLOOKUP("N2O", Table_GWPData[Gas],Table_GWPData[CO2-e factor]))} -> 62.358769 | I15: {=Common_Equations.Common_ConvertN2OToCO2e(F15,_xlfn.XLOOKUP("N2O", Table_GWPData[Gas],Table_GWPData[CO2-e factor]))} -> 62.358769 | J15: t CO2e
A16: =HYPERLINK("#'Input - Common farm inputs'!A1", "Common farm inputs") -> Common farm inputs | D16: 6.3.1.1-2 Leach & runoff (crop) | E16: {=VEERG_6_3_1_1__1__LeachingAndRunoffEmissionsCropAndPastureResidue_CropOnly_Result_Method1} -> 0.12424691 | F16: {=VEERG_6_3_1_1__1__LeachingAndRunoffEmissionsCropAndPastureResidue_CropOnly_Result_Method2} -> 0.12424691 | G16: t N2O | H16: {=Common_Equations.Common_ConvertN2OToCO2e(E16,_xlfn.XLOOKUP("N2O", Table_GWPData[Gas],Table_GWPData[CO2-e factor]))} -> 32.92543 | I16: {=Common_Equations.Common_ConvertN2OToCO2e(F16,_xlfn.XLOOKUP("N2O", Table_GWPData[Gas],Table_GWPData[CO2-e factor]))} -> 32.92543 | J16: t CO2e
A17: =HYPERLINK("#'Input - Crop pasture farm input'!A1", "Crop pasture farm input") -> Crop pasture farm input | D17: 8.1.1.1-2 Transport fuel CO2 | E17: {=VEERG_8_1_1_1__1_FuelCombustionTransport_Result_CO2} -> 83.182 | F17: =E17 -> 83.182 | G17: t CO2 | H17: =E17 -> 83.182 | I17: =F17 -> 83.182 | J17: t CO2e
A18: =HYPERLINK("#'Input - Freight'!A1", "Freight") -> Freight | D18: 8.1.1.1-2 Transport fuel CH4 | E18: {=VEERG_8_1_1_1__1_FuelCombustionTransport_Result_CH4} -> 0.19906 | F18: =E18 -> 0.19906 | G18: t CH4 | H18: {=Common_Equations.Common_ConvertCH4ToCO2e(E18,_xlfn.XLOOKUP("CH4", Table_GWPData[Gas],Table_GWPData[CO2-e factor]))} -> 5.57368 | I18: {=Common_Equations.Common_ConvertCH4ToCO2e(F18,_xlfn.XLOOKUP("CH4", Table_GWPData[Gas],Table_GWPData[CO2-e factor]))} -> 5.57368 | J18: t CO2e
A19: =HYPERLINK("#'Input - Solid waste'!A1", "Solid waste") -> Solid waste | D19: 8.1.1.1-2 Transport fuel N2O | E19: {=VEERG_8_1_1_1__1_FuelCombustionTransport_Result_N2O} -> 0.5845 | F19: =E19 -> 0.5845 | G19: t N2O | H19: {=Common_Equations.Common_ConvertN2OToCO2e(E19,_xlfn.XLOOKUP("N2O", Table_GWPData[Gas],Table_GWPData[CO2-e factor]))} -> 154.8925 | I19: {=Common_Equations.Common_ConvertN2OToCO2e(F19,_xlfn.XLOOKUP("N2O", Table_GWPData[Gas],Table_GWPData[CO2-e factor]))} -> 154.8925 | J19: t CO2e
A20: =HYPERLINK("#'Input - Data quality'!A1", "Data quality") -> Data quality | D20: 8.2.1.1-2 Stationary fuel CO2 | E20: {=VEERG_8_2_1_1__1_FuelCombustionStationary_Result_CO2} -> 29.0708 | F20: =E20 -> 29.0708 | G20: t CO2 | H20: =E20 -> 29.0708 | I20: =F20 -> 29.0708 | J20: t CO2e
D21: 8.2.1.1-2 Stationary fuel CH4 | E21: {=VEERG_8_2_1_1__1_FuelCombustionStationary_Result_CH4} -> 0.0724 | F21: =E21 -> 0.0724 | G21: t CH4 | H21: {=Common_Equations.Common_ConvertCH4ToCO2e(E21,_xlfn.XLOOKUP("CH4", Table_GWPData[Gas],Table_GWPData[CO2-e factor]))} -> 2.0272 | I21: {=Common_Equations.Common_ConvertCH4ToCO2e(F21,_xlfn.XLOOKUP("CH4", Table_GWPData[Gas],Table_GWPData[CO2-e factor]))} -> 2.0272 | J21: t CO2e
D22: 8.2.1.1-2 Stationary fuel N2O | E22: {=VEERG_8_2_1_1__1_FuelCombustionStationary_Result_N2O} -> 0.0714 | F22: =E22 -> 0.0714 | G22: t N2O | H22: {=Common_Equations.Common_ConvertN2OToCO2e(E22,_xlfn.XLOOKUP("N2O", Table_GWPData[Gas],Table_GWPData[CO2-e factor]))} -> 18.921 | I22: {=Common_Equations.Common_ConvertN2OToCO2e(F22,_xlfn.XLOOKUP("N2O", Table_GWPData[Gas],Table_GWPData[CO2-e factor]))} -> 18.921 | J22: t CO2e
A23: CALCULATIONS | D23: 14.1.1-2 Purchased electricity (Location-based) | E23: {=VEERG_14_1_1__1_LocationBasedScopeElectricityEmissions_Result_Method1} -> 16.8 | F23: =E23 -> 16.8 | G23: t CO2e | H23: =E23 -> 16.8 | I23: =F23 -> 16.8 | J23: t CO2e
A24: =HYPERLINK("#'5.1.1.1-2 Inorganic fert N2O'!A1", "5.1.1.1-2 Inorganic fert N2O") -> 5.1.1.1-2 Inorganic fert N2O | D24: 14.1.1-2 Purchased electricity (Market-based) | E24: {=VEERG_14_1_2__1_MarketBasedScopeElectricityEmissionsVariation_Result_Method1} -> 9.72 | F24: =E24 -> 9.72 | G24: t CO2e | H24: =E24 -> 9.72 | I24: =F24 -> 9.72 | J24: t CO2e
A25: =HYPERLINK("#'5.1.1.3-4 Inorganic fert CO2'!A1", "5.1.1.3-4 Inorganic fert CO2") -> 5.1.1.3-4 Inorganic fert CO2 | D25: Total | H25: =SUM(H9:H24) -> 1927.5147 | I25: =SUM(I9:I24) -> 1397.0401 | J25: t CO2e
A26: =HYPERLINK("#'5.2.1.1-2 Organic Fert N2O'!A1", "5.2.1.1-2 Organic fert N2O") -> 5.2.1.1-2 Organic fert N2O
A27: =HYPERLINK("#'5.3.1.1-2 Lime CO2'!A1", "5.3.1.1-2 Lime CO2") -> 5.3.1.1-2 Lime CO2
A28: =HYPERLINK("#'5.4.1.1-4 Atmos deposition'!A1", "5.4.1.1-4 Atmos. deposition") -> 5.4.1.1-4 Atmos. deposition | D28: Scope 2
A29: =HYPERLINK("#'5.5.1.1-2 Leaching and runoff'!A1", "5.5.1.1-2 Leaching & runoff") -> 5.5.1.1-2 Leaching & runoff
A30: =HYPERLINK("#'6.1.1.1-2 Crop residue N2O'!A1", "6.1.1.1-2 Crop residue N2O") -> 6.1.1.1-2 Crop residue N2O | D30: Scope 2 source | E30: GHG emissions method 1 | F30: GHG emissions method 2 | G30: GHG Unit | H30: CO2-e emissions method 1 | I30: CO2-e emissions method 2
A31: =HYPERLINK("#'6.3.1.1-2 Leach runoff crop'!A1", "6.3.1.1-2 Leach & runoff (crop)") -> 6.3.1.1-2 Leach & runoff (crop) | D31: {="14.1.1-2 Purchased electricity " & IF(X_Cell_Electricity_CalculationMethod="Location-based (simpler)", "(Location-based)", "(Market-based)")} -> 14.1.1-2 Purchased electricity (Location-based) | E31: {=IF(X_Cell_Electricity_CalculationMethod="Location-based (simpler)", VEERG_14_1_1__1_LocationBasedScopeElectricityEmissions_Result_Method1, VEERG_14_1_2__1_MarketBasedScopeElectricityEmissionsVariation_Result_Method1)} -> 16.8 | F31: =E31 -> 16.8 | G31: t CO2e | H31: =E31 -> 16.8 | I31: =F31 -> 16.8 | J31: t CO2e
A32: =HYPERLINK("#'8.1.1.1-2 Transport fuel'!A1", "8.1.1.1-2 Transport fuel") -> 8.1.1.1-2 Transport fuel | D32: Total scope 2 | H32: =SUM(H31:H31) -> 16.8 | I32: =SUM(I31:I31) -> 16.8 | J32: t CO2e
A33: =HYPERLINK("#'8.2.1.1-2 Stationary fuel'!A1", "8.2.1.1-2 Stationary fuel") -> 8.2.1.1-2 Stationary fuel
A34: =HYPERLINK("#'10.1.1-2 Solid waste treatment'!A1", "10.1.1.1-2 Solid waste") -> 10.1.1.1-2 Solid waste
A35: =HYPERLINK("#'14.1.1-2 Purchased electricity'!A1", "14.1.1-2 Purchased electricity") -> 14.1.1-2 Purchased electricity | D35: Scope 3
A36: =HYPERLINK("#'15 Scope 3'!A1", "15 Scope 3") -> 15 Scope 3
D37: Scope 3 source | E37: GHG emissions method 1 | F37: GHG emissions method 2 | G37: GHG Unit | H37: CO2-e emissions method 1 | I37: CO2-e emissions method 2
D38: 15.4.1.1 Fertiliser | E38: {=VEERG_15_4_1_1__2_EmissionsFromPurchasedFertiliserComponentsVariation_Result_Method1} -> 666.11034 | F38: {=VEERG_15_4_1_1__2_EmissionsFromPurchasedFertiliserComponentsVariation_Result_Method2} -> 650.23034 | G38: t CO2e | H38: =E38 -> 666.11034 | I38: =F38 -> 650.23034 | J38: t CO2e
A39: APPENDICES | D39: 15.5.1.1 Agrichemicals | E39: {=VEERG_15_5_1_1__1_EmissionsFromPurchasedAgrichemicals_Result_Method1} -> 7.516 | F39: {=VEERG_15_5_1_1__1_EmissionsFromPurchasedAgrichemicals_Result_Method2} -> 7.496 | G39: t CO2e | H39: =E39 -> 7.516 | I39: =F39 -> 7.496 | J39: t CO2e
A40: =HYPERLINK("#'Constants - Ag Residue'!A1", "Constants - Ag residue") -> Constants - Ag residue | D40: 15.6.1.1 Lime | E40: {=VEERG_15_6_1_1__1_EmissionsFromPurchasedLime_Result_Method1} -> 0.16554 | F40: {=VEERG_15_6_1_1__1_EmissionsFromPurchasedLime_Result_Method2} -> 0.144 | G40: t CO2e | H40: =E40 -> 0.16554 | I40: =F40 -> 0.144 | J40: t CO2e
A41: =HYPERLINK("#'Constants - Electricity'!A1", "Constants - Electricity") -> Constants - Electricity | D41: 15.7.1.1 Services and contractor operations | E41: {=VEERG_15_7_1_1__1_EmissionsFromPurchasedServices_Result_Method1} -> No data | F41: {=VEERG_15_7_1_1__1_EmissionsFromPurchasedServices_Result_Method2} -> 1.1 | G41: t CO2e | H41: =E41 -> No data | I41: =F41 -> 1.1 | J41: t CO2e
A42: =HYPERLINK("#'Constants - Fertiliser'!A1", "Constants - Fertiliser") -> Constants - Fertiliser | D42: 15.10.1.1 Other: Cleaning chemicals | E42: {=VEERG_15_10_1_1__1_OtherPurchasedGoodsAndServices_CleaningChemicals_Result_Method1} -> 0.5051 | F42: {=VEERG_15_10_1_1__1_OtherPurchasedGoodsAndServices_CleaningChemicals_Result_Method2} -> 0.5 | G42: t CO2e | H42: =E42 -> 0.5051 | I42: =F42 -> 0.5 | J42: t CO2e
...

Sheet Results - Product EI
A1: #VALUE! | C1: Results - Product emissions intensity
A3: =HYPERLINK("#'Home'!A1", "Home") -> Home
A4: =HYPERLINK("#'Results - Activity period'!A1", "Results - Activity period") -> Results - Activity period
A5: =HYPERLINK("#'Results - Product EI'!A1", "Results - Product EI") -> Results - Product EI
A8: INPUTS
A9: =HYPERLINK("#'Input - Enterprise'!A1", "Enterprise") -> Enterprise
A10: =HYPERLINK("#'Input - Site'!A1", "Site") -> Site
A11: =HYPERLINK("#'Input - Crop'!A1", "Crop") -> Crop
A12: =HYPERLINK("#'Input - Fert Prod System'!A1", "Fert Prod System") -> Fert Prod System
A13: =HYPERLINK("#'Input - Fertiliser'!A1", "Fertiliser") -> Fertiliser
A14: =HYPERLINK("#'Input - Fuel'!A1", "Fuel") -> Fuel
A15: =HYPERLINK("#'Input - Electricity'!A1", "Electricity") -> Electricity
A16: =HYPERLINK("#'Input - Common farm inputs'!A1", "Common farm inputs") -> Common farm inputs
A17: =HYPERLINK("#'Input - Crop pasture farm input'!A1", "Crop pasture farm input") -> Crop pasture farm input
A18: =HYPERLINK("#'Input - Freight'!A1", "Freight") -> Freight
A19: =HYPERLINK("#'Input - Solid waste'!A1", "Solid waste") -> Solid waste
A20: =HYPERLINK("#'Input - Data quality'!A1", "Data quality") -> Data quality
A23: CALCULATIONS
A24: =HYPERLINK("#'5.1.1.1-2 Inorganic fert N2O'!A1", "5.1.1.1-2 Inorganic fert N2O") -> 5.1.1.1-2 Inorganic fert N2O
A25: =HYPERLINK("#'5.1.1.3-4 Inorganic fert CO2'!A1", "5.1.1.3-4 Inorganic fert CO2") -> 5.1.1.3-4 Inorganic fert CO2
A26: =HYPERLINK("#'5.2.1.1-2 Organic Fert N2O'!A1", "5.2.1.1-2 Organic fert N2O") -> 5.2.1.1-2 Organic fert N2O
A27: =HYPERLINK("#'5.3.1.1-2 Lime CO2'!A1", "5.3.1.1-2 Lime CO2") -> 5.3.1.1-2 Lime CO2
A28: =HYPERLINK("#'5.4.1.1-4 Atmos deposition'!A1", "5.4.1.1-4 Atmos. deposition") -> 5.4.1.1-4 Atmos. deposition
A29: =HYPERLINK("#'5.5.1.1-2 Leaching and runoff'!A1", "5.5.1.1-2 Leaching & runoff") -> 5.5.1.1-2 Leaching & runoff
A30: =HYPERLINK("#'6.1.1.1-2 Crop residue N2O'!A1", "6.1.1.1-2 Crop residue N2O") -> 6.1.1.1-2 Crop residue N2O
A31: =HYPERLINK("#'6.3.1.1-2 Leach runoff crop'!A1", "6.3.1.1-2 Leach & runoff (crop)") -> 6.3.1.1-2 Leach & runoff (crop)
A32: =HYPERLINK("#'8.1.1.1-2 Transport fuel'!A1", "8.1.1.1-2 Transport fuel") -> 8.1.1.1-2 Transport fuel | D32: ="Emissions for whole production cycle running between " & TEXT(X_Cell_Enterprise_ProductionTimeframeStart, "d mmmm yyyy") & " and " & TEXT(X_Cell_Enterprise_ProductionTimeframeEnd, "d mmmm yyyy") -> Emissions for whole production cycle running between 1 November 2025 and 31 March 2026
A33: =HYPERLINK("#'8.2.1.1-2 Stationary fuel'!A1", "8.2.1.1-2 Stationary fuel") -> 8.2.1.1-2 Stationary fuel
A34: =HYPERLINK("#'10.1.1-2 Solid waste treatment'!A1", "10.1.1.1-2 Solid waste") -> 10.1.1.1-2 Solid waste
A35: =HYPERLINK("#'14.1.1-2 Purchased electricity'!A1", "14.1.1-2 Purchased electricity") -> 14.1.1-2 Purchased electricity | E35: Method 1 | F35: Method 2
A36: =HYPERLINK("#'15 Scope 3'!A1", "15 Scope 3") -> 15 Scope 3 | D36: Emissions for production cycle excluding removals | E36: =Result_EmissionsForWholeProductionCycle_Gross_Method1 -> 3089.2557 | F36: =Result_EmissionsForWholeProductionCycle_Gross_Method2 -> 12386.154 | G36: t CO2e
D37: Net emissions for production cycle | E37: =Result_EmissionsForWholeProductionCycle_Net_Method1 -> 3089.2557 | F37: =Result_EmissionsForWholeProductionCycle_Net_Method2 -> 12386.154 | G37: t CO2e
A39: APPENDICES | D39: ="Product emissions intensity for whole production cycle running between " & TEXT(X_Cell_Enterprise_ProductionTimeframeStart, "d mmmm yyyy") & " and " & TEXT(X_Cell_Enterprise_ProductionTimeframeEnd, "d mmmm yyyy") -> Product emissions intensity for whole production cycle running between 1 November 2025 and 31 March 2026
A40: =HYPERLINK("#'Constants - Ag Residue'!A1", "Constants - Ag residue") -> Constants - Ag residue
A41: =HYPERLINK("#'Constants - Electricity'!A1", "Constants - Electricity") -> Constants - Electricity
A42: =HYPERLINK("#'Constants - Fertiliser'!A1", "Constants - Fertiliser") -> Constants - Fertiliser | D42: Product emissions - Mass
A43: =HYPERLINK("#'Constants - Fuel'!A1", "Constants - Fuel") -> Constants - Fuel | D43: Product | E43: Product type | F43: Amount (tonnnes) | G43: Mass emissions assignment | H43: Emissions intensity (Method 1) | I43: Emissions intensity (Method 2) | J43: Unit
A44: =HYPERLINK("#'Constants - Scope 3'!A1", "Constants - Scope 3") -> Constants - Scope 3 | D44: Cotton lint sold - excluding removals | E44: Main product | F44: =X_Cell_Enterprise_CottonLintYield*X_Cell_Enterprise_PercentCottonLintSold -> 2502.032 | G44: =F44/(F44+F46) -> 0.80012996 | H44: =(E36/F44)*G44 -> 0.98791945 | I44: =(F36/F44)*G44 -> 3.9609938 | J44: t co2e/t cotton lint sold
A45: =HYPERLINK("#'Constants - Solid Waste'!A1", "Constants - Solid Waste") -> Constants - Solid Waste | D45: Cotton lint sold - net emissions | E45: Main product | F45: =F44 -> 2502.032 | G45: =G44 -> 0.80012996 | H45: =(E37/F45)*G45 -> 0.98791945 | I45: =(F37/F45)*G45 -> 3.9609938 | J45: t co2e/t cotton lint sold
A46: =HYPERLINK("#'Constants - Common'!A1", "Constants - Common") -> Constants - Common | D46: Cottonseed sold - excluding removals | E46: Co-product | F46: =X_Cell_Enterprise_CottonseedYield*X_Cell_Enterprise_PercentCottonseedSold -> 625 | G46: =F46/(F44+F46) -> 0.19987004 | H46: =(E36/F46)*G46 -> 0.98791945 | I46: =(F36/F46)*G46 -> 3.9609938 | J46: t co2e/t cottonseed sold
...

Sheet Input - Enterprise
A1: #VALUE! | C1: Input - Enterprise
A3: =HYPERLINK("#'Home'!A1", "Home") -> Home
A4: =HYPERLINK("#'Results - Activity period'!A1", "Results - Activity period") -> Results - Activity period
A5: =HYPERLINK("#'Results - Product EI'!A1", "Results - Product EI") -> Results - Product EI | D5: Your business
D7: Farm name | E7: Test Farms
A8: INPUTS | D8: Reporting entity name | E8: Test Farms Pty Ltd
A9: =HYPERLINK("#'Input - Enterprise'!A1", "Enterprise") -> Enterprise
A10: =HYPERLINK("#'Input - Site'!A1", "Site") -> Site | D10: 💡An 'Emissions accounting period' is a 12 month period where the business can report on the emissions, and is typically the same as the business' financial accounting period.
A11: =HYPERLINK("#'Input - Crop'!A1", "Crop") -> Crop
A12: =HYPERLINK("#'Input - Fert Prod System'!A1", "Fert Prod System") -> Fert Prod System | D12: Emissions calculation period start date | E12: 45658 | F12: ← DD/MM/YYYY or DD Month YYYY
A13: =HYPERLINK("#'Input - Fertiliser'!A1", "Fertiliser") -> Fertiliser | D13: Emissions calculation period end date | E13: =DATE(YEAR(E12)+1,MONTH(E12),DAY(E12))-1 -> 46022 | F13: ← Automatically calculated, 12 months after start date
A14: =HYPERLINK("#'Input - Fuel'!A1", "Fuel") -> Fuel
A15: =HYPERLINK("#'Input - Electricity'!A1", "Electricity") -> Electricity
A16: =HYPERLINK("#'Input - Common farm inputs'!A1", "Common farm inputs") -> Common farm inputs | D16: Production
A17: =HYPERLINK("#'Input - Crop pasture farm input'!A1", "Crop pasture farm input") -> Crop pasture farm input
A18: =HYPERLINK("#'Input - Freight'!A1", "Freight") -> Freight | D18: Production timeframe start | E18: 45962 | F18: ← DD/MM/YYYY or DD Month YYYY
A19: =HYPERLINK("#'Input - Solid waste'!A1", "Solid waste") -> Solid waste | D19: Production timeframe end | E19: 46112 | F19: ← DD/MM/YYYY or DD Month YYYY
A20: =HYPERLINK("#'Input - Data quality'!A1", "Data quality") -> Data quality | D20: Production timeframe length | E20: =DATEDIF(E18,E19+1,"m") -> 5 | F20: Months
D22: Cotton lint yield | E22: =X_Cell_Crop_LintYieldTotal -> 2502.032 | F22: tonnes
A23: CALCULATIONS | D23: Percent cotton lint sold | E23: 1 | F23: percent
A24: =HYPERLINK("#'5.1.1.1-2 Inorganic fert N2O'!A1", "5.1.1.1-2 Inorganic fert N2O") -> 5.1.1.1-2 Inorganic fert N2O | D24: Percent cotton lint stored and not sold | E24: =100%-E23 -> 0 | F24: percent
A25: =HYPERLINK("#'5.1.1.3-4 Inorganic fert CO2'!A1", "5.1.1.3-4 Inorganic fert CO2") -> 5.1.1.3-4 Inorganic fert CO2
A26: =HYPERLINK("#'5.2.1.1-2 Organic Fert N2O'!A1", "5.2.1.1-2 Organic fert N2O") -> 5.2.1.1-2 Organic fert N2O | D26: Cottonseed yield | E26: =X_Cell_Crop_CottonseedYieldTotal -> 625 | F26: tonnes
A27: =HYPERLINK("#'5.3.1.1-2 Lime CO2'!A1", "5.3.1.1-2 Lime CO2") -> 5.3.1.1-2 Lime CO2 | D27: Percent cottonseed sold | E27: 1 | F27: percent
A28: =HYPERLINK("#'5.4.1.1-4 Atmos deposition'!A1", "5.4.1.1-4 Atmos. deposition") -> 5.4.1.1-4 Atmos. deposition | D28: Percent grain stored and not sold or used | E28: =100%-E27 -> 0 | F28: percent
A29: =HYPERLINK("#'5.5.1.1-2 Leaching and runoff'!A1", "5.5.1.1-2 Leaching & runoff") -> 5.5.1.1-2 Leaching & runoff
A30: =HYPERLINK("#'6.1.1.1-2 Crop residue N2O'!A1", "6.1.1.1-2 Crop residue N2O") -> 6.1.1.1-2 Crop residue N2O | D30: Unprocessed cotton yield | E30: =X_Cell_Crop_TotalUnprocessedCottonYield -> 3127.032 | F30: tonnes
A31: =HYPERLINK("#'6.3.1.1-2 Leach runoff crop'!A1", "6.3.1.1-2 Leach & runoff (crop)") -> 6.3.1.1-2 Leach & runoff (crop)
A32: =HYPERLINK("#'8.1.1.1-2 Transport fuel'!A1", "8.1.1.1-2 Transport fuel") -> 8.1.1.1-2 Transport fuel | D32: Percentage of income from cotton lint sold | E32: 0.8 | F32: percent
A33: =HYPERLINK("#'8.2.1.1-2 Stationary fuel'!A1", "8.2.1.1-2 Stationary fuel") -> 8.2.1.1-2 Stationary fuel | D33: Percentage of income from cottonseed sold | E33: 0.2 | F33: percent
A34: =HYPERLINK("#'10.1.1-2 Solid waste treatment'!A1", "10.1.1.1-2 Solid waste") -> 10.1.1.1-2 Solid waste
A35: =HYPERLINK("#'14.1.1-2 Purchased electricity'!A1", "14.1.1-2 Purchased electricity") -> 14.1.1-2 Purchased electricity
A36: =HYPERLINK("#'15 Scope 3'!A1", "15 Scope 3") -> 15 Scope 3 | D36: Carbon removals
A39: APPENDICES | D39: ="Carbon captured from " & TEXT(X_Cell_Site_StartDate, "d mmmm yyyy") & " to " & TEXT(X_Cell_Site_EndDate, "d, mmmm, yyyy") & " from environmental plantings" -> Carbon captured from 1 January 2025 to 31, December, 2025 from environmental plantings
A40: =HYPERLINK("#'Constants - Ag Residue'!A1", "Constants - Ag residue") -> Constants - Ag residue
A41: =HYPERLINK("#'Constants - Electricity'!A1", "Constants - Electricity") -> Constants - Electricity | D41: Planting name | E41: Total removed CO2 | F41: Percent allocated to this enterprise | G41: Removal allocated to this enterprise
A42: =HYPERLINK("#'Constants - Fertiliser'!A1", "Constants - Fertiliser") -> Constants - Fertiliser | G42: =Table_Input_Enterprise_PlantingRemovals[[#This Row],[Total removed CO2]]*Table_Input_Enterprise_PlantingRemovals[[#This Row],[Percent allocated to this enterprise]] -> 0
A43: =HYPERLINK("#'Constants - Fuel'!A1", "Constants - Fuel") -> Constants - Fuel
A44: =HYPERLINK("#'Constants - Scope 3'!A1", "Constants - Scope 3") -> Constants - Scope 3
A45: =HYPERLINK("#'Constants - Solid Waste'!A1", "Constants - Solid Waste") -> Constants - Solid Waste
...

Sheet Input - Site
A1: #VALUE! | C1: Input - Site
A3: =HYPERLINK("#'Home'!A1", "Home") -> Home
A4: =HYPERLINK("#'Results - Activity period'!A1", "Results - Activity period") -> Results - Activity period
A5: =HYPERLINK("#'Results - Product EI'!A1", "Results - Product EI") -> Results - Product EI | D5: Location and climate
D7: Location information is used to reference some region and climate-specific emission factors
A8: INPUTS | D8: Tip: Use the web-based GAF Location Helper tool to easily get region and climate information. You will need an internet connection to use the GAF Location Helper.
A9: =HYPERLINK("#'Input - Enterprise'!A1", "Enterprise") -> Enterprise
A10: =HYPERLINK("#'Input - Site'!A1", "Site") -> Site | D10: State | E10: Western Australia | F10: ← Please select
A11: =HYPERLINK("#'Input - Crop'!A1", "Crop") -> Crop | D11: Region (ABS Statistical area level 4) if state is WA | E11: Western Australia - Outback (South) | F11: ← Please select
A12: =HYPERLINK("#'Input - Fert Prod System'!A1", "Fert Prod System") -> Fert Prod System | D12: Leaching zone | E12: NO - Not in leaching zone | F12: ← Please select
A13: =HYPERLINK("#'Input - Fertiliser'!A1", "Fertiliser") -> Fertiliser | D13: Elevation | E13: 307.7 | F13: Meters
A14: =HYPERLINK("#'Input - Fuel'!A1", "Fuel") -> Fuel | D14: Average temperature for reporting period | E14: 18 | F14: Degrees celsius
A15: =HYPERLINK("#'Input - Electricity'!A1", "Electricity") -> Electricity | D15: Total rainfall for reporting period | E15: 601 | F15: Millimetres
A16: =HYPERLINK("#'Input - Common farm inputs'!A1", "Common farm inputs") -> Common farm inputs | D16: Potential evapotranspiration for reporting period | E16: 1326 | F16: Millimetres
A17: =HYPERLINK("#'Input - Crop pasture farm input'!A1", "Crop pasture farm input") -> Crop pasture farm input | D17: Number of frost days for reporting period | E17: 7 | F17: Days
A18: =HYPERLINK("#'Input - Freight'!A1", "Freight") -> Freight | D18: MAP:PET ratio | E18: =E15/E16 -> 0.45324284
A19: =HYPERLINK("#'Input - Solid waste'!A1", "Solid waste") -> Solid waste | D19: Rainfall zone | E19: =Common_InputFunctions.Utility_LookupItemFromMinMax(E15,Table_SourceData_RainfallZones[Min rainfall],Table_SourceData_RainfallZones[Max rainfall],Table_SourceData_RainfallZones[Rainfall Zone]) -> High rainfall
A20: =HYPERLINK("#'Input - Data quality'!A1", "Data quality") -> Data quality | D20: Climate zone | E20: =Common_InputFunctions.Utility_GetClimateZone(E14,E15,E17,E13,E18,Table_SourceData_ClimateZones[Min temp],Table_SourceData_ClimateZones[Max temp],Table_SourceData_ClimateZones[Min rainfall],Table_SourceData_ClimateZones[Max rainfall],Table_SourceData_ClimateZones[Min frost days],Table_SourceData_ClimateZones[Max frost days],Table_SourceData_ClimateZones[Min elevation],Table_SourceData_ClimateZones[Max elevation],Table_SourceData_ClimateZones[Min MAP:PET],Table_SourceData_ClimateZones[Max MAP:PET],Table_SourceData_ClimateZones[Climate zone]) -> Warm temperate dry
D21: Wet or dry climate zone | E21: =Common_InputFunctions.Utility_LookupValueInTable($E$20,Table_SourceData_WetDryZones[Climate zone],Table_SourceData_WetDryZones[Wet or Dry Zone]) -> Dry climate zone
D22: Temperature zone | E22: =Common_InputFunctions.Utility_LookupItemFromMinMax(E14,Table_SourceData_TemperatureZones[Min MAT],Table_SourceData_TemperatureZones[Max MAT],Table_SourceData_TemperatureZones[Temperature Zone]) -> Temperate
A23: CALCULATIONS
A24: =HYPERLINK("#'5.1.1.1-2 Inorganic fert N2O'!A1", "5.1.1.1-2 Inorganic fert N2O") -> 5.1.1.1-2 Inorganic fert N2O
A25: =HYPERLINK("#'5.1.1.3-4 Inorganic fert CO2'!A1", "5.1.1.3-4 Inorganic fert CO2") -> 5.1.1.3-4 Inorganic fert CO2
A26: =HYPERLINK("#'5.2.1.1-2 Organic Fert N2O'!A1", "5.2.1.1-2 Organic fert N2O") -> 5.2.1.1-2 Organic fert N2O
A27: =HYPERLINK("#'5.3.1.1-2 Lime CO2'!A1", "5.3.1.1-2 Lime CO2") -> 5.3.1.1-2 Lime CO2
A28: =HYPERLINK("#'5.4.1.1-4 Atmos deposition'!A1", "5.4.1.1-4 Atmos. deposition") -> 5.4.1.1-4 Atmos. deposition
A29: =HYPERLINK("#'5.5.1.1-2 Leaching and runoff'!A1", "5.5.1.1-2 Leaching & runoff") -> 5.5.1.1-2 Leaching & runoff
A30: =HYPERLINK("#'6.1.1.1-2 Crop residue N2O'!A1", "6.1.1.1-2 Crop residue N2O") -> 6.1.1.1-2 Crop residue N2O
A31: =HYPERLINK("#'6.3.1.1-2 Leach runoff crop'!A1", "6.3.1.1-2 Leach & runoff (crop)") -> 6.3.1.1-2 Leach & runoff (crop)
A32: =HYPERLINK("#'8.1.1.1-2 Transport fuel'!A1", "8.1.1.1-2 Transport fuel") -> 8.1.1.1-2 Transport fuel
A33: =HYPERLINK("#'8.2.1.1-2 Stationary fuel'!A1", "8.2.1.1-2 Stationary fuel") -> 8.2.1.1-2 Stationary fuel
A34: =HYPERLINK("#'10.1.1-2 Solid waste treatment'!A1", "10.1.1.1-2 Solid waste") -> 10.1.1.1-2 Solid waste
A35: =HYPERLINK("#'14.1.1-2 Purchased electricity'!A1", "14.1.1-2 Purchased electricity") -> 14.1.1-2 Purchased electricity
A36: =HYPERLINK("#'15 Scope 3'!A1", "15 Scope 3") -> 15 Scope 3
A39: APPENDICES
A40: =HYPERLINK("#'Constants - Ag Residue'!A1", "Constants - Ag residue") -> Constants - Ag residue
A41: =HYPERLINK("#'Constants - Electricity'!A1", "Constants - Electricity") -> Constants - Electricity
A42: =HYPERLINK("#'Constants - Fertiliser'!A1", "Constants - Fertiliser") -> Constants - Fertiliser
A43: =HYPERLINK("#'Constants - Fuel'!A1", "Constants - Fuel") -> Constants - Fuel
A44: =HYPERLINK("#'Constants - Scope 3'!A1", "Constants - Scope 3") -> Constants - Scope 3
...

Sheet Input - Crop
A3: =HYPERLINK("#'Home'!A1", "Home") -> Home
A4: =HYPERLINK("#'Results - Activity period'!A1", "Results - Activity period") -> Results - Activity period
A5: =HYPERLINK("#'Results - Product EI'!A1", "Results - Product EI") -> Results - Product EI | D5: Area
D7: If multiple paddocks were managed in the same way at the same time, you can enter information for them all together.
A8: INPUTS
A9: =HYPERLINK("#'Input - Enterprise'!A1", "Enterprise") -> Enterprise | D9: Crop type | E9: Cotton
A10: =HYPERLINK("#'Input - Site'!A1", "Site") -> Site | D10: Irrigation method | E10: Sprinkler irrigation | F10: ← Please select
A11: =HYPERLINK("#'Input - Crop'!A1", "Crop") -> Crop
A12: =HYPERLINK("#'Input - Fert Prod System'!A1", "Fert Prod System") -> Fert Prod System | D12: Area under cropping | E12: 1000 | F12: hectares
A13: =HYPERLINK("#'Input - Fertiliser'!A1", "Fertiliser") -> Fertiliser
A14: =HYPERLINK("#'Input - Fuel'!A1", "Fuel") -> Fuel | D14: Yield
A15: =HYPERLINK("#'Input - Electricity'!A1", "Electricity") -> Electricity | D15: Average weight per round module | E15: 2392 | F15: kg / round module
A16: =HYPERLINK("#'Input - Common farm inputs'!A1", "Common farm inputs") -> Common farm inputs | D16: Total number of round modules | E16: 2500 | F16: round modules
A17: =HYPERLINK("#'Input - Crop pasture farm input'!A1", "Crop pasture farm input") -> Crop pasture farm input | D17: Round modules produced per hectare | E17: =X_Cell_Crop_TotalRoundModules/X_Cell_Crop_AreaUnderCropping -> 2.5 | F17: round modules / ha
A18: =HYPERLINK("#'Input - Freight'!A1", "Freight") -> Freight
A19: =HYPERLINK("#'Input - Solid waste'!A1", "Solid waste") -> Solid waste | D19: Average weight per lint bale | E19: 227 | F19: kg / lint bale
A20: =HYPERLINK("#'Input - Data quality'!A1", "Data quality") -> Data quality | D20: Turnout rate | E20: 0.4184 | F20: percent
D21: Number of lint bales per round module | E21: =(X_Cell_Crop_AverageWeightPerRoundModule*X_Cell_Crop_TurnoutRate)/X_Cell_Crop_WeightPerLintBale -> 4.408867 | F21: lint bales / round module
D22: Total lint yield | E22: =(X_Cell_Crop_TotalRoundModules*X_Cell_Crop_LintBalesPerRoundModule)*E19*10^-3 -> 2502.032 | F22: tonnes
A23: CALCULATIONS | D23: Lint yield per hectare | E23: =E22/X_Cell_Crop_AreaUnderCropping -> 2.502032 | F23: tonnes / hectare
A24: =HYPERLINK("#'5.1.1.1-2 Inorganic fert N2O'!A1", "5.1.1.1-2 Inorganic fert N2O") -> 5.1.1.1-2 Inorganic fert N2O
A25: =HYPERLINK("#'5.1.1.3-4 Inorganic fert CO2'!A1", "5.1.1.3-4 Inorganic fert CO2") -> 5.1.1.3-4 Inorganic fert CO2 | D25: Average amount of cottonseed produced per round module | E25: 250 | F25: kg / round module
A26: =HYPERLINK("#'5.2.1.1-2 Organic Fert N2O'!A1", "5.2.1.1-2 Organic fert N2O") -> 5.2.1.1-2 Organic fert N2O | D26: Total cottonseed produced | E26: =X_Cell_Crop_CottonSeedAmountPerRoundModule*X_Cell_Crop_TotalRoundModules*10^-3 -> 625 | F26: tonnes
A27: =HYPERLINK("#'5.3.1.1-2 Lime CO2'!A1", "5.3.1.1-2 Lime CO2") -> 5.3.1.1-2 Lime CO2
A28: =HYPERLINK("#'5.4.1.1-4 Atmos deposition'!A1", "5.4.1.1-4 Atmos. deposition") -> 5.4.1.1-4 Atmos. deposition | D28: Total trash produced | E28: =(X_Cell_Crop_AverageWeightPerRoundModule*X_Cell_Crop_TotalRoundModules*10^-3)-(X_Cell_Crop_LintYieldTotal+X_Cell_Crop_CottonseedYieldTotal) -> 2852.968 | F28: tonnes
A29: =HYPERLINK("#'5.5.1.1-2 Leaching and runoff'!A1", "5.5.1.1-2 Leaching & runoff") -> 5.5.1.1-2 Leaching & runoff
A30: =HYPERLINK("#'6.1.1.1-2 Crop residue N2O'!A1", "6.1.1.1-2 Crop residue N2O") -> 6.1.1.1-2 Crop residue N2O | D30: Total unprocessed cotton yield (excluding trash) | E30: =(X_Cell_Crop_AverageWeightPerRoundModule*X_Cell_Crop_TotalRoundModules*10^-3)-X_Cell_Crop_TrashTotalProduced -> 3127.032 | F30: tonnes
A31: =HYPERLINK("#'6.3.1.1-2 Leach runoff crop'!A1", "6.3.1.1-2 Leach & runoff (crop)") -> 6.3.1.1-2 Leach & runoff (crop)
A32: =HYPERLINK("#'8.1.1.1-2 Transport fuel'!A1", "8.1.1.1-2 Transport fuel") -> 8.1.1.1-2 Transport fuel
A33: =HYPERLINK("#'8.2.1.1-2 Stationary fuel'!A1", "8.2.1.1-2 Stationary fuel") -> 8.2.1.1-2 Stationary fuel | D33: Residue management
A34: =HYPERLINK("#'10.1.1-2 Solid waste treatment'!A1", "10.1.1.1-2 Solid waste") -> 10.1.1.1-2 Solid waste | D34: Residue:crop ratio | E34: =Common_InputFunctions.Utility_LookupValueInTableNumber(X_Cell_Crop_CropType, INDIRECT("Table_SourceData_CropAttributes[Crop type]"),INDIRECT("Table_SourceData_CropAttributes[Residue: Crop ratio]")) -> 1.9
A35: =HYPERLINK("#'14.1.1-2 Purchased electricity'!A1", "14.1.1-2 Purchased electricity") -> 14.1.1-2 Purchased electricity | D35: Residue after harvest | E35: =X_Cell_Crop_LintYieldTotal*X_Cell_Crop_ResidueToCropRatio -> 4753.8608 | F35: tonnes
A36: =HYPERLINK("#'15 Scope 3'!A1", "15 Scope 3") -> 15 Scope 3
D37: Baled residue
D38: Percentage of residue that was baled | E38: 0.1 | F38: Percent
A39: APPENDICES | D39: Average weight per bale | E39: 0.6 | F39: Kilograms
A40: =HYPERLINK("#'Constants - Ag Residue'!A1", "Constants - Ag residue") -> Constants - Ag residue | D40: Number of bales | E40: =IFERROR((X_Cell_Crop_TotalResidueBaled*10^3)/X_Cell_Crop_AverageWeightPerBale, 0) -> 792310.13 | F40: Bales
A41: =HYPERLINK("#'Constants - Electricity'!A1", "Constants - Electricity") -> Constants - Electricity | D41: Total residue baled | E41: =X_Cell_Crop_ResidueAfterHarvest*X_Cell_Crop_PercentResidueBaled -> 475.38608 | F41: Tonnes
A42: =HYPERLINK("#'Constants - Fertiliser'!A1", "Constants - Fertiliser") -> Constants - Fertiliser
A43: =HYPERLINK("#'Constants - Fuel'!A1", "Constants - Fuel") -> Constants - Fuel | D43: Residue retained on paddocks | E43: =E35-X_Cell_Crop_TotalResidueBaled -> 4278.4747 | F43: Tonnes
...

Sheet Input - Fert Prod System
A1: #VALUE! | C1: Input - Fertiliser Production System
A3: =HYPERLINK("#'Home'!A1", "Home") -> Home
A4: =HYPERLINK("#'Results - Activity period'!A1", "Results - Activity period") -> Results - Activity period
A5: =HYPERLINK("#'Results - Product EI'!A1", "Results - Product EI") -> Results - Product EI | D5: These inputs are used for fertiliser calculations, and they take their values from the "Input - Crop" sheet. Do not edit these cells.
D7: Production system | E7: Crop
A8: INPUTS | D8: Crop type | E8: {=_xlfn.IFS(X_Cell_Crop_CropType="Maize", "Maize", X_Cell_Crop_CropType="Cotton", "Cotton", TRUE, "Grains")} -> Cotton
A9: =HYPERLINK("#'Input - Enterprise'!A1", "Enterprise") -> Enterprise | D9: Irrigation method | E9: {=X_Cell_Crop_IrrigationMethod} -> Sprinkler irrigation
A10: =HYPERLINK("#'Input - Site'!A1", "Site") -> Site | D10: Area under cropping | E10: {=X_Cell_Crop_AreaUnderCropping} -> 1000
A11: =HYPERLINK("#'Input - Crop'!A1", "Crop") -> Crop
A12: =HYPERLINK("#'Input - Fert Prod System'!A1", "Fert Prod System") -> Fert Prod System
A13: =HYPERLINK("#'Input - Fertiliser'!A1", "Fertiliser") -> Fertiliser
A14: =HYPERLINK("#'Input - Fuel'!A1", "Fuel") -> Fuel
A15: =HYPERLINK("#'Input - Electricity'!A1", "Electricity") -> Electricity
A16: =HYPERLINK("#'Input - Common farm inputs'!A1", "Common farm inputs") -> Common farm inputs
A17: =HYPERLINK("#'Input - Crop pasture farm input'!A1", "Crop pasture farm input") -> Crop pasture farm input
A18: =HYPERLINK("#'Input - Freight'!A1", "Freight") -> Freight
A19: =HYPERLINK("#'Input - Solid waste'!A1", "Solid waste") -> Solid waste
A20: =HYPERLINK("#'Input - Data quality'!A1", "Data quality") -> Data quality
A23: CALCULATIONS
A24: =HYPERLINK("#'5.1.1.1-2 Inorganic fert N2O'!A1", "5.1.1.1-2 Inorganic fert N2O") -> 5.1.1.1-2 Inorganic fert N2O
A25: =HYPERLINK("#'5.1.1.3-4 Inorganic fert CO2'!A1", "5.1.1.3-4 Inorganic fert CO2") -> 5.1.1.3-4 Inorganic fert CO2
A26: =HYPERLINK("#'5.2.1.1-2 Organic Fert N2O'!A1", "5.2.1.1-2 Organic fert N2O") -> 5.2.1.1-2 Organic fert N2O
A27: =HYPERLINK("#'5.3.1.1-2 Lime CO2'!A1", "5.3.1.1-2 Lime CO2") -> 5.3.1.1-2 Lime CO2
A28: =HYPERLINK("#'5.4.1.1-4 Atmos deposition'!A1", "5.4.1.1-4 Atmos. deposition") -> 5.4.1.1-4 Atmos. deposition
A29: =HYPERLINK("#'5.5.1.1-2 Leaching and runoff'!A1", "5.5.1.1-2 Leaching & runoff") -> 5.5.1.1-2 Leaching & runoff
A30: =HYPERLINK("#'6.1.1.1-2 Crop residue N2O'!A1", "6.1.1.1-2 Crop residue N2O") -> 6.1.1.1-2 Crop residue N2O
A31: =HYPERLINK("#'6.3.1.1-2 Leach runoff crop'!A1", "6.3.1.1-2 Leach & runoff (crop)") -> 6.3.1.1-2 Leach & runoff (crop)
A32: =HYPERLINK("#'8.1.1.1-2 Transport fuel'!A1", "8.1.1.1-2 Transport fuel") -> 8.1.1.1-2 Transport fuel
A33: =HYPERLINK("#'8.2.1.1-2 Stationary fuel'!A1", "8.2.1.1-2 Stationary fuel") -> 8.2.1.1-2 Stationary fuel
A34: =HYPERLINK("#'10.1.1-2 Solid waste treatment'!A1", "10.1.1.1-2 Solid waste") -> 10.1.1.1-2 Solid waste
A35: =HYPERLINK("#'14.1.1-2 Purchased electricity'!A1", "14.1.1-2 Purchased electricity") -> 14.1.1-2 Purchased electricity
A36: =HYPERLINK("#'15 Scope 3'!A1", "15 Scope 3") -> 15 Scope 3
A39: APPENDICES
A40: =HYPERLINK("#'Constants - Ag Residue'!A1", "Constants - Ag residue") -> Constants - Ag residue
A41: =HYPERLINK("#'Constants - Electricity'!A1", "Constants - Electricity") -> Constants - Electricity
A42: =HYPERLINK("#'Constants - Fertiliser'!A1", "Constants - Fertiliser") -> Constants - Fertiliser
A43: =HYPERLINK("#'Constants - Fuel'!A1", "Constants - Fuel") -> Constants - Fuel
A44: =HYPERLINK("#'Constants - Scope 3'!A1", "Constants - Scope 3") -> Constants - Scope 3
A45: =HYPERLINK("#'Constants - Solid Waste'!A1", "Constants - Solid Waste") -> Constants - Solid Waste
A46: =HYPERLINK("#'Constants - Common'!A1", "Constants - Common") -> Constants - Common
...

Sheet Input - Fertiliser
A1: #VALUE! | C1: Input - Fertiliser
A3: =HYPERLINK("#'Home'!A1", "Home") -> Home
A4: =HYPERLINK("#'Results - Activity period'!A1", "Results - Activity period") -> Results - Activity period
A5: =HYPERLINK("#'Results - Product EI'!A1", "Results - Product EI") -> Results - Product EI | D5: Inorganic fertiliser applied
D7: 💡You can add more rows to tables by right-clicking on the table and selecting "Insert > Table rows above/below".
A8: INPUTS | D8: 💡The application area is the same as the area under pasture / cropping by default. You can edit it if the application area is different.
A9: =HYPERLINK("#'Input - Enterprise'!A1", "Enterprise") -> Enterprise
A10: =HYPERLINK("#'Input - Site'!A1", "Site") -> Site | D10: Branded fertiliser products
A11: =HYPERLINK("#'Input - Crop'!A1", "Crop") -> Crop | D11: Product (select) | E11: Amount applied per hectare | F11: Application unit | G11: Application area (ha) | H11: Density | I11: Total applied (kg) | J11: Ingredient 1 | K11: Ingredient 1 percent | L11: Ingredient 2 | M11: Ingredient 2 percent | N11: Ingredient 3 | O11: Ingredient 3 percent | P11: Ingredient 4 | Q11: Ingredient 4 percent | R11: Ingredient 5 | S11: Ingredient 5 percent | T11: Ingredient 6 | U11: Ingredient 6 percent | V11: % N (Ingredients) | W11: % N (declared) | X11: N application rate (kg/ha) | Y11: Urea source | Z11: Ammonia source
A12: =HYPERLINK("#'Input - Fert Prod System'!A1", "Fert Prod System") -> Fert Prod System | D12: Urea | E12: 100 | F12: =IFERROR(_xlfn.XLOOKUP(Table_Input_InorganicFertiliser_Brands[[#This Row],[Product (select)]],FertiliserProducts[Product],FertiliserProducts[Unit]), "kg") -> kg | G12: =X_Cell_Fertiliser_AreaUnderCropping -> 1000 | H12: =IFERROR(_xlfn.XLOOKUP(Table_Input_InorganicFertiliser_Brands[[#This Row],[Product (select)]],FertiliserProducts[Product],FertiliserProducts[Density]), 1) -> 1 | I12: =(Table_Input_InorganicFertiliser_Brands[[#This Row],[Amount applied per hectare]]*Table_Input_InorganicFertiliser_Brands[[#This Row],[Density]])*Table_Input_InorganicFertiliser_Brands[[#This Row],[Application area (ha)]] -> 100000 | J12: {=Fertiliser_InputFunctions.Fertiliser_FertiliserProductLookup(Table_Input_InorganicFertiliser_Brands[[#This Row],[Product (select)]], Table_Input_InorganicFertiliser_Brands[[#Headers],[Ingredient 1]], FertiliserProducts[#Data], FertiliserProducts[Product], FertiliserProducts[#Headers])} -> Urea | K12: {=Fertiliser_InputFunctions.Fertiliser_FertiliserProductLookup(Table_Input_InorganicFertiliser_Brands[[#This Row],[Product (select)]], Table_Input_InorganicFertiliser_Brands[[#Headers],[Ingredient 1 percent]], FertiliserProducts[#Data], FertiliserProducts[Product], FertiliserProducts[#Headers])} -> 1 | L12: {=Fertiliser_InputFunctions.Fertiliser_FertiliserProductLookup(Table_Input_InorganicFertiliser_Brands[[#This Row],[Product (select)]], Table_Input_InorganicFertiliser_Brands[[#Headers],[Ingredient 2]], FertiliserProducts[#Data], FertiliserProducts[Product], FertiliserProducts[#Headers])} | M12: {=Fertiliser_InputFunctions.Fertiliser_FertiliserProductLookup(Table_Input_InorganicFertiliser_Brands[[#This Row],[Product (select)]], Table_Input_InorganicFertiliser_Brands[[#Headers],[Ingredient 2 percent]], FertiliserProducts[#Data], FertiliserProducts[Product], FertiliserProducts[#Headers])} | N12: {=Fertiliser_InputFunctions.Fertiliser_FertiliserProductLookup(Table_Input_InorganicFertiliser_Brands[[#This Row],[Product (select)]], Table_Input_InorganicFertiliser_Brands[[#Headers],[Ingredient 3]], FertiliserProducts[#Data], FertiliserProducts[Product], FertiliserProducts[#Headers])} | O12: {=Fertiliser_InputFunctions.Fertiliser_FertiliserProductLookup(Table_Input_InorganicFertiliser_Brands[[#This Row],[Product (select)]], Table_Input_InorganicFertiliser_Brands[[#Headers],[Ingredient 3 percent]], FertiliserProducts[#Data], FertiliserProducts[Product], FertiliserProducts[#Headers])} | P12: {=Fertiliser_InputFunctions.Fertiliser_FertiliserProductLookup(Table_Input_InorganicFertiliser_Brands[[#This Row],[Product (select)]], Table_Input_InorganicFertiliser_Brands[[#Headers],[Ingredient 4]], FertiliserProducts[#Data], FertiliserProducts[Product], FertiliserProducts[#Headers])} | Q12: {=Fertiliser_InputFunctions.Fertiliser_FertiliserProductLookup(Table_Input_InorganicFertiliser_Brands[[#This Row],[Product (select)]], Table_Input_InorganicFertiliser_Brands[[#Headers],[Ingredient 4 percent]], FertiliserProducts[#Data], FertiliserProducts[Product], FertiliserProducts[#Headers])} | R12: {=Fertiliser_InputFunctions.Fertiliser_FertiliserProductLookup(Table_Input_InorganicFertiliser_Brands[[#This Row],[Product (select)]], Table_Input_InorganicFertiliser_Brands[[#Headers],[Ingredient 5]], FertiliserProducts[#Data], FertiliserProducts[Product], FertiliserProducts[#Headers])} | S12: {=Fertiliser_InputFunctions.Fertiliser_FertiliserProductLookup(Table_Input_InorganicFertiliser_Brands[[#This Row],[Product (select)]], Table_Input_InorganicFertiliser_Brands[[#Headers],[Ingredient 5 percent]], FertiliserProducts[#Data], FertiliserProducts[Product], FertiliserProducts[#Headers])} | T12: {=Fertiliser_InputFunctions.Fertiliser_FertiliserProductLookup(Table_Input_InorganicFertiliser_Brands[[#This Row],[Product (select)]], Table_Input_InorganicFertiliser_Brands[[#Headers],[Ingredient 6]], FertiliserProducts[#Data], FertiliserProducts[Product], FertiliserProducts[#Headers])} | U12: {=Fertiliser_InputFunctions.Fertiliser_FertiliserProductLookup(Table_Input_InorganicFertiliser_Brands[[#This Row],[Product (select)]], Table_Input_InorganicFertiliser_Brands[[#Headers],[Ingredient 6 percent]], FertiliserProducts[#Data], FertiliserProducts[Product], FertiliserProducts[#Headers])} | V12: =IFERROR((_xlfn.XLOOKUP(Table_Input_InorganicFertiliser_Brands[[#This Row],[Ingredient 1]], Table_Fertiliser_ChemicalCompounds[Fertiliser type f],Table_Fertiliser_ChemicalCompounds[FNinorganic f])*Table_Input_InorganicFertiliser_Brands[[#This Row],[Ingredient 1 percent]]), 0)+ IFERROR((_xlfn.XLOOKUP(Table_Input_InorganicFertiliser_Brands[[#This Row],[Ingredient 2]],Table_Fertiliser_ChemicalCompounds[Fertiliser type f],Table_Fertiliser_ChemicalCompounds[FNinorganic f])*Table_Input_InorganicFertiliser_Brands[[#This Row],[Ingredient 2 percent]]), 0)+ IFERROR((_xlfn.XLOOKUP(Table_Input_InorganicFertiliser_Brands[[#This Row],[Ingredient 3]],Table_Fertiliser_ChemicalCompounds[Fertiliser type f],Table_Fertiliser_ChemicalCompounds[FNinorganic f])*Table_Input_InorganicFertiliser_Brands[[#This Row],[Ingredient 3 percent]]), 0)+ IFERROR((_xlfn.XLOOKUP(Table_Input_InorganicFertiliser_Brands[[#This Row],[Ingredient 4]],Table_Fertiliser_ChemicalCompounds[Fertiliser type f],Table_Fertiliser_ChemicalCompounds[FNinorganic f])*Table_Input_InorganicFertiliser_Brands[[#This Row],[Ingredient 4 percent]]), 0)+ IFERROR((_xlfn.XLOOKUP(Table_Input_InorganicFertiliser_Brands[[#This Row],[Ingredient 5]],Table_Fertiliser_ChemicalCompounds[Fertiliser type f],Table_Fertiliser_ChemicalCompounds[FNinorganic f])*Table_Input_InorganicFertiliser_Brands[[#This Row],[Ingredient 5 percent]]), 0)+ IFERROR((_xlfn.XLOOKUP(Table_Input_InorganicFertiliser_Brands[[#This Row],[Ingredient 6]],Table_Fertiliser_ChemicalCompounds[Fertiliser type f],Table_Fertiliser_ChemicalCompounds[FNinorganic f])*Table_Input_InorganicFertiliser_Brands[[#This Row],[Ingredient 6 percent]]), 0) -> 0.46 | W12: {=IFERROR(Fertiliser_InputFunctions.Fertiliser_FertiliserProductLookup(Table_Input_InorganicFertiliser_Brands[[#This Row],[Product (select)]], "N declared", FertiliserProducts[#Data], FertiliserProducts[Product], FertiliserProducts[#Headers])*0.01, 0)} -> 0.46 | X12: =(Table_Input_InorganicFertiliser_Brands[[#This Row],[Amount applied per hectare]]*Table_Input_InorganicFertiliser_Brands[[#This Row],[Density]])*(IF(Table_Input_InorganicFertiliser_Brands[[#This Row],[% N (declared)]], Table_Input_InorganicFertiliser_Brands[[#This Row],[% N (declared)]], Table_Input_InorganicFertiliser_Brands[[#This Row],[% N (Ingredients)]])) -> 46 | Y12: =IFERROR(_xlfn.XLOOKUP(Table_Input_InorganicFertiliser_Brands[[#This Row],[Product (select)]],FertiliserProducts[Product],FertiliserProducts[Urea source]), "") | Z12: =IFERROR(_xlfn.XLOOKUP(Table_Input_InorganicFertiliser_Brands[[#This Row],[Product (select)]],FertiliserProducts[Product],FertiliserProducts[Ammonia source]), "")
