Workbook
Name AgResidue_Equations_FieldBurning.VEERG_6_4_1_1__1__MethaneEmissionsFromBurningOfCropResidues: _xlfn.LAMBDA(_xlpm.Mburnc,_xlpm.CCc,_xlpm.EFCH4,_xlpm.C_CH4, _xlpm.Mburnc * _xlpm.CCc * _xlpm.EFCH4 * _xlpm.C_CH4 * 10 ^ (-3))
Name AgResidue_Equations_FieldBurning.VEERG_6_4_1_1__1__MethaneEmissionsFromBurningOfCropResidues_FunctionName: _xlfn.LAMBDA("VEERG_6_4_1_1__1__MethaneEmissionsFromBurningOfCropResidues")
Name AgResidue_Equations_FieldBurning.VEERG_6_4_1_1__1__MethaneEmissionsFromBurningOfCropResidues_LatexEquation: _xlfn.LAMBDA("E_{CH4}=\sum_{c}(M_{burn,c}\times CC_{c}\times EF_{CH4}\times C_{CH4}\times 10^{-3})")
Name AgResidue_Equations_FieldBurning.VEERG_6_4_1_1__1__MethaneEmissionsFromBurningOfCropResidues_NIRReference: _xlfn.LAMBDA("")
Name AgResidue_Equations_FieldBurning.VEERG_6_4_1_1__1__MethaneEmissionsFromBurningOfCropResidues_Source: _xlfn.LAMBDA("VEERG 2026: 6.4.1.1, Equation (1)")
Name AgResidue_Equations_FieldBurning.VEERG_6_4_1_1__1__MethaneEmissionsFromBurningOfCropResidues_Title: _xlfn.LAMBDA("Methane emissions from the burning of crop residues")
Name AgResidue_Equations_FieldBurning.VEERG_6_4_1_1__1__MethaneEmissionsFromBurningOfCropResidues_Unit: _xlfn.LAMBDA("t CH4")
Name AgResidue_Equations_FieldBurning.VEERG_6_4_1_1__1__MethaneEmissionsFromBurningOfCropResidues_Variable: _xlfn.LAMBDA("ECH4")
Name AgResidue_Equations_FieldBurning.VEERG_6_4_1_1__2__NitrousOxideEmissionsFromBurningOfCropResidues: _xlfn.LAMBDA(_xlpm.Mburnc,_xlpm.NCAGc,_xlpm.EFN2O,_xlpm.CN2O, _xlpm.Mburnc * _xlpm.NCAGc * _xlpm.EFN2O * _xlpm.CN2O * 10 ^ (-3))
Name AgResidue_Equations_FieldBurning.VEERG_6_4_1_1__2__NitrousOxideEmissionsFromBurningOfCropResidues_FunctionName: _xlfn.LAMBDA("VEERG_6_4_1_1__2__NitrousOxideEmissionsFromBurningOfCropResidues")
Name AgResidue_Equations_FieldBurning.VEERG_6_4_1_1__2__NitrousOxideEmissionsFromBurningOfCropResidues_LatexEquation: _xlfn.LAMBDA("E_{N2O}=\sum_{c}(M_{burn,c}\times NC_{AGc}\times EF_{N2O}\times C_{N2O}\times 10^{-3})")
Name AgResidue_Equations_FieldBurning.VEERG_6_4_1_1__2__NitrousOxideEmissionsFromBurningOfCropResidues_NIRReference: _xlfn.LAMBDA("")
Name AgResidue_Equations_FieldBurning.VEERG_6_4_1_1__2__NitrousOxideEmissionsFromBurningOfCropResidues_Source: _xlfn.LAMBDA("VEERG 2026: 6.4.1.1, Equation (2)")
Name AgResidue_Equations_FieldBurning.VEERG_6_4_1_1__2__NitrousOxideEmissionsFromBurningOfCropResidues_Title: _xlfn.LAMBDA("Nitrous oxide emissions from the burning of crop residues")
Name AgResidue_Equations_FieldBurning.VEERG_6_4_1_1__2__NitrousOxideEmissionsFromBurningOfCropResidues_Unit: _xlfn.LAMBDA("t N2O")
Name AgResidue_Equations_FieldBurning.VEERG_6_4_1_1__2__NitrousOxideEmissionsFromBurningOfCropResidues_Variable: _xlfn.LAMBDA("EN2O")
Name AgResidue_Equations_FieldBurning.VEERG_6_4_1_1__3__MassOfCropResidueBurnt: _xlfn.LAMBDA(_xlpm.Pc,_xlpm.RAGc,_xlpm.Sc,_xlpm.DMc,_xlpm.Zc,_xlpm.Fc, _xlpm.Pc * _xlpm.RAGc * _xlpm.Sc * _xlpm.DMc * _xlpm.Zc * _xlpm.Fc)
Name AgResidue_Equations_FieldBurning.VEERG_6_4_1_1__3__MassOfCropResidueBurnt_FunctionName: _xlfn.LAMBDA("VEERG_6_4_1_1__3__MassOfCropResidueBurnt")
Name AgResidue_Equations_FieldBurning.VEERG_6_4_1_1__3__MassOfCropResidueBurnt_LatexEquation: _xlfn.LAMBDA("M_{burn,c}=P_{c}\times R_{AGc}\times S_{c}\times DM_{c}\times Z_{c}\times F_{c}")
Name AgResidue_Equations_FieldBurning.VEERG_6_4_1_1__3__MassOfCropResidueBurnt_NIRReference: _xlfn.LAMBDA("")
Name AgResidue_Equations_FieldBurning.VEERG_6_4_1_1__3__MassOfCropResidueBurnt_Source: _xlfn.LAMBDA("VEERG 2026: 6.4.1.1, Equation (3)")
Name AgResidue_Equations_FieldBurning.VEERG_6_4_1_1__3__MassOfCropResidueBurnt_Title: _xlfn.LAMBDA("Mass of residue of crop c burnt")
Name AgResidue_Equations_FieldBurning.VEERG_6_4_1_1__3__MassOfCropResidueBurnt_Unit: _xlfn.LAMBDA("kg")
Name AgResidue_Equations_FieldBurning.VEERG_6_4_1_1__3__MassOfCropResidueBurnt_Variable: _xlfn.LAMBDA("Mburnc")
Name AgResidues_Equations_CropResidues.VEERG_6_1_1_1__1__NitrousOxideEmissionsFromCropResidues: _xlfn.LAMBDA(_xlpm.Mc,_xlpm.EFNi,_xlpm.CgN2O, _xlpm.Mc * _xlpm.EFNi * _xlpm.CgN2O * 10 ^ (-3))
Name AgResidues_Equations_CropResidues.VEERG_6_1_1_1__1__NitrousOxideEmissionsFromCropResidues_FunctionName: _xlfn.LAMBDA("VEERG_6_1_1_1__1__NitrousOxideEmissionsFromCropResidues")
Name AgResidues_Equations_CropResidues.VEERG_6_1_1_1__1__NitrousOxideEmissionsFromCropResidues_LatexEquation: _xlfn.LAMBDA("E=\sum_{c}{M_{c}\times EF_{N}\times C_{g,N2O}\times 10^{-3}}")
Name AgResidues_Equations_CropResidues.VEERG_6_1_1_1__1__NitrousOxideEmissionsFromCropResidues_NIRReference: _xlfn.LAMBDA("")
Name AgResidues_Equations_CropResidues.VEERG_6_1_1_1__1__NitrousOxideEmissionsFromCropResidues_Source: _xlfn.LAMBDA("VEERG 2026: 6.1.1.1, Equation (1)")
Name AgResidues_Equations_CropResidues.VEERG_6_1_1_1__1__NitrousOxideEmissionsFromCropResidues_Title: _xlfn.LAMBDA("Nitrous oxide emissions from the return of crop residues across all crops c to the soil")
Name AgResidues_Equations_CropResidues.VEERG_6_1_1_1__1__NitrousOxideEmissionsFromCropResidues_Unit: _xlfn.LAMBDA("t N2O")
Name AgResidues_Equations_CropResidues.VEERG_6_1_1_1__1__NitrousOxideEmissionsFromCropResidues_Variable: _xlfn.LAMBDA("E")
Name AgResidues_Equations_CropResidues.VEERG_6_1_1_1__2__MassOfNitrogenInCropResidues_LatexEquation: _xlfn.LAMBDA("M_{c}=(P_{c}\times R_{AGc}\times(1-F_{c}-FFOD_{c})\times DM_{c}\times NC_{AGc})+(P_{c}\times R_{AGc}\times R_{BGc}\times DM_{c}\times NC_{BGc})")
Name AgResidues_Equations_CropResidues.VEERG_6_1_1_1__2__MassOfNitrogenInCropResidues_NIRReference: _xlfn.LAMBDA("")
Name AgResidues_Equations_CropResidues.VEERG_6_1_1_1__2__MassOfNitrogenInCropResidues_Source: _xlfn.LAMBDA("VEERG 2026: 6.1.1.1, Equation (2)")
Name AgResidues_Equations_CropResidues.VEERG_6_1_1_1__2__MassOfNitrogenInCropResidues_Title: _xlfn.LAMBDA("Mass of nitrogen in crop residues returned to the soil")
Name AgResidues_Equations_CropResidues.VEERG_6_1_1_1__2__MassOfNitrogenInCropResidues_Unit: _xlfn.LAMBDA("kg N")
Name AgResidues_Equations_CropResidues.VEERG_6_1_1_1__2__MassOfNitrogenInCropResidues_Variable: _xlfn.LAMBDA("Mc")
Name AgResidues_Equations_CropResidues.VEERG_6_1_1_2__1__FractionOfCropResidueRemovedBaled: _xlfn.LAMBDA(_xlpm.B,_xlpm.MB,_xlpm.Pc,_xlpm.RAGc, IFERROR((_xlpm.B * _xlpm.MB) / (_xlpm.Pc * _xlpm.RAGc), 0))
Name AgResidues_Equations_CropResidues.VEERG_6_1_1_2__1__FractionOfCropResidueRemovedBaled_LatexEquation: _xlfn.LAMBDA("FFOD_{c,baled}=\frac{B\times M_{B}}{P_{c}\times R_{AG,c}}")
Name AgResidues_Equations_CropResidues.VEERG_6_1_1_2__1__FractionOfCropResidueRemovedBaled_NIRReference: _xlfn.LAMBDA("")
Name AgResidues_Equations_CropResidues.VEERG_6_1_1_2__1__FractionOfCropResidueRemovedBaled_Source: _xlfn.LAMBDA("VEERG 2026: 6.1.1.2, Equation (1)")
Name AgResidues_Equations_CropResidues.VEERG_6_1_1_2__1__FractionOfCropResidueRemovedBaled_Title: _xlfn.LAMBDA("Fraction of crop residue that is removed for crop c, calculated where residues are baled")
Name AgResidues_Equations_CropResidues.VEERG_6_1_1_2__1__FractionOfCropResidueRemovedBaled_Unit: _xlfn.LAMBDA("dimensionless")
Name AgResidues_Equations_CropResidues.VEERG_6_1_1_2__1__FractionOfCropResidueRemovedBaled_Variable: _xlfn.LAMBDA("FFODcbaled")
Name AgResidues_Equations_CropResidues.VEERG_6_1_1_2__1__FractionOfCropResidueRemovedBaled_Variation: _xlfn.LAMBDA("VARIATION FROM SOURCE: Added 'baled' to variable subscript")
Name AgResidues_Equations_CropResidues.VEERG_6_1_1_2__1a__FractionOfCropResidueRemoved: _xlfn.LAMBDA(_xlpm.FFODcbaled,_xlpm.FFODcother, _xlpm.FFODcbaled + _xlpm.FFODcother)
Name AgResidues_Equations_CropResidues.VEERG_6_1_1_2__1a__FractionOfCropResidueRemoved_LatexEquation: _xlfn.LAMBDA("FFOD_{c} = FFOD_{c,baled} + FFOD_{c,other}")
Name AgResidues_Equations_CropResidues.VEERG_6_1_1_2__1a__FractionOfCropResidueRemoved_NIRReference: _xlfn.LAMBDA("")
Name AgResidues_Equations_CropResidues.VEERG_6_1_1_2__1a__FractionOfCropResidueRemoved_Source: _xlfn.LAMBDA("")
Name AgResidues_Equations_CropResidues.VEERG_6_1_1_2__1a__FractionOfCropResidueRemoved_Title: _xlfn.LAMBDA("Fraction of crop residue that is removed for crop c")
Name AgResidues_Equations_CropResidues.VEERG_6_1_1_2__1a__FractionOfCropResidueRemoved_Unit: _xlfn.LAMBDA("dimensionless")
Name AgResidues_Equations_CropResidues.VEERG_6_1_1_2__1a__FractionOfCropResidueRemoved_Variable: _xlfn.LAMBDA("FFODc")
Name AgResidues_Equations_CropResidues.VEERG_6_1_1_2__1a__FractionOfCropResidueRemoved_Variation: _xlfn.LAMBDA("VARIATION FROM SOURCE: Added this equation to accommodate user-defined residue removal other than baling.")
Name AgResidues_Equations_Leaching.VEERG_6_3_1_1__1__LeachingAndRunoffEmissionsCropAndPastureResidue: _xlfn.LAMBDA(_xlpm.Mleachcp,_xlpm.EFleach,_xlpm.CgN2O, _xlpm.Mleachcp * _xlpm.EFleach * _xlpm.CgN2O * 10 ^ (-3))
Name AgResidues_Equations_Leaching.VEERG_6_3_1_1__1__LeachingAndRunoffEmissionsCropAndPastureResidue_LatexEquation: _xlfn.LAMBDA("E_{N2O}=\sum_{c}\sum_{p}(M_{leach,cp}\times EF_{leach}\times Cg_{N2O}\times 10^{-3})")
Name AgResidues_Equations_Leaching.VEERG_6_3_1_1__1__LeachingAndRunoffEmissionsCropAndPastureResidue_NIRReference: _xlfn.LAMBDA("")
Name AgResidues_Equations_Leaching.VEERG_6_3_1_1__1__LeachingAndRunoffEmissionsCropAndPastureResidue_Source: _xlfn.LAMBDA("VEERG 2026: 6.3.1.1, Equation (1)")
Name AgResidues_Equations_Leaching.VEERG_6_3_1_1__1__LeachingAndRunoffEmissionsCropAndPastureResidue_Title: _xlfn.LAMBDA("Nitrous oxide leaching and runoff emissions from crop and pasture residues returned to the soil")
Name AgResidues_Equations_Leaching.VEERG_6_3_1_1__1__LeachingAndRunoffEmissionsCropAndPastureResidue_Unit: _xlfn.LAMBDA("t N2O")

Sheet Home
A1: Home
A3: =HYPERLINK("#'Home'!A1", "Home") -> Home
A6: APPENDICES
A7: =HYPERLINK("#'Constants - Common'!A1", "Constants - Common") -> Constants - Common
A8: =HYPERLINK("#'Acknowledgements'!A1", "Acknowledgements") -> Acknowledgements

Sheet Results
A1: #VALUE! | C1: 4.2 Manure management: Pasture Beef: Results
A3: =HYPERLINK("#'Home'!A1", "Home") -> Home
A4: =HYPERLINK("#'Results'!A1", "Results") -> Results | D4: Emissions breakdown
D6: Scope 1 source | E6: GHG emissions method 1 | F6: GHG emissions method 2 | G6: GHG Unit | H6: CO2-e emissions method 1 | I6: CO2-e emissions method 2 | J6: CO2-e unit
A7: INPUTS | D7: 4.2.1.1-2 Manure methane | E7: =VEERG_4_2_1_1__1_TotalAnnualMethaneProductionFromManureManagement_Result_Method1 -> 0.88628531 | F7: =VEERG_4_2_1_1__1_TotalAnnualMethaneProductionFromManureManagement_Result_Method2 -> 0.89029635 | G7: t CH4 | H7: ='4.2.1.1-2 Methane'!$E$249 -> 24.815989 | I7: ='4.2.1.1-2 Methane'!$X$281 -> 24.928298 | J7: t CO2e
A8: =HYPERLINK("#'Input - Site'!A1", "Site") -> Site | D8: 4.2.1.3-4 Soil direct N2O | E8: =VEERG_4_2_1_3__1_DirectNitrousOxideEmissionsOnPasture_Result_Method1 -> 0.19011253 | F8: =VEERG_4_2_1_3__1_DirectNitrousOxideEmissionsOnPasture_Result_Method2 -> 0.18424526 | G8: t N2O | H8: ='4.2.1.3-4 Soil direct N20'!$E$234 -> 50.37982 | I8: ='4.2.1.3-4 Soil direct N20'!$V$272 -> 48.824993 | J8: t CO2e
A9: =HYPERLINK("#'Input - Pasture Beef'!A1", "Pasture Beef") -> Pasture Beef | D9: 4.2.1.5-6 Soil atmospheric deposition | E9: =VEERG_4_2_1_5__1_AtmosphericDepositionEmissionsFromUrineAndDungOnPasture_Result_Method1 -> 0.11777471 | F9: =VEERG_4_2_1_5__1_AtmosphericDepositionEmissionsFromUrineAndDungOnPasture_Result_Method2 -> 0.11413994 | G9: ='4.2.1.5-6 Soil Atmos Dep'!$F$35 -> t N2O | H9: ='4.2.1.5-6 Soil Atmos Dep'!$E$40 -> 31.210298 | I9: ='4.2.1.5-6 Soil Atmos Dep'!$O$40 -> 30.247083 | J9: t CO2e
D10: 4.2.1.7-8 Soil leaching and runoff | E10: =VEERG_4_2_1_7__1_LeachingAndRunoffEmissionsFromUrineAndDungOnPasture_Result_Method1 -> 0.25094854 | F10: =VEERG_4_2_1_7__1_LeachingAndRunoffEmissionsFromUrineAndDungOnPasture_Result_Method2 -> 0.24320374 | G10: ='4.2.1.7-8 Soil leach runoff'!$F$36 -> t N2O | H10: ='4.2.1.7-8 Soil leach runoff'!$E$41 -> 66.501362 | I10: ='4.2.1.7-8 Soil leach runoff'!$N$41 -> 64.44899 | J10: t CO2e
D11: Total | H11: =SUM(H7:H10) -> 172.90747 | I11: =SUM(I7:I10) -> 168.44936 | J11: t CO2e
A12: CALCULATIONS
A13: =HYPERLINK("#'4.2.1.1-2 Methane'!A1", "4.2.1.1-2 Methane") -> 4.2.1.1-2 Methane
A14: =HYPERLINK("#'4.2.1.3-4 Soil direct N20'!A1", "4.2.1.3-4 Soil direct N20") -> 4.2.1.3-4 Soil direct N20
A15: =HYPERLINK("#'4.2.1.5-6 Soil Atmos Dep'!A1", "4.2.1.5-6 Soil Atmos Dep") -> 4.2.1.5-6 Soil Atmos Dep
A16: =HYPERLINK("#'4.2.1.7-8 Soil leach runoff'!A1", "4.2.1.7-8 Soil leach runoff") -> 4.2.1.7-8 Soil leach runoff
A19: APPENDICES
A20: =HYPERLINK("#'Constants - Pasture Beef'!A1", "Constants - Pasture Beef") -> Constants - Pasture Beef
A21: =HYPERLINK("#'Constants - Common'!A1", "Constants - Common") -> Constants - Common
A22: =HYPERLINK("#'Constants - Common Livestock'!A1", "Constants - Common Livestock") -> Constants - Common Livestock
A23: =HYPERLINK("#'Acknowledgements'!A1", "Acknowledgements") -> Acknowledgements
A24: =HYPERLINK("#'Tab template'!A1", "Tab template") -> Tab template

Sheet Input - Site
A1: #VALUE! | C1: Input - Site
A3: =HYPERLINK("#'Home'!A1", "Home") -> Home
A4: =HYPERLINK("#'Results'!A1", "Results") -> Results
D5: Your business
A7: INPUTS | D7: Farm name | E7: Test Farms
A8: =HYPERLINK("#'Input - Site'!A1", "Site") -> Site | D8: Reporting entity name | E8: Test Farms Pty Ltd
A9: =HYPERLINK("#'Input - Pasture Beef'!A1", "Pasture Beef") -> Pasture Beef
D10: 💡An 'Emissions accounting period' is a 12 month period where the business can report on the emissions, and is typically the same as the business' financial accounting period.
A12: CALCULATIONS | D12: Emissions calculation period start date | E12: 45292 | F12: ← DD/MM/YYYY or DD Month YYYY
A13: =HYPERLINK("#'4.2.1.1-2 Methane'!A1", "4.2.1.1-2 Methane") -> 4.2.1.1-2 Methane | D13: Emissions calculation period end date | E13: =DATE(YEAR(X_Cell_Site_StartDate)+1,MONTH(X_Cell_Site_StartDate),DAY(X_Cell_Site_StartDate))-1 -> 45657 | F13: ← Automatically calculated, 12 months after start date
A14: =HYPERLINK("#'4.2.1.3-4 Soil direct N20'!A1", "4.2.1.3-4 Soil direct N20") -> 4.2.1.3-4 Soil direct N20
A15: =HYPERLINK("#'4.2.1.5-6 Soil Atmos Dep'!A1", "4.2.1.5-6 Soil Atmos Dep") -> 4.2.1.5-6 Soil Atmos Dep
A16: =HYPERLINK("#'4.2.1.7-8 Soil leach runoff'!A1", "4.2.1.7-8 Soil leach runoff") -> 4.2.1.7-8 Soil leach runoff | D16: Location and climate
D18: Location information is used to reference some region and climate-specific emission factors
A19: APPENDICES | D19: Tip: Use the web-based GAF Location Helper tool to easily get region and climate information. You will need an internet connection to use the GAF Location Helper.
A20: =HYPERLINK("#'Constants - Pasture Beef'!A1", "Constants - Pasture Beef") -> Constants - Pasture Beef
A21: =HYPERLINK("#'Constants - Common'!A1", "Constants - Common") -> Constants - Common | D21: State | E21: Western Australia | F21: ← Please select
A22: =HYPERLINK("#'Constants - Common Livestock'!A1", "Constants - Common Livestock") -> Constants - Common Livestock | D22: Region (ABS Statistical area level 4) if state is WA | E22: Western Australia - Outback (South) | F22: ← Please select
A23: =HYPERLINK("#'Acknowledgements'!A1", "Acknowledgements") -> Acknowledgements | D23: Leaching zone | E23: NO - Not in leaching zone | F23: ← Please select
A24: =HYPERLINK("#'Tab template'!A1", "Tab template") -> Tab template | D24: Elevation | E24: 307.7 | F24: Meters
D25: Average temperature for reporting period | E25: 18 | F25: Degrees celsius
D26: Total rainfall for reporting period | E26: 601 | F26: Millimetres
D27: Potential evapotranspiration for reporting period | E27: 1326 | F27: Millimetres
D28: Number of frost days for reporting period | E28: 7 | F28: Days
D29: MAP:PET ratio | E29: =X_Cell_Site_TotalRainfall/X_Cell_Site_PotentialEvapotranspiration -> 0.45324284
D30: Rainfall zone | E30: =Common_InputFunctions.Utility_LookupItemFromMinMax(X_Cell_Site_TotalRainfall,Table_SourceData_RainfallZones[Min rainfall],Table_SourceData_RainfallZones[Max rainfall],Table_SourceData_RainfallZones[Rainfall Zone]) -> High rainfall
D31: Climate zone | E31: =Common_InputFunctions.Utility_GetClimateZone(X_Cell_Site_AverageTemperature,X_Cell_Site_TotalRainfall,X_Cell_Site_FrostDays,X_Cell_Site_Elevation,X_Cell_Site_MapPetRatio,Table_SourceData_ClimateZones[Min temp],Table_SourceData_ClimateZones[Max temp],Table_SourceData_ClimateZones[Min rainfall],Table_SourceData_ClimateZones[Max rainfall],Table_SourceData_ClimateZones[Min frost days],Table_SourceData_ClimateZones[Max frost days],Table_SourceData_ClimateZones[Min elevation],Table_SourceData_ClimateZones[Max elevation],Table_SourceData_ClimateZones[Min MAP:PET],Table_SourceData_ClimateZones[Max MAP:PET],Table_SourceData_ClimateZones[Climate zone]) -> Warm temperate dry
D32: Wet or dry climate zone | E32: =Common_InputFunctions.Utility_LookupValueInTable(X_Cell_Site_ClimateZone,Table_SourceData_WetDryZones[Climate zone],Table_SourceData_WetDryZones[Wet or Dry Zone]) -> Dry climate zone
D33: Temperature zone | E33: =Common_InputFunctions.Utility_LookupItemFromMinMax(X_Cell_Site_AverageTemperature,Table_SourceData_TemperatureZones[Min MAT],Table_SourceData_TemperatureZones[Max MAT],Table_SourceData_TemperatureZones[Temperature Zone]) -> Temperate

Sheet Input - Pasture Beef
A1: #VALUE! | C1: Input -Pasture Beef
A3: =HYPERLINK("#'Home'!A1", "Home") -> Home
A4: =HYPERLINK("#'Results'!A1", "Results") -> Results
D5: Herd movement
A7: INPUTS | D7: State | E7: =X_Cell_Site_State -> Western Australia
A8: =HYPERLINK("#'Input - Site'!A1", "Site") -> Site | D8: Livestock production region | E8: South West | F8: ← Please select
A9: =HYPERLINK("#'Input - Pasture Beef'!A1", "Pasture Beef") -> Pasture Beef | D9: Cattle breed | E9: Hereford or Shorthorn breeds | F9: ← Please select
A12: CALCULATIONS
A13: =HYPERLINK("#'4.2.1.1-2 Methane'!A1", "4.2.1.1-2 Methane") -> 4.2.1.1-2 Methane | D13: NOTE: VEERG states that under method 2, time periods may be seasons, months or a custom time period. In this example, method 2 time periods are months.
A14: =HYPERLINK("#'4.2.1.3-4 Soil direct N20'!A1", "4.2.1.3-4 Soil direct N20") -> 4.2.1.3-4 Soil direct N20
A15: =HYPERLINK("#'4.2.1.5-6 Soil Atmos Dep'!A1", "4.2.1.5-6 Soil Atmos Dep") -> 4.2.1.5-6 Soil Atmos Dep | D15: Duration on farm
A16: =HYPERLINK("#'4.2.1.7-8 Soil leach runoff'!A1", "4.2.1.7-8 Soil leach runoff") -> 4.2.1.7-8 Soil leach runoff | D16: Method 1 default values (do not edit) | E16: Bulls < 1 year | F16: Bulls > 1 year | G16: Cows < 1 year | H16: Cows 1-2 years | I16: Cows 2-3 years | J16: Cows > 3 years | K16: Steers < 1 year | L16: Steers 1-2 years | M16: Steers 2-3 years | N16: Steers >3 years
D17: Spring | E17: =91.25 -> 91.25 | F17: =91.25 -> 91.25 | G17: =91.25 -> 91.25 | H17: =91.25 -> 91.25 | I17: =91.25 -> 91.25 | J17: =91.25 -> 91.25 | K17: =91.25 -> 91.25 | L17: =91.25 -> 91.25 | ... N17: =91.25 -> 91.25 | O17: Days
D18: Summer | E18: =91.25 -> 91.25 | F18: =91.25 -> 91.25 | G18: =91.25 -> 91.25 | H18: =91.25 -> 91.25 | I18: =91.25 -> 91.25 | J18: =91.25 -> 91.25 | K18: =91.25 -> 91.25 | L18: =91.25 -> 91.25 | ... N18: =91.25 -> 91.25 | O18: Days
A19: APPENDICES | D19: Autumn | E19: =91.25 -> 91.25 | F19: =91.25 -> 91.25 | G19: =91.25 -> 91.25 | H19: =91.25 -> 91.25 | I19: =91.25 -> 91.25 | J19: =91.25 -> 91.25 | K19: =91.25 -> 91.25 | L19: =91.25 -> 91.25 | ... N19: =91.25 -> 91.25 | O19: Days
A20: =HYPERLINK("#'Constants - Pasture Beef'!A1", "Constants - Pasture Beef") -> Constants - Pasture Beef | D20: Winter | E20: =91.25 -> 91.25 | F20: =91.25 -> 91.25 | G20: =91.25 -> 91.25 | H20: =91.25 -> 91.25 | I20: =91.25 -> 91.25 | J20: =91.25 -> 91.25 | K20: =91.25 -> 91.25 | L20: =91.25 -> 91.25 | ... N20: =91.25 -> 91.25 | O20: Days
A21: =HYPERLINK("#'Constants - Common'!A1", "Constants - Common") -> Constants - Common
A22: =HYPERLINK("#'Constants - Common Livestock'!A1", "Constants - Common Livestock") -> Constants - Common Livestock | D22: Method 2 custom values (edit if known) | E22: Bulls < 1 year | F22: Bulls > 1 year | G22: Cows < 1 year | H22: Cows 1-2 years | I22: Cows 2-3 years | J22: Cows > 3 years | K22: Steers < 1 year | L22: Steers 1-2 years | M22: Steers 2-3 years | N22: Steers >3 years
A23: =HYPERLINK("#'Acknowledgements'!A1", "Acknowledgements") -> Acknowledgements | D23: =TEXT(X_Cell_Site_StartDate, "mmmm yyyy") -> January 2024 | E23: =DAY(EOMONTH($D23,0)) -> 31 | F23: =DAY(EOMONTH($D23,0)) -> 31 | G23: =DAY(EOMONTH($D23,0)) -> 31 | H23: =DAY(EOMONTH($D23,0)) -> 31 | I23: =DAY(EOMONTH($D23,0)) -> 31 | J23: =DAY(EOMONTH($D23,0)) -> 31 | K23: =DAY(EOMONTH($D23,0)) -> 31 | L23: =DAY(EOMONTH($D23,0)) -> 31 | ... N23: =DAY(EOMONTH($D23,0)) -> 31 | O23: Days
A24: =HYPERLINK("#'Tab template'!A1", "Tab template") -> Tab template | D24: =TEXT(EDATE(X_Cell_Site_StartDate,1), "mmmm yyyy") -> February 2024 | E24: =DAY(EOMONTH($D24,0)) -> 29 | F24: =DAY(EOMONTH($D24,0)) -> 29 | G24: =DAY(EOMONTH($D24,0)) -> 29 | H24: =DAY(EOMONTH($D24,0)) -> 29 | I24: =DAY(EOMONTH($D24,0)) -> 29 | J24: =DAY(EOMONTH($D24,0)) -> 29 | K24: =DAY(EOMONTH($D24,0)) -> 29 | L24: =DAY(EOMONTH($D24,0)) -> 29 | ... N24: =DAY(EOMONTH($D24,0)) -> 29 | O24: Days
D25: =TEXT(EDATE(X_Cell_Site_StartDate,2), "mmmm yyyy") -> March 2024 | E25: =DAY(EOMONTH($D25,0)) -> 31 | F25: =DAY(EOMONTH($D25,0)) -> 31 | G25: =DAY(EOMONTH($D25,0)) -> 31 | H25: =DAY(EOMONTH($D25,0)) -> 31 | I25: =DAY(EOMONTH($D25,0)) -> 31 | J25: =DAY(EOMONTH($D25,0)) -> 31 | K25: =DAY(EOMONTH($D25,0)) -> 31 | L25: =DAY(EOMONTH($D25,0)) -> 31 | ... N25: =DAY(EOMONTH($D25,0)) -> 31 | O25: Days
D26: =TEXT(EDATE(X_Cell_Site_StartDate,3), "mmmm yyyy") -> April 2024 | E26: =DAY(EOMONTH($D26,0)) -> 30 | F26: =DAY(EOMONTH($D26,0)) -> 30 | G26: =DAY(EOMONTH($D26,0)) -> 30 | H26: =DAY(EOMONTH($D26,0)) -> 30 | I26: =DAY(EOMONTH($D26,0)) -> 30 | J26: =DAY(EOMONTH($D26,0)) -> 30 | K26: =DAY(EOMONTH($D26,0)) -> 30 | L26: =DAY(EOMONTH($D26,0)) -> 30 | ... N26: =DAY(EOMONTH($D26,0)) -> 30 | O26: Days
D27: =TEXT(EDATE(X_Cell_Site_StartDate,4), "mmmm yyyy") -> May 2024 | E27: =DAY(EOMONTH($D27,0)) -> 31 | F27: =DAY(EOMONTH($D27,0)) -> 31 | G27: =DAY(EOMONTH($D27,0)) -> 31 | H27: =DAY(EOMONTH($D27,0)) -> 31 | I27: =DAY(EOMONTH($D27,0)) -> 31 | J27: =DAY(EOMONTH($D27,0)) -> 31 | K27: =DAY(EOMONTH($D27,0)) -> 31 | L27: =DAY(EOMONTH($D27,0)) -> 31 | ... N27: =DAY(EOMONTH($D27,0)) -> 31 | O27: Days
D28: =TEXT(EDATE(X_Cell_Site_StartDate,5), "mmmm yyyy") -> June 2024 | E28: =DAY(EOMONTH($D28,0)) -> 30 | F28: =DAY(EOMONTH($D28,0)) -> 30 | G28: =DAY(EOMONTH($D28,0)) -> 30 | H28: =DAY(EOMONTH($D28,0)) -> 30 | I28: =DAY(EOMONTH($D28,0)) -> 30 | J28: =DAY(EOMONTH($D28,0)) -> 30 | K28: =DAY(EOMONTH($D28,0)) -> 30 | L28: =DAY(EOMONTH($D28,0)) -> 30 | ... N28: =DAY(EOMONTH($D28,0)) -> 30 | O28: Days
D29: =TEXT(EDATE(X_Cell_Site_StartDate,6), "mmmm yyyy") -> July 2024 | E29: =DAY(EOMONTH($D29,0)) -> 31 | F29: =DAY(EOMONTH($D29,0)) -> 31 | G29: =DAY(EOMONTH($D29,0)) -> 31 | H29: =DAY(EOMONTH($D29,0)) -> 31 | I29: =DAY(EOMONTH($D29,0)) -> 31 | J29: =DAY(EOMONTH($D29,0)) -> 31 | K29: =DAY(EOMONTH($D29,0)) -> 31 | L29: =DAY(EOMONTH($D29,0)) -> 31 | ... N29: =DAY(EOMONTH($D29,0)) -> 31 | O29: Days
D30: =TEXT(EDATE(X_Cell_Site_StartDate,7), "mmmm yyyy") -> August 2024 | E30: =DAY(EOMONTH($D30,0)) -> 31 | F30: =DAY(EOMONTH($D30,0)) -> 31 | G30: =DAY(EOMONTH($D30,0)) -> 31 | H30: =DAY(EOMONTH($D30,0)) -> 31 | I30: =DAY(EOMONTH($D30,0)) -> 31 | J30: =DAY(EOMONTH($D30,0)) -> 31 | K30: =DAY(EOMONTH($D30,0)) -> 31 | L30: =DAY(EOMONTH($D30,0)) -> 31 | ... N30: =DAY(EOMONTH($D30,0)) -> 31 | O30: Days
D31: =TEXT(EDATE(X_Cell_Site_StartDate,8), "mmmm yyyy") -> September 2024 | E31: =DAY(EOMONTH($D31,0)) -> 30 | F31: =DAY(EOMONTH($D31,0)) -> 30 | G31: =DAY(EOMONTH($D31,0)) -> 30 | H31: =DAY(EOMONTH($D31,0)) -> 30 | I31: =DAY(EOMONTH($D31,0)) -> 30 | J31: =DAY(EOMONTH($D31,0)) -> 30 | K31: =DAY(EOMONTH($D31,0)) -> 30 | L31: =DAY(EOMONTH($D31,0)) -> 30 | ... N31: =DAY(EOMONTH($D31,0)) -> 30 | O31: Days
D32: =TEXT(EDATE(X_Cell_Site_StartDate,9), "mmmm yyyy") -> October 2024 | E32: =DAY(EOMONTH($D32,0)) -> 31 | F32: =DAY(EOMONTH($D32,0)) -> 31 | G32: =DAY(EOMONTH($D32,0)) -> 31 | H32: =DAY(EOMONTH($D32,0)) -> 31 | I32: =DAY(EOMONTH($D32,0)) -> 31 | J32: =DAY(EOMONTH($D32,0)) -> 31 | K32: =DAY(EOMONTH($D32,0)) -> 31 | L32: =DAY(EOMONTH($D32,0)) -> 31 | ... N32: =DAY(EOMONTH($D32,0)) -> 31 | O32: Days
D33: =TEXT(EDATE(X_Cell_Site_StartDate,10), "mmmm yyyy") -> November 2024 | E33: =DAY(EOMONTH($D33,0)) -> 30 | F33: =DAY(EOMONTH($D33,0)) -> 30 | G33: =DAY(EOMONTH($D33,0)) -> 30 | H33: =DAY(EOMONTH($D33,0)) -> 30 | I33: =DAY(EOMONTH($D33,0)) -> 30 | J33: =DAY(EOMONTH($D33,0)) -> 30 | K33: =DAY(EOMONTH($D33,0)) -> 30 | L33: =DAY(EOMONTH($D33,0)) -> 30 | ... N33: =DAY(EOMONTH($D33,0)) -> 30 | O33: Days
D34: =TEXT(EDATE(X_Cell_Site_StartDate,11), "mmmm yyyy") -> December 2024 | E34: =DAY(EOMONTH($D34,0)) -> 31 | F34: =DAY(EOMONTH($D34,0)) -> 31 | G34: =DAY(EOMONTH($D34,0)) -> 31 | H34: =DAY(EOMONTH($D34,0)) -> 31 | I34: =DAY(EOMONTH($D34,0)) -> 31 | J34: =DAY(EOMONTH($D34,0)) -> 31 | K34: =DAY(EOMONTH($D34,0)) -> 31 | L34: =DAY(EOMONTH($D34,0)) -> 31 | ... N34: =DAY(EOMONTH($D34,0)) -> 31 | O34: Days
D37: Head
D38: Method 1 values | E38: Bulls < 1 year | F38: Bulls > 1 year | G38: Cows < 1 year | H38: Cows 1-2 years | I38: Cows 2-3 years | J38: Cows > 3 years | K38: Steers < 1 year | L38: Steers 1-2 years | M38: Steers 2-3 years | N38: Steers >3 years
D39: Spring | E39: 100 | F39: 100 | G39: 100 | H39: 100 | I39: 100 | J39: 100 | K39: 100 | L39: 100 | M39: 100 | N39: 100 | O39: Head
D40: Summer | E40: 100 | F40: 100 | G40: 100 | H40: 100 | I40: 100 | J40: 100 | K40: 100 | L40: 100 | M40: 100 | N40: 100 | O40: Head
D41: Autumn | E41: 100 | F41: 100 | G41: 100 | H41: 100 | I41: 100 | J41: 100 | K41: 100 | L41: 100 | M41: 100 | N41: 100 | O41: Head
D42: Winter | E42: 100 | F42: 100 | G42: 100 | H42: 100 | I42: 100 | J42: 100 | K42: 100 | L42: 100 | M42: 100 | N42: 100 | O42: Head
D44: Method 2 values | E44: Bulls < 1 year | F44: Bulls > 1 year | G44: Cows < 1 year | H44: Cows 1-2 years | I44: Cows 2-3 years | J44: Cows > 3 years | K44: Steers < 1 year | L44: Steers 1-2 years | M44: Steers 2-3 years | N44: Steers >3 years
D45: =TEXT(X_Cell_Site_StartDate, "mmmm yyyy") -> January 2024 | E45: 100 | F45: 100 | G45: 100 | H45: 100 | I45: 100 | J45: 100 | K45: 100 | L45: 100 | M45: 100 | N45: 100 | O45: Head
D46: =TEXT(EDATE(X_Cell_Site_StartDate,1), "mmmm yyyy") -> February 2024 | E46: 100 | F46: 100 | G46: 100 | H46: 100 | I46: 100 | J46: 100 | K46: 100 | L46: 100 | M46: 100 | N46: 100 | O46: Head
D47: =TEXT(EDATE(X_Cell_Site_StartDate,2), "mmmm yyyy") -> March 2024 | E47: 100 | F47: 100 | G47: 100 | H47: 100 | I47: 100 | J47: 100 | K47: 100 | L47: 100 | M47: 100 | N47: 100 | O47: Head
...

Sheet 4.2.1.1-2 Methane
A1: #VALUE! | C1: 4.2.1.1-2 Manure Methane
A3: =HYPERLINK("#'Home'!A1", "Home") -> Home | D3: Method 1 | W3: Method 2
A4: =HYPERLINK("#'Results'!A1", "Results") -> Results
D5: {=EntericMethane_PastureBeef_Equations.VEERG_3_2_1_1__4_AdditionalIntakeForMilkProduction_Title()} -> Additional intake for milk production in the season of calving and the season after calving
D6: {=EntericMethane_PastureBeef_Equations.VEERG_3_2_1_1__4_AdditionalIntakeForMilkProduction_Source()} -> VEERG 2026: 3.2.1.1, Equation (4)
A7: INPUTS | D7: Function name | E7: EntericMethane_PastureBeef_Equations.VEERG_3_2_1_1__4_AdditionalIntakeForMilkProduction
A8: =HYPERLINK("#'Input - Site'!A1", "Site") -> Site
A9: =HYPERLINK("#'Input - Pasture Beef'!A1", "Pasture Beef") -> Pasture Beef
D10: Variable | E10: {=EntericMethane_PastureBeef_Equations.VEERG_3_2_1_1__4_AdditionalIntakeForMilkProduction_Variable()} -> MA_jk45
D11: Unit | E11: {=EntericMethane_PastureBeef_Equations.VEERG_3_2_1_1__4_AdditionalIntakeForMilkProduction_Unit()} -> fraction
A12: CALCULATIONS
A13: =HYPERLINK("#'4.2.1.1-2 Methane'!A1", "4.2.1.1-2 Methane") -> 4.2.1.1-2 Methane | D13: {=_xlfn.CHOOSECOLS(EntericMethane_PastureBeef_Equations.VEERG_3_2_1_1__4_AdditionalIntakeForMilkProduction_ArgumentsVariation(), 1, 2)} -> LC_jk45 | E13: proportion of cows greater than 1 year in calf in the season of calving expressed as a fraction | H13: {=_xlfn.CHOOSECOLS(EntericMethane_PastureBeef_Equations.VEERG_3_2_1_1__4_AdditionalIntakeForMilkProduction_ArgumentsVariation(), 3,4)} -> fraction | I13: Input | J13: {=HYPERLINK(Common_InputFunctions.Utility_SourceHyperlink($D$19), $D$19)} -> M1_Table_LC_j_k-4-5
A14: =HYPERLINK("#'4.2.1.3-4 Soil direct N20'!A1", "4.2.1.3-4 Soil direct N20") -> 4.2.1.3-4 Soil direct N20 | D14: FA_jk45calv | E14: feed adjustment value for lactating cows in the season of calving expressed as a fraction | H14: fraction | I14: Constant | J14: {=_xlfn.XLOOKUP(1, (Table_SourceData_PastureBeef_FeedIntakeAdjustment_Variation[Breed]=$J$16)*(Table_SourceData_PastureBeef_FeedIntakeAdjustment_Variation[Season]=+"Calving season"),Table_SourceData_PastureBeef_FeedIntakeAdjustment_Variation[Feed adjustment])} -> 1.3
A15: =HYPERLINK("#'4.2.1.5-6 Soil Atmos Dep'!A1", "4.2.1.5-6 Soil Atmos Dep") -> 4.2.1.5-6 Soil Atmos Dep | D15: FA_jk45after | E15: feed adjustment value for lactating cows in the season immediately after calving expressed as a fraction | H15: fraction | I15: Constant | J15: {=_xlfn.XLOOKUP(1, (Table_SourceData_PastureBeef_FeedIntakeAdjustment_Variation[Breed]=$J$16)*(Table_SourceData_PastureBeef_FeedIntakeAdjustment_Variation[Season]=+"Season after calving"),Table_SourceData_PastureBeef_FeedIntakeAdjustment_Variation[Feed adjustment])} -> 1.1
A16: =HYPERLINK("#'4.2.1.7-8 Soil leach runoff'!A1", "4.2.1.7-8 Soil leach runoff") -> 4.2.1.7-8 Soil leach runoff | D16: b | E16: breed of cattle | I16: Input | J16: =X_Cell_PastureBeef_Breed -> Hereford or Shorthorn breeds
A19: APPENDICES | D19: M1_Table_LC_j_k-4-5 | W19: M2_Table_LC_j_k-4-5
A20: =HYPERLINK("#'Constants - Pasture Beef'!A1", "Constants - Pasture Beef") -> Constants - Pasture Beef | D20: Proportion of cows in calf during season (Method 1) | W20: Proportion of cows in calf during season (Method 2)
A21: =HYPERLINK("#'Constants - Common'!A1", "Constants - Common") -> Constants - Common | D21: Season | E21: Calving season | F21: Cows 1-2 years | G21: Cows 2-3 years | H21: Cows > 3 years | W21: Month | X21: Cows 1-2 years | Y21: Cows 2-3 years | Z21: Cows > 3 years
A22: =HYPERLINK("#'Constants - Common Livestock'!A1", "Constants - Common Livestock") -> Constants - Common Livestock | D22: Spring | E22: ='Input - Pasture Beef'!$E169 -> Yes | F22: ='Input - Pasture Beef'!$F169 -> 0.1 | G22: ='Input - Pasture Beef'!$G169 -> 0.4 | H22: ='Input - Pasture Beef'!$H169 -> 0.4 | I22: Fraction | W22: =TEXT(EDATE('Input - Pasture Beef'!$D$182,0), "mmmm") & ", " & TEXT(EDATE('Input - Pasture Beef'!$D$183,0), "mmmm") & ", " & TEXT(EDATE('Input - Pasture Beef'!$D$184,0), "mmmm") -> August, September, October | X22: ='Input - Pasture Beef'!$E$185 -> 0.75 | Y22: ='Input - Pasture Beef'!$F$185 -> 0.75 | Z22: ='Input - Pasture Beef'!$G$185 -> 0.75 | AA22: Fraction
A23: =HYPERLINK("#'Acknowledgements'!A1", "Acknowledgements") -> Acknowledgements | D23: Summer | E23: ='Input - Pasture Beef'!$E170 -> Yes | F23: ='Input - Pasture Beef'!$F170 -> 0.1 | G23: ='Input - Pasture Beef'!$G170 -> 0 | H23: ='Input - Pasture Beef'!$H170 -> 0 | W23: =TEXT(EDATE('Input - Pasture Beef'!$D$184,1), "mmmm") & ", " & TEXT(EDATE('Input - Pasture Beef'!$D$184,2), "mmmm") & ", " & TEXT(EDATE('Input - Pasture Beef'!$D$184,3), "mmmm") -> November, December, January
A24: =HYPERLINK("#'Tab template'!A1", "Tab template") -> Tab template | D24: Autumn | E24: ='Input - Pasture Beef'!$E171 -> No | F24: ='Input - Pasture Beef'!$F171 -> 0 | G24: ='Input - Pasture Beef'!$G171 -> 0 | H24: ='Input - Pasture Beef'!$H171 -> 0
D25: Winter | E25: ='Input - Pasture Beef'!$E168 -> Yes | F25: ='Input - Pasture Beef'!$F$168 -> 0.7 | G25: ='Input - Pasture Beef'!$G$168 -> 0.5 | H25: ='Input - Pasture Beef'!$H$168 -> 0.5 | W25: M2_Table_MA_j_k-4-5
W26: Additional intake for milk production in calving and post-calving seasons (Method 2)
D27: M1_Table_MA_j_k-4-5 | W27: Month | X27: Calving season | Y27: FAjk=4,5 | Z27: Bulls < 1 year | AA27: Bulls > 1 year | AB27: Cows < 1 year | AC27: Cows 1-2 years | AD27: Cows 2-3 years | AE27: Cows > 3 years | AF27: Steers < 1 year | AG27: Steers 1-2 years | AH27: Steers 2-3 years | AI27: Steers >3 years
D28: Additional intake for milk production in calving and post-calving seasons (Method 1) | W28: =TEXT(X_Cell_Site_StartDate,"mmmm") -> January | X28: {=IFERROR(_xlfn.IFS(SUMPRODUCT(ISNUMBER(SEARCH(TRIM(_xlfn.TEXTSPLIT($W$22,",")),W28))*1)>0,"Calving season",SUMPRODUCT(ISNUMBER(SEARCH(TRIM(_xlfn.TEXTSPLIT($W$23,",")),W28))*1)>0,"Season after calving"), "")} -> Season after calving | Y28: {=_xlfn.IFS(X28="Calving season", $J$14, X28="Season after calving", $J$15, X28="", "")} -> 1.1 | Z28: 1 | AA28: 1 | AB28: 1 | AC28: {=IFERROR(EntericMethane_PastureBeef_Equations.VEERG_3_2_1_1__4_AdditionalIntakeForMilkProduction(X$22,$Y28), 1)} -> 1.075 | AD28: {=IFERROR(EntericMethane_PastureBeef_Equations.VEERG_3_2_1_1__4_AdditionalIntakeForMilkProduction(Y$22,$Y28), 1)} -> 1.075 | AE28: {=IFERROR(EntericMethane_PastureBeef_Equations.VEERG_3_2_1_1__4_AdditionalIntakeForMilkProduction(Z$22,$Y28), 1)} -> 1.075 | AF28: 1 | AG28: 1 | AH28: 1 | AI28: 1 | AJ28: =$E$11 -> fraction
D29: Season | E29: Calving season | F29: Season after calving | G29: FAjk=4,5 | H29: FAjk=4,5 | I29: Bulls < 1 year | J29: Bulls > 1 year | K29: Cows < 1 year | L29: Cows 1-2 years | M29: Cows 2-3 years | N29: Cows > 3 years | O29: Steers < 1 year | P29: Steers 1-2 years | Q29: Steers 2-3 years | R29: Steers >3 years | W29: =TEXT(EDATE(X_Cell_Site_StartDate,1), "mmmm") -> February | X29: {=IFERROR(_xlfn.IFS(SUMPRODUCT(ISNUMBER(SEARCH(TRIM(_xlfn.TEXTSPLIT($W$22,",")),W29))*1)>0,"Calving season",SUMPRODUCT(ISNUMBER(SEARCH(TRIM(_xlfn.TEXTSPLIT($W$23,",")),W29))*1)>0,"Season after calving"), "")} | Y29: {=_xlfn.IFS(X29="Calving season", $J$14, X29="Season after calving", $J$15, X29="", "")} | Z29: 1 | AA29: 1 | AB29: 1 | AC29: {=IFERROR(EntericMethane_PastureBeef_Equations.VEERG_3_2_1_1__4_AdditionalIntakeForMilkProduction(X$22,$Y29), 1)} -> 1 | AD29: {=IFERROR(EntericMethane_PastureBeef_Equations.VEERG_3_2_1_1__4_AdditionalIntakeForMilkProduction(Y$22,$Y29), 1)} -> 1 | AE29: {=IFERROR(EntericMethane_PastureBeef_Equations.VEERG_3_2_1_1__4_AdditionalIntakeForMilkProduction(Z$22,$Y29), 1)} -> 1 | AF29: 1 | AG29: 1 | AH29: 1 | AI29: 1 | AJ29: =$E$11 -> fraction
D30: Spring | E30: =IF('Input - Pasture Beef'!E169="Yes", "Calving season", "") -> Calving season | F30: =IF('Input - Pasture Beef'!E168="Yes", "Season after calving","") -> Season after calving | G30: =IF(E30="Calving season", $J$14, 1) -> 1.3 | H30: =IF(F30="Season after calving", $J$15, 1) -> 1.1 | I30: 1 | J30: 1 | K30: 1 | L30: {=EntericMethane_PastureBeef_Equations.VEERG_3_2_1_1__4_AdditionalIntakeForMilkProductionVariation(F22,F25,$G30,$H30)} -> 1.1 | M30: {=EntericMethane_PastureBeef_Equations.VEERG_3_2_1_1__4_AdditionalIntakeForMilkProductionVariation(G22,G25,$G30,$H30)} -> 1.17 | N30: {=EntericMethane_PastureBeef_Equations.VEERG_3_2_1_1__4_AdditionalIntakeForMilkProductionVariation(H22,H25,$G30,$H30)} -> 1.17 | O30: 1 | P30: 1 | Q30: 1 | R30: 1 | S30: =$E$11 -> fraction | W30: =TEXT(EDATE(X_Cell_Site_StartDate,2), "mmmm") -> March | X30: {=IFERROR(_xlfn.IFS(SUMPRODUCT(ISNUMBER(SEARCH(TRIM(_xlfn.TEXTSPLIT($W$22,",")),W30))*1)>0,"Calving season",SUMPRODUCT(ISNUMBER(SEARCH(TRIM(_xlfn.TEXTSPLIT($W$23,",")),W30))*1)>0,"Season after calving"), "")} | Y30: {=_xlfn.IFS(X30="Calving season", $J$14, X30="Season after calving", $J$15, X30="", "")} | Z30: 1 | AA30: 1 | AB30: 1 | AC30: {=IFERROR(EntericMethane_PastureBeef_Equations.VEERG_3_2_1_1__4_AdditionalIntakeForMilkProduction(X$22,$Y30), 1)} -> 1 | AD30: {=IFERROR(EntericMethane_PastureBeef_Equations.VEERG_3_2_1_1__4_AdditionalIntakeForMilkProduction(Y$22,$Y30), 1)} -> 1 | AE30: {=IFERROR(EntericMethane_PastureBeef_Equations.VEERG_3_2_1_1__4_AdditionalIntakeForMilkProduction(Z$22,$Y30), 1)} -> 1 | AF30: 1 | AG30: 1 | AH30: 1 | AI30: 1 | AJ30: =$E$11 -> fraction
D31: Summer | E31: =IF('Input - Pasture Beef'!E170="Yes", "Calving season", "") -> Calving season | F31: =IF('Input - Pasture Beef'!E169="Yes", "Season after calving","") -> Season after calving | G31: =IF(E31="Calving season", $J$14, 1) -> 1.3 | H31: =IF(F31="Season after calving", $J$15, 1) -> 1.1 | I31: 1 | J31: 1 | K31: 1 | L31: {=EntericMethane_PastureBeef_Equations.VEERG_3_2_1_1__4_AdditionalIntakeForMilkProductionVariation(F23,F22,$G31,$H31)} -> 1.04 | M31: {=EntericMethane_PastureBeef_Equations.VEERG_3_2_1_1__4_AdditionalIntakeForMilkProductionVariation(G23,G22,$G31,$H31)} -> 1.04 | N31: {=EntericMethane_PastureBeef_Equations.VEERG_3_2_1_1__4_AdditionalIntakeForMilkProductionVariation(H23,H22,$G31,$H31)} -> 1.04 | O31: 1 | P31: 1 | Q31: 1 | R31: 1 | S31: =$E$11 -> fraction | W31: =TEXT(EDATE(X_Cell_Site_StartDate,3), "mmmm") -> April | X31: {=IFERROR(_xlfn.IFS(SUMPRODUCT(ISNUMBER(SEARCH(TRIM(_xlfn.TEXTSPLIT($W$22,",")),W31))*1)>0,"Calving season",SUMPRODUCT(ISNUMBER(SEARCH(TRIM(_xlfn.TEXTSPLIT($W$23,",")),W31))*1)>0,"Season after calving"), "")} | Y31: {=_xlfn.IFS(X31="Calving season", $J$14, X31="Season after calving", $J$15, X31="", "")} | Z31: 1 | AA31: 1 | AB31: 1 | AC31: {=IFERROR(EntericMethane_PastureBeef_Equations.VEERG_3_2_1_1__4_AdditionalIntakeForMilkProduction(X$22,$Y31), 1)} -> 1 | AD31: {=IFERROR(EntericMethane_PastureBeef_Equations.VEERG_3_2_1_1__4_AdditionalIntakeForMilkProduction(Y$22,$Y31), 1)} -> 1 | AE31: {=IFERROR(EntericMethane_PastureBeef_Equations.VEERG_3_2_1_1__4_AdditionalIntakeForMilkProduction(Z$22,$Y31), 1)} -> 1 | AF31: 1 | AG31: 1 | AH31: 1 | AI31: 1 | AJ31: =$E$11 -> fraction
D32: Autumn | E32: =IF('Input - Pasture Beef'!E171="Yes", "Calving season", "") | F32: =IF('Input - Pasture Beef'!E170="Yes", "Season after calving","") -> Season after calving | G32: =IF(E32="Calving season", $J$14, 1) -> 1 | H32: =IF(F32="Season after calving", $J$15, 1) -> 1.1 | I32: 1 | J32: 1 | K32: 1 | L32: {=EntericMethane_PastureBeef_Equations.VEERG_3_2_1_1__4_AdditionalIntakeForMilkProductionVariation(F24,F23,$G32,$H32)} -> 1.01 | M32: {=EntericMethane_PastureBeef_Equations.VEERG_3_2_1_1__4_AdditionalIntakeForMilkProductionVariation(G24,G23,$G32,$H32)} -> 1 | N32: {=EntericMethane_PastureBeef_Equations.VEERG_3_2_1_1__4_AdditionalIntakeForMilkProductionVariation(H24,H23,$G32,$H32)} -> 1 | O32: 1 | P32: 1 | Q32: 1 | R32: 1 | S32: =$E$11 -> fraction | W32: =TEXT(EDATE(X_Cell_Site_StartDate,4), "mmmm") -> May | X32: {=IFERROR(_xlfn.IFS(SUMPRODUCT(ISNUMBER(SEARCH(TRIM(_xlfn.TEXTSPLIT($W$22,",")),W32))*1)>0,"Calving season",SUMPRODUCT(ISNUMBER(SEARCH(TRIM(_xlfn.TEXTSPLIT($W$23,",")),W32))*1)>0,"Season after calving"), "")} | Y32: {=_xlfn.IFS(X32="Calving season", $J$14, X32="Season after calving", $J$15, X32="", "")} | Z32: 1 | AA32: 1 | AB32: 1 | AC32: {=IFERROR(EntericMethane_PastureBeef_Equations.VEERG_3_2_1_1__4_AdditionalIntakeForMilkProduction(X$22,$Y32), 1)} -> 1 | AD32: {=IFERROR(EntericMethane_PastureBeef_Equations.VEERG_3_2_1_1__4_AdditionalIntakeForMilkProduction(Y$22,$Y32), 1)} -> 1 | AE32: {=IFERROR(EntericMethane_PastureBeef_Equations.VEERG_3_2_1_1__4_AdditionalIntakeForMilkProduction(Z$22,$Y32), 1)} -> 1 | AF32: 1 | AG32: 1 | AH32: 1 | AI32: 1 | AJ32: =$E$11 -> fraction
D33: Winter | E33: =IF('Input - Pasture Beef'!E168="Yes", "Calving season", "") -> Calving season | F33: =IF('Input - Pasture Beef'!E171="Yes", "Season after calving","") | G33: =IF(E33="Calving season", $J$14, 1) -> 1.3 | H33: =IF(F33="Season after calving", $J$15, 1) -> 1 | I33: 1 | J33: 1 | K33: 1 | L33: {=EntericMethane_PastureBeef_Equations.VEERG_3_2_1_1__4_AdditionalIntakeForMilkProductionVariation(F25,F24,$G33,$H33)} -> 1.21 | M33: {=EntericMethane_PastureBeef_Equations.VEERG_3_2_1_1__4_AdditionalIntakeForMilkProductionVariation(G25,G24,$G33,$H33)} -> 1.15 | N33: {=EntericMethane_PastureBeef_Equations.VEERG_3_2_1_1__4_AdditionalIntakeForMilkProductionVariation(H25,H24,$G33,$H33)} -> 1.15 | O33: 1 | P33: 1 | Q33: 1 | R33: 1 | S33: =$E$11 -> fraction | W33: =TEXT(EDATE(X_Cell_Site_StartDate,5), "mmmm") -> June | X33: {=IFERROR(_xlfn.IFS(SUMPRODUCT(ISNUMBER(SEARCH(TRIM(_xlfn.TEXTSPLIT($W$22,",")),W33))*1)>0,"Calving season",SUMPRODUCT(ISNUMBER(SEARCH(TRIM(_xlfn.TEXTSPLIT($W$23,",")),W33))*1)>0,"Season after calving"), "")} | Y33: {=_xlfn.IFS(X33="Calving season", $J$14, X33="Season after calving", $J$15, X33="", "")} | Z33: 1 | AA33: 1 | AB33: 1 | AC33: {=IFERROR(EntericMethane_PastureBeef_Equations.VEERG_3_2_1_1__4_AdditionalIntakeForMilkProduction(X$22,$Y33), 1)} -> 1 | AD33: {=IFERROR(EntericMethane_PastureBeef_Equations.VEERG_3_2_1_1__4_AdditionalIntakeForMilkProduction(Y$22,$Y33), 1)} -> 1 | AE33: {=IFERROR(EntericMethane_PastureBeef_Equations.VEERG_3_2_1_1__4_AdditionalIntakeForMilkProduction(Z$22,$Y33), 1)} -> 1 | AF33: 1 | AG33: 1 | AH33: 1 | AI33: 1 | AJ33: =$E$11 -> fraction
W34: =TEXT(EDATE(X_Cell_Site_StartDate,6), "mmmm") -> July | X34: {=IFERROR(_xlfn.IFS(SUMPRODUCT(ISNUMBER(SEARCH(TRIM(_xlfn.TEXTSPLIT($W$22,",")),W34))*1)>0,"Calving season",SUMPRODUCT(ISNUMBER(SEARCH(TRIM(_xlfn.TEXTSPLIT($W$23,",")),W34))*1)>0,"Season after calving"), "")} | Y34: {=_xlfn.IFS(X34="Calving season", $J$14, X34="Season after calving", $J$15, X34="", "")} | Z34: 1 | AA34: 1 | AB34: 1 | AC34: {=IFERROR(EntericMethane_PastureBeef_Equations.VEERG_3_2_1_1__4_AdditionalIntakeForMilkProduction(X$22,$Y34), 1)} -> 1 | AD34: {=IFERROR(EntericMethane_PastureBeef_Equations.VEERG_3_2_1_1__4_AdditionalIntakeForMilkProduction(Y$22,$Y34), 1)} -> 1 | AE34: {=IFERROR(EntericMethane_PastureBeef_Equations.VEERG_3_2_1_1__4_AdditionalIntakeForMilkProduction(Z$22,$Y34), 1)} -> 1 | AF34: 1 | AG34: 1 | AH34: 1 | AI34: 1 | AJ34: =$E$11 -> fraction
W35: =TEXT(EDATE(X_Cell_Site_StartDate,7), "mmmm") -> August | X35: {=IFERROR(_xlfn.IFS(SUMPRODUCT(ISNUMBER(SEARCH(TRIM(_xlfn.TEXTSPLIT($W$22,",")),W35))*1)>0,"Calving season",SUMPRODUCT(ISNUMBER(SEARCH(TRIM(_xlfn.TEXTSPLIT($W$23,",")),W35))*1)>0,"Season after calving"), "")} -> Calving season | Y35: {=_xlfn.IFS(X35="Calving season", $J$14, X35="Season after calving", $J$15, X35="", "")} -> 1.3 | Z35: 1 | AA35: 1 | AB35: 1 | AC35: {=IFERROR(EntericMethane_PastureBeef_Equations.VEERG_3_2_1_1__4_AdditionalIntakeForMilkProduction(X$22,$Y35), 1)} -> 1.225 | AD35: {=IFERROR(EntericMethane_PastureBeef_Equations.VEERG_3_2_1_1__4_AdditionalIntakeForMilkProduction(Y$22,$Y35), 1)} -> 1.225 | AE35: {=IFERROR(EntericMethane_PastureBeef_Equations.VEERG_3_2_1_1__4_AdditionalIntakeForMilkProduction(Z$22,$Y35), 1)} -> 1.225 | AF35: 1 | AG35: 1 | AH35: 1 | AI35: 1 | AJ35: =$E$11 -> fraction
W36: =TEXT(EDATE(X_Cell_Site_StartDate,8), "mmmm") -> September | X36: {=IFERROR(_xlfn.IFS(SUMPRODUCT(ISNUMBER(SEARCH(TRIM(_xlfn.TEXTSPLIT($W$22,",")),W36))*1)>0,"Calving season",SUMPRODUCT(ISNUMBER(SEARCH(TRIM(_xlfn.TEXTSPLIT($W$23,",")),W36))*1)>0,"Season after calving"), "")} -> Calving season | Y36: {=_xlfn.IFS(X36="Calving season", $J$14, X36="Season after calving", $J$15, X36="", "")} -> 1.3 | Z36: 1 | AA36: 1 | AB36: 1 | AC36: {=IFERROR(EntericMethane_PastureBeef_Equations.VEERG_3_2_1_1__4_AdditionalIntakeForMilkProduction(X$22,$Y36), 1)} -> 1.225 | AD36: {=IFERROR(EntericMethane_PastureBeef_Equations.VEERG_3_2_1_1__4_AdditionalIntakeForMilkProduction(Y$22,$Y36), 1)} -> 1.225 | AE36: {=IFERROR(EntericMethane_PastureBeef_Equations.VEERG_3_2_1_1__4_AdditionalIntakeForMilkProduction(Z$22,$Y36), 1)} -> 1.225 | AF36: 1 | AG36: 1 | AH36: 1 | AI36: 1 | AJ36: =$E$11 -> fraction
D37: {=EntericMethane_PastureBeef_Equations.VEERG_3_2_1_1__3_FeedIntakeForGrazingBeef_Title()} -> Feed intake for grazing beef cattle | W37: =TEXT(EDATE(X_Cell_Site_StartDate,9), "mmmm") -> October | X37: {=IFERROR(_xlfn.IFS(SUMPRODUCT(ISNUMBER(SEARCH(TRIM(_xlfn.TEXTSPLIT($W$22,",")),W37))*1)>0,"Calving season",SUMPRODUCT(ISNUMBER(SEARCH(TRIM(_xlfn.TEXTSPLIT($W$23,",")),W37))*1)>0,"Season after calving"), "")} -> Calving season | Y37: {=_xlfn.IFS(X37="Calving season", $J$14, X37="Season after calving", $J$15, X37="", "")} -> 1.3 | Z37: 1 | AA37: 1 | AB37: 1 | AC37: {=IFERROR(EntericMethane_PastureBeef_Equations.VEERG_3_2_1_1__4_AdditionalIntakeForMilkProduction(X$22,$Y37), 1)} -> 1.225 | AD37: {=IFERROR(EntericMethane_PastureBeef_Equations.VEERG_3_2_1_1__4_AdditionalIntakeForMilkProduction(Y$22,$Y37), 1)} -> 1.225 | AE37: {=IFERROR(EntericMethane_PastureBeef_Equations.VEERG_3_2_1_1__4_AdditionalIntakeForMilkProduction(Z$22,$Y37), 1)} -> 1.225 | AF37: 1 | AG37: 1 | AH37: 1 | AI37: 1 | AJ37: =$E$11 -> fraction
D38: {=EntericMethane_PastureBeef_Equations.VEERG_3_2_1_1__3_FeedIntakeForGrazingBeef_Source()} -> VEERG 2026: 3.2.1.1, Equation (3) | K38: Cows < 3 months | L38: Cows 3-6 months | M38: Cows 6 months-1 year | W38: =TEXT(EDATE(X_Cell_Site_StartDate,10), "mmmm") -> November | X38: {=IFERROR(_xlfn.IFS(SUMPRODUCT(ISNUMBER(SEARCH(TRIM(_xlfn.TEXTSPLIT($W$22,",")),W38))*1)>0,"Calving season",SUMPRODUCT(ISNUMBER(SEARCH(TRIM(_xlfn.TEXTSPLIT($W$23,",")),W38))*1)>0,"Season after calving"), "")} -> Season after calving | Y38: {=_xlfn.IFS(X38="Calving season", $J$14, X38="Season after calving", $J$15, X38="", "")} -> 1.1 | Z38: 1 | AA38: 1 | AB38: 1 | AC38: {=IFERROR(EntericMethane_PastureBeef_Equations.VEERG_3_2_1_1__4_AdditionalIntakeForMilkProduction(X$22,$Y38), 1)} -> 1.075 | AD38: {=IFERROR(EntericMethane_PastureBeef_Equations.VEERG_3_2_1_1__4_AdditionalIntakeForMilkProduction(Y$22,$Y38), 1)} -> 1.075 | AE38: {=IFERROR(EntericMethane_PastureBeef_Equations.VEERG_3_2_1_1__4_AdditionalIntakeForMilkProduction(Z$22,$Y38), 1)} -> 1.075 | AF38: 1 | AG38: 1 | AH38: 1 | AI38: 1 | AJ38: =$E$11 -> fraction
D39: Function name | E39: {=Common_InputFunctions.Utility_DisplayFunctionName($E$84)} -> =EntericMethane_PastureBeef_Equations.VEERG_3_2_1_1__3_FeedIntakeForGrazingBeef | W39: =TEXT(EDATE(X_Cell_Site_StartDate,11), "mmmm") -> December | X39: {=IFERROR(_xlfn.IFS(SUMPRODUCT(ISNUMBER(SEARCH(TRIM(_xlfn.TEXTSPLIT($W$22,",")),W39))*1)>0,"Calving season",SUMPRODUCT(ISNUMBER(SEARCH(TRIM(_xlfn.TEXTSPLIT($W$23,",")),W39))*1)>0,"Season after calving"), "")} -> Season after calving | Y39: {=_xlfn.IFS(X39="Calving season", $J$14, X39="Season after calving", $J$15, X39="", "")} -> 1.1 | Z39: 1 | AA39: 1 | AB39: 1 | AC39: {=IFERROR(EntericMethane_PastureBeef_Equations.VEERG_3_2_1_1__4_AdditionalIntakeForMilkProduction(X$22,$Y39), 1)} -> 1.075 | AD39: {=IFERROR(EntericMethane_PastureBeef_Equations.VEERG_3_2_1_1__4_AdditionalIntakeForMilkProduction(Y$22,$Y39), 1)} -> 1.075 | AE39: {=IFERROR(EntericMethane_PastureBeef_Equations.VEERG_3_2_1_1__4_AdditionalIntakeForMilkProduction(Z$22,$Y39), 1)} -> 1.075 | AF39: 1 | AG39: 1 | AH39: 1 | AI39: 1 | AJ39: =$E$11 -> fraction
W41: M2_Table_W_j_k_l
D42: Variable | E42: {=EntericMethane_PastureBeef_Equations.VEERG_3_2_1_1__3_FeedIntakeForGrazingBeef_Variable()} -> I_jkl | W42: Liveweight (Method 2)
D43: Unit | E43: {=EntericMethane_PastureBeef_Equations.VEERG_3_2_1_1__3_FeedIntakeForGrazingBeef_Unit()} -> kg DM/head/day | W43: Month | X43: Bulls < 1 year | Y43: Bulls > 1 year | Z43: Cows < 1 year | AA43: Cows 1-2 years | AB43: Cows 2-3 years | AC43: Cows > 3 years | AD43: Steers < 1 year | AE43: Steers 1-2 years | AF43: Steers 2-3 years | AG43: Steers >3 years
W44: =TEXT(X_Cell_Site_StartDate,"mmmm") -> January | X44: {=OFFSET(X_Table_PastureBeef_Liveweight_Method2, 1,1, 12,10)} -> 380 | Y44: 780 | Z44: 300 | AA44: 450 | AB44: 530 | AC44: 530 | AD44: 340 | AE44: 470 | AF44: 470 | AG44: 470 | AH44: kg/head
...

Sheet 4.2.1.3-4 Soil direct N20
A1: #VALUE! | C1: 4.2.1.3-4 Manure Direct N2O
A3: =HYPERLINK("#'Home'!A1", "Home") -> Home | D3: Method 1 | U3: Method 2
A4: =HYPERLINK("#'Results'!A1", "Results") -> Results
D5: {=MMS_PastureBeef_Soil_N2ODirect_Equations.VEERG_4_2_1_3__7_RelativeSize_Title()} -> Relative size of the cattle
D6: {=MMS_PastureBeef_Soil_N2ODirect_Equations.VEERG_4_2_1_3__7_RelativeSize_Source()} -> VEERG 2026: 4.2.1.3, Equation (7)
A7: INPUTS | D7: Function name | E7: {=Common_InputFunctions.Utility_DisplayFunctionName(E33)} -> =MMS_PastureBeef_Soil_N2ODirect_Equations.VEERG_4_2_1_3__7_RelativeSize
A8: =HYPERLINK("#'Input - Site'!A1", "Site") -> Site
A9: =HYPERLINK("#'Input - Pasture Beef'!A1", "Pasture Beef") -> Pasture Beef
D10: Variable | E10: {=MMS_PastureBeef_Soil_N2ODirect_Equations.VEERG_4_2_1_3__7_RelativeSize_Variable()} -> Z_jkl
D11: Unit | E11: {=MMS_PastureBeef_Soil_N2ODirect_Equations.VEERG_4_2_1_3__7_RelativeSize_Unit()} -> ratio
A12: CALCULATIONS
A13: =HYPERLINK("#'4.2.1.1-2 Methane'!A1", "4.2.1.1-2 Methane") -> 4.2.1.1-2 Methane | D13: {=_xlfn.CHOOSECOLS(MMS_PastureBeef_Soil_N2ODirect_Equations.VEERG_4_2_1_3__7_RelativeSize_Arguments(),1,2)} -> W_jkl | E13: liveweight (kg) | F13: {=_xlfn.CHOOSECOLS(MMS_PastureBeef_Soil_N2ODirect_Equations.VEERG_4_2_1_3__7_RelativeSize_Arguments(),3,4)} -> kg | G13: Input | H13: {=HYPERLINK(Common_InputFunctions.Utility_SourceHyperlink(D17), D17)} -> M1_Table_W_j_k_l
A14: =HYPERLINK("#'4.2.1.3-4 Soil direct N20'!A1", "4.2.1.3-4 Soil direct N20") -> 4.2.1.3-4 Soil direct N20 | D14: SRW_k | E14: standard reference weight (kg) | F14: kg | G14: Constant | H14: {=HYPERLINK(Common_InputFunctions.Utility_SourceHyperlink(D25), D25)} -> Table_SRW_k
A15: =HYPERLINK("#'4.2.1.5-6 Soil Atmos Dep'!A1", "4.2.1.5-6 Soil Atmos Dep") -> 4.2.1.5-6 Soil Atmos Dep | D15: i | E15: state | G15: Input | H15: =X_Cell_Site_State -> Western Australia
A16: =HYPERLINK("#'4.2.1.7-8 Soil leach runoff'!A1", "4.2.1.7-8 Soil leach runoff") -> 4.2.1.7-8 Soil leach runoff
D17: M1_Table_W_j_k_l | U17: M2_Table_LW_j_k_l
D18: Liveweight (Method 1) | U18: Liveweight (Method 2)
A19: APPENDICES | D19: Season | E19: Bulls < 1 year | F19: Bulls > 1 year | G19: Cows < 1 year | H19: Cows 1-2 years | I19: Cows 2-3 years | J19: Cows > 3 years | K19: Steers < 1 year | L19: Steers 1-2 years | M19: Steers 2-3 years | N19: Steers >3 years | U19: Month | V19: Bulls < 1 year | W19: Bulls > 1 year | X19: Cows < 1 year | Y19: Cows 1-2 years | Z19: Cows 2-3 years | AA19: Cows > 3 years | AB19: Steers < 1 year | AC19: Steers 1-2 years | AD19: Steers 2-3 years | AE19: Steers >3 years
A20: =HYPERLINK("#'Constants - Pasture Beef'!A1", "Constants - Pasture Beef") -> Constants - Pasture Beef | D20: =INDEX(X_Table_PastureBeef_Liveweight_Method1,2,1) -> Spring | E20: {=OFFSET(X_Table_PastureBeef_Liveweight_Method1, 1,1, 4,10)} -> 340 | F20: 800 | G20: 260 | H20: 420 | I20: 550 | J20: 550 | K20: 300 | L20: 480 | M20: 480 | N20: 480 | O20: kg/head | U20: =TEXT(X_Cell_Site_StartDate,"mmmm") -> January | V20: {=OFFSET(X_Table_PastureBeef_Liveweight_Method2, 1,1, 12,10)} -> 380 | W20: 780 | X20: 300 | Y20: 450 | Z20: 530 | AA20: 530 | AB20: 340 | AC20: 470 | AD20: 470 | AE20: 470 | AF20: kg/head
A21: =HYPERLINK("#'Constants - Common'!A1", "Constants - Common") -> Constants - Common | D21: =INDEX(X_Table_PastureBeef_Liveweight_Method1,3,1) -> Summer | E21: 380 | F21: 780 | G21: 300 | H21: 450 | I21: 530 | J21: 530 | K21: 340 | L21: 470 | M21: 470 | N21: 470 | O21: kg/head | U21: =TEXT(EDATE(X_Cell_Site_StartDate,1), "mmmm") -> February | V21: 380 | W21: 780 | X21: 300 | Y21: 450 | Z21: 530 | AA21: 530 | AB21: 340 | AC21: 470 | AD21: 470 | AE21: 470 | AF21: kg/head
A22: =HYPERLINK("#'Constants - Common Livestock'!A1", "Constants - Common Livestock") -> Constants - Common Livestock | D22: =INDEX(X_Table_PastureBeef_Liveweight_Method1,4,1) -> Autumn | E22: 100 | F22: 680 | G22: 80 | H22: 320 | I22: 480 | J22: 480 | K22: 100 | L22: 340 | M22: 340 | N22: 340 | O22: kg/head | U22: =TEXT(EDATE(X_Cell_Site_StartDate,2), "mmmm") -> March | V22: 100 | W22: 680 | X22: 80 | Y22: 320 | Z22: 480 | AA22: 480 | AB22: 100 | AC22: 340 | AD22: 340 | AE22: 340 | AF22: kg/head
A23: =HYPERLINK("#'Acknowledgements'!A1", "Acknowledgements") -> Acknowledgements | D23: =INDEX(X_Table_PastureBeef_Liveweight_Method1,5,1) -> Winter | E23: 190 | F23: 700 | G23: 150 | H23: 330 | I23: 490 | J23: 490 | K23: 170 | L23: 360 | M23: 360 | N23: 360 | O23: kg/head | U23: =TEXT(EDATE(X_Cell_Site_StartDate,3), "mmmm") -> April | V23: 100 | W23: 680 | X23: 80 | Y23: 320 | Z23: 480 | AA23: 480 | AB23: 100 | AC23: 340 | AD23: 340 | AE23: 340 | AF23: kg/head
A24: =HYPERLINK("#'Tab template'!A1", "Tab template") -> Tab template | U24: =TEXT(EDATE(X_Cell_Site_StartDate,4), "mmmm") -> May | V24: 100 | W24: 680 | X24: 80 | Y24: 320 | Z24: 480 | AA24: 480 | AB24: 100 | AC24: 340 | AD24: 340 | AE24: 340 | AF24: kg/head
D25: Table_SRW_k | U25: =TEXT(EDATE(X_Cell_Site_StartDate,5), "mmmm") -> June | V25: 190 | W25: 700 | X25: 150 | Y25: 330 | Z25: 490 | AA25: 490 | AB25: 170 | AC25: 360 | AD25: 360 | AE25: 360 | AF25: kg/head
D26: Standard reference weight | U26: =TEXT(EDATE(X_Cell_Site_StartDate,6), "mmmm") -> July | V26: 190 | W26: 700 | X26: 150 | Y26: 330 | Z26: 490 | AA26: 490 | AB26: 170 | AC26: 360 | AD26: 360 | AE26: 360 | AF26: kg/head
D27: Bulls < 1 year | E27: Bulls > 1 year | F27: Cows < 1 year | G27: Cows 1-2 years | H27: Cows 2-3 years | I27: Cows > 3 years | J27: Steers < 1 year | K27: Steers 1-2 years | L27: Steers 2-3 years | M27: Steers >3 years | U27: =TEXT(EDATE(X_Cell_Site_StartDate,7), "mmmm") -> August | V27: 190 | W27: 700 | X27: 150 | Y27: 330 | Z27: 490 | AA27: 490 | AB27: 170 | AC27: 360 | AD27: 360 | AE27: 360 | AF27: kg/head
D28: =Common_InputFunctions.Utility_LookupValueInTableOneColumnAndHeader(Common_InputFunctions.Utility_ConvertStateCommonNameToAbbreviation($H$15,Table_AustralianStates[Common Name],Table_AustralianStates[Abbreviation]),D27,Table_SourceData_PastureBeef_StandardReferenceWeightsExpanded[State abbreviation],Table_SourceData_PastureBeef_StandardReferenceWeightsExpanded[#Headers],Table_SourceData_PastureBeef_StandardReferenceWeightsExpanded[]) -> 770 | E28: =Common_InputFunctions.Utility_LookupValueInTableOneColumnAndHeader(Common_InputFunctions.Utility_ConvertStateCommonNameToAbbreviation($H$15,Table_AustralianStates[Common Name],Table_AustralianStates[Abbreviation]),E27,Table_SourceData_PastureBeef_StandardReferenceWeightsExpanded[State abbreviation],Table_SourceData_PastureBeef_StandardReferenceWeightsExpanded[#Headers],Table_SourceData_PastureBeef_StandardReferenceWeightsExpanded[]) -> 770 | F28: =Common_InputFunctions.Utility_LookupValueInTableOneColumnAndHeader(Common_InputFunctions.Utility_ConvertStateCommonNameToAbbreviation($H$15,Table_AustralianStates[Common Name],Table_AustralianStates[Abbreviation]),F27,Table_SourceData_PastureBeef_StandardReferenceWeightsExpanded[State abbreviation],Table_SourceData_PastureBeef_StandardReferenceWeightsExpanded[#Headers],Table_SourceData_PastureBeef_StandardReferenceWeightsExpanded[]) -> 550 | G28: =Common_InputFunctions.Utility_LookupValueInTableOneColumnAndHeader(Common_InputFunctions.Utility_ConvertStateCommonNameToAbbreviation($H$15,Table_AustralianStates[Common Name],Table_AustralianStates[Abbreviation]),G27,Table_SourceData_PastureBeef_StandardReferenceWeightsExpanded[State abbreviation],Table_SourceData_PastureBeef_StandardReferenceWeightsExpanded[#Headers],Table_SourceData_PastureBeef_StandardReferenceWeightsExpanded[]) -> 550 | H28: =Common_InputFunctions.Utility_LookupValueInTableOneColumnAndHeader(Common_InputFunctions.Utility_ConvertStateCommonNameToAbbreviation($H$15,Table_AustralianStates[Common Name],Table_AustralianStates[Abbreviation]),H27,Table_SourceData_PastureBeef_StandardReferenceWeightsExpanded[State abbreviation],Table_SourceData_PastureBeef_StandardReferenceWeightsExpanded[#Headers],Table_SourceData_PastureBeef_StandardReferenceWeightsExpanded[]) -> 550 | I28: =Common_InputFunctions.Utility_LookupValueInTableOneColumnAndHeader(Common_InputFunctions.Utility_ConvertStateCommonNameToAbbreviation($H$15,Table_AustralianStates[Common Name],Table_AustralianStates[Abbreviation]),I27,Table_SourceData_PastureBeef_StandardReferenceWeightsExpanded[State abbreviation],Table_SourceData_PastureBeef_StandardReferenceWeightsExpanded[#Headers],Table_SourceData_PastureBeef_StandardReferenceWeightsExpanded[]) -> 550 | J28: =Common_InputFunctions.Utility_LookupValueInTableOneColumnAndHeader(Common_InputFunctions.Utility_ConvertStateCommonNameToAbbreviation($H$15,Table_AustralianStates[Common Name],Table_AustralianStates[Abbreviation]),J27,Table_SourceData_PastureBeef_StandardReferenceWeightsExpanded[State abbreviation],Table_SourceData_PastureBeef_StandardReferenceWeightsExpanded[#Headers],Table_SourceData_PastureBeef_StandardReferenceWeightsExpanded[]) -> 660 | K28: =Common_InputFunctions.Utility_LookupValueInTableOneColumnAndHeader(Common_InputFunctions.Utility_ConvertStateCommonNameToAbbreviation($H$15,Table_AustralianStates[Common Name],Table_AustralianStates[Abbreviation]),K27,Table_SourceData_PastureBeef_StandardReferenceWeightsExpanded[State abbreviation],Table_SourceData_PastureBeef_StandardReferenceWeightsExpanded[#Headers],Table_SourceData_PastureBeef_StandardReferenceWeightsExpanded[]) -> 660 | ... M28: =Common_InputFunctions.Utility_LookupValueInTableOneColumnAndHeader(Common_InputFunctions.Utility_ConvertStateCommonNameToAbbreviation($H$15,Table_AustralianStates[Common Name],Table_AustralianStates[Abbreviation]),M27,Table_SourceData_PastureBeef_StandardReferenceWeightsExpanded[State abbreviation],Table_SourceData_PastureBeef_StandardReferenceWeightsExpanded[#Headers],Table_SourceData_PastureBeef_StandardReferenceWeightsExpanded[]) -> 660 | N28: kg/head | U28: =TEXT(EDATE(X_Cell_Site_StartDate,8), "mmmm") -> September | V28: 340 | W28: 800 | X28: 260 | Y28: 420 | Z28: 550 | AA28: 550 | AB28: 300 | AC28: 480 | AD28: 480 | AE28: 480 | AF28: kg/head
U29: =TEXT(EDATE(X_Cell_Site_StartDate,9), "mmmm") -> October | V29: 340 | W29: 800 | X29: 260 | Y29: 420 | Z29: 550 | AA29: 550 | AB29: 300 | AC29: 480 | AD29: 480 | AE29: 480 | AF29: kg/head
D30: M1_Table_Z_j_k_l | U30: =TEXT(EDATE(X_Cell_Site_StartDate,10), "mmmm") -> November | V30: 340 | W30: 800 | X30: 260 | Y30: 420 | Z30: 550 | AA30: 550 | AB30: 300 | AC30: 480 | AD30: 480 | AE30: 480 | AF30: kg/head
D31: Relative size (Method 1) | U31: =TEXT(EDATE(X_Cell_Site_StartDate,11), "mmmm") -> December | V31: 380 | W31: 780 | X31: 300 | Y31: 450 | Z31: 530 | AA31: 530 | AB31: 340 | AC31: 470 | AD31: 470 | AE31: 470 | AF31: kg/head
D32: Season | E32: Bulls < 1 year | F32: Bulls > 1 year | G32: Cows < 1 year | H32: Cows 1-2 years | I32: Cows 2-3 years | J32: Cows > 3 years | K32: Steers < 1 year | L32: Steers 1-2 years | M32: Steers 2-3 years | N32: Steers >3 years
D33: =INDEX(X_Table_PastureBeef_Liveweight_Method1,2,1) -> Spring | E33: {=MMS_PastureBeef_Soil_N2ODirect_Equations.VEERG_4_2_1_3__7_RelativeSize(E20,D$28)} -> 0.44155844 | F33: {=MMS_PastureBeef_Soil_N2ODirect_Equations.VEERG_4_2_1_3__7_RelativeSize(F20,E$28)} -> 1.038961 | G33: {=MMS_PastureBeef_Soil_N2ODirect_Equations.VEERG_4_2_1_3__7_RelativeSize(G20,F$28)} -> 0.47272727 | H33: {=MMS_PastureBeef_Soil_N2ODirect_Equations.VEERG_4_2_1_3__7_RelativeSize(H20,G$28)} -> 0.76363636 | I33: {=MMS_PastureBeef_Soil_N2ODirect_Equations.VEERG_4_2_1_3__7_RelativeSize(I20,H$28)} -> 1 | J33: {=MMS_PastureBeef_Soil_N2ODirect_Equations.VEERG_4_2_1_3__7_RelativeSize(J20,I$28)} -> 1 | K33: {=MMS_PastureBeef_Soil_N2ODirect_Equations.VEERG_4_2_1_3__7_RelativeSize(K20,J$28)} -> 0.45454545 | L33: {=MMS_PastureBeef_Soil_N2ODirect_Equations.VEERG_4_2_1_3__7_RelativeSize(L20,K$28)} -> 0.72727273 | ... N33: {=MMS_PastureBeef_Soil_N2ODirect_Equations.VEERG_4_2_1_3__7_RelativeSize(N20,M$28)} -> 0.72727273 | O33: =$E$11 -> ratio | U33: M2_Table_Z_j_k_l
