Workbook
Name AgResidue_Equations_FieldBurning.VEERG_6_4_1_1__1__MethaneEmissionsFromBurningOfCropResidues: _xlfn.LAMBDA(_xlpm.Mburnc,_xlpm.CCc,_xlpm.EFCH4,_xlpm.C_CH4, _xlpm.Mburnc * _xlpm.CCc * _xlpm.EFCH4 * _xlpm.C_CH4 * 10 ^ (-3))
Name AgResidue_Equations_FieldBurning.VEERG_6_4_1_1__1__MethaneEmissionsFromBurningOfCropResidues_FunctionName: _xlfn.LAMBDA("VEERG_6_4_1_1__1__MethaneEmissionsFromBurningOfCropResidues")
Name AgResidue_Equations_FieldBurning.VEERG_6_4_1_1__1__MethaneEmissionsFromBurningOfCropResidues_LatexEquation: _xlfn.LAMBDA("E_{CH4}=\sum_{c}(M_{burn,c}\times CC_{c}\times EF_{CH4}\times C_{CH4}\times 10^{-3})")
Name AgResidue_Equations_FieldBurning.VEERG_6_4_1_1__1__MethaneEmissionsFromBurningOfCropResidues_NIRReference: _xlfn.LAMBDA("")
Name AgResidue_Equations_FieldBurning.VEERG_6_4_1_1__1__MethaneEmissionsFromBurningOfCropResidues_Source: _xlfn.LAMBDA("VEERG 2026: 6.4.1.1, Equation (1)")
Name AgResidue_Equations_FieldBurning.VEERG_6_4_1_1__1__MethaneEmissionsFromBurningOfCropResidues_Title: _xlfn.LAMBDA("Methane emissions from the burning of crop residues")
Name AgResidue_Equations_FieldBurning.VEERG_6_4_1_1__1__MethaneEmissionsFromBurningOfCropResidues_Unit: _xlfn.LAMBDA("t CH4")
Name AgResidue_Equations_FieldBurning.VEERG_6_4_1_1__1__MethaneEmissionsFromBurningOfCropResidues_Variable: _xlfn.LAMBDA("ECH4")
Name AgResidue_Equations_FieldBurning.VEERG_6_4_1_1__2__NitrousOxideEmissionsFromBurningOfCropResidues: _xlfn.LAMBDA(_xlpm.Mburnc,_xlpm.NCAGc,_xlpm.EFN2O,_xlpm.CN2O, _xlpm.Mburnc * _xlpm.NCAGc * _xlpm.EFN2O * _xlpm.CN2O * 10 ^ (-3))
Name AgResidue_Equations_FieldBurning.VEERG_6_4_1_1__2__NitrousOxideEmissionsFromBurningOfCropResidues_FunctionName: _xlfn.LAMBDA("VEERG_6_4_1_1__2__NitrousOxideEmissionsFromBurningOfCropResidues")
Name AgResidue_Equations_FieldBurning.VEERG_6_4_1_1__2__NitrousOxideEmissionsFromBurningOfCropResidues_LatexEquation: _xlfn.LAMBDA("E_{N2O}=\sum_{c}(M_{burn,c}\times NC_{AGc}\times EF_{N2O}\times C_{N2O}\times 10^{-3})")
Name AgResidue_Equations_FieldBurning.VEERG_6_4_1_1__2__NitrousOxideEmissionsFromBurningOfCropResidues_NIRReference: _xlfn.LAMBDA("")
Name AgResidue_Equations_FieldBurning.VEERG_6_4_1_1__2__NitrousOxideEmissionsFromBurningOfCropResidues_Source: _xlfn.LAMBDA("VEERG 2026: 6.4.1.1, Equation (2)")
Name AgResidue_Equations_FieldBurning.VEERG_6_4_1_1__2__NitrousOxideEmissionsFromBurningOfCropResidues_Title: _xlfn.LAMBDA("Nitrous oxide emissions from the burning of crop residues")
Name AgResidue_Equations_FieldBurning.VEERG_6_4_1_1__2__NitrousOxideEmissionsFromBurningOfCropResidues_Unit: _xlfn.LAMBDA("t N2O")
Name AgResidue_Equations_FieldBurning.VEERG_6_4_1_1__2__NitrousOxideEmissionsFromBurningOfCropResidues_Variable: _xlfn.LAMBDA("EN2O")
Name AgResidue_Equations_FieldBurning.VEERG_6_4_1_1__3__MassOfCropResidueBurnt: _xlfn.LAMBDA(_xlpm.Pc,_xlpm.RAGc,_xlpm.Sc,_xlpm.DMc,_xlpm.Zc,_xlpm.Fc, _xlpm.Pc * _xlpm.RAGc * _xlpm.Sc * _xlpm.DMc * _xlpm.Zc * _xlpm.Fc)
Name AgResidue_Equations_FieldBurning.VEERG_6_4_1_1__3__MassOfCropResidueBurnt_FunctionName: _xlfn.LAMBDA("VEERG_6_4_1_1__3__MassOfCropResidueBurnt")
Name AgResidue_Equations_FieldBurning.VEERG_6_4_1_1__3__MassOfCropResidueBurnt_LatexEquation: _xlfn.LAMBDA("M_{burn,c}=P_{c}\times R_{AGc}\times S_{c}\times DM_{c}\times Z_{c}\times F_{c}")
Name AgResidue_Equations_FieldBurning.VEERG_6_4_1_1__3__MassOfCropResidueBurnt_NIRReference: _xlfn.LAMBDA("")
Name AgResidue_Equations_FieldBurning.VEERG_6_4_1_1__3__MassOfCropResidueBurnt_Source: _xlfn.LAMBDA("VEERG 2026: 6.4.1.1, Equation (3)")
Name AgResidue_Equations_FieldBurning.VEERG_6_4_1_1__3__MassOfCropResidueBurnt_Title: _xlfn.LAMBDA("Mass of residue of crop c burnt")
Name AgResidue_Equations_FieldBurning.VEERG_6_4_1_1__3__MassOfCropResidueBurnt_Unit: _xlfn.LAMBDA("kg")
Name AgResidue_Equations_FieldBurning.VEERG_6_4_1_1__3__MassOfCropResidueBurnt_Variable: _xlfn.LAMBDA("Mburnc")
Name AgResidues_Equations_CropResidues.VEERG_6_1_1_1__1__NitrousOxideEmissionsFromCropResidues: _xlfn.LAMBDA(_xlpm.Mc,_xlpm.EFNi,_xlpm.CgN2O, _xlpm.Mc * _xlpm.EFNi * _xlpm.CgN2O * 10 ^ (-3))
Name AgResidues_Equations_CropResidues.VEERG_6_1_1_1__1__NitrousOxideEmissionsFromCropResidues_FunctionName: _xlfn.LAMBDA("VEERG_6_1_1_1__1__NitrousOxideEmissionsFromCropResidues")
Name AgResidues_Equations_CropResidues.VEERG_6_1_1_1__1__NitrousOxideEmissionsFromCropResidues_LatexEquation: _xlfn.LAMBDA("E=\sum_{c}{M_{c}\times EF_{N}\times C_{g,N2O}\times 10^{-3}}")
Name AgResidues_Equations_CropResidues.VEERG_6_1_1_1__1__NitrousOxideEmissionsFromCropResidues_NIRReference: _xlfn.LAMBDA("")
Name AgResidues_Equations_CropResidues.VEERG_6_1_1_1__1__NitrousOxideEmissionsFromCropResidues_Source: _xlfn.LAMBDA("VEERG 2026: 6.1.1.1, Equation (1)")
Name AgResidues_Equations_CropResidues.VEERG_6_1_1_1__1__NitrousOxideEmissionsFromCropResidues_Title: _xlfn.LAMBDA("Nitrous oxide emissions from the return of crop residues across all crops c to the soil")
Name AgResidues_Equations_CropResidues.VEERG_6_1_1_1__1__NitrousOxideEmissionsFromCropResidues_Unit: _xlfn.LAMBDA("t N2O")
Name AgResidues_Equations_CropResidues.VEERG_6_1_1_1__1__NitrousOxideEmissionsFromCropResidues_Variable: _xlfn.LAMBDA("E")
Name AgResidues_Equations_CropResidues.VEERG_6_1_1_1__2__MassOfNitrogenInCropResidues_LatexEquation: _xlfn.LAMBDA("M_{c}=(P_{c}\times R_{AGc}\times(1-F_{c}-FFOD_{c})\times DM_{c}\times NC_{AGc})+(P_{c}\times R_{AGc}\times R_{BGc}\times DM_{c}\times NC_{BGc})")
Name AgResidues_Equations_CropResidues.VEERG_6_1_1_1__2__MassOfNitrogenInCropResidues_NIRReference: _xlfn.LAMBDA("")
Name AgResidues_Equations_CropResidues.VEERG_6_1_1_1__2__MassOfNitrogenInCropResidues_Source: _xlfn.LAMBDA("VEERG 2026: 6.1.1.1, Equation (2)")
Name AgResidues_Equations_CropResidues.VEERG_6_1_1_1__2__MassOfNitrogenInCropResidues_Title: _xlfn.LAMBDA("Mass of nitrogen in crop residues returned to the soil")
Name AgResidues_Equations_CropResidues.VEERG_6_1_1_1__2__MassOfNitrogenInCropResidues_Unit: _xlfn.LAMBDA("kg N")
Name AgResidues_Equations_CropResidues.VEERG_6_1_1_1__2__MassOfNitrogenInCropResidues_Variable: _xlfn.LAMBDA("Mc")
Name AgResidues_Equations_CropResidues.VEERG_6_1_1_2__1__FractionOfCropResidueRemovedBaled: _xlfn.LAMBDA(_xlpm.B,_xlpm.MB,_xlpm.Pc,_xlpm.RAGc, IFERROR((_xlpm.B * _xlpm.MB) / (_xlpm.Pc * _xlpm.RAGc), 0))
Name AgResidues_Equations_CropResidues.VEERG_6_1_1_2__1__FractionOfCropResidueRemovedBaled_LatexEquation: _xlfn.LAMBDA("FFOD_{c,baled}=\frac{B\times M_{B}}{P_{c}\times R_{AG,c}}")
Name AgResidues_Equations_CropResidues.VEERG_6_1_1_2__1__FractionOfCropResidueRemovedBaled_NIRReference: _xlfn.LAMBDA("")
Name AgResidues_Equations_CropResidues.VEERG_6_1_1_2__1__FractionOfCropResidueRemovedBaled_Source: _xlfn.LAMBDA("VEERG 2026: 6.1.1.2, Equation (1)")
Name AgResidues_Equations_CropResidues.VEERG_6_1_1_2__1__FractionOfCropResidueRemovedBaled_Title: _xlfn.LAMBDA("Fraction of crop residue that is removed for crop c, calculated where residues are baled")
Name AgResidues_Equations_CropResidues.VEERG_6_1_1_2__1__FractionOfCropResidueRemovedBaled_Unit: _xlfn.LAMBDA("dimensionless")
Name AgResidues_Equations_CropResidues.VEERG_6_1_1_2__1__FractionOfCropResidueRemovedBaled_Variable: _xlfn.LAMBDA("FFODcbaled")
Name AgResidues_Equations_CropResidues.VEERG_6_1_1_2__1__FractionOfCropResidueRemovedBaled_Variation: _xlfn.LAMBDA("VARIATION FROM SOURCE: Added 'baled' to variable subscript")
Name AgResidues_Equations_CropResidues.VEERG_6_1_1_2__1a__FractionOfCropResidueRemoved: _xlfn.LAMBDA(_xlpm.FFODcbaled,_xlpm.FFODcother, _xlpm.FFODcbaled + _xlpm.FFODcother)
Name AgResidues_Equations_CropResidues.VEERG_6_1_1_2__1a__FractionOfCropResidueRemoved_LatexEquation: _xlfn.LAMBDA("FFOD_{c} = FFOD_{c,baled} + FFOD_{c,other}")
Name AgResidues_Equations_CropResidues.VEERG_6_1_1_2__1a__FractionOfCropResidueRemoved_NIRReference: _xlfn.LAMBDA("")
Name AgResidues_Equations_CropResidues.VEERG_6_1_1_2__1a__FractionOfCropResidueRemoved_Source: _xlfn.LAMBDA("")
Name AgResidues_Equations_CropResidues.VEERG_6_1_1_2__1a__FractionOfCropResidueRemoved_Title: _xlfn.LAMBDA("Fraction of crop residue that is removed for crop c")
Name AgResidues_Equations_CropResidues.VEERG_6_1_1_2__1a__FractionOfCropResidueRemoved_Unit: _xlfn.LAMBDA("dimensionless")
Name AgResidues_Equations_CropResidues.VEERG_6_1_1_2__1a__FractionOfCropResidueRemoved_Variable: _xlfn.LAMBDA("FFODc")
Name AgResidues_Equations_CropResidues.VEERG_6_1_1_2__1a__FractionOfCropResidueRemoved_Variation: _xlfn.LAMBDA("VARIATION FROM SOURCE: Added this equation to accommodate user-defined residue removal other than baling.")
Name AgResidues_Equations_Leaching.VEERG_6_3_1_1__1__LeachingAndRunoffEmissionsCropAndPastureResidue: _xlfn.LAMBDA(_xlpm.Mleachcp,_xlpm.EFleach,_xlpm.CgN2O, _xlpm.Mleachcp * _xlpm.EFleach * _xlpm.CgN2O * 10 ^ (-3))
Name AgResidues_Equations_Leaching.VEERG_6_3_1_1__1__LeachingAndRunoffEmissionsCropAndPastureResidue_LatexEquation: _xlfn.LAMBDA("E_{N2O}=\sum_{c}\sum_{p}(M_{leach,cp}\times EF_{leach}\times Cg_{N2O}\times 10^{-3})")
Name AgResidues_Equations_Leaching.VEERG_6_3_1_1__1__LeachingAndRunoffEmissionsCropAndPastureResidue_NIRReference: _xlfn.LAMBDA("")
Name AgResidues_Equations_Leaching.VEERG_6_3_1_1__1__LeachingAndRunoffEmissionsCropAndPastureResidue_Source: _xlfn.LAMBDA("VEERG 2026: 6.3.1.1, Equation (1)")
Name AgResidues_Equations_Leaching.VEERG_6_3_1_1__1__LeachingAndRunoffEmissionsCropAndPastureResidue_Title: _xlfn.LAMBDA("Nitrous oxide leaching and runoff emissions from crop and pasture residues returned to the soil")
Name AgResidues_Equations_Leaching.VEERG_6_3_1_1__1__LeachingAndRunoffEmissionsCropAndPastureResidue_Unit: _xlfn.LAMBDA("t N2O")

Sheet Overview
A1: #VALUE! | C1: 13: Sope 3 emissions: Overview
A3: =HYPERLINK("#'Overview'!A1", "Overview") -> Overview
A4: =HYPERLINK("#'Results'!A1", "Results") -> Results
A7: INPUTS
A8: =HYPERLINK("#'Input - Site'!A1", "Site") -> Site
A9: =HYPERLINK("#'Input - Fuel'!A1", "Fuel") -> Fuel
A10: =HYPERLINK("#'Input - Fert Prod System'!A1", "Fert Prod System") -> Fert Prod System
A11: =HYPERLINK("#'Input - Fertiliser'!A1", "Fertiliser") -> Fertiliser
A12: =HYPERLINK("#'Input - Common farm inputs'!A1", "Common farm inputs") -> Common farm inputs
A13: =HYPERLINK("#'Input - Processing inputs'!A1", "Processing inputs") -> Processing inputs
A14: =HYPERLINK("#'Input - Crop pasture farm input'!A1", "Crop pasture farm input") -> Crop pasture farm input
A15: =HYPERLINK("#'Input - Hort farm Inputs'!A1", "Hort farm Inputs") -> Hort farm Inputs
A16: =HYPERLINK("#'Input - Livestock farm Inputs'!A1", "Livestock farm Inputs") -> Livestock farm Inputs
A17: =HYPERLINK("#'Input - Aquaculture inputs'!A1", "Aquaculture inputs") -> Aquaculture inputs
A18: =HYPERLINK("#'Input - Beef cattle purchases'!A1", "Beef cattle purchases") -> Beef cattle purchases
A19: =HYPERLINK("#'Input - Dairy cattle purchases'!A1", "Dairy cattle purchases") -> Dairy cattle purchases
A20: =HYPERLINK("#'Input - Pig purchases'!A1", "Pig purchases") -> Pig purchases
A21: =HYPERLINK("#'Input - Poultry purchases'!A1", "Poultry purchases") -> Poultry purchases
A22: =HYPERLINK("#'Input - Freight'!A1", "Freight") -> Freight
A23: =HYPERLINK("#'Input - Solid waste'!A1", "Solid waste") -> Solid waste
A24: =HYPERLINK("#'Input - Manure sent off-site'!A1", "Manure sent off-site") -> Manure sent off-site
A25: =HYPERLINK("#'Input - Electricity'!A1", "Electricity") -> Electricity
A28: CALCULATIONS
A29: =HYPERLINK("#'15 Scope 3'!A1", "15 Scope 3") -> 15 Scope 3
A30: =HYPERLINK("#'10.1.1-2 Solid waste treatment'!A1", "10.1.1-2 Solid waste treatment") -> 10.1.1-2 Solid waste treatment
A31: =HYPERLINK("#'Calcs - Manure sent off-site'!A1", "Calcs - Manure sent off-site") -> Calcs - Manure sent off-site
A32: =HYPERLINK("#'8.1.1.1-2 Transport fuel'!A1", "8.1.1.1-2 Transport fuel") -> 8.1.1.1-2 Transport fuel
A33: =HYPERLINK("#'8.2.1.1-2 Stationary fuel'!A1", "8.2.1.1-2 Stationary fuel") -> 8.2.1.1-2 Stationary fuel
A36: APPENDICES
A37: =HYPERLINK("#'Constants - Scope 3'!A1", "Constants - Scope 3") -> Constants - Scope 3
A38: =HYPERLINK("#'Constants - Solid Waste'!A1", "Constants - Solid Waste") -> Constants - Solid Waste
A39: =HYPERLINK("#'Constants - Fuel'!A1", "Constants - Fuel") -> Constants - Fuel
A40: =HYPERLINK("#'Constants - Poultry'!A1", "Constants - Poultry") -> Constants - Poultry
A41: =HYPERLINK("#'Constants - Swine'!A1", "Constants - Swine") -> Constants - Swine
A42: =HYPERLINK("#'Constants - Dairy'!A1", "Constants - Dairy") -> Constants - Dairy
A43: =HYPERLINK("#'Constants - Pasture Beef'!A1", "Constants - Pasture Beef") -> Constants - Pasture Beef
A44: =HYPERLINK("#'Constants - Common Livestock'!A1", "Constants - Common Livestock") -> Constants - Common Livestock
A45: =HYPERLINK("#'Constants - Fertiliser'!A1", "Constants - Fertiliser") -> Constants - Fertiliser
A46: =HYPERLINK("#'Constants - Electricity'!A1", "Constants - Electricity") -> Constants - Electricity
A47: =HYPERLINK("#'Constants - Common'!A1", "Constants - Common") -> Constants - Common

Sheet Results
A1: #VALUE! | C1: 13: Sope 3 emissions: Results
A3: =HYPERLINK("#'Overview'!A1", "Overview") -> Overview
A4: =HYPERLINK("#'Results'!A1", "Results") -> Results
D5: Emissions breakdown
A7: INPUTS | D7: 💡 NOTE: When there is no Method 2, the Method 2 result are the same as Method 1
A8: =HYPERLINK("#'Input - Site'!A1", "Site") -> Site
A9: =HYPERLINK("#'Input - Fuel'!A1", "Fuel") -> Fuel | D9: Scope 1 source | E9: CO2-e emissions method 1 | F9: CO2-e emissions method 2
A10: =HYPERLINK("#'Input - Fert Prod System'!A1", "Fert Prod System") -> Fert Prod System | D10: 15.1.1.1 Total emissions from purchased livestock | E10: - | F10: - | G10: t CO2e
A11: =HYPERLINK("#'Input - Fertiliser'!A1", "Fertiliser") -> Fertiliser | D11: Beef cattle | E11: =VEERG_15_1_1_1__1_EmissionsFromPurchasedLivestock_BeefCattle_Result_Method1 -> 1052.5 | F11: =VEERG_15_1_1_1__1_EmissionsFromPurchasedLivestock_BeefCattle_Result_Method2 -> 1014.5 | G11: t CO2e
A12: =HYPERLINK("#'Input - Common farm inputs'!A1", "Common farm inputs") -> Common farm inputs | D12: Dairy cattle | E12: =VEERG_15_1_1_1__1_EmissionsFromPurchasedLivestock_DairyCattle_Result_Method1 -> 295.47 | F12: =VEERG_15_1_1_1__1_EmissionsFromPurchasedLivestock_DairyCattle_Result_Method2 -> 415.625 | G12: t CO2e
A13: =HYPERLINK("#'Input - Processing inputs'!A1", "Processing inputs") -> Processing inputs | D13: Pigs | E13: =VEERG_15_1_1_1__1_EmissionsFromPurchasedLivestock_Pigs_Result_Method1 -> 127.088 | F13: =VEERG_15_1_1_1__1_EmissionsFromPurchasedLivestock_Pigs_Result_Method2 -> 73.38 | G13: t CO2e
A14: =HYPERLINK("#'Input - Crop pasture farm input'!A1", "Crop pasture farm input") -> Crop pasture farm input | D14: Poultry | E14: =VEERG_15_1_1_1__1_EmissionsFromPurchasedLivestock_Poultry_Result_Method1 -> 0.3672 | F14: =VEERG_15_1_1_1__1_EmissionsFromPurchasedLivestock_Poultry_Result_Method2 -> 0.3594 | G14: t CO2e
A15: =HYPERLINK("#'Input - Hort farm Inputs'!A1", "Hort farm Inputs") -> Hort farm Inputs | D15: 15.2.1.1 Emissions from purchased feed | E15: =VEERG_15_2_1_1__1_EmissionsFromPurchasedFeed_Result_Method1 -> 1.140652 | F15: =VEERG_15_2_1_1__1_EmissionsFromPurchasedFeed_Result_Method2 -> 0.86778 | G15: t CO2e
A16: =HYPERLINK("#'Input - Livestock farm Inputs'!A1", "Livestock farm Inputs") -> Livestock farm Inputs | D16: 15.3.1.1 Total emissions from purchased mineral supplements | E16: =VEERG_15_3_1_1__1_EmissionsFromPurchasedMineralSupplements_Result_Method1 -> 0.1789 | F16: =VEERG_15_3_1_1__1_EmissionsFromPurchasedMineralSupplements_Result_Method2 -> 0.16 | G16: t CO2e
A17: =HYPERLINK("#'Input - Aquaculture inputs'!A1", "Aquaculture inputs") -> Aquaculture inputs | D17: 15.4.1.1 Emissions from purchased fertiliser | E17: =VEERG_15_4_1_1__2_EmissionsFromPurchasedFertiliserComponentsVariation_Result_Method1 -> 66.611034 | F17: =VEERG_15_4_1_1__2_EmissionsFromPurchasedFertiliserComponentsVariation_Result_Method2 -> 65.023034 | G17: t CO2e
A18: =HYPERLINK("#'Input - Beef cattle purchases'!A1", "Beef cattle purchases") -> Beef cattle purchases | D18: 15.5.1.1 Total emissions from purchased agrichemicals | E18: =VEERG_15_5_1_1__1_EmissionsFromPurchasedAgrichemicals_Result_Method1 -> 7.516 | F18: =VEERG_15_5_1_1__1_EmissionsFromPurchasedAgrichemicals_Result_Method2 -> 7.496 | G18: t CO2e
A19: =HYPERLINK("#'Input - Dairy cattle purchases'!A1", "Dairy cattle purchases") -> Dairy cattle purchases | D19: 15.6.1.1 Embedded emissions for purchased lime | E19: =VEERG_15_6_1_1__1_EmissionsFromPurchasedLime_Result_Method1 -> 0.016554 | F19: =VEERG_15_6_1_1__1_EmissionsFromPurchasedLime_Result_Method2 -> 0.0144 | G19: t CO2e
A20: =HYPERLINK("#'Input - Pig purchases'!A1", "Pig purchases") -> Pig purchases | D20: 15.7.1.1 Emissions of purchased services and contractor operations | E20: =VEERG_15_7_1_1__1_EmissionsFromPurchasedServices_Result_Method1 -> No data | F20: =VEERG_15_7_1_1__1_EmissionsFromPurchasedServices_Result_Method2 -> 42 | G20: t CO2e
A21: =HYPERLINK("#'Input - Poultry purchases'!A1", "Poultry purchases") -> Poultry purchases | D21: 15.8.1.1 Embedded emissions from use of packaging materials | E21: =VEERG_15_8_1_1__1_EmissionsFromPurchasedPackaging_Result_Method1 -> 7.44 | F21: =VEERG_15_8_1_1__1_EmissionsFromPurchasedPackaging_Result_Method2 -> 6 | G21: t CO2e
A22: =HYPERLINK("#'Input - Freight'!A1", "Freight") -> Freight | D22: 15.9.1.1 Embedded emissions from use of grow media products | E22: =VEERG_15_9_1_1__1_EmissionsFromPurchasedGrowMedia_Result_Method1 -> No data | F22: =VEERG_15_9_1_1__1_EmissionsFromPurchasedGrowMedia_Result_Method2 -> 40.2 | G22: t CO2e
A23: =HYPERLINK("#'Input - Solid waste'!A1", "Solid waste") -> Solid waste | D23: 15.10 Other purchased goods and services generic estimate | E23: - | F23: - | G23: t CO2e
A24: =HYPERLINK("#'Input - Manure sent off-site'!A1", "Manure sent off-site") -> Manure sent off-site | D24: Cleaning chemical purchases | E24: =VEERG_15_10_1_1__1_OtherPurchasedGoodsAndServices_CleaningChemicals_Result_Method1 -> 0.5051 | F24: =VEERG_15_10_1_1__1_OtherPurchasedGoodsAndServices_CleaningChemicals_Result_Method2 -> 2.73 | G24: t CO2e
A25: =HYPERLINK("#'Input - Electricity'!A1", "Electricity") -> Electricity | D25: Pharmacy chemical purchases | E25: =VEERG_15_10_1_1__1_OtherPurchasedGoodsAndServices_PharmacyChemicals_Result_Method1 -> 0.015636 | F25: =VEERG_15_10_1_1__1_OtherPurchasedGoodsAndServices_PharmacyChemicals_Result_Method2 -> 0.0134 | G25: t CO2e
D26: Seed | E26: =VEERG_15_10_1_1__1_OtherPurchasedGoodsAndServices_Seed_Result_Method1 -> 0.8439 | F26: =VEERG_15_10_1_1__1_OtherPurchasedGoodsAndServices_Seed_Result_Method2 -> 0.7142 | G26: t CO2e
D27: Miscellaneous Inputs | E27: =VEERG_15_10_1_1__1_OtherPurchasedGoodsAndServices_Misc_Result_Method1 -> 2.9531 | F27: =VEERG_15_10_1_1__1_OtherPurchasedGoodsAndServices_Misc_Result_Method2 -> 0.08586 | G27: t CO2e
A28: CALCULATIONS | D28: Uncategorised products with no Method 1 EF data | E28: =VEERG_15_10_1_1__1_OtherPurchasedGoodsAndServices_Uncategorised_Result_Method1 -> No data | F28: =VEERG_15_10_1_1__1_OtherPurchasedGoodsAndServices_Uncategorised_Result_Method2 -> 4000 | G28: t CO2e
A29: =HYPERLINK("#'15 Scope 3'!A1", "15 Scope 3") -> 15 Scope 3 | D29: 15.11.1.1 Total upstream emissions from scope 1 fuel consumption | E29: =VEERG_15_11_1_1__1_TotalUpstreamEmissionsFromFuel_Result -> 26.794 | F29: =E29 -> 26.794 | G29: t CO2e
A30: =HYPERLINK("#'10.1.1-2 Solid waste treatment'!A1", "10.1.1-2 Solid waste treatment") -> 10.1.1-2 Solid waste treatment | D30: 15.12.1.1 Scope 3 emissions from purchased electricity location based | E30: =VEERG_15_12_1_1__1_UpstreamPurchasedElectricityLocationBased_Result -> 2.7 | F30: =E30 -> 2.7 | G30: t CO2e
A31: =HYPERLINK("#'Calcs - Manure sent off-site'!A1", "Calcs - Manure sent off-site") -> Calcs - Manure sent off-site | D31: 15.12.1.2 Scope 3 emissions from purchased electricity market based | E31: =VEERG_15_12_1_2__1_UpstreamPurchasedElectricityMarketBasedVariation_Result -> 1.5 | F31: =E31 -> 1.5 | G31: t CO2e
A32: =HYPERLINK("#'8.1.1.1-2 Transport fuel'!A1", "8.1.1.1-2 Transport fuel") -> 8.1.1.1-2 Transport fuel | D32: 15.13.1.1 Emissions from manure sent off site applied to soils in another farming system or enterprise | E32: =VEERG_15_13_1_1__1_EmissionsFromManureSentOffSite_Result_Method1_CO2e -> 3.7936643 | F32: =VEERG_15_13_1_1__1_EmissionsFromManureSentOffSite_Result_Method2_CO2e -> 7.5873286 | G32: t CO2e
A33: =HYPERLINK("#'8.2.1.1-2 Stationary fuel'!A1", "8.2.1.1-2 Stationary fuel") -> 8.2.1.1-2 Stationary fuel | D33: 15.13.1.3 Emissions from solid waste sent to a treatment facility | E33: =VEERG_10_1_1_1__1_EmissionsFromWasteManagement_Scope3_Result_Method1 -> 441.15 | F33: =E33 -> 441.15 | G33: t CO2e
D34: 15.14.1.1 Embedded emissions from upstream freight | E34: - | F34: - | G34: t CO2e
D35: Incoming freight | E35: =VEERG_15_14_1_1__1_EmbeddedEmissionsFromUpstreamFreight_Incoming_Result_Method1 -> No data | F35: =VEERG_15_14_1_1__1_EmbeddedEmissionsFromUpstreamFreight_Incoming_Result_Method2 -> 5146700 | G35: t CO2e
A36: APPENDICES | D36: Outgoing freight | E36: =VEERG_15_14_1_1__1_EmbeddedEmissionsFromUpstreamFreight_Outgoing_Result_Method1 -> No data | F36: =VEERG_15_14_1_1__1_EmbeddedEmissionsFromUpstreamFreight_Outgoing_Result_Method2 -> 432640 | G36: t CO2e
A37: =HYPERLINK("#'Constants - Scope 3'!A1", "Constants - Scope 3") -> Constants - Scope 3 | D37: Total | E37: =SUM(E10:E36) -> 2038.5837 | F37: =SUM(F10:F36) -> 5585488.9 | G37: t CO2e
A38: =HYPERLINK("#'Constants - Solid Waste'!A1", "Constants - Solid Waste") -> Constants - Solid Waste
A39: =HYPERLINK("#'Constants - Fuel'!A1", "Constants - Fuel") -> Constants - Fuel
A40: =HYPERLINK("#'Constants - Poultry'!A1", "Constants - Poultry") -> Constants - Poultry
A41: =HYPERLINK("#'Constants - Swine'!A1", "Constants - Swine") -> Constants - Swine
A42: =HYPERLINK("#'Constants - Dairy'!A1", "Constants - Dairy") -> Constants - Dairy
...

Sheet Input - Site
A1: #VALUE! | C1: Input - Site
A3: =HYPERLINK("#'Overview'!A1", "Overview") -> Overview
A4: =HYPERLINK("#'Results'!A1", "Results") -> Results
D5: Your business
A7: INPUTS | D7: Farm name | E7: Test Farms
A8: =HYPERLINK("#'Input - Site'!A1", "Site") -> Site | D8: Reporting entity name | E8: Test Farms Pty Ltd
A9: =HYPERLINK("#'Input - Fuel'!A1", "Fuel") -> Fuel
A10: =HYPERLINK("#'Input - Fert Prod System'!A1", "Fert Prod System") -> Fert Prod System | D10: 💡An 'Emissions accounting period' is a 12 month period where the business can report on the emissions, and is typically the same as the business' financial accounting period.
A11: =HYPERLINK("#'Input - Fertiliser'!A1", "Fertiliser") -> Fertiliser
A12: =HYPERLINK("#'Input - Common farm inputs'!A1", "Common farm inputs") -> Common farm inputs | D12: Emissions calculation period start date | E12: 45292 | F12: ← DD/MM/YYYY or DD Month YYYY
A13: =HYPERLINK("#'Input - Processing inputs'!A1", "Processing inputs") -> Processing inputs | D13: Emissions calculation period end date | E13: =DATE(YEAR(X_Cell_Site_StartDate)+1,MONTH(X_Cell_Site_StartDate),DAY(X_Cell_Site_StartDate))-1 -> 45657 | F13: ← Automatically calculated, 12 months after start date
A14: =HYPERLINK("#'Input - Crop pasture farm input'!A1", "Crop pasture farm input") -> Crop pasture farm input
A15: =HYPERLINK("#'Input - Hort farm Inputs'!A1", "Hort farm Inputs") -> Hort farm Inputs
A16: =HYPERLINK("#'Input - Livestock farm Inputs'!A1", "Livestock farm Inputs") -> Livestock farm Inputs | D16: Location and climate
A17: =HYPERLINK("#'Input - Aquaculture inputs'!A1", "Aquaculture inputs") -> Aquaculture inputs
A18: =HYPERLINK("#'Input - Beef cattle purchases'!A1", "Beef cattle purchases") -> Beef cattle purchases | D18: Location information is used to reference some region and climate-specific emission factors
A19: =HYPERLINK("#'Input - Dairy cattle purchases'!A1", "Dairy cattle purchases") -> Dairy cattle purchases | D19: Tip: Use the web-based GAF Location Helper tool to easily get region and climate information. You will need an internet connection to use the GAF Location Helper.
A20: =HYPERLINK("#'Input - Pig purchases'!A1", "Pig purchases") -> Pig purchases
A21: =HYPERLINK("#'Input - Poultry purchases'!A1", "Poultry purchases") -> Poultry purchases | D21: State | E21: Western Australia | F21: ← Please select
A22: =HYPERLINK("#'Input - Freight'!A1", "Freight") -> Freight | D22: Region (ABS Statistical area level 4) if state is WA | E22: Western Australia - Outback (South) | F22: ← Please select
A23: =HYPERLINK("#'Input - Solid waste'!A1", "Solid waste") -> Solid waste | D23: Leaching zone | E23: NO - Not in leaching zone | F23: ← Please select
A24: =HYPERLINK("#'Input - Manure sent off-site'!A1", "Manure sent off-site") -> Manure sent off-site | D24: Elevation | E24: 307.7 | F24: Meters
A25: =HYPERLINK("#'Input - Electricity'!A1", "Electricity") -> Electricity | D25: Average temperature for reporting period | E25: 18 | F25: Degrees celsius
D26: Total rainfall for reporting period | E26: 599 | F26: Millimetres
D27: Potential evapotranspiration for reporting period | E27: 1326 | F27: Millimetres
A28: CALCULATIONS | D28: Number of frost days for reporting period | E28: 7 | F28: Days
A29: =HYPERLINK("#'15 Scope 3'!A1", "15 Scope 3") -> 15 Scope 3 | D29: MAP:PET ratio | E29: =X_Cell_Site_TotalRainfall/X_Cell_Site_PotentialEvapotranspiration -> 0.45173454
A30: =HYPERLINK("#'10.1.1-2 Solid waste treatment'!A1", "10.1.1-2 Solid waste treatment") -> 10.1.1-2 Solid waste treatment | D30: Rainfall zone | E30: =Common_InputFunctions.Utility_LookupItemFromMinMax(X_Cell_Site_TotalRainfall,Table_SourceData_RainfallZones[Min rainfall],Table_SourceData_RainfallZones[Max rainfall],Table_SourceData_RainfallZones[Rainfall Zone]) -> Low rainfall
A31: =HYPERLINK("#'Calcs - Manure sent off-site'!A1", "Calcs - Manure sent off-site") -> Calcs - Manure sent off-site | D31: Climate zone | E31: =Common_InputFunctions.Utility_GetClimateZone(X_Cell_Site_AverageTemperature,X_Cell_Site_TotalRainfall,X_Cell_Site_FrostDays,X_Cell_Site_Elevation,X_Cell_Site_MapPetRatio,Table_SourceData_ClimateZones[Min temp],Table_SourceData_ClimateZones[Max temp],Table_SourceData_ClimateZones[Min rainfall],Table_SourceData_ClimateZones[Max rainfall],Table_SourceData_ClimateZones[Min frost days],Table_SourceData_ClimateZones[Max frost days],Table_SourceData_ClimateZones[Min elevation],Table_SourceData_ClimateZones[Max elevation],Table_SourceData_ClimateZones[Min MAP:PET],Table_SourceData_ClimateZones[Max MAP:PET],Table_SourceData_ClimateZones[Climate zone]) -> Warm temperate dry
A32: =HYPERLINK("#'8.1.1.1-2 Transport fuel'!A1", "8.1.1.1-2 Transport fuel") -> 8.1.1.1-2 Transport fuel | D32: Wet or dry climate zone | E32: =Common_InputFunctions.Utility_LookupValueInTable(X_Cell_Site_ClimateZone,Table_SourceData_WetDryZones[Climate zone],Table_SourceData_WetDryZones[Wet or Dry Zone]) -> Dry climate zone
A33: =HYPERLINK("#'8.2.1.1-2 Stationary fuel'!A1", "8.2.1.1-2 Stationary fuel") -> 8.2.1.1-2 Stationary fuel | D33: Temperature zone | E33: =Common_InputFunctions.Utility_LookupItemFromMinMax(X_Cell_Site_AverageTemperature,Table_SourceData_TemperatureZones[Min MAT],Table_SourceData_TemperatureZones[Max MAT],Table_SourceData_TemperatureZones[Temperature Zone]) -> Temperate
A36: APPENDICES
A37: =HYPERLINK("#'Constants - Scope 3'!A1", "Constants - Scope 3") -> Constants - Scope 3
A38: =HYPERLINK("#'Constants - Solid Waste'!A1", "Constants - Solid Waste") -> Constants - Solid Waste
A39: =HYPERLINK("#'Constants - Fuel'!A1", "Constants - Fuel") -> Constants - Fuel
A40: =HYPERLINK("#'Constants - Poultry'!A1", "Constants - Poultry") -> Constants - Poultry
A41: =HYPERLINK("#'Constants - Swine'!A1", "Constants - Swine") -> Constants - Swine
A42: =HYPERLINK("#'Constants - Dairy'!A1", "Constants - Dairy") -> Constants - Dairy
A43: =HYPERLINK("#'Constants - Pasture Beef'!A1", "Constants - Pasture Beef") -> Constants - Pasture Beef
A44: =HYPERLINK("#'Constants - Common Livestock'!A1", "Constants - Common Livestock") -> Constants - Common Livestock
...

Sheet Input - Fuel
A1: #VALUE! | C1: Input - Fuel
A3: =HYPERLINK("#'Overview'!A1", "Overview") -> Overview
A4: =HYPERLINK("#'Results'!A1", "Results") -> Results
D5: Fuel purchases and consumption
A7: INPUTS | D7: A 'Metropolitan' location is:
A8: =HYPERLINK("#'Input - Site'!A1", "Site") -> Site | D8: ● On or east of the dividing range in NSW (including Canberra and Queanbeyan)
A9: =HYPERLINK("#'Input - Fuel'!A1", "Fuel") -> Fuel | D9: ● In Melbourne, Brisbane, Adelaide or Perth
A10: =HYPERLINK("#'Input - Fert Prod System'!A1", "Fert Prod System") -> Fert Prod System
A11: =HYPERLINK("#'Input - Fertiliser'!A1", "Fertiliser") -> Fertiliser | D11: Is the property in a Metropolitan location? | E11: Metro | F11: ← Please select
A12: =HYPERLINK("#'Input - Common farm inputs'!A1", "Common farm inputs") -> Common farm inputs
A13: =HYPERLINK("#'Input - Processing inputs'!A1", "Processing inputs") -> Processing inputs | D13: 💡 You can add more rows to the table by right-clicking on the table and selecting "Insert > Table rows above/below"
A14: =HYPERLINK("#'Input - Crop pasture farm input'!A1", "Crop pasture farm input") -> Crop pasture farm input | D14: 💡 'Percent consumed" is 100% by default. If you purchased more fuel than was consumed you can edit this field.
A15: =HYPERLINK("#'Input - Hort farm Inputs'!A1", "Hort farm Inputs") -> Hort farm Inputs
A16: =HYPERLINK("#'Input - Livestock farm Inputs'!A1", "Livestock farm Inputs") -> Livestock farm Inputs | D16: Fuel use (select) | E16: Fuel type (select) | F16: Amount purchased | G16: Amount unit | H16: Percent consumed | I16: Amount consumed | J16: Amount consumed unit
A17: =HYPERLINK("#'Input - Aquaculture inputs'!A1", "Aquaculture inputs") -> Aquaculture inputs | D17: Power standalone machinery or heating | E17: Town gas in GJ | F17: 100 | G17: {=Common_InputFunctions.Utility_LookupValueInTable(Table_Input_Fuel[[#This Row],[Fuel type (select)]],Table_FuelTypes_Units[Fuel type], Table_FuelTypes_Units[Input Unit])} -> GJ | H17: =1 -> 1 | I17: =Table_Input_Fuel[[#This Row],[Amount purchased]]*Table_Input_Fuel[[#This Row],[Percent consumed]]*IF(Table_Input_Fuel[[#This Row],[Amount unit]]="L", 10^-3, 1) -> 100 | J17: {=Common_InputFunctions.Utility_LookupValueInTable(Table_Input_Fuel[[#This Row],[Fuel type (select)]],Table_FuelTypes_Units[Fuel type], Table_FuelTypes_Units[Unit])} -> GJ
A18: =HYPERLINK("#'Input - Beef cattle purchases'!A1", "Beef cattle purchases") -> Beef cattle purchases | D18: Power standalone machinery or heating | E18: Petrol | F18: 10000 | G18: {=Common_InputFunctions.Utility_LookupValueInTable(Table_Input_Fuel[[#This Row],[Fuel type (select)]],Table_FuelTypes_Units[Fuel type], Table_FuelTypes_Units[Input Unit])} -> L | H18: =1 -> 1 | I18: =Table_Input_Fuel[[#This Row],[Amount purchased]]*Table_Input_Fuel[[#This Row],[Percent consumed]]*IF(Table_Input_Fuel[[#This Row],[Amount unit]]="L", 10^-3, 1) -> 10 | J18: {=Common_InputFunctions.Utility_LookupValueInTable(Table_Input_Fuel[[#This Row],[Fuel type (select)]],Table_FuelTypes_Units[Fuel type], Table_FuelTypes_Units[Unit])} -> kL
A19: =HYPERLINK("#'Input - Dairy cattle purchases'!A1", "Dairy cattle purchases") -> Dairy cattle purchases | D19: Cars and light commercial vehicles | E19: Diesel | F19: 10000 | G19: {=Common_InputFunctions.Utility_LookupValueInTable(Table_Input_Fuel[[#This Row],[Fuel type (select)]],Table_FuelTypes_Units[Fuel type], Table_FuelTypes_Units[Input Unit])} -> L | H19: =1 -> 1 | I19: =Table_Input_Fuel[[#This Row],[Amount purchased]]*Table_Input_Fuel[[#This Row],[Percent consumed]]*IF(Table_Input_Fuel[[#This Row],[Amount unit]]="L", 10^-3, 1) -> 10 | J19: {=Common_InputFunctions.Utility_LookupValueInTable(Table_Input_Fuel[[#This Row],[Fuel type (select)]],Table_FuelTypes_Units[Fuel type], Table_FuelTypes_Units[Unit])} -> kL
A20: =HYPERLINK("#'Input - Pig purchases'!A1", "Pig purchases") -> Pig purchases | D20: Off-road Agriculture and forestry equipment | E20: Diesel | F20: 10000 | G20: {=Common_InputFunctions.Utility_LookupValueInTable(Table_Input_Fuel[[#This Row],[Fuel type (select)]],Table_FuelTypes_Units[Fuel type], Table_FuelTypes_Units[Input Unit])} -> L | H20: =1 -> 1 | I20: =Table_Input_Fuel[[#This Row],[Amount purchased]]*Table_Input_Fuel[[#This Row],[Percent consumed]]*IF(Table_Input_Fuel[[#This Row],[Amount unit]]="L", 10^-3, 1) -> 10 | J20: {=Common_InputFunctions.Utility_LookupValueInTable(Table_Input_Fuel[[#This Row],[Fuel type (select)]],Table_FuelTypes_Units[Fuel type], Table_FuelTypes_Units[Unit])} -> kL
A21: =HYPERLINK("#'Input - Poultry purchases'!A1", "Poultry purchases") -> Poultry purchases | D21: Vessels | E21: Fuel oil | F21: 10000 | G21: {=Common_InputFunctions.Utility_LookupValueInTable(Table_Input_Fuel[[#This Row],[Fuel type (select)]],Table_FuelTypes_Units[Fuel type], Table_FuelTypes_Units[Input Unit])} -> L | H21: =1 -> 1 | I21: =Table_Input_Fuel[[#This Row],[Amount purchased]]*Table_Input_Fuel[[#This Row],[Percent consumed]]*IF(Table_Input_Fuel[[#This Row],[Amount unit]]="L", 10^-3, 1) -> 10 | J21: {=Common_InputFunctions.Utility_LookupValueInTable(Table_Input_Fuel[[#This Row],[Fuel type (select)]],Table_FuelTypes_Units[Fuel type], Table_FuelTypes_Units[Unit])} -> kL
A22: =HYPERLINK("#'Input - Freight'!A1", "Freight") -> Freight
A23: =HYPERLINK("#'Input - Solid waste'!A1", "Solid waste") -> Solid waste
A24: =HYPERLINK("#'Input - Manure sent off-site'!A1", "Manure sent off-site") -> Manure sent off-site
A25: =HYPERLINK("#'Input - Electricity'!A1", "Electricity") -> Electricity
A28: CALCULATIONS
A29: =HYPERLINK("#'15 Scope 3'!A1", "15 Scope 3") -> 15 Scope 3
A30: =HYPERLINK("#'10.1.1-2 Solid waste treatment'!A1", "10.1.1-2 Solid waste treatment") -> 10.1.1-2 Solid waste treatment
A31: =HYPERLINK("#'Calcs - Manure sent off-site'!A1", "Calcs - Manure sent off-site") -> Calcs - Manure sent off-site
A32: =HYPERLINK("#'8.1.1.1-2 Transport fuel'!A1", "8.1.1.1-2 Transport fuel") -> 8.1.1.1-2 Transport fuel
A33: =HYPERLINK("#'8.2.1.1-2 Stationary fuel'!A1", "8.2.1.1-2 Stationary fuel") -> 8.2.1.1-2 Stationary fuel
A36: APPENDICES
A37: =HYPERLINK("#'Constants - Scope 3'!A1", "Constants - Scope 3") -> Constants - Scope 3
A38: =HYPERLINK("#'Constants - Solid Waste'!A1", "Constants - Solid Waste") -> Constants - Solid Waste
A39: =HYPERLINK("#'Constants - Fuel'!A1", "Constants - Fuel") -> Constants - Fuel
A40: =HYPERLINK("#'Constants - Poultry'!A1", "Constants - Poultry") -> Constants - Poultry
A41: =HYPERLINK("#'Constants - Swine'!A1", "Constants - Swine") -> Constants - Swine
A42: =HYPERLINK("#'Constants - Dairy'!A1", "Constants - Dairy") -> Constants - Dairy
A43: =HYPERLINK("#'Constants - Pasture Beef'!A1", "Constants - Pasture Beef") -> Constants - Pasture Beef
A44: =HYPERLINK("#'Constants - Common Livestock'!A1", "Constants - Common Livestock") -> Constants - Common Livestock
A45: =HYPERLINK("#'Constants - Fertiliser'!A1", "Constants - Fertiliser") -> Constants - Fertiliser
A46: =HYPERLINK("#'Constants - Electricity'!A1", "Constants - Electricity") -> Constants - Electricity
...

Sheet Input - Fert Prod System
A1: #VALUE! | C1: Input - Fertiliser Production System
A3: =HYPERLINK("#'Overview'!A1", "Overview") -> Overview
A4: =HYPERLINK("#'Results'!A1", "Results") -> Results
D5: Production system | E5: Crop | F5: ← Please select
D6: Crop type | E6: Maize | F6: ← Please select
A7: INPUTS | D7: Irrigation method | E7: Drip irrigation | F7: ← Please select
A8: =HYPERLINK("#'Input - Site'!A1", "Site") -> Site | D8: Area under cropping | E8: 100 | F8: hectares
A9: =HYPERLINK("#'Input - Fuel'!A1", "Fuel") -> Fuel
A10: =HYPERLINK("#'Input - Fert Prod System'!A1", "Fert Prod System") -> Fert Prod System
A11: =HYPERLINK("#'Input - Fertiliser'!A1", "Fertiliser") -> Fertiliser
A12: =HYPERLINK("#'Input - Common farm inputs'!A1", "Common farm inputs") -> Common farm inputs
A13: =HYPERLINK("#'Input - Processing inputs'!A1", "Processing inputs") -> Processing inputs
A14: =HYPERLINK("#'Input - Crop pasture farm input'!A1", "Crop pasture farm input") -> Crop pasture farm input
A15: =HYPERLINK("#'Input - Hort farm Inputs'!A1", "Hort farm Inputs") -> Hort farm Inputs
A16: =HYPERLINK("#'Input - Livestock farm Inputs'!A1", "Livestock farm Inputs") -> Livestock farm Inputs
A17: =HYPERLINK("#'Input - Aquaculture inputs'!A1", "Aquaculture inputs") -> Aquaculture inputs
A18: =HYPERLINK("#'Input - Beef cattle purchases'!A1", "Beef cattle purchases") -> Beef cattle purchases
A19: =HYPERLINK("#'Input - Dairy cattle purchases'!A1", "Dairy cattle purchases") -> Dairy cattle purchases
A20: =HYPERLINK("#'Input - Pig purchases'!A1", "Pig purchases") -> Pig purchases
A21: =HYPERLINK("#'Input - Poultry purchases'!A1", "Poultry purchases") -> Poultry purchases
A22: =HYPERLINK("#'Input - Freight'!A1", "Freight") -> Freight
A23: =HYPERLINK("#'Input - Solid waste'!A1", "Solid waste") -> Solid waste
A24: =HYPERLINK("#'Input - Manure sent off-site'!A1", "Manure sent off-site") -> Manure sent off-site
A25: =HYPERLINK("#'Input - Electricity'!A1", "Electricity") -> Electricity
A28: CALCULATIONS
A29: =HYPERLINK("#'15 Scope 3'!A1", "15 Scope 3") -> 15 Scope 3
A30: =HYPERLINK("#'10.1.1-2 Solid waste treatment'!A1", "10.1.1-2 Solid waste treatment") -> 10.1.1-2 Solid waste treatment
A31: =HYPERLINK("#'Calcs - Manure sent off-site'!A1", "Calcs - Manure sent off-site") -> Calcs - Manure sent off-site
A32: =HYPERLINK("#'8.1.1.1-2 Transport fuel'!A1", "8.1.1.1-2 Transport fuel") -> 8.1.1.1-2 Transport fuel
A33: =HYPERLINK("#'8.2.1.1-2 Stationary fuel'!A1", "8.2.1.1-2 Stationary fuel") -> 8.2.1.1-2 Stationary fuel
A36: APPENDICES
A37: =HYPERLINK("#'Constants - Scope 3'!A1", "Constants - Scope 3") -> Constants - Scope 3
A38: =HYPERLINK("#'Constants - Solid Waste'!A1", "Constants - Solid Waste") -> Constants - Solid Waste
A39: =HYPERLINK("#'Constants - Fuel'!A1", "Constants - Fuel") -> Constants - Fuel
A40: =HYPERLINK("#'Constants - Poultry'!A1", "Constants - Poultry") -> Constants - Poultry
A41: =HYPERLINK("#'Constants - Swine'!A1", "Constants - Swine") -> Constants - Swine
A42: =HYPERLINK("#'Constants - Dairy'!A1", "Constants - Dairy") -> Constants - Dairy
A43: =HYPERLINK("#'Constants - Pasture Beef'!A1", "Constants - Pasture Beef") -> Constants - Pasture Beef
A44: =HYPERLINK("#'Constants - Common Livestock'!A1", "Constants - Common Livestock") -> Constants - Common Livestock
A45: =HYPERLINK("#'Constants - Fertiliser'!A1", "Constants - Fertiliser") -> Constants - Fertiliser
...

Sheet Input - Fertiliser
A1: #VALUE! | C1: Input - Fertiliser
A3: =HYPERLINK("#'Overview'!A1", "Overview") -> Overview
A4: =HYPERLINK("#'Results'!A1", "Results") -> Results
D5: Inorganic fertiliser applied
A7: INPUTS | D7: 💡You can add more rows to tables by right-clicking on the table and selecting "Insert > Table rows above/below".
A8: =HYPERLINK("#'Input - Site'!A1", "Site") -> Site | D8: 💡The application area is the same as the area under pasture / cropping by default. You can edit it if the application area is different.
A9: =HYPERLINK("#'Input - Fuel'!A1", "Fuel") -> Fuel
A10: =HYPERLINK("#'Input - Fert Prod System'!A1", "Fert Prod System") -> Fert Prod System | D10: Branded fertiliser products
A11: =HYPERLINK("#'Input - Fertiliser'!A1", "Fertiliser") -> Fertiliser | D11: Product (select) | E11: Amount applied per hectare | F11: Application unit | G11: Application area (ha) | H11: Density | I11: Total applied (kg) | J11: Ingredient 1 | K11: Ingredient 1 percent | L11: Ingredient 2 | M11: Ingredient 2 percent | N11: Ingredient 3 | O11: Ingredient 3 percent | P11: Ingredient 4 | Q11: Ingredient 4 percent | R11: Ingredient 5 | S11: Ingredient 5 percent | T11: Ingredient 6 | U11: Ingredient 6 percent | V11: % N (Ingredients) | W11: % N (declared) | X11: N application rate (kg/ha) | Y11: Urea source | Z11: Ammonia source
A12: =HYPERLINK("#'Input - Common farm inputs'!A1", "Common farm inputs") -> Common farm inputs | D12: Urea | E12: 100 | F12: =IFERROR(_xlfn.XLOOKUP(Table_Input_InorganicFertiliser_Brands[[#This Row],[Product (select)]],FertiliserProducts[Product],FertiliserProducts[Unit]), "kg") -> kg | G12: =X_Cell_Fertiliser_AreaUnderCropping -> 100 | H12: =IFERROR(_xlfn.XLOOKUP(Table_Input_InorganicFertiliser_Brands[[#This Row],[Product (select)]],FertiliserProducts[Product],FertiliserProducts[Density]), 1) -> 1 | I12: =(Table_Input_InorganicFertiliser_Brands[[#This Row],[Amount applied per hectare]]*Table_Input_InorganicFertiliser_Brands[[#This Row],[Density]])*Table_Input_InorganicFertiliser_Brands[[#This Row],[Application area (ha)]] -> 10000 | J12: {=Fertiliser_InputFunctions.Fertiliser_FertiliserProductLookup(Table_Input_InorganicFertiliser_Brands[[#This Row],[Product (select)]], Table_Input_InorganicFertiliser_Brands[[#Headers],[Ingredient 1]], FertiliserProducts[#Data], FertiliserProducts[Product], FertiliserProducts[#Headers])} -> Urea | K12: {=Fertiliser_InputFunctions.Fertiliser_FertiliserProductLookup(Table_Input_InorganicFertiliser_Brands[[#This Row],[Product (select)]], Table_Input_InorganicFertiliser_Brands[[#Headers],[Ingredient 1 percent]], FertiliserProducts[#Data], FertiliserProducts[Product], FertiliserProducts[#Headers])} -> 1 | L12: {=Fertiliser_InputFunctions.Fertiliser_FertiliserProductLookup(Table_Input_InorganicFertiliser_Brands[[#This Row],[Product (select)]], Table_Input_InorganicFertiliser_Brands[[#Headers],[Ingredient 2]], FertiliserProducts[#Data], FertiliserProducts[Product], FertiliserProducts[#Headers])} | M12: {=Fertiliser_InputFunctions.Fertiliser_FertiliserProductLookup(Table_Input_InorganicFertiliser_Brands[[#This Row],[Product (select)]], Table_Input_InorganicFertiliser_Brands[[#Headers],[Ingredient 2 percent]], FertiliserProducts[#Data], FertiliserProducts[Product], FertiliserProducts[#Headers])} | N12: {=Fertiliser_InputFunctions.Fertiliser_FertiliserProductLookup(Table_Input_InorganicFertiliser_Brands[[#This Row],[Product (select)]], Table_Input_InorganicFertiliser_Brands[[#Headers],[Ingredient 3]], FertiliserProducts[#Data], FertiliserProducts[Product], FertiliserProducts[#Headers])} | O12: {=Fertiliser_InputFunctions.Fertiliser_FertiliserProductLookup(Table_Input_InorganicFertiliser_Brands[[#This Row],[Product (select)]], Table_Input_InorganicFertiliser_Brands[[#Headers],[Ingredient 3 percent]], FertiliserProducts[#Data], FertiliserProducts[Product], FertiliserProducts[#Headers])} | P12: {=Fertiliser_InputFunctions.Fertiliser_FertiliserProductLookup(Table_Input_InorganicFertiliser_Brands[[#This Row],[Product (select)]], Table_Input_InorganicFertiliser_Brands[[#Headers],[Ingredient 4]], FertiliserProducts[#Data], FertiliserProducts[Product], FertiliserProducts[#Headers])} | Q12: {=Fertiliser_InputFunctions.Fertiliser_FertiliserProductLookup(Table_Input_InorganicFertiliser_Brands[[#This Row],[Product (select)]], Table_Input_InorganicFertiliser_Brands[[#Headers],[Ingredient 4 percent]], FertiliserProducts[#Data], FertiliserProducts[Product], FertiliserProducts[#Headers])} | R12: {=Fertiliser_InputFunctions.Fertiliser_FertiliserProductLookup(Table_Input_InorganicFertiliser_Brands[[#This Row],[Product (select)]], Table_Input_InorganicFertiliser_Brands[[#Headers],[Ingredient 5]], FertiliserProducts[#Data], FertiliserProducts[Product], FertiliserProducts[#Headers])} | S12: {=Fertiliser_InputFunctions.Fertiliser_FertiliserProductLookup(Table_Input_InorganicFertiliser_Brands[[#This Row],[Product (select)]], Table_Input_InorganicFertiliser_Brands[[#Headers],[Ingredient 5 percent]], FertiliserProducts[#Data], FertiliserProducts[Product], FertiliserProducts[#Headers])} | T12: {=Fertiliser_InputFunctions.Fertiliser_FertiliserProductLookup(Table_Input_InorganicFertiliser_Brands[[#This Row],[Product (select)]], Table_Input_InorganicFertiliser_Brands[[#Headers],[Ingredient 6]], FertiliserProducts[#Data], FertiliserProducts[Product], FertiliserProducts[#Headers])} | U12: {=Fertiliser_InputFunctions.Fertiliser_FertiliserProductLookup(Table_Input_InorganicFertiliser_Brands[[#This Row],[Product (select)]], Table_Input_InorganicFertiliser_Brands[[#Headers],[Ingredient 6 percent]], FertiliserProducts[#Data], FertiliserProducts[Product], FertiliserProducts[#Headers])} | V12: =IFERROR((_xlfn.XLOOKUP(Table_Input_InorganicFertiliser_Brands[[#This Row],[Ingredient 1]], Table_Fertiliser_ChemicalCompounds[Fertiliser type f],Table_Fertiliser_ChemicalCompounds[FNinorganic f])*Table_Input_InorganicFertiliser_Brands[[#This Row],[Ingredient 1 percent]]), 0)+ IFERROR((_xlfn.XLOOKUP(Table_Input_InorganicFertiliser_Brands[[#This Row],[Ingredient 2]],Table_Fertiliser_ChemicalCompounds[Fertiliser type f],Table_Fertiliser_ChemicalCompounds[FNinorganic f])*Table_Input_InorganicFertiliser_Brands[[#This Row],[Ingredient 2 percent]]), 0)+ IFERROR((_xlfn.XLOOKUP(Table_Input_InorganicFertiliser_Brands[[#This Row],[Ingredient 3]],Table_Fertiliser_ChemicalCompounds[Fertiliser type f],Table_Fertiliser_ChemicalCompounds[FNinorganic f])*Table_Input_InorganicFertiliser_Brands[[#This Row],[Ingredient 3 percent]]), 0)+ IFERROR((_xlfn.XLOOKUP(Table_Input_InorganicFertiliser_Brands[[#This Row],[Ingredient 4]],Table_Fertiliser_ChemicalCompounds[Fertiliser type f],Table_Fertiliser_ChemicalCompounds[FNinorganic f])*Table_Input_InorganicFertiliser_Brands[[#This Row],[Ingredient 4 percent]]), 0)+ IFERROR((_xlfn.XLOOKUP(Table_Input_InorganicFertiliser_Brands[[#This Row],[Ingredient 5]],Table_Fertiliser_ChemicalCompounds[Fertiliser type f],Table_Fertiliser_ChemicalCompounds[FNinorganic f])*Table_Input_InorganicFertiliser_Brands[[#This Row],[Ingredient 5 percent]]), 0)+ IFERROR((_xlfn.XLOOKUP(Table_Input_InorganicFertiliser_Brands[[#This Row],[Ingredient 6]],Table_Fertiliser_ChemicalCompounds[Fertiliser type f],Table_Fertiliser_ChemicalCompounds[FNinorganic f])*Table_Input_InorganicFertiliser_Brands[[#This Row],[Ingredient 6 percent]]), 0) -> 0.46 | W12: {=IFERROR(Fertiliser_InputFunctions.Fertiliser_FertiliserProductLookup(Table_Input_InorganicFertiliser_Brands[[#This Row],[Product (select)]], "N declared", FertiliserProducts[#Data], FertiliserProducts[Product], FertiliserProducts[#Headers])*0.01, 0)} -> 0.46 | X12: =(Table_Input_InorganicFertiliser_Brands[[#This Row],[Amount applied per hectare]]*Table_Input_InorganicFertiliser_Brands[[#This Row],[Density]])*(IF(Table_Input_InorganicFertiliser_Brands[[#This Row],[% N (declared)]], Table_Input_InorganicFertiliser_Brands[[#This Row],[% N (declared)]], Table_Input_InorganicFertiliser_Brands[[#This Row],[% N (Ingredients)]])) -> 46 | Y12: =IFERROR(_xlfn.XLOOKUP(Table_Input_InorganicFertiliser_Brands[[#This Row],[Product (select)]],FertiliserProducts[Product],FertiliserProducts[Urea source]), "") | Z12: =IFERROR(_xlfn.XLOOKUP(Table_Input_InorganicFertiliser_Brands[[#This Row],[Product (select)]],FertiliserProducts[Product],FertiliserProducts[Ammonia source]), "")
A13: =HYPERLINK("#'Input - Processing inputs'!A1", "Processing inputs") -> Processing inputs | D13: Boost-It | E13: 100 | F13: =IFERROR(_xlfn.XLOOKUP(Table_Input_InorganicFertiliser_Brands[[#This Row],[Product (select)]],FertiliserProducts[Product],FertiliserProducts[Unit]), "kg") -> kg | G13: =X_Cell_Fertiliser_AreaUnderCropping -> 100 | H13: =IFERROR(_xlfn.XLOOKUP(Table_Input_InorganicFertiliser_Brands[[#This Row],[Product (select)]],FertiliserProducts[Product],FertiliserProducts[Density]), 1) -> 1 | I13: =(Table_Input_InorganicFertiliser_Brands[[#This Row],[Amount applied per hectare]]*Table_Input_InorganicFertiliser_Brands[[#This Row],[Density]])*Table_Input_InorganicFertiliser_Brands[[#This Row],[Application area (ha)]] -> 10000 | J13: {=Fertiliser_InputFunctions.Fertiliser_FertiliserProductLookup(Table_Input_InorganicFertiliser_Brands[[#This Row],[Product (select)]], Table_Input_InorganicFertiliser_Brands[[#Headers],[Ingredient 1]], FertiliserProducts[#Data], FertiliserProducts[Product], FertiliserProducts[#Headers])} -> Urea | K13: {=Fertiliser_InputFunctions.Fertiliser_FertiliserProductLookup(Table_Input_InorganicFertiliser_Brands[[#This Row],[Product (select)]], Table_Input_InorganicFertiliser_Brands[[#Headers],[Ingredient 1 percent]], FertiliserProducts[#Data], FertiliserProducts[Product], FertiliserProducts[#Headers])} -> 0.521739 | L13: {=Fertiliser_InputFunctions.Fertiliser_FertiliserProductLookup(Table_Input_InorganicFertiliser_Brands[[#This Row],[Product (select)]], Table_Input_InorganicFertiliser_Brands[[#Headers],[Ingredient 2]], FertiliserProducts[#Data], FertiliserProducts[Product], FertiliserProducts[#Headers])} -> Potassium - Generic | M13: {=Fertiliser_InputFunctions.Fertiliser_FertiliserProductLookup(Table_Input_InorganicFertiliser_Brands[[#This Row],[Product (select)]], Table_Input_InorganicFertiliser_Brands[[#Headers],[Ingredient 2 percent]], FertiliserProducts[#Data], FertiliserProducts[Product], FertiliserProducts[#Headers])} -> 0.08 | N13: {=Fertiliser_InputFunctions.Fertiliser_FertiliserProductLookup(Table_Input_InorganicFertiliser_Brands[[#This Row],[Product (select)]], Table_Input_InorganicFertiliser_Brands[[#Headers],[Ingredient 3]], FertiliserProducts[#Data], FertiliserProducts[Product], FertiliserProducts[#Headers])} -> Sulfur - Generic | O13: {=Fertiliser_InputFunctions.Fertiliser_FertiliserProductLookup(Table_Input_InorganicFertiliser_Brands[[#This Row],[Product (select)]], Table_Input_InorganicFertiliser_Brands[[#Headers],[Ingredient 3 percent]], FertiliserProducts[#Data], FertiliserProducts[Product], FertiliserProducts[#Headers])} -> 0.053 | P13: {=Fertiliser_InputFunctions.Fertiliser_FertiliserProductLookup(Table_Input_InorganicFertiliser_Brands[[#This Row],[Product (select)]], Table_Input_InorganicFertiliser_Brands[[#Headers],[Ingredient 4]], FertiliserProducts[#Data], FertiliserProducts[Product], FertiliserProducts[#Headers])} -> Phosphorus - Generic | Q13: {=Fertiliser_InputFunctions.Fertiliser_FertiliserProductLookup(Table_Input_InorganicFertiliser_Brands[[#This Row],[Product (select)]], Table_Input_InorganicFertiliser_Brands[[#Headers],[Ingredient 4 percent]], FertiliserProducts[#Data], FertiliserProducts[Product], FertiliserProducts[#Headers])} -> 0.052 | R13: {=Fertiliser_InputFunctions.Fertiliser_FertiliserProductLookup(Table_Input_InorganicFertiliser_Brands[[#This Row],[Product (select)]], Table_Input_InorganicFertiliser_Brands[[#Headers],[Ingredient 5]], FertiliserProducts[#Data], FertiliserProducts[Product], FertiliserProducts[#Headers])} -> Magnesium | S13: {=Fertiliser_InputFunctions.Fertiliser_FertiliserProductLookup(Table_Input_InorganicFertiliser_Brands[[#This Row],[Product (select)]], Table_Input_InorganicFertiliser_Brands[[#Headers],[Ingredient 5 percent]], FertiliserProducts[#Data], FertiliserProducts[Product], FertiliserProducts[#Headers])} -> 0.013 | T13: {=Fertiliser_InputFunctions.Fertiliser_FertiliserProductLookup(Table_Input_InorganicFertiliser_Brands[[#This Row],[Product (select)]], Table_Input_InorganicFertiliser_Brands[[#Headers],[Ingredient 6]], FertiliserProducts[#Data], FertiliserProducts[Product], FertiliserProducts[#Headers])} -> Zinc | U13: {=Fertiliser_InputFunctions.Fertiliser_FertiliserProductLookup(Table_Input_InorganicFertiliser_Brands[[#This Row],[Product (select)]], Table_Input_InorganicFertiliser_Brands[[#Headers],[Ingredient 6 percent]], FertiliserProducts[#Data], FertiliserProducts[Product], FertiliserProducts[#Headers])} -> 0.002 | V13: =IFERROR((_xlfn.XLOOKUP(Table_Input_InorganicFertiliser_Brands[[#This Row],[Ingredient 1]], Table_Fertiliser_ChemicalCompounds[Fertiliser type f],Table_Fertiliser_ChemicalCompounds[FNinorganic f])*Table_Input_InorganicFertiliser_Brands[[#This Row],[Ingredient 1 percent]]), 0)+ IFERROR((_xlfn.XLOOKUP(Table_Input_InorganicFertiliser_Brands[[#This Row],[Ingredient 2]],Table_Fertiliser_ChemicalCompounds[Fertiliser type f],Table_Fertiliser_ChemicalCompounds[FNinorganic f])*Table_Input_InorganicFertiliser_Brands[[#This Row],[Ingredient 2 percent]]), 0)+ IFERROR((_xlfn.XLOOKUP(Table_Input_InorganicFertiliser_Brands[[#This Row],[Ingredient 3]],Table_Fertiliser_ChemicalCompounds[Fertiliser type f],Table_Fertiliser_ChemicalCompounds[FNinorganic f])*Table_Input_InorganicFertiliser_Brands[[#This Row],[Ingredient 3 percent]]), 0)+ IFERROR((_xlfn.XLOOKUP(Table_Input_InorganicFertiliser_Brands[[#This Row],[Ingredient 4]],Table_Fertiliser_ChemicalCompounds[Fertiliser type f],Table_Fertiliser_ChemicalCompounds[FNinorganic f])*Table_Input_InorganicFertiliser_Brands[[#This Row],[Ingredient 4 percent]]), 0)+ IFERROR((_xlfn.XLOOKUP(Table_Input_InorganicFertiliser_Brands[[#This Row],[Ingredient 5]],Table_Fertiliser_ChemicalCompounds[Fertiliser type f],Table_Fertiliser_ChemicalCompounds[FNinorganic f])*Table_Input_InorganicFertiliser_Brands[[#This Row],[Ingredient 5 percent]]), 0)+ IFERROR((_xlfn.XLOOKUP(Table_Input_InorganicFertiliser_Brands[[#This Row],[Ingredient 6]],Table_Fertiliser_ChemicalCompounds[Fertiliser type f],Table_Fertiliser_ChemicalCompounds[FNinorganic f])*Table_Input_InorganicFertiliser_Brands[[#This Row],[Ingredient 6 percent]]), 0) -> 0.23999994 | W13: {=IFERROR(Fertiliser_InputFunctions.Fertiliser_FertiliserProductLookup(Table_Input_InorganicFertiliser_Brands[[#This Row],[Product (select)]], "N declared", FertiliserProducts[#Data], FertiliserProducts[Product], FertiliserProducts[#Headers])*0.01, 0)} -> 0.24 | X13: =(Table_Input_InorganicFertiliser_Brands[[#This Row],[Amount applied per hectare]]*Table_Input_InorganicFertiliser_Brands[[#This Row],[Density]])*(IF(Table_Input_InorganicFertiliser_Brands[[#This Row],[% N (declared)]], Table_Input_InorganicFertiliser_Brands[[#This Row],[% N (declared)]], Table_Input_InorganicFertiliser_Brands[[#This Row],[% N (Ingredients)]])) -> 24 | Y13: =IFERROR(_xlfn.XLOOKUP(Table_Input_InorganicFertiliser_Brands[[#This Row],[Product (select)]],FertiliserProducts[Product],FertiliserProducts[Urea source]), "") | Z13: =IFERROR(_xlfn.XLOOKUP(Table_Input_InorganicFertiliser_Brands[[#This Row],[Product (select)]],FertiliserProducts[Product],FertiliserProducts[Ammonia source]), "")
